<?xml version="1.0" encoding="utf-8"?>
<sdf version="1.5">
  <model name="Tank8">
    <pose>0 0 -0.0704849999999997 0 0 0</pose>
    <plugin name="clock" filename="libclock.so">
      <topic>/gazebo/frc/time</topic>
    </plugin>
    <link name="Frame">
      <gravity>1</gravity>
      <self_collide>0</self_collide>
      <pose>-0.413960078812764 -0.247076724643536 0.0412395950821988 1.5707963267949 0 1.5707963267949</pose>
      <must_be_base_link>1</must_be_base_link>
      <velocity_decay>
        <linear>0</linear>
        <angular>0</angular>
      </velocity_decay>
      <inertial>
        <mass>5.61517972657168</mass>
        <pose>0 0 0 0 0 0</pose>
        <inertia>
          <ixx>0.53568702779828</ixx>
          <ixy>0.00141729760900026</ixy>
          <ixz>0.0015637144490817</ixz>
          <iyy>0.763662622156092</iyy>
          <iyz>2.755962000102E-05</iyz>
          <izz>0.237195905553374</izz>
        </inertia>
      </inertial>
      <collision name="Frame_collision">
        <pose>-0.580323559618613 -0.679492246788705 -0.97319598714996 0 0 0</pose>
        <geometry>
          <mesh>
            <scale>1 1 1</scale>
            <uri>model://Tank8/meshes/Frame_col.STL</uri>
          </mesh>
        </geometry>
        <surface>
          <contact>
            <ode />
          </contact>
          <friction>
            <ode>
              <mu>0</mu>
              <mu2>0</mu2>
            </ode>
          </friction>
        </surface>
      </collision>
      <visual name="Frame_visual">
        <pose>-0.580323559618613 -0.679492246788705 -0.97319598714996 0 0 0</pose>
        <material>
          <ambient>0 0.250980392156863 1 1</ambient>
          <diffuse>0 0.250980392156863 1 1</diffuse>
        </material>
        <geometry>
          <mesh>
            <scale>1 1 1</scale>
            <uri>model://Tank8/meshes/Frame.STL</uri>
          </mesh>
        </geometry>
      </visual>
      <sensor name="FrameCamera" type="camera">
        <visualize>1</visualize>
        <always_on>1</always_on>
        <update_rate>100</update_rate>
        <pose>-0.000573275356463565 0.3 -0.392489921187236 0 1.5707963267949 1.5707963267949</pose>
        <camera name="Framecamera">
          <horizontal_fov>1.05</horizontal_fov>
          <image>
            <width>320</width>
            <height>240</height>
          </image>
          <clip>
            <near>0.1</near>
            <far>100</far>
          </clip>
          <save enabled="true">
              <path>/tmp/shooter-camera</path>
          </save>
        </camera>
      </sensor>
    </link>
    <link name="L1Wheel">
      <gravity>1</gravity>
      <self_collide>0</self_collide>
      <pose>-0.723265 -0.537083 0.0476250000000001 1.5707963267949 0 1.5707963267949</pose>
      <must_be_base_link>0</must_be_base_link>
      <velocity_decay>
        <linear>0</linear>
        <angular>0</angular>
      </velocity_decay>
      <inertial>
        <mass>1.3252011832177</mass>
        <pose>0 0 0 0 0 0</pose>
        <inertia>
          <ixx>0.00636122013463714</ixx>
          <ixy>1.36307392078681E-19</ixy>
          <ixz>3.70169017252915E-19</ixz>
          <iyy>0.00340889332640425</iyy>
          <iyz>2.81970421070718E-19</iyz>
          <izz>0.00340889332640425</izz>
        </inertia>
      </inertial>
      <collision name="L1Wheel_collision">
        <pose>-0.29031728426215 -0.685877651706507 -0.663891065962725 0 0 0</pose>
        <geometry>
          <mesh>
            <scale>1 1 1</scale>
            <uri>model://Tank8/meshes/L1Wheel_col.STL</uri>
          </mesh>
        </geometry>
        <surface>
		  <contact>
			<ode>
			  <max_vel>0.1</max_vel>
			  <soft_cfm>0.8</soft_cfm>
			  <soft_erp>0.8</soft_erp>
			  <kd>200</kd>
			  <kp>50000</kp>
			  <min_depth>0.0001</min_depth>
			</ode>
		  </contact>
          <friction>
            <ode>
              <mu>2</mu>
              <mu2>2</mu2>
            </ode>
          </friction>
        </surface>
      </collision>
      <visual name="L1Wheel_visual">
        <pose>-0.29031728426215 -0.685877651706507 -0.663891065962725 0 0 0</pose>
        <material>
          <ambient>0.501960784313725 0.501960784313725 0.501960784313725 1</ambient>
          <diffuse>0.501960784313725 0.501960784313725 0.501960784313725 1</diffuse>
        </material>
        <geometry>
          <mesh>
            <scale>1 1 1</scale>
            <uri>model://Tank8/meshes/L1Wheel.STL</uri>
          </mesh>
        </geometry>
      </visual>
    </link>
    <joint name="Frame-L1Wheel" type="revolute">
      <parent>Frame</parent>
      <child>L1Wheel</child>
      <pose>0 -1.11022302462516E-16 0 0 0 0</pose>
      <axis>
        <xyz>-1 0 0</xyz>
        <dynamics>
          <damping>2</damping>
          <friction>1</friction>
        </dynamics>
        <limit>
          <effort>50</effort>
        </limit>
      </axis>
    </joint>
    <link name="L2Wheel">
      <gravity>1</gravity>
      <self_collide>0</self_collide>
      <pose>-0.516255 -0.537083 0.0317500000000002 1.5707963267949 0 1.5707963267949</pose>
      <must_be_base_link>0</must_be_base_link>
      <velocity_decay>
        <linear>0</linear>
        <angular>0</angular>
      </velocity_decay>
      <inertial>
        <mass>1.3252011832177</mass>
        <pose>0 0 0 0 0 0</pose>
        <inertia>
          <ixx>0.00636122013463714</ixx>
          <ixy>5.85274319284212E-36</ixy>
          <ixz>1.07916954507332E-37</ixz>
          <iyy>0.00340889332640425</iyy>
          <iyz>1.20770044092795E-35</iyz>
          <izz>0.00340889332640425</izz>
        </inertia>
      </inertial>
      <collision name="L2Wheel_collision">
        <pose>-0.29031728426215 -0.670002651706507 -0.870901065962725 0 0 0</pose>
        <geometry>
          <mesh>
            <scale>1 1 1</scale>
            <uri>model://Tank8/meshes/L2Wheel_col.STL</uri>
          </mesh>
        </geometry>
        <surface>
		  <contact>
			<ode>
			  <max_vel>0.1</max_vel>
			  <soft_cfm>0.8</soft_cfm>
			  <soft_erp>0.8</soft_erp>
			  <kd>200</kd>
			  <kp>50000</kp>
			  <min_depth>0.0001</min_depth>
			</ode>
		  </contact>
          <friction>
            <ode>
              <mu>2</mu>
              <mu2>2</mu2>
            </ode>
          </friction>
        </surface>
      </collision>
      <visual name="L2Wheel_visual">
        <pose>-0.29031728426215 -0.670002651706507 -0.870901065962725 0 0 0</pose>
        <material>
          <ambient>1 0.501960784313725 0.501960784313725 1</ambient>
          <diffuse>1 0.501960784313725 0.501960784313725 1</diffuse>
        </material>
        <geometry>
          <mesh>
            <scale>1 1 1</scale>
            <uri>model://Tank8/meshes/L2Wheel.STL</uri>
          </mesh>
        </geometry>
      </visual>
    </link>
    <joint name="Frame-L2Wheel" type="revolute">
      <parent>Frame</parent>
      <child>L2Wheel</child>
      <pose>0 0 -1.11022302462516E-16 0 0 0</pose>
      <axis>
        <xyz>-1 0 0</xyz>
        <dynamics>
          <damping>2</damping>
          <friction>1</friction>
        </dynamics>
        <limit>
          <effort>50</effort>
        </limit>
      </axis>
    </joint>
    <link name="L3Wheel">
      <gravity>1</gravity>
      <self_collide>0</self_collide>
      <pose>-0.309245 -0.537083 0.0317500000000002 1.5707963267949 0 1.5707963267949</pose>
      <must_be_base_link>0</must_be_base_link>
      <velocity_decay>
        <linear>0</linear>
        <angular>0</angular>
      </velocity_decay>
      <inertial>
        <mass>1.3252011832177</mass>
        <pose>0 0 0 0 0 0</pose>
        <inertia>
          <ixx>0.00636122013463714</ixx>
          <ixy>7.97906990264509E-20</ixy>
          <ixz>1.02386629412868E-19</ixz>
          <iyy>0.00340889332640425</iyy>
          <iyz>3.68262106610134E-19</iyz>
          <izz>0.00340889332640425</izz>
        </inertia>
      </inertial>
      <collision name="L3Wheel_collision">
        <pose>-0.29031728426215 -0.670002651706507 -1.07791106596272 0 0 0</pose>
        <geometry>
          <mesh>
            <scale>1 1 1</scale>
            <uri>model://Tank8/meshes/L3Wheel_col.STL</uri>
          </mesh>
        </geometry>
        <surface>
		  <contact>
			<ode>
			  <max_vel>0.1</max_vel>
			  <soft_cfm>0.8</soft_cfm>
			  <soft_erp>0.8</soft_erp>
			  <kd>200</kd>
			  <kp>50000</kp>
			  <min_depth>0.0001</min_depth>
			</ode>
		  </contact>
          <friction>
            <ode>
              <mu>2</mu>
              <mu2>2</mu2>
            </ode>
          </friction>
        </surface>
      </collision>
      <visual name="L3Wheel_visual">
        <pose>-0.29031728426215 -0.670002651706507 -1.07791106596272 0 0 0</pose>
        <material>
          <ambient>0.501960784313725 0.501960784313725 0.501960784313725 1</ambient>
          <diffuse>0.501960784313725 0.501960784313725 0.501960784313725 1</diffuse>
        </material>
        <geometry>
          <mesh>
            <scale>1 1 1</scale>
            <uri>model://Tank8/meshes/L3Wheel.STL</uri>
          </mesh>
        </geometry>
      </visual>
    </link>
    <joint name="Frame-L3Wheel" type="revolute">
      <parent>Frame</parent>
      <child>L3Wheel</child>
      <pose>0 0 0 0 0 0</pose>
      <axis>
        <xyz>-1 0 0</xyz>
        <dynamics>
          <damping>2</damping>
          <friction>1</friction>
        </dynamics>
        <limit>
          <effort>50</effort>
        </limit>
      </axis>
    </joint>
    <link name="L4Wheel">
      <gravity>1</gravity>
      <self_collide>0</self_collide>
      <pose>-0.102235 -0.537083 0.0476250000000003 1.5707963267949 0 1.5707963267949</pose>
      <must_be_base_link>0</must_be_base_link>
      <velocity_decay>
        <linear>0</linear>
        <angular>0</angular>
      </velocity_decay>
      <inertial>
        <mass>1.3252011832177</mass>
        <pose>0 0 0 0 0 0</pose>
        <inertia>
          <ixx>0.00636122013463714</ixx>
          <ixy>6.86348456741288E-20</ixy>
          <ixz>1.38576977777865E-19</ixz>
          <iyy>0.00340889332640425</iyy>
          <iyz>1.89654714074048E-33</iyz>
          <izz>0.00340889332640425</izz>
        </inertia>
      </inertial>
      <collision name="L4Wheel_collision">
        <pose>-0.29031728426215 -0.685877651706507 -1.28492106596272 0 0 0</pose>
        <geometry>
          <mesh>
            <scale>1 1 1</scale>
            <uri>model://Tank8/meshes/L4Wheel_col.STL</uri>
          </mesh>
        </geometry>
        <surface>
		  <contact>
			<ode>
			  <max_vel>0.1</max_vel>
			  <soft_cfm>0.8</soft_cfm>
			  <soft_erp>0.8</soft_erp>
			  <kd>200</kd>
			  <kp>50000</kp>
			  <min_depth>0.0001</min_depth>
			</ode>
		  </contact>
          <friction>
            <ode>
              <mu>2</mu>
              <mu2>2</mu2>
            </ode>
          </friction>
        </surface>
      </collision>
      <visual name="L4Wheel_visual">
        <pose>-0.29031728426215 -0.685877651706507 -1.28492106596272 0 0 0</pose>
        <material>
          <ambient>0.501960784313725 0.501960784313725 0.501960784313725 1</ambient>
          <diffuse>0.501960784313725 0.501960784313725 0.501960784313725 1</diffuse>
        </material>
        <geometry>
          <mesh>
            <scale>1 1 1</scale>
            <uri>model://Tank8/meshes/L4Wheel.STL</uri>
          </mesh>
        </geometry>
      </visual>
    </link>
    <joint name="Frame-L4Wheel" type="revolute">
      <parent>Frame</parent>
      <child>L4Wheel</child>
      <pose>0 0 0 0 0 0</pose>
      <axis>
        <xyz>-1 0 0</xyz>
        <dynamics>
          <damping>2</damping>
          <friction>1</friction>
        </dynamics>
        <limit>
          <effort>50</effort>
        </limit>
      </axis>
    </joint>
    <link name="R1Wheel">
      <gravity>1</gravity>
      <self_collide>0</self_collide>
      <pose>-0.723265 0.0417830000000001 0.047625 1.5707963267949 0 1.5707963267949</pose>
      <must_be_base_link>0</must_be_base_link>
      <velocity_decay>
        <linear>0</linear>
        <angular>0</angular>
      </velocity_decay>
      <inertial>
        <mass>1.3252011832177</mass>
        <pose>0 0 0 0 0 0</pose>
        <inertia>
          <ixx>0.00636122013463714</ixx>
          <ixy>1.12324333274603E-21</ixy>
          <ixz>4.49297333098413E-21</ixz>
          <iyy>0.00340889332640425</iyy>
          <iyz>1.02505983071404E-19</iyz>
          <izz>0.00340889332640425</izz>
        </inertia>
      </inertial>
      <collision name="R1Wheel_collision">
        <pose>-0.86918328426215 -0.685877651706507 -0.663891065962725 0 0 0</pose>
        <geometry>
          <mesh>
            <scale>1 1 1</scale>
            <uri>model://Tank8/meshes/R1Wheel_col.STL</uri>
          </mesh>
        </geometry>
        <surface>
		  <contact>
			<ode>
			  <max_vel>0.1</max_vel>
			  <soft_cfm>0.8</soft_cfm>
			  <soft_erp>0.8</soft_erp>
			  <kd>200</kd>
			  <kp>50000</kp>
			  <min_depth>0.0001</min_depth>
			</ode>
		  </contact>
          <friction>
            <ode>
              <mu>2</mu>
              <mu2>2</mu2>
            </ode>
          </friction>
        </surface>
      </collision>
      <visual name="R1Wheel_visual">
        <pose>-0.86918328426215 -0.685877651706507 -0.663891065962725 0 0 0</pose>
        <material>
          <ambient>0.501960784313725 0.501960784313725 0.501960784313725 1</ambient>
          <diffuse>0.501960784313725 0.501960784313725 0.501960784313725 1</diffuse>
        </material>
        <geometry>
          <mesh>
            <scale>1 1 1</scale>
            <uri>model://Tank8/meshes/R1Wheel.STL</uri>
          </mesh>
        </geometry>
      </visual>
    </link>
    <joint name="Frame-R1Wheel" type="revolute">
      <parent>Frame</parent>
      <child>R1Wheel</child>
      <pose>-1.11022302462516E-16 0 0 0 0 0</pose>
      <axis>
        <xyz>1 0 0</xyz>
        <dynamics>
          <damping>2</damping>
          <friction>1</friction>
        </dynamics>
        <limit>
          <effort>50</effort>
        </limit>
      </axis>
    </joint>
    <link name="R2Wheel">
      <gravity>1</gravity>
      <self_collide>0</self_collide>
      <pose>-0.516255 0.041783 0.0317500000000002 1.5707963267949 0 1.5707963267949</pose>
      <must_be_base_link>0</must_be_base_link>
      <velocity_decay>
        <linear>0</linear>
        <angular>0</angular>
      </velocity_decay>
      <inertial>
        <mass>1.3252011832177</mass>
        <pose>0 0 0 0 0 0</pose>
        <inertia>
          <ixx>0.00636122013463714</ixx>
          <ixy>2.1452948708883E-20</ixy>
          <ixz>4.16955197352756E-21</ixz>
          <iyy>0.00340889332640425</iyy>
          <iyz>4.95999384415892E-20</iyz>
          <izz>0.00340889332640425</izz>
        </inertia>
      </inertial>
      <collision name="R2Wheel_collision">
        <pose>-0.86918328426215 -0.670002651706507 -0.870901065962725 0 0 0</pose>
        <geometry>
          <mesh>
            <scale>1 1 1</scale>
            <uri>model://Tank8/meshes/R2Wheel_col.STL</uri>
          </mesh>
        </geometry>
        <surface>
		  <contact>
			<ode>
			  <max_vel>0.1</max_vel>
			  <soft_cfm>0.8</soft_cfm>
			  <soft_erp>0.8</soft_erp>
			  <kd>200</kd>
			  <kp>50000</kp>
			  <min_depth>0.0001</min_depth>
			</ode>
		  </contact>
          <friction>
            <ode>
              <mu>2</mu>
              <mu2>2</mu2>
            </ode>
          </friction>
        </surface>
      </collision>
      <visual name="R2Wheel_visual">
        <pose>-0.86918328426215 -0.670002651706507 -0.870901065962725 0 0 0</pose>
        <material>
          <ambient>0.501960784313725 1 0.501960784313725 1</ambient>
          <diffuse>0.501960784313725 1 0.501960784313725 1</diffuse>
        </material>
        <geometry>
          <mesh>
            <scale>1 1 1</scale>
            <uri>model://Tank8/meshes/R2Wheel.STL</uri>
          </mesh>
        </geometry>
      </visual>
    </link>
    <joint name="Frame-R2Wheel" type="revolute">
      <parent>Frame</parent>
      <child>R2Wheel</child>
      <pose>0 0 -1.11022302462516E-16 0 0 0</pose>
      <axis>
        <xyz>1 0 0</xyz>
        <dynamics>
          <damping>2</damping>
          <friction>1</friction>
        </dynamics>
        <limit>
          <effort>50</effort>
        </limit>
      </axis>
    </joint>
    <link name="R3Wheel">
      <gravity>1</gravity>
      <self_collide>0</self_collide>
      <pose>-0.309245 0.0417829999999999 0.0317500000000002 1.5707963267949 0 1.5707963267949</pose>
      <must_be_base_link>0</must_be_base_link>
      <velocity_decay>
        <linear>0</linear>
        <angular>0</angular>
      </velocity_decay>
      <inertial>
        <mass>1.3252011832177</mass>
        <pose>0 0 0 0 0 0</pose>
        <inertia>
          <ixx>0.00636122013463714</ixx>
          <ixy>7.83061066257235E-20</ixy>
          <ixz>2.36683416542921E-21</ixz>
          <iyy>0.00340889332640425</iyy>
          <iyz>1.60820614889872E-20</iyz>
          <izz>0.00340889332640425</izz>
        </inertia>
      </inertial>
      <collision name="R3Wheel_collision">
        <pose>-0.86918328426215 -0.670002651706507 -1.07791106596272 0 0 0</pose>
        <geometry>
          <mesh>
            <scale>1 1 1</scale>
            <uri>model://Tank8/meshes/R3Wheel_col.STL</uri>
          </mesh>
        </geometry>
        <surface>
		  <contact>
			<ode>
			  <max_vel>0.1</max_vel>
			  <soft_cfm>0.8</soft_cfm>
			  <soft_erp>0.8</soft_erp>
			  <kd>200</kd>
			  <kp>50000</kp>
			  <min_depth>0.0001</min_depth>
			</ode>
		  </contact>
          <friction>
            <ode>
              <mu>2</mu>
              <mu2>2</mu2>
            </ode>
          </friction>
        </surface>
      </collision>
      <visual name="R3Wheel_visual">
        <pose>-0.86918328426215 -0.670002651706507 -1.07791106596272 0 0 0</pose>
        <material>
          <ambient>0.501960784313725 0.501960784313725 0.501960784313725 1</ambient>
          <diffuse>0.501960784313725 0.501960784313725 0.501960784313725 1</diffuse>
        </material>
        <geometry>
          <mesh>
            <scale>1 1 1</scale>
            <uri>model://Tank8/meshes/R3Wheel.STL</uri>
          </mesh>
        </geometry>
      </visual>
    </link>
    <joint name="Frame-R3Wheel" type="revolute">
      <parent>Frame</parent>
      <child>R3Wheel</child>
      <pose>0 0 0 0 0 0</pose>
      <axis>
        <xyz>1 0 0</xyz>
        <dynamics>
          <damping>2</damping>
          <friction>1</friction>
        </dynamics>
        <limit>
          <effort>50</effort>
        </limit>
      </axis>
    </joint>
    <link name="R4Wheel">
      <gravity>1</gravity>
      <self_collide>0</self_collide>
      <pose>-0.102235 0.0417829999999999 0.0476250000000003 1.5707963267949 0 1.5707963267949</pose>
      <must_be_base_link>0</must_be_base_link>
      <velocity_decay>
        <linear>0</linear>
        <angular>0</angular>
      </velocity_decay>
      <inertial>
        <mass>1.3252011832177</mass>
        <pose>0 0 0 0 0 0</pose>
        <inertia>
          <ixx>0.00636122013463714</ixx>
          <ixy>1.28370666599545E-21</ixy>
          <ixz>6.41853332997747E-22</ixz>
          <iyy>0.00340889332640425</iyy>
          <iyz>5.60756601329572E-19</iyz>
          <izz>0.00340889332640425</izz>
        </inertia>
      </inertial>
      <collision name="R4Wheel_collision">
        <pose>-0.86918328426215 -0.685877651706507 -1.28492106596272 0 0 0</pose>
        <geometry>
          <mesh>
            <scale>1 1 1</scale>
            <uri>model://Tank8/meshes/R4Wheel_col.STL</uri>
          </mesh>
        </geometry>
        <surface>
		  <contact>
			<ode>
			  <max_vel>0.1</max_vel>
			  <soft_cfm>0.8</soft_cfm>
			  <soft_erp>0.8</soft_erp>
			  <kd>200</kd>
			  <kp>50000</kp>
			  <min_depth>0.0001</min_depth>
			</ode>
		  </contact>
          <friction>
            <ode>
              <mu>2</mu>
              <mu2>2</mu2>
            </ode>
          </friction>
        </surface>
      </collision>
      <visual name="R4Wheel_visual">
        <pose>-0.86918328426215 -0.685877651706507 -1.28492106596272 0 0 0</pose>
        <material>
          <ambient>0.501960784313725 0.501960784313725 0.501960784313725 1</ambient>
          <diffuse>0.501960784313725 0.501960784313725 0.501960784313725 1</diffuse>
        </material>
        <geometry>
          <mesh>
            <scale>1 1 1</scale>
            <uri>model://Tank8/meshes/R4Wheel.STL</uri>
          </mesh>
        </geometry>
      </visual>
    </link>
    <joint name="Frame-R4Wheel" type="revolute">
      <parent>Frame</parent>
      <child>R4Wheel</child>
      <pose>-1.11022302462516E-16 -1.11022302462516E-16 0 0 0 0</pose>
      <axis>
        <xyz>1 0 0</xyz>
        <dynamics>
          <damping>2</damping>
          <friction>1</friction>
        </dynamics>
        <limit>
          <effort>50</effort>
        </limit>
      </axis>
    </joint>
    <plugin name="Frame-L1Wheel_motor" filename="libdc_motor.so">
      <joint>Frame-L1Wheel</joint>
      <topic>/gazebo/frc/simulator/pwm/2</topic>
      <multiplier>25</multiplier>
    </plugin>
    <plugin name="Frame-L2Wheel_motor" filename="libdc_motor.so">
      <joint>Frame-L2Wheel</joint>
      <topic>/gazebo/frc/simulator/pwm/2</topic>
      <multiplier>25</multiplier>
    </plugin>
    <plugin name="Frame-L2Wheel_encoder" filename="libencoder.so">
      <joint>Frame-L2Wheel</joint>
       <topic>/gazebo/frc/simulator/dio/3/4</topic>
      <units>degrees</units>
    </plugin>
    <plugin name="Frame-L3Wheel_motor" filename="libdc_motor.so">
      <joint>Frame-L3Wheel</joint>
      <topic>/gazebo/frc/simulator/pwm/2</topic>
      <multiplier>25</multiplier>
    </plugin>
    <plugin name="Frame-L4Wheel_motor" filename="libdc_motor.so">
      <joint>Frame-L4Wheel</joint>
      <topic>/gazebo/frc/simulator/pwm/2</topic>
      <multiplier>25</multiplier>
    </plugin>
    <plugin name="Frame-R1Wheel_motor" filename="libdc_motor.so">
      <joint>Frame-R1Wheel</joint>
      <topic>/gazebo/frc/simulator/pwm/4</topic>
      <multiplier>25</multiplier>
    </plugin>
    <plugin name="Frame-R2Wheel_motor" filename="libdc_motor.so">
      <joint>Frame-R2Wheel</joint>
      <topic>/gazebo/frc/simulator/pwm/4</topic>
      <multiplier>25</multiplier>
    </plugin>
    <plugin name="Frame-R2Wheel_encoder" filename="libencoder.so">
      <joint>Frame-R2Wheel</joint>
       <topic>/gazebo/frc/simulator/dio/7/8</topic>
      <units>degrees</units>
    </plugin>
    <plugin name="Frame-R3Wheel_motor" filename="libdc_motor.so">
      <joint>Frame-R3Wheel</joint>
      <topic>/gazebo/frc/simulator/pwm/4</topic>
      <multiplier>25</multiplier>
    </plugin>
    <plugin name="Frame-R4Wheel_motor" filename="libdc_motor.so">
      <joint>Frame-R4Wheel</joint>
      <topic>/gazebo/frc/simulator/pwm/4</topic>
      <multiplier>25</multiplier>
    </plugin>
  </model>
</sdf>
