<?xml version="1.0" encoding="utf-8"?>
<sdf version="1.6">
  <model name="SimBot2019">
    <pose>0 0 0.12446 0 0 0</pose>
    <plugin name="clock" filename="libgz_clock.so">
      <topic>/gazebo/frc/time</topic>
    </plugin>
    <link name="Frame">
      <gravity>1</gravity>
      <self_collide>0</self_collide>
      <pose>-0.361971005219412 9.73002743968874E-05 0.000203773655997785 -1.5707963267949 0 1.5707963267949</pose>
      <must_be_base_link>1</must_be_base_link>
      <velocity_decay>
        <linear>0</linear>
        <angular>0</angular>
      </velocity_decay>
      <inertial>
        <mass>20.54775337549655</mass>
        <pose>0 0 0 0 0 0</pose>
        <inertia>
          <ixx>0.185600502507156</ixx>
          <ixy>4.48948889772195E-06</ixy>
          <ixz>3.17811232261817E-06</ixz>
          <iyy>0.407101018435186</iyy>
          <iyz>0.000264509089000804</iyz>
          <izz>0.221550649644869</izz>
        </inertia>
      </inertial>
      <collision name="Frame_collision">
        <pose>-9.73002743968071E-05 0.000203773655997708 0.0444290041805068 0 0 0</pose>
        <geometry>
          <mesh>
            <scale>1 1 1</scale>
            <uri>model://SimBot2019/meshes/Frame_col.STL</uri>
          </mesh>
        </geometry>
        <surface>
          <contact>
            <ode />
          </contact>
          <friction>
            <ode>
              <mu>1</mu>
              <mu2>1</mu2>
            </ode>
          </friction>
        </surface>
      </collision>
      <visual name="Frame_visual">
        <pose>-9.73002743968071E-05 0.000203773655997708 0.0444290041805068 0 0 0</pose>
        <material>
          <ambient>0.501960784313725 0.501960784313725 0.501960784313725 1</ambient>
          <diffuse>0.501960784313725 0.501960784313725 0.501960784313725 1</diffuse>
        </material>
        <geometry>
          <mesh>
            <scale>1 1 1</scale>
            <uri>model://SimBot2019/meshes/Frame.STL</uri>
          </mesh>
        </geometry>
      </visual>
    </link>
    <link name="LFWheel">
      <gravity>1</gravity>
      <self_collide>0</self_collide>
      <pose>-0.673096893872116 -0.303262709940692 0.00169528357489551 -1.5707963267949 0 1.5707963267949</pose>
      <must_be_base_link>0</must_be_base_link>
      <velocity_decay>
        <linear>0</linear>
        <angular>0</angular>
      </velocity_decay>
      <inertial>
        <mass>0.255325203825891</mass>
        <pose>0 0 0 0 0 0</pose>
        <inertia>
          <ixx>0</ixx>
          <ixy>0</ixy>
          <ixz>0</ixz>
          <iyy>0</iyy>
          <iyz>0</iyz>
          <izz>0</izz>
        </inertia>
      </inertial>
      <collision name="LFWheel_collision">
        <pose>0.303262709940693 0.00169528357489536 -0.266696884472198 0 0 0</pose>
        <geometry>
          <mesh>
            <scale>1 1 1</scale>
            <uri>model://SimBot2019/meshes/LFWheel_col.STL</uri>
          </mesh>
        </geometry>
        <surface>
          <contact>
            <ode />
          </contact>
          <friction>
            <ode>
              <mu>1</mu>
              <mu2>1</mu2>
            </ode>
          </friction>
        </surface>
      </collision>
      <visual name="LFWheel_visual">
        <pose>0.303262709940693 0.00169528357489536 -0.266696884472198 0 0 0</pose>
        <material>
          <ambient>0.501960784313725 0.501960784313725 0.501960784313725 1</ambient>
          <diffuse>0.501960784313725 0.501960784313725 0.501960784313725 1</diffuse>
        </material>
        <geometry>
          <mesh>
            <scale>1 1 1</scale>
            <uri>model://SimBot2019/meshes/LFWheel.STL</uri>
          </mesh>
        </geometry>
      </visual>
    </link>
    <joint name="Frame-LFWheel" type="revolute">
      <parent>Frame</parent>
      <child>LFWheel</child>
      <pose>0 4.42835748985051E-05 -1.22287001208532E-06 0 0 3.14159265358979</pose>
      <axis>
        <xyz>-1 1.22460635382238E-16 0</xyz>
        <dynamics>
          <damping>1</damping>
          <friction>1</friction>
        </dynamics>
        <limit>
          <effort>50</effort>
        </limit>
      </axis>
    </joint>
    <link name="LCWheel">
      <gravity>1</gravity>
      <self_collide>0</self_collide>
      <pose>-0.406431076654579 -0.303368868926879 -0.0036834982409925 -1.5707963267949 0 1.5707963267949</pose>
      <must_be_base_link>0</must_be_base_link>
      <velocity_decay>
        <linear>0</linear>
        <angular>0</angular>
      </velocity_decay>
      <inertial>
        <mass>0.255325203825891</mass>
        <pose>0 0 0 0 0 0</pose>
        <inertia>
          <ixx>0</ixx>
          <ixy>0</ixy>
          <ixz>0</ixz>
          <iyy>0</iyy>
          <iyz>0</iyz>
          <izz>0</izz>
        </inertia>
      </inertial>
      <collision name="LCWheel_collision">
        <pose>0.30336886892688 -0.00368349824099259 -3.10672546609658E-05 0 0 0</pose>
        <geometry>
          <mesh>
            <scale>1 1 1</scale>
            <uri>model://SimBot2019/meshes/LCWheel_col.STL</uri>
          </mesh>
        </geometry>
        <surface>
          <contact>
            <ode />
          </contact>
          <friction>
            <ode>
              <mu>1</mu>
              <mu2>1</mu2>
            </ode>
          </friction>
        </surface>
      </collision>
      <visual name="LCWheel_visual">
        <pose>0.30336886892688 -0.00368349824099259 -3.10672546609658E-05 0 0 0</pose>
        <material>
          <ambient>0.501960784313725 0.501960784313725 0.501960784313725 1</ambient>
          <diffuse>0.501960784313725 0.501960784313725 0.501960784313725 1</diffuse>
        </material>
        <geometry>
          <mesh>
            <scale>1 1 1</scale>
            <uri>model://SimBot2019/meshes/LCWheel.STL</uri>
          </mesh>
        </geometry>
      </visual>
    </link>
    <joint name="Frame-LCWheel" type="revolute">
      <parent>Frame</parent>
      <child>LCWheel</child>
      <pose>-4.44089209850063E-16 4.1069653700849E-05 1.65975582725047E-05 0 0 0</pose>
      <axis>
        <xyz>1 0 0</xyz>
        <dynamics>
          <damping>1</damping>
          <friction>1</friction>
        </dynamics>
        <limit>
          <effort>50</effort>
        </limit>
      </axis>
    </joint>
    <link name="LBWheel">
      <gravity>1</gravity>
      <self_collide>0</self_collide>
      <pose>-0.139681443305567 -0.303262709940693 0.0016889037946457 -1.5707963267949 0 1.5707963267949</pose>
      <must_be_base_link>0</must_be_base_link>
      <velocity_decay>
        <linear>0</linear>
        <angular>0</angular>
      </velocity_decay>
      <inertial>
        <mass>0.255325203825891</mass>
        <pose>0 0 0 0 0 0</pose>
        <inertia>
          <ixx>0</ixx>
          <ixy>0</ixy>
          <ixz>0</ixz>
          <iyy>0</iyy>
          <iyz>0</iyz>
          <izz>0</izz>
        </inertia>
      </inertial>
      <collision name="LBWheel_collision">
        <pose>0.303262709940693 0.00168890379464568 0.266718566094352 0 0 0</pose>
        <geometry>
          <mesh>
            <scale>1 1 1</scale>
            <uri>model://SimBot2019/meshes/LBWheel_col.STL</uri>
          </mesh>
        </geometry>
        <surface>
          <contact>
            <ode />
          </contact>
          <friction>
            <ode>
              <mu>1</mu>
              <mu2>1</mu2>
            </ode>
          </friction>
        </surface>
      </collision>
      <visual name="LBWheel_visual">
        <pose>0.303262709940693 0.00168890379464568 0.266718566094352 0 0 0</pose>
        <material>
          <ambient>0.501960784313725 0.501960784313725 0.501960784313725 1</ambient>
          <diffuse>0.501960784313725 0.501960784313725 0.501960784313725 1</diffuse>
        </material>
        <geometry>
          <mesh>
            <scale>1 1 1</scale>
            <uri>model://SimBot2019/meshes/LBWheel.STL</uri>
          </mesh>
        </geometry>
      </visual>
    </link>
    <joint name="Frame-LBWheel" type="revolute">
      <parent>Frame</parent>
      <child>LBWheel</child>
      <pose>0 3.79037946424412E-05 2.29211444965904E-05 0 0 3.14159265358979</pose>
      <axis>
        <xyz>-1 1.22460635382238E-16 0</xyz>
        <dynamics>
          <damping>1</damping>
          <friction>1</friction>
        </dynamics>
        <limit>
          <effort>50</effort>
        </limit>
      </axis>
    </joint>
    <link name="RFWheel">
      <gravity>1</gravity>
      <self_collide>0</self_collide>
      <pose>-0.673098436426671 0.303262709940693 0.00169521560483079 -1.5707963267949 0 1.5707963267949</pose>
      <must_be_base_link>0</must_be_base_link>
      <velocity_decay>
        <linear>0</linear>
        <angular>0</angular>
      </velocity_decay>
      <inertial>
        <mass>0.255325203825891</mass>
        <pose>0 0 0 0 0 0</pose>
        <inertia>
          <ixx>0</ixx>
          <ixy>0</ixy>
          <ixz>0</ixz>
          <iyy>0</iyy>
          <iyz>0</iyz>
          <izz>0</izz>
        </inertia>
      </inertial>
      <collision name="RFWheel_collision">
        <pose>-0.303262709940693 0.00169521560483064 -0.266698427026753 0 0 0</pose>
        <geometry>
          <mesh>
            <scale>1 1 1</scale>
            <uri>model://SimBot2019/meshes/RFWheel_col.STL</uri>
          </mesh>
        </geometry>
        <surface>
          <contact>
            <ode />
          </contact>
          <friction>
            <ode>
              <mu>1</mu>
              <mu2>1</mu2>
            </ode>
          </friction>
        </surface>
      </collision>
      <visual name="RFWheel_visual">
        <pose>-0.303262709940693 0.00169521560483064 -0.266698427026753 0 0 0</pose>
        <material>
          <ambient>0.501960784313725 0.501960784313725 0.501960784313725 1</ambient>
          <diffuse>0.501960784313725 0.501960784313725 0.501960784313725 1</diffuse>
        </material>
        <geometry>
          <mesh>
            <scale>1 1 1</scale>
            <uri>model://SimBot2019/meshes/RFWheel.STL</uri>
          </mesh>
        </geometry>
      </visual>
    </link>
    <joint name="Frame-RFWheel" type="revolute">
      <parent>Frame</parent>
      <child>RFWheel</child>
      <pose>0 4.42156048225013E-05 -2.74578542491799E-06 0 0 0</pose>
      <axis>
        <xyz>1 0 0</xyz>
        <dynamics>
          <damping>1</damping>
          <friction>1</friction>
        </dynamics>
        <limit>
          <effort>50</effort>
        </limit>
      </axis>
    </joint>
    <link name="RCWheel">
      <gravity>1</gravity>
      <self_collide>0</self_collide>
      <pose>-0.405312671639957 0.303262709940693 -0.00385752270000407 -1.5707963267949 0 1.5707963267949</pose>
      <must_be_base_link>0</must_be_base_link>
      <velocity_decay>
        <linear>0</linear>
        <angular>0</angular>
      </velocity_decay>
      <inertial>
        <mass>0.255325203825891</mass>
        <pose>0 0 0 0 0 0</pose>
        <inertia>
          <ixx>0</ixx>
          <ixy>0</ixy>
          <ixz>0</ixz>
          <iyy>0</iyy>
          <iyz>0</iyz>
          <izz>0</izz>
        </inertia>
      </inertial>
      <collision name="RCWheel_collision">
        <pose>-0.303262709940693 -0.00385752270000416 0.0010873377599609 0 0 0</pose>
        <geometry>
          <mesh>
            <scale>1 1 1</scale>
            <uri>model://SimBot2019/meshes/RCWheel_col.STL</uri>
          </mesh>
        </geometry>
        <surface>
          <contact>
            <ode />
          </contact>
          <friction>
            <ode>
              <mu>1</mu>
              <mu2>1</mu2>
            </ode>
          </friction>
        </surface>
      </collision>
      <visual name="RCWheel_visual">
        <pose>-0.303262709940693 -0.00385752270000416 0.0010873377599609 0 0 0</pose>
        <material>
          <ambient>0.501960784313725 0.501960784313725 0.501960784313725 1</ambient>
          <diffuse>0.501960784313725 0.501960784313725 0.501960784313725 1</diffuse>
        </material>
        <geometry>
          <mesh>
            <scale>1 1 1</scale>
            <uri>model://SimBot2019/meshes/RCWheel.STL</uri>
          </mesh>
        </geometry>
      </visual>
    </link>
    <joint name="Frame-RCWheel" type="revolute">
      <parent>Frame</parent>
      <child>RCWheel</child>
      <pose>0 4.38148899713046E-05 -6.5487372136921E-06 0 0 3.14159265358979</pose>
      <axis>
        <xyz>-1 1.22460635382238E-16 0</xyz>
        <dynamics>
          <damping>1</damping>
          <friction>1</friction>
        </dynamics>
        <limit>
          <effort>50</effort>
        </limit>
      </axis>
    </joint>
    <link name="RBWheel">
      <gravity>1</gravity>
      <self_collide>0</self_collide>
      <pose>-0.139700620681278 0.303199220635695 0.00169514092477994 -1.5707963267949 0 1.5707963267949</pose>
      <must_be_base_link>0</must_be_base_link>
      <velocity_decay>
        <linear>0</linear>
        <angular>0</angular>
      </velocity_decay>
      <inertial>
        <mass>0.255325203825891</mass>
        <pose>0 0 0 0 0 0</pose>
        <inertia>
          <ixx>0</ixx>
          <ixy>0</ixy>
          <ixz>0</ixz>
          <iyy>0</iyy>
          <iyz>0</iyz>
          <izz>0</izz>
        </inertia>
      </inertial>
      <collision name="RBWheel_collision">
        <pose>-0.303199220635695 0.00169514092477991 0.26669938871864 0 0 0</pose>
        <geometry>
          <mesh>
            <scale>1 1 1</scale>
            <uri>model://SimBot2019/meshes/RBWheel_col.STL</uri>
          </mesh>
        </geometry>
        <surface>
          <contact>
            <ode />
          </contact>
          <friction>
            <ode>
              <mu>0</mu>
              <mu2>0</mu2>
            </ode>
          </friction>
        </surface>
      </collision>
      <visual name="RBWheel_visual">
        <pose>-0.303199220635695 0.00169514092477991 0.26669938871864 0 0 0</pose>
        <material>
          <ambient>0.501960784313725 0.501960784313725 0.501960784313725 1</ambient>
          <diffuse>0.501960784313725 0.501960784313725 0.501960784313725 1</diffuse>
        </material>
        <geometry>
          <mesh>
            <scale>1 1 1</scale>
            <uri>model://SimBot2019/meshes/RBWheel.STL</uri>
          </mesh>
        </geometry>
      </visual>
    </link>
    <joint name="Frame-RBWheel" type="revolute">
      <parent>Frame</parent>
      <child>RBWheel</child>
      <pose>5.55111512312578E-17 4.41409247766734E-05 3.74376878548022E-06 0 0 0</pose>
      <axis>
        <xyz>1 0 0</xyz>
        <dynamics>
          <damping>1</damping>
          <friction>1</friction>
        </dynamics>
        <limit>
          <effort>50</effort>
        </limit>
      </axis>
    </joint>
    <link name="Climber1">
      <gravity>1</gravity>
      <self_collide>0</self_collide>
      <pose>-0.371884162408801 1.75852174551724E-12 0.0532317217795126 -1.5707963267949 0 1.5707963267949</pose>
      <must_be_base_link>0</must_be_base_link>
      <velocity_decay>
        <linear>0</linear>
        <angular>0</angular>
      </velocity_decay>
      <inertial>
        <mass>1.8185029422411</mass>
        <pose>0 0 0 0 0 0</pose>
        <inertia>
          <ixx>0.00595096678677999</ixx>
          <ixy>3.64525677167254E-13</ixy>
          <ixz>6.31918562615796E-14</ixz>
          <iyy>0.0204470713571254</iyy>
          <iyz>0.000377882351492175</iyz>
          <izz>0.0148396566325775</izz>
        </inertia>
      </inertial>
      <collision name="Climber1_collision">
        <pose>-1.75843917064532E-12 0.0532317217795125 0.0345158469911177 0 0 0</pose>
        <geometry>
          <mesh>
            <scale>1 1 1</scale>
            <uri>model://SimBot2019/meshes/Climber1_col.STL</uri>
          </mesh>
        </geometry>
        <surface>
          <contact>
            <ode />
          </contact>
          <friction>
            <ode>
              <mu>0</mu>
              <mu2>0</mu2>
            </ode>
          </friction>
        </surface>
      </collision>
      <visual name="Climber1_visual">
        <pose>-1.75843917064532E-12 0.0532317217795125 0.0345158469911177 0 0 0</pose>
        <material>
          <ambient>0 0 1 1</ambient>
          <diffuse>0 0 1 1</diffuse>
        </material>
        <geometry>
          <mesh>
            <scale>1 1 1</scale>
            <uri>model://SimBot2019/meshes/Climber1.STL</uri>
          </mesh>
        </geometry>
      </visual>
    </link>
    <joint name="Frame-Climber1" type="revolute">
      <parent>Frame</parent>
      <child>Climber1</child>
      <pose>-1.75376235615409E-12 0.0119567217795125 -0.295684153008881 0 0 0</pose>
      <axis>
        <xyz>-1 0 0</xyz>
        <dynamics>
          <damping>1</damping>
          <friction>1</friction>
        </dynamics>
        <limit>
          <upper>2.5</upper>
          <lower>0</lower>
          <effort>200</effort>
        </limit>
      </axis>
    </joint>
    <link name="Climber2">
      <gravity>1</gravity>
      <self_collide>0</self_collide>
      <pose>-0.47089417267914 -0.00297142421941335 0.0460716635188657 -1.5707963267949 0 1.5707963267949</pose>
      <must_be_base_link>0</must_be_base_link>
      <velocity_decay>
        <linear>0</linear>
        <angular>0</angular>
      </velocity_decay>
      <inertial>
        <mass>0.790365756487698</mass>
        <pose>0 0 0 0 0 0</pose>
        <inertia>
          <ixx>0.00839975269474861</ixx>
          <ixy>1.30683226120096E-07</ixy>
          <ixz>4.1211402897892E-05</ixz>
          <iyy>0.0136860179616724</iyy>
          <iyz>0.000158154045892428</iyz>
          <izz>0.00529400442326679</izz>
        </inertia>
      </inertial>
      <collision name="Climber2_collision">
        <pose>0.00297142421941346 0.0460716635188656 -0.0644941632792219 0 0 0</pose>
        <geometry>
          <mesh>
            <scale>1 1 1</scale>
            <uri>model://SimBot2019/meshes/Climber2_col.STL</uri>
          </mesh>
        </geometry>
        <surface>
          <contact>
            <ode />
          </contact>
          <friction>
            <ode>
              <mu>1</mu>
              <mu2>1</mu2>
            </ode>
          </friction>
        </surface>
      </collision>
      <visual name="Climber2_visual">
        <pose>0.00297142421941346 0.0460716635188656 -0.0644941632792219 0 0 0</pose>
        <material>
          <ambient>0 0 0.501960784313725 1</ambient>
          <diffuse>0 0 0.501960784313725 1</diffuse>
        </material>
        <geometry>
          <mesh>
            <scale>1 1 1</scale>
            <uri>model://SimBot2019/meshes/Climber2.STL</uri>
          </mesh>
        </geometry>
      </visual>
    </link>
    <joint name="Climber1-Climber2" type="revolute">
      <parent>Climber1</parent>
      <child>Climber2</child>
      <pose>1.71041566326968E-13 0.000941350784481758 0.164092537138487 0 0 0</pose>
      <axis>
        <xyz>1 0 0</xyz>
        <dynamics>
          <damping>1</damping>
          <friction>1</friction>
        </dynamics>
        <limit>
          <upper>2.5</upper>
          <lower>0</lower>
          <effort>200</effort>
        </limit>
      </axis>
    </joint>
    <link name="Bumpers">
      <gravity>1</gravity>
      <self_collide>0</self_collide>
      <pose>-0.406400009399918 0.00079375000000007 -0.0126987965985534 -1.5707963267949 0 1.5707963267949</pose>
      <must_be_base_link>0</must_be_base_link>
      <velocity_decay>
        <linear>0</linear>
        <angular>0</angular>
      </velocity_decay>
      <inertial>
        <mass>0.413207943277131</mass>
        <pose>0 0 0 0 0 0</pose>
        <inertia>
          <ixx>3.84618615195701E-11</ixx>
          <ixy>2.6684558113521E-16</ixy>
          <ixz>1.43807283131322E-06</ixz>
          <iyy>0.0537689385779799</iyy>
          <iyz>7.13689707868226E-21</iyz>
          <izz>0.053768938539518</izz>
        </inertia>
      </inertial>
      <collision name="Bumpers_collision">
        <pose>-0.00079374999999998 -0.0126987965985534 -4.58756278805706E-17 0 0 0</pose>
        <geometry>
          <mesh>
            <scale>1 1 1</scale>
            <uri>model://SimBot2019/meshes/Bumpers_col.STL</uri>
          </mesh>
        </geometry>
        <surface>
          <contact>
            <ode />
          </contact>
          <friction>
            <ode>
              <mu>0</mu>
              <mu2>0</mu2>
            </ode>
          </friction>
        </surface>
      </collision>
      <visual name="Bumpers_visual">
        <pose>-0.00079374999999998 -0.0126987965985534 -4.58756278805706E-17 0 0 0</pose>
        <material>
          <ambient>1 0 0 1</ambient>
          <diffuse>1 0 0 1</diffuse>
        </material>
        <geometry>
          <mesh>
            <scale>1 1 1</scale>
            <uri>model://SimBot2019/meshes/Bumpers.STL</uri>
          </mesh>
        </geometry>
      </visual>
    </link>
    <joint name="Frame-Bumpers" type="prismatic">
      <parent>Frame</parent>
      <child>Bumpers</child>
      <pose>-0.24209375 0.0127012034014436 9.6355233506872E-18 0 0 0</pose>
      <axis>
        <xyz>0 0 -1</xyz>
        <dynamics>
          <damping>0</damping>
          <friction>0</friction>
        </dynamics>
        <limit>
          <upper>0</upper>
          <lower>0</lower>
          <effort>1</effort>
        </limit>
      </axis>
    </joint>
    <plugin name="Frame-LFWheel_motor" filename="libgz_dc_motor.so">
      <joint>Frame-LFWheel</joint>
      <topic>/gazebo/frc/simulator/pwm/1</topic>
      <multiplier>10</multiplier>
    </plugin>
    <plugin name="Frame-LCWheel_motor" filename="libgz_dc_motor.so">
      <joint>Frame-LCWheel</joint>
      <topic>/gazebo/frc/simulator/pwm/1</topic>
      <multiplier>10</multiplier>
    </plugin>
    <plugin name="Frame-LBWheel_motor" filename="libgz_dc_motor.so">
      <joint>Frame-LBWheel</joint>
      <topic>/gazebo/frc/simulator/pwm/3</topic>
      <multiplier>10</multiplier>
    </plugin>
    <plugin name="Frame-RFWheel_motor" filename="libgz_dc_motor.so">
      <joint>Frame-RFWheel</joint>
      <topic>/gazebo/frc/simulator/pwm/4</topic>
      <multiplier>10</multiplier>
    </plugin>
    <plugin name="Frame-RCWheel_motor" filename="libgz_dc_motor.so">
      <joint>Frame-RCWheel</joint>
      <topic>/gazebo/frc/simulator/pwm/4</topic>
      <multiplier>10</multiplier>
    </plugin>
    <plugin name="Frame-RBWheel_motor" filename="libgz_dc_motor.so">
      <joint>Frame-RBWheel</joint>
      <topic>/gazebo/frc/simulator/pwm/4</topic>
      <multiplier>10</multiplier>
    </plugin>
    <plugin name="Frame-Climber1_motor" filename="libgz_dc_motor.so">
      <joint>Frame-Climber1</joint>
      <topic>/gazebo/frc/simulator/pwm/6</topic>
      <multiplier>100</multiplier>
    </plugin>
    <plugin name="Frame-Climber2_motor" filename="libgz_dc_motor.so">
      <joint>Climber1-Climber2</joint>
      <topic>/gazebo/frc/simulator/pwm/6</topic>
      <multiplier>100</multiplier>
    </plugin>
  </model>
</sdf>