<?xml version="1.0" encoding="utf-8"?>
<sdf version="1.6">
  <model name="ClimberBot">
    <pose>0 0 0.12446 0 0 0</pose>
    <plugin name="clock" filename="libgz_clock.so">
      <topic>/gazebo/frc/time</topic>
    </plugin>
    <link name="Frame">
      <gravity>1</gravity>
      <self_collide>0</self_collide>
      <pose>-0.3510746437947 -2.97343237634824E-05 0.0014436640004077 -1.5707963267949 0 1.5707963267949</pose>
      <must_be_base_link>1</must_be_base_link>
      <velocity_decay>
        <linear>0</linear>
        <angular>0</angular>
      </velocity_decay>
      <inertial>
        <mass>30.02032480526164</mass>
        <pose>0 0 0 0 0 0</pose>
        <inertia>
          <ixx>0.171790686924595</ixx>
          <ixy>3.3395833458263E-07</ixy>
          <ixz>7.19648864492203E-05</ixz>
          <iyy>0.334028507267946</iyy>
          <iyz>0.000450659509649651</iyz>
          <izz>0.162408497885479</izz>
        </inertia>
      </inertial>
      <collision name="Frame_collision">
        <pose>2.97343237635603E-05 0.00144366400040762 0.0553253459660766 0 0 0</pose>
        <geometry>
          <mesh>
            <scale>1 1 1</scale>
            <uri>model://ClimberBot/meshes/Frame_col.STL</uri>
          </mesh>
        </geometry>
        <surface>
          <contact>
            <ode />
          </contact>
          <friction>
            <ode>
              <mu>1</mu>
              <mu2>1</mu2>
            </ode>
          </friction>
        </surface>
      </collision>
      <visual name="Frame_visual">
        <pose>2.97343237635603E-05 0.00144366400040762 0.0553253459660766 0 0 0</pose>
        <material>
          <ambient>0.501960784313725 0.501960784313725 0.501960784313725 1</ambient>
          <diffuse>0.501960784313725 0.501960784313725 0.501960784313725 1</diffuse>
        </material>
        <geometry>
          <mesh>
            <scale>1 1 1</scale>
            <uri>model://ClimberBot/meshes/Frame.STL</uri>
          </mesh>
        </geometry>
      </visual>
    </link>
    <link name="R1Wheel">
      <gravity>1</gravity>
      <self_collide>0</self_collide>
      <pose>-0.673116386398924 -0.303262709940692 0.00161185200133652 -1.5707963267949 0 1.5707963267949</pose>
      <must_be_base_link>0</must_be_base_link>
      <velocity_decay>
        <linear>0</linear>
        <angular>0.01</angular>
      </velocity_decay>
      <inertial>
        <mass>0.255325203825891</mass>
        <pose>0 0 0 0 0 0</pose>
        <inertia>
          <ixx>0</ixx>
          <ixy>0</ixy>
          <ixz>0</ixz>
          <iyy>0</iyy>
          <iyz>0</iyz>
          <izz>0</izz>
        </inertia>
      </inertial>
      <collision name="R1Wheel_collision">
        <pose>0.303262709940693 0.00161185200133637 -0.266716396638148 0 0 0</pose>
        <geometry>
          <mesh>
            <scale>1 1 1</scale>
            <uri>model://ClimberBot/meshes/R1Wheel_col.STL</uri>
          </mesh>
        </geometry>
        <surface>
          <contact>
            <ode />
          </contact>
          <friction>
            <ode>
              <mu>1</mu>
              <mu2>1</mu2>
            </ode>
          </friction>
        </surface>
      </collision>
      <visual name="R1Wheel_visual">
        <pose>0.303262709940693 0.00161185200133637 -0.266716396638148 0 0 0</pose>
        <material>
          <ambient>0.501960784313725 0.501960784313725 0.501960784313725 1</ambient>
          <diffuse>0.501960784313725 0.501960784313725 0.501960784313725 1</diffuse>
        </material>
        <geometry>
          <mesh>
            <scale>1 1 1</scale>
            <uri>model://ClimberBot/meshes/R1Wheel.STL</uri>
          </mesh>
        </geometry>
      </visual>
    </link>
    <joint name="Frame-R1Wheel" type="revolute">
      <parent>Frame</parent>
      <child>R1Wheel</child>
      <pose>-1.3290059307336E-05 -3.91479986604842E-05 -2.07350359620051E-05 0 0 0</pose>
      <axis>
        <xyz>-1 -1.22460635382238E-16 0</xyz>
        <dynamics>
          <damping>1</damping>
          <friction>1</friction>
        </dynamics>
        <limit>
          <effort>50</effort>
        </limit>
      </axis>
    </joint>
    <link name="R2Wheel">
      <gravity>1</gravity>
      <self_collide>0</self_collide>
      <pose>-0.408023151778347 -0.303262709940693 0.0104427983225408 -1.5707963267949 0 1.5707963267949</pose>
      <must_be_base_link>0</must_be_base_link>
      <velocity_decay>
        <linear>0</linear>
        <angular>0.01</angular>
      </velocity_decay>
      <inertial>
        <mass>0.255325203825891</mass>
        <pose>0 0 0 0 0 0</pose>
        <inertia>
          <ixx>0</ixx>
          <ixy>0</ixy>
          <ixz>0</ixz>
          <iyy>0</iyy>
          <iyz>0</iyz>
          <izz>0</izz>
        </inertia>
      </inertial>
      <collision name="R2Wheel_collision">
        <pose>0.303262709940693 0.0104427983225407 -0.00162316201757093 0 0 0</pose>
        <geometry>
          <mesh>
            <scale>1 1 1</scale>
            <uri>model://ClimberBot/meshes/R2Wheel_col.STL</uri>
          </mesh>
        </geometry>
        <surface>
          <contact>
            <ode />
          </contact>
          <friction>
            <ode>
              <mu>1</mu>
              <mu2>1</mu2>
            </ode>
          </friction>
        </surface>
      </collision>
      <visual name="R2Wheel_visual">
        <pose>0.303262709940693 0.0104427983225407 -0.00162316201757093 0 0 0</pose>
        <material>
          <ambient>0.501960784313725 0.501960784313725 0.501960784313725 1</ambient>
          <diffuse>0.501960784313725 0.501960784313725 0.501960784313725 1</diffuse>
        </material>
        <geometry>
          <mesh>
            <scale>1 1 1</scale>
            <uri>model://ClimberBot/meshes/R2Wheel.STL</uri>
          </mesh>
        </geometry>
      </visual>
    </link>
    <joint name="Frame-R2Wheel" type="revolute">
      <parent>Frame</parent>
      <child>R2Wheel</child>
      <pose>-1.32900593072249E-05 7.18157269403302E-06 4.37142142683622E-05 0 0 0</pose>
      <axis>
        <xyz>-1 0 0</xyz>
        <dynamics>
          <damping>1</damping>
          <friction>1</friction>
        </dynamics>
        <limit>
          <effort>50</effort>
        </limit>
      </axis>
    </joint>
    <link name="R3Wheel">
      <gravity>1</gravity>
      <self_collide>0</self_collide>
      <pose>-0.139721260811227 -0.303262709940693 0.00161005666783426 -1.5707963267949 0 1.5707963267949</pose>
      <must_be_base_link>0</must_be_base_link>
      <velocity_decay>
        <linear>0</linear>
        <angular>0.01</angular>
      </velocity_decay>
      <inertial>
        <mass>0.255325203825891</mass>
        <pose>0 0 0 0 0 0</pose>
        <inertia>
          <ixx>0</ixx>
          <ixy>0</ixy>
          <ixz>0</ixz>
          <iyy>0</iyy>
          <iyz>0</iyz>
          <izz>0</izz>
        </inertia>
      </inertial>
      <collision name="R3Wheel_collision">
        <pose>0.303262709940693 0.00161005666783423 0.266678728949549 0 0 0</pose>
        <geometry>
          <mesh>
            <scale>1 1 1</scale>
            <uri>model://ClimberBot/meshes/R3Wheel_col.STL</uri>
          </mesh>
        </geometry>
        <surface>
          <contact>
            <ode />
          </contact>
          <friction>
            <ode>
              <mu>1</mu>
              <mu2>1</mu2>
            </ode>
          </friction>
        </surface>
      </collision>
      <visual name="R3Wheel_visual">
        <pose>0.303262709940693 0.00161005666783423 0.266678728949549 0 0 0</pose>
        <material>
          <ambient>0.501960784313725 0.501960784313725 0.501960784313725 1</ambient>
          <diffuse>0.501960784313725 0.501960784313725 0.501960784313725 1</diffuse>
        </material>
        <geometry>
          <mesh>
            <scale>1 1 1</scale>
            <uri>model://ClimberBot/meshes/R3Wheel.STL</uri>
          </mesh>
        </geometry>
      </visual>
    </link>
    <joint name="Frame-R3Wheel" type="revolute">
      <parent>Frame</parent>
      <child>R3Wheel</child>
      <pose>-1.32900593072249E-05 -4.09433321690025E-05 -1.69160003058999E-05 0 0 0</pose>
      <axis>
        <xyz>-1 0 0</xyz>
        <dynamics>
          <damping>1</damping>
          <friction>1</friction>
        </dynamics>
        <limit>
          <effort>50</effort>
        </limit>
      </axis>
    </joint>
    <link name="L1Wheel">
      <gravity>1</gravity>
      <self_collide>0</self_collide>
      <pose>-0.673051394231998 0.303262709940693 0.00165295291430823 -1.5707963267949 0 1.5707963267949</pose>
      <must_be_base_link>0</must_be_base_link>
      <velocity_decay>
        <linear>0</linear>
        <angular>0.01</angular>
      </velocity_decay>
      <inertial>
        <mass>0.255325203825891</mass>
        <pose>0 0 0 0 0 0</pose>
        <inertia>
          <ixx>0</ixx>
          <ixy>0</ixy>
          <ixz>0</ixz>
          <iyy>0</iyy>
          <iyz>0</iyz>
          <izz>0</izz>
        </inertia>
      </inertial>
      <collision name="L1Wheel_collision">
        <pose>-0.303262709940693 0.00165295291430808 -0.266651404471222 0 0 0</pose>
        <geometry>
          <mesh>
            <scale>1 1 1</scale>
            <uri>model://ClimberBot/meshes/L1Wheel_col.STL</uri>
          </mesh>
        </geometry>
        <surface>
          <contact>
            <ode />
          </contact>
          <friction>
            <ode>
              <mu>1</mu>
              <mu2>1</mu2>
            </ode>
          </friction>
        </surface>
      </collision>
      <visual name="L1Wheel_visual">
        <pose>-0.303262709940693 0.00165295291430808 -0.266651404471222 0 0 0</pose>
        <material>
          <ambient>0.501960784313725 0.501960784313725 0.501960784313725 1</ambient>
          <diffuse>0.501960784313725 0.501960784313725 0.501960784313725 1</diffuse>
        </material>
        <geometry>
          <mesh>
            <scale>1 1 1</scale>
            <uri>model://ClimberBot/meshes/L1Wheel.STL</uri>
          </mesh>
        </geometry>
      </visual>
    </link>
    <joint name="Frame-L1Wheel" type="revolute">
      <parent>Frame</parent>
      <child>L1Wheel</child>
      <pose>0.000375096488045179 1.95291429993887E-06 4.42767701058222E-05 0 0 0</pose>
      <axis>
        <xyz>-1 0 0</xyz>
        <dynamics>
          <damping>1</damping>
          <friction>1</friction>
        </dynamics>
        <limit>
          <effort>50</effort>
        </limit>
      </axis>
    </joint>
    <link name="L2Wheel">
      <gravity>1</gravity>
      <self_collide>0</self_collide>
      <pose>-0.404776910127774 0.303262709940693 0.0104878780088853 -1.5707963267949 0 1.5707963267949</pose>
      <must_be_base_link>0</must_be_base_link>
      <velocity_decay>
        <linear>0</linear>
        <angular>0.01</angular>
      </velocity_decay>
      <inertial>
        <mass>0.255325203825891</mass>
        <pose>0 0 0 0 0 0</pose>
        <inertia>
          <ixx>0</ixx>
          <ixy>0</ixy>
          <ixz>0</ixz>
          <iyy>0</iyy>
          <iyz>0</iyz>
          <izz>0</izz>
        </inertia>
      </inertial>
      <collision name="L2Wheel_collision">
        <pose>-0.303262709940693 0.0104878780088852 0.00162307963300241 0 0 0</pose>
        <geometry>
          <mesh>
            <scale>1 1 1</scale>
            <uri>model://ClimberBot/meshes/L2Wheel_col.STL</uri>
          </mesh>
        </geometry>
        <surface>
          <contact>
            <ode />
          </contact>
          <friction>
            <ode>
              <mu>1</mu>
              <mu2>1</mu2>
            </ode>
          </friction>
        </surface>
      </collision>
      <visual name="L2Wheel_visual">
        <pose>-0.303262709940693 0.0104878780088852 0.00162307963300241 0 0 0</pose>
        <material>
          <ambient>0.501960784313725 0.501960784313725 0.501960784313725 1</ambient>
          <diffuse>0.501960784313725 0.501960784313725 0.501960784313725 1</diffuse>
        </material>
        <geometry>
          <mesh>
            <scale>1 1 1</scale>
            <uri>model://ClimberBot/meshes/L2Wheel.STL</uri>
          </mesh>
        </geometry>
      </visual>
    </link>
    <joint name="Frame-L2Wheel" type="revolute">
      <parent>Frame</parent>
      <child>L2Wheel</child>
      <pose>1.32900593072249E-05 4.38148899713081E-05 -6.53933729534775E-06 0 0 0</pose>
      <axis>
        <xyz>-1 2.82701482950913E-15 -8.64198840208855E-16</xyz>
        <dynamics>
          <damping>1</damping>
          <friction>1</friction>
        </dynamics>
        <limit>
          <effort>50</effort>
        </limit>
      </axis>
    </joint>
    <link name="L3Wheel">
      <gravity>1</gravity>
      <self_collide>0</self_collide>
      <pose>-0.139682225579056 0.303199220635695 0.00168938290110701 -1.5707963267949 0 1.5707963267949</pose>
      <must_be_base_link>0</must_be_base_link>
      <velocity_decay>
        <linear>0</linear>
        <angular>0.01</angular>
      </velocity_decay>
      <inertial>
        <mass>0.255325203825891</mass>
        <pose>0 0 0 0 0 0</pose>
        <inertia>
          <ixx>0</ixx>
          <ixy>0</ixy>
          <ixz>0</ixz>
          <iyy>0</iyy>
          <iyz>0</iyz>
          <izz>0</izz>
        </inertia>
      </inertial>
      <collision name="L3Wheel_collision">
        <pose>-0.303199220635695 0.00168938290110699 0.26671776418172 0 0 0</pose>
        <geometry>
          <mesh>
            <scale>1 1 1</scale>
            <uri>model://ClimberBot/meshes/L3Wheel_col.STL</uri>
          </mesh>
        </geometry>
        <surface>
          <contact>
            <ode />
          </contact>
          <friction>
            <ode>
              <mu>1</mu>
              <mu2>1</mu2>
            </ode>
          </friction>
        </surface>
      </collision>
      <visual name="L3Wheel_visual">
        <pose>-0.303199220635695 0.00168938290110699 0.26671776418172 0 0 0</pose>
        <material>
          <ambient>0.501960784313725 0.501960784313725 0.501960784313725 1</ambient>
          <diffuse>0.501960784313725 0.501960784313725 0.501960784313725 1</diffuse>
        </material>
        <geometry>
          <mesh>
            <scale>1 1 1</scale>
            <uri>model://ClimberBot/meshes/L3Wheel.STL</uri>
          </mesh>
        </geometry>
      </visual>
    </link>
    <joint name="Frame-L3Wheel" type="revolute">
      <parent>Frame</parent>
      <child>L3Wheel</child>
      <pose>1.32900593072804E-05 3.838290110375E-05 2.21192318655139E-05 0 0 0</pose>
      <axis>
        <xyz>-1 0 0</xyz>
        <dynamics>
          <damping>1</damping>
          <friction>1</friction>
        </dynamics>
        <limit>
          <effort>50</effort>
        </limit>
      </axis>
    </joint>
    <link name="Climber1">
      <gravity>1</gravity>
      <self_collide>0</self_collide>
      <pose>-0.377766700900613 -4.07700460166053E-16 0.0307545735435157 -1.5707963267949 0 1.5707963267949</pose>
      <must_be_base_link>0</must_be_base_link>
      <velocity_decay>
        <linear>0</linear>
        <angular>0</angular>
      </velocity_decay>
      <inertial>
        <mass>1.77832603470066</mass>
        <pose>0 0 0 0 0 0</pose>
        <inertia>
          <ixx>0.00321375368173924</ixx>
          <ixy>5.63245485001767E-15</ixy>
          <ixz>5.40745833527145E-17</ixz>
          <iyy>0.0174980858969123</iyy>
          <iyz>0.000433389151753912</iyz>
          <izz>0.0146229301642562</izz>
        </inertia>
      </inertial>
      <collision name="Climber1_collision">
        <pose>4.91581518021363E-16 0.0307545735435156 0.0286332888601632 0 0 0</pose>
        <geometry>
          <mesh>
            <scale>1 1 1</scale>
            <uri>model://ClimberBot/meshes/Climber1_col.STL</uri>
          </mesh>
        </geometry>
        <surface>
          <contact>
            <ode />
          </contact>
          <friction>
            <ode>
              <mu>0</mu>
              <mu2>0</mu2>
            </ode>
          </friction>
        </surface>
      </collision>
      <visual name="Climber1_visual">
        <pose>4.91581518021363E-16 0.0307545735435156 0.0286332888601632 0 0 0</pose>
        <material>
          <ambient>0 0 1 1</ambient>
          <diffuse>0 0 1 1</diffuse>
        </material>
        <geometry>
          <mesh>
            <scale>1 1 1</scale>
            <uri>model://ClimberBot/meshes/Climber1.STL</uri>
          </mesh>
        </geometry>
      </visual>
    </link>
    <joint name="Frame-Climber1" type="revolute">
      <parent>Frame</parent>
      <child>Climber1</child>
      <pose>-7.71297172489753E-16 -0.0105204264564844 -0.301566700900612 0 1.11022302462516E-16 3.14159265358991</pose>
      <frame name="climber1-frame"/>
      <axis>
        <xyz>1 0 0</xyz>
        <dynamics>
          <damping>1</damping>
          <friction>1</friction>
        </dynamics>
        <limit>
          <upper>0</upper>
          <lower>-0.7</lower>
          <effort>200</effort>
        </limit>
      </axis>
    </joint>
    <link name="Climber2">
      <gravity>1</gravity>
      <self_collide>0</self_collide>
      <pose>-0.470905991009128 -0.00297142421927649 0.0409337986199918 -1.5707963267949 0 1.5707963267949</pose>
      <must_be_base_link>0</must_be_base_link>
      <velocity_decay>
        <linear>0</linear>
        <angular>0</angular>
      </velocity_decay>
      <inertial>
        <mass>0.790365756487698</mass>
        <pose>0 0 0 0 0 0</pose>
        <inertia>
          <ixx>0.00839975269474826</ixx>
          <ixy>1.30683235970531E-07</ixy>
          <ixz>4.12114029020404E-05</ixz>
          <iyy>0.0136860179616977</iyy>
          <iyz>0.000158154045889581</iyz>
          <izz>0.00529400442329184</izz>
        </inertia>
      </inertial>
      <collision name="Climber2_collision">
        <pose>0.0029714242192766 0.0409337986199917 -0.0645060012483518 0 0 0</pose>
        <geometry>
          <mesh>
            <scale>1 1 1</scale>
            <uri>model://ClimberBot/meshes/Climber2_col.STL</uri>
          </mesh>
        </geometry>
        <surface>
          <contact>
            <ode />
          </contact>
          <friction>
            <ode>
              <mu>1</mu>
              <mu2>1</mu2>
            </ode>
          </friction>
        </surface>
      </collision>
      <visual name="Climber2_visual">
        <pose>0.0029714242192766 0.0409337986199917 -0.0645060012483518 0 0 0</pose>
        <material>
          <ambient>0 0 0.501960784313725 1</ambient>
          <diffuse>0 0 0.501960784313725 1</diffuse>
        </material>
        <geometry>
          <mesh>
            <scale>1 1 1</scale>
            <uri>model://ClimberBot/meshes/Climber2.STL</uri>
          </mesh>
        </geometry>
      </visual>
    </link>
    <joint name="Climber1-Climber2" type="revolute">
      <parent>Climber1</parent>
      <child>Climber2</child>
      <pose>0.000317671351160371 0.000941350784374191 0.164092537138493 0 0 0</pose>
      <axis>
        <xyz>1 0 0</xyz>
        <dynamics>
          <damping>1</damping>
          <friction>1</friction>
        </dynamics>
        <limit>
          <upper>0</upper>
          <lower>-1</lower>
          <effort>200</effort>
        </limit>
      </axis>
      <frame name="climber2-frame">
        <pose frame="climber1-frame"/>
      </frame>
    </joint>
    <plugin name="Frame-R1Wheel_motor" filename="libgz_dc_motor.so">
      <joint>Frame-R1Wheel</joint>
      <topic>/gazebo/frc/simulator/pwm/1</topic>
      <multiplier>20</multiplier>
    </plugin>
    <plugin name="Frame-R2Wheel_motor" filename="libgz_dc_motor.so">
      <joint>Frame-R2Wheel</joint>
      <topic>/gazebo/frc/simulator/pwm/1</topic>
      <multiplier>20</multiplier>
    </plugin>
    <plugin name="Frame-R3Wheel_motor" filename="libgz_dc_motor.so">
      <joint>Frame-R3Wheel</joint>
      <topic>/gazebo/frc/simulator/pwm/3</topic>
      <multiplier>20</multiplier>
    </plugin>
    <plugin name="Frame-L1Wheel_motor" filename="libgz_dc_motor.so">
      <joint>Frame-L1Wheel</joint>
      <topic>/gazebo/frc/simulator/pwm/4</topic>
      <multiplier>20</multiplier>
    </plugin>
    <plugin name="Frame-L2Wheel_motor" filename="libgz_dc_motor.so">
      <joint>Frame-L2Wheel</joint>
      <topic>/gazebo/frc/simulator/pwm/4</topic>
      <multiplier>20</multiplier>
    </plugin>
    <plugin name="Frame-L3Wheel_motor" filename="libgz_dc_motor.so">
      <joint>Frame-L3Wheel</joint>
      <topic>/gazebo/frc/simulator/pwm/4</topic>
      <multiplier>20</multiplier>
    </plugin>
    <plugin name="Frame-Climber1_motor" filename="libgz_dc_motor.so">
      <joint>Frame-Climber1</joint>
      <topic>/gazebo/frc/simulator/pwm/6</topic>
      <multiplier>150</multiplier>
    </plugin>
    <plugin name="Frame-Climber2_motor" filename="libgz_dc_motor.so">
      <joint>Climber1-Climber2</joint>
      <topic>/gazebo/frc/simulator/pwm/6</topic>
      <multiplier>150</multiplier>
    </plugin>
  </model>
</sdf>
