<?xml version="1.0" encoding="utf-8"?>
<sdf version="1.5">
  <model name="SimBot2019-4">
    <pose>0 0 0.12446 0 0 0</pose>
    <plugin name="clock" filename="libgz_clock.so">
      <topic>/gazebo/frc/time</topic>
    </plugin>
    <link name="Frame">
      <gravity>1</gravity>
      <self_collide>0</self_collide>
      <pose>-0.406400009399918 9.02389295287339E-17 8.71268615132043E-17 -1.5707963267949 0 1.5707963267949</pose>
      <must_be_base_link>1</must_be_base_link>
      <velocity_decay>
        <linear>0</linear>
        <angular>0</angular>
      </velocity_decay>
      <inertial>
        <mass>20</mass>
        <pose>-0.00117983358945936 -0.000429934584262839 -0.0787218957234474 0 0 0</pose>
        <inertia>
          <ixx>0.21342895</ixx>
          <ixy>1.615E-05</ixy>
          <ixz>0.00118497</ixz>
          <iyy>0.43425222</iyy>
          <iyz>0.00046367</iyz>
          <izz>0.22127647</izz>
        </inertia>
      </inertial>
      <collision name="Frame_collision">
        <pose>0 0 0 0 0 0</pose>
        <geometry>
          <mesh>
            <scale>1 1 1</scale>
            <uri>model://SimBot2019-4/meshes/Frame_col.STL</uri>
          </mesh>
        </geometry>
        <surface>
          <contact>
            <ode />
          </contact>
          <friction>
            <ode>
              <mu>1</mu>
              <mu2>1</mu2>
            </ode>
          </friction>
        </surface>
      </collision>
      <visual name="Frame_visual">
        <pose>0 0 0 0 0 0</pose>
        <material>
          <ambient>0.501960784313725 0.501960784313725 0.501960784313725 1</ambient>
          <diffuse>0.501960784313725 0.501960784313725 0.501960784313725 1</diffuse>
        </material>
        <geometry>
          <mesh>
            <scale>1 1 1</scale>
            <uri>model://SimBot2019-4/meshes/Frame.STL</uri>
          </mesh>
        </geometry>
      </visual>
    </link>
    <link name="R1Wheel">
      <gravity>1</gravity>
      <self_collide>0</self_collide>
      <pose>-0.673098427026752 0.303262709940696 0.00169521560482934 -1.5707963267949 0 1.5707963267949</pose>
      <must_be_base_link>0</must_be_base_link>
      <velocity_decay>
        <linear>0</linear>
        <angular>0</angular>
      </velocity_decay>
      <inertial>
        <mass>0.255325203825891</mass>
        <pose>0 0 0 0 0 0</pose>
        <inertia>
          <ixx>0</ixx>
          <ixy>0</ixy>
          <ixz>0</ixz>
          <iyy>0</iyy>
          <iyz>0</iyz>
          <izz>0</izz>
        </inertia>
      </inertial>
      <collision name="R1Wheel_collision">
        <pose>-0.303262709940696 0.00169521560482919 -0.266698417626834 0 0 0</pose>
        <geometry>
          <mesh>
            <scale>1 1 1</scale>
            <uri>model://SimBot2019-4/meshes/R1Wheel_col.STL</uri>
          </mesh>
        </geometry>
        <surface>
          <contact>
            <ode />
          </contact>
          <friction>
            <ode>
              <mu>1</mu>
              <mu2>1</mu2>
            </ode>
          </friction>
        </surface>
      </collision>
      <visual name="R1Wheel_visual">
        <pose>-0.303262709940696 0.00169521560482919 -0.266698417626834 0 0 0</pose>
        <material>
          <ambient>0.501960784313725 0.501960784313725 0.501960784313725 1</ambient>
          <diffuse>0.501960784313725 0.501960784313725 0.501960784313725 1</diffuse>
        </material>
        <geometry>
          <mesh>
            <scale>1 1 1</scale>
            <uri>model://SimBot2019-4/meshes/R1Wheel.STL</uri>
          </mesh>
        </geometry>
      </visual>
    </link>
    <joint name="Frame-R1Wheel" type="revolute">
      <parent>Frame</parent>
      <child>R1Wheel</child>
      <pose>0 4.42156048210489E-05 -2.73638550629673E-06 0 0 0</pose>
      <axis>
        <xyz>1 0 0</xyz>
        <dynamics>
          <damping>1</damping>
          <friction>1</friction>
        </dynamics>
        <limit>
          <effort>50</effort>
        </limit>
      </axis>
    </joint>
    <link name="R2Wheel">
      <gravity>1</gravity>
      <self_collide>0</self_collide>
      <pose>-0.405312662240039 0.303262709940696 -0.00385752270000407 -1.5707963267949 0 1.5707963267949</pose>
      <must_be_base_link>0</must_be_base_link>
      <velocity_decay>
        <linear>0</linear>
        <angular>0</angular>
      </velocity_decay>
      <inertial>
        <mass>0.255325203825891</mass>
        <pose>0 0 0 0 0 0</pose>
        <inertia>
          <ixx>0</ixx>
          <ixy>0</ixy>
          <ixz>0</ixz>
          <iyy>0</iyy>
          <iyz>0</iyz>
          <izz>0</izz>
        </inertia>
      </inertial>
      <collision name="R2Wheel_collision">
        <pose>-0.303262709940696 -0.00385752270000415 0.00108734715987955 0 0 0</pose>
        <geometry>
          <mesh>
            <scale>1 1 1</scale>
            <uri>model://SimBot2019-4/meshes/R2Wheel_col.STL</uri>
          </mesh>
        </geometry>
        <surface>
          <contact>
            <ode />
          </contact>
          <friction>
            <ode>
              <mu>1</mu>
              <mu2>1</mu2>
            </ode>
          </friction>
        </surface>
      </collision>
      <visual name="R2Wheel_visual">
        <pose>-0.303262709940696 -0.00385752270000415 0.00108734715987955 0 0 0</pose>
        <material>
          <ambient>0.501960784313725 0.501960784313725 0.501960784313725 1</ambient>
          <diffuse>0.501960784313725 0.501960784313725 0.501960784313725 1</diffuse>
        </material>
        <geometry>
          <mesh>
            <scale>1 1 1</scale>
            <uri>model://SimBot2019-4/meshes/R2Wheel.STL</uri>
          </mesh>
        </geometry>
      </visual>
    </link>
    <joint name="Frame-R2Wheel" type="revolute">
      <parent>Frame</parent>
      <child>R2Wheel</child>
      <pose>0 4.38148899713098E-05 -6.5393372950496E-06 0 0 0</pose>
      <axis>
        <xyz>1 0 0</xyz>
        <dynamics>
          <damping>1</damping>
          <friction>1</friction>
        </dynamics>
        <limit>
          <effort>50</effort>
        </limit>
      </axis>
    </joint>
    <link name="R3Wheel">
      <gravity>1</gravity>
      <self_collide>0</self_collide>
      <pose>-0.139700611281359 0.303199220635698 0.00169514092478139 -1.5707963267949 0 1.5707963267949</pose>
      <must_be_base_link>0</must_be_base_link>
      <velocity_decay>
        <linear>0</linear>
        <angular>0</angular>
      </velocity_decay>
      <inertial>
        <mass>0.255325203825891</mass>
        <pose>0 0 0 0 0 0</pose>
        <inertia>
          <ixx>0</ixx>
          <ixy>0</ixy>
          <ixz>0</ixz>
          <iyy>0</iyy>
          <iyz>0</iyz>
          <izz>0</izz>
        </inertia>
      </inertial>
      <collision name="R3Wheel_collision">
        <pose>-0.303199220635698 0.00169514092478136 0.266699398118559 0 0 0</pose>
        <geometry>
          <mesh>
            <scale>1 1 1</scale>
            <uri>model://SimBot2019-4/meshes/R3Wheel_col.STL</uri>
          </mesh>
        </geometry>
        <surface>
          <contact>
            <ode />
          </contact>
          <friction>
            <ode>
              <mu>1</mu>
              <mu2>1</mu2>
            </ode>
          </friction>
        </surface>
      </collision>
      <visual name="R3Wheel_visual">
        <pose>-0.303199220635698 0.00169514092478136 0.266699398118559 0 0 0</pose>
        <material>
          <ambient>0.501960784313725 0.501960784313725 0.501960784313725 1</ambient>
          <diffuse>0.501960784313725 0.501960784313725 0.501960784313725 1</diffuse>
        </material>
        <geometry>
          <mesh>
            <scale>1 1 1</scale>
            <uri>model://SimBot2019-4/meshes/R3Wheel.STL</uri>
          </mesh>
        </geometry>
      </visual>
    </link>
    <joint name="Frame-R3Wheel" type="revolute">
      <parent>Frame</parent>
      <child>R3Wheel</child>
      <pose>0 4.41409247781261E-05 3.75316870410147E-06 0 0 0</pose>
      <axis>
        <xyz>1 0 0</xyz>
        <dynamics>
          <damping>1</damping>
          <friction>1</friction>
        </dynamics>
        <limit>
          <effort>50</effort>
        </limit>
      </axis>
    </joint>
    <link name="L1Wheel">
      <gravity>1</gravity>
      <self_collide>0</self_collide>
      <pose>-0.673096884472197 -0.30326270994069 0.00169528357489406 -1.5707963267949 0 1.5707963267949</pose>
      <must_be_base_link>0</must_be_base_link>
      <velocity_decay>
        <linear>0</linear>
        <angular>0</angular>
      </velocity_decay>
      <inertial>
        <mass>0.255325203825891</mass>
        <pose>0 0 0 0 0 0</pose>
        <inertia>
          <ixx>0</ixx>
          <ixy>0</ixy>
          <ixz>0</ixz>
          <iyy>0</iyy>
          <iyz>0</iyz>
          <izz>0</izz>
        </inertia>
      </inertial>
      <collision name="L1Wheel_collision">
        <pose>0.30326270994069 0.00169528357489391 -0.266696875072279 0 0 0</pose>
        <geometry>
          <mesh>
            <scale>1 1 1</scale>
            <uri>model://SimBot2019-4/meshes/L1Wheel_col.STL</uri>
          </mesh>
        </geometry>
        <surface>
          <contact>
            <ode />
          </contact>
          <friction>
            <ode>
              <mu>1</mu>
              <mu2>1</mu2>
            </ode>
          </friction>
        </surface>
      </collision>
      <visual name="L1Wheel_visual">
        <pose>0.30326270994069 0.00169528357489391 -0.266696875072279 0 0 0</pose>
        <material>
          <ambient>0.501960784313725 0.501960784313725 0.501960784313725 1</ambient>
          <diffuse>0.501960784313725 0.501960784313725 0.501960784313725 1</diffuse>
        </material>
        <geometry>
          <mesh>
            <scale>1 1 1</scale>
            <uri>model://SimBot2019-4/meshes/L1Wheel.STL</uri>
          </mesh>
        </geometry>
      </visual>
    </link>
    <joint name="Frame-L1Wheel" type="revolute">
      <parent>Frame</parent>
      <child>L1Wheel</child>
      <pose>0 4.42835748970557E-05 -1.21347009340855E-06 0 0 0</pose>
      <axis>
        <xyz>1 0 0</xyz>
        <dynamics>
          <damping>1</damping>
          <friction>1</friction>
        </dynamics>
        <limit>
          <effort>50</effort>
        </limit>
      </axis>
    </joint>
    <link name="L2Wheel">
      <gravity>1</gravity>
      <self_collide>0</self_collide>
      <pose>-0.406431067254661 -0.303368868926877 -0.0036834982409925 -1.5707963267949 0 1.5707963267949</pose>
      <must_be_base_link>0</must_be_base_link>
      <velocity_decay>
        <linear>0</linear>
        <angular>0</angular>
      </velocity_decay>
      <inertial>
        <mass>0.255325203825891</mass>
        <pose>0 0 0 0 0 0</pose>
        <inertia>
          <ixx>0</ixx>
          <ixy>0</ixy>
          <ixz>0</ixz>
          <iyy>0</iyy>
          <iyz>0</iyz>
          <izz>0</izz>
        </inertia>
      </inertial>
      <collision name="L2Wheel_collision">
        <pose>0.303368868926877 -0.00368349824099259 -3.10578547423262E-05 0 0 0</pose>
        <geometry>
          <mesh>
            <scale>1 1 1</scale>
            <uri>model://SimBot2019-4/meshes/L2Wheel_col.STL</uri>
          </mesh>
        </geometry>
        <surface>
          <contact>
            <ode />
          </contact>
          <friction>
            <ode>
              <mu>1</mu>
              <mu2>1</mu2>
            </ode>
          </friction>
        </surface>
      </collision>
      <visual name="L2Wheel_visual">
        <pose>0.303368868926877 -0.00368349824099259 -3.10578547423262E-05 0 0 0</pose>
        <material>
          <ambient>0.501960784313725 0.501960784313725 0.501960784313725 1</ambient>
          <diffuse>0.501960784313725 0.501960784313725 0.501960784313725 1</diffuse>
        </material>
        <geometry>
          <mesh>
            <scale>1 1 1</scale>
            <uri>model://SimBot2019-4/meshes/L2Wheel.STL</uri>
          </mesh>
        </geometry>
      </visual>
    </link>
    <joint name="Frame-L2Wheel" type="revolute">
      <parent>Frame</parent>
      <child>L2Wheel</child>
      <pose>0 4.10696537008477E-05 1.66069581911443E-05 0 0 0</pose>
      <axis>
        <xyz>1 0 0</xyz>
        <dynamics>
          <damping>1</damping>
          <friction>1</friction>
        </dynamics>
        <limit>
          <effort>50</effort>
        </limit>
      </axis>
    </joint>
    <link name="L3Wheel">
      <gravity>1</gravity>
      <self_collide>0</self_collide>
      <pose>-0.139684826378901 -0.30326270994069 0.00169075891461175 -1.5707963267949 0 1.5707963267949</pose>
      <must_be_base_link>0</must_be_base_link>
      <velocity_decay>
        <linear>0</linear>
        <angular>0</angular>
      </velocity_decay>
      <inertial>
        <mass>0.255325203825891</mass>
        <pose>0 0 0 0 0 0</pose>
        <inertia>
          <ixx>0</ixx>
          <ixy>0</ixy>
          <ixz>0</ixz>
          <iyy>0</iyy>
          <iyz>0</iyz>
          <izz>0</izz>
        </inertia>
      </inertial>
      <collision name="L3Wheel_collision">
        <pose>0.30326270994069 0.00169075891461172 0.266715183021017 0 0 0</pose>
        <geometry>
          <mesh>
            <scale>1 1 1</scale>
            <uri>model://SimBot2019-4/meshes/L3Wheel_col.STL</uri>
          </mesh>
        </geometry>
        <surface>
          <contact>
            <ode />
          </contact>
          <friction>
            <ode>
              <mu>0</mu>
              <mu2>0</mu2>
            </ode>
          </friction>
        </surface>
      </collision>
      <visual name="L3Wheel_visual">
        <pose>0.30326270994069 0.00169075891461172 0.266715183021017 0 0 0</pose>
        <material>
          <ambient>0.501960784313725 0.501960784313725 0.501960784313725 1</ambient>
          <diffuse>0.501960784313725 0.501960784313725 0.501960784313725 1</diffuse>
        </material>
        <geometry>
          <mesh>
            <scale>1 1 1</scale>
            <uri>model://SimBot2019-4/meshes/L3Wheel.STL</uri>
          </mesh>
        </geometry>
      </visual>
    </link>
    <joint name="Frame-L3Wheel" type="revolute">
      <parent>Frame</parent>
      <child>L3Wheel</child>
      <pose>0 3.97589146084862E-05 1.95380711622839E-05 0 0 0</pose>
      <axis>
        <xyz>1 0 0</xyz>
        <dynamics>
          <damping>1</damping>
          <friction>1</friction>
        </dynamics>
        <limit>
          <effort>50</effort>
        </limit>
      </axis>
    </joint>
    <link name="Climber1">
      <gravity>1</gravity>
      <self_collide>0</self_collide>
      <pose>-0.323353974586063 0.00362463179526783 -0.0265995667576985 -1.5707963267949 0 1.5707963267949</pose>
      <must_be_base_link>0</must_be_base_link>
      <velocity_decay>
        <linear>0</linear>
        <angular>0</angular>
      </velocity_decay>
      <inertial>
        <mass>1.09137603293812</mass>
        <pose>0 0 0 0 0 0</pose>
        <inertia>
          <ixx>0.0103076735668263</ixx>
          <ixy>5.56761692691938E-07</ixy>
          <ixz>2.11133902749831E-05</ixz>
          <iyy>0.0182769914047259</iyy>
          <iyz>0.000619355046120763</iyz>
          <izz>0.0081555512950746</izz>
        </inertia>
      </inertial>
      <collision name="Climber1_collision">
        <pose>-0.00362463179526776 -0.0265995667576986 0.0830460348138553 0 0 0</pose>
        <geometry>
          <mesh>
            <scale>1 1 1</scale>
            <uri>model://SimBot2019-4/meshes/Climber1_col.STL</uri>
          </mesh>
        </geometry>
        <surface>
          <contact>
            <ode />
          </contact>
          <friction>
            <ode>
              <mu>0</mu>
              <mu2>0</mu2>
            </ode>
          </friction>
        </surface>
      </collision>
      <visual name="Climber1_visual">
        <pose>-0.00362463179526776 -0.0265995667576986 0.0830460348138553 0 0 0</pose>
        <material>
          <ambient>0 0 1 1</ambient>
          <diffuse>0 0 1 1</diffuse>
        </material>
        <geometry>
          <mesh>
            <scale>1 1 1</scale>
            <uri>model://SimBot2019-4/meshes/Climber1.STL</uri>
          </mesh>
        </geometry>
      </visual>
    </link>
    <joint name="Frame-Climber1" type="revolute">
      <parent>Frame</parent>
      <child>Climber1</child>
      <pose>-1.36175792864179E-16 0.0146754332423 -0.265262701386064 0 6.28318530717959 3.14159265358979</pose>
      <axis>
        <xyz>1 1.4891775285408E-16 -6.11592854247524E-16</xyz>
        <dynamics>
          <damping>1</damping>
          <friction>1</friction>
        </dynamics>
        <limit>
          <upper>2.4</upper>
          <lower>0</lower>
          <effort>100</effort>
        </limit>
      </axis>
    </joint>
    <link name="Bumpers">
      <gravity>1</gravity>
      <self_collide>0</self_collide>
      <pose>-0.409584647856141 4.15478934425978E-15 -0.000359091198846843 -1.5707963267949 0 1.5707963267949</pose>
      <must_be_base_link>0</must_be_base_link>
      <velocity_decay>
        <linear>0</linear>
        <angular>0</angular>
      </velocity_decay>
      <inertial>
        <mass>0.413207943277132</mass>
        <pose>0 0 0 0 0 0</pose>
        <inertia>
          <ixx>8.96616576612369E-07</ixx>
          <ixy>0.000220051172388853</ixy>
          <ixz>2.46183247718063E-18</ixz>
          <iyy>0.0540058256034707</iyy>
          <iyz>1.00309386399555E-20</iyz>
          <izz>0.0540067222200473</izz>
        </inertia>
      </inertial>
      <collision name="Bumpers_collision">
        <pose>-4.06384328294321E-15 -0.000359091198846931 -0.00318463845622289 0 0 0</pose>
        <geometry>
          <mesh>
            <scale>1 1 1</scale>
            <uri>model://SimBot2019-4/meshes/Bumpers_col.STL</uri>
          </mesh>
        </geometry>
        <surface>
          <contact>
            <ode />
          </contact>
          <friction>
            <ode>
              <mu>1</mu>
              <mu2>1</mu2>
            </ode>
          </friction>
        </surface>
      </collision>
      <visual name="Bumpers_visual">
        <pose>-4.06384328294321E-15 -0.000359091198846931 -0.00318463845622289 0 0 0</pose>
        <material>
          <ambient>1 0 0 1</ambient>
          <diffuse>1 0 0 1</diffuse>
        </material>
        <geometry>
          <mesh>
            <scale>1 1 1</scale>
            <uri>model://SimBot2019-4/meshes/Bumpers.STL</uri>
          </mesh>
        </geometry>
      </visual>
    </link>
    <joint name="Frame-Bumpers" type="prismatic">
      <parent>Frame</parent>
      <child>Bumpers</child>
      <pose>0.190499999999996 -3.79470760369927E-19 0.377815370943695 0 0 0</pose>
      <axis>
        <xyz>0 1 0</xyz>
        <dynamics>
          <damping>0</damping>
          <friction>0</friction>
        </dynamics>
        <limit>
          <upper>0</upper>
          <lower>0</lower>
          <effort>1</effort>
        </limit>
      </axis>
    </joint>
    <link name="Climber2">
      <gravity>1</gravity>
      <self_collide>0</self_collide>
      <pose>-0.406400009399918 9.02389295287339E-17 8.71268615132043E-17-1.5708 0 1.5708</pose>
      <must_be_base_link>0</must_be_base_link>
      <velocity_decay>
        <linear>0</linear>
        <angular>0</angular>
      </velocity_decay>
      <inertial>
        <mass>0.403193478176846</mass>
        <pose>0.00362463179526282 0.0659461435902103 0.0193650485046986 0 0 0</pose>
        <inertia>
          <ixx>4.13E-06</ixx>
          <ixy>1.2E-06</ixy>
          <ixz>0.0005</ixz>
          <iyy>0.005</iyy>
          <iyz>4E-08</iyz>
          <izz>0.005</izz>
        </inertia>
      </inertial>
      <collision name="Climber2_collision">
        <pose>0 0 0 0 0 0</pose>
        <geometry>
          <mesh>
            <scale>1 1 1</scale>
            <uri>model://SimBot2019-4/meshes/Climber2_col.STL</uri>
          </mesh>
        </geometry>
        <surface>
          <contact>
            <ode />
          </contact>
          <friction>
            <ode>
              <mu>1</mu>
              <mu2>1</mu2>
            </ode>
          </friction>
        </surface>
      </collision>
      <visual name="Climber2_visual">
        <pose>0 0 0 0 0 0</pose>
        <material>
          <ambient>0 0.250980392156863 0.501960784313725 1</ambient>
          <diffuse>0 0.250980392156863 0.501960784313725 1</diffuse>
        </material>
        <geometry>
          <mesh>
            <scale>1 1 1</scale>
            <uri>model://SimBot2019-4/meshes/Climber2.STL</uri>
          </mesh>
        </geometry>
      </visual>
    </link>
    <joint name="Climber1-Climber2" type="revolute">
      <parent>Climber1</parent>
      <child>Climber2</child>
      <pose>0.00362463179526294 0.0235235511000238 0.261018975648933 0 5.21506836217076E-16 3.09090404763131</pose>
      <axis>
        <xyz>-0.998715607651152 -0.0506669027471588 -1.04234385304384E-15</xyz>
        <dynamics>
          <damping>1</damping>
          <friction>1</friction>
        </dynamics>
        <limit>
          <upper>2.4</upper>
          <lower>0</lower>
          <effort>100</effort>
        </limit>
      </axis>
    </joint>
    <plugin name="Frame-R1Wheel_motor" filename="libgz_dc_motor.so">
      <joint>Frame-R1Wheel</joint>
      <topic>/gazebo/frc/simulator/pwm/1</topic>
      <multiplier>10</multiplier>
    </plugin>
    <plugin name="Frame-R2Wheel_motor" filename="libgz_dc_motor.so">
      <joint>Frame-R2Wheel</joint>
      <topic>/gazebo/frc/simulator/pwm/1</topic>
      <multiplier>10</multiplier>
    </plugin>
    <plugin name="Frame-R3Wheel_motor" filename="libgz_dc_motor.so">
      <joint>Frame-R3Wheel</joint>
      <topic>/gazebo/frc/simulator/pwm/3</topic>
      <multiplier>10</multiplier>
    </plugin>
    <plugin name="Frame-L1Wheel_motor" filename="libgz_dc_motor.so">
      <joint>Frame-L1Wheel</joint>
      <topic>/gazebo/frc/simulator/pwm/4</topic>
      <multiplier>10</multiplier>
    </plugin>
    <plugin name="Frame-L2Wheel_motor" filename="libgz_dc_motor.so">
      <joint>Frame-L2Wheel</joint>
      <topic>/gazebo/frc/simulator/pwm/4</topic>
      <multiplier>10</multiplier>
    </plugin>
    <plugin name="Frame-L3Wheel_motor" filename="libgz_dc_motor.so">
      <joint>Frame-L3Wheel</joint>
      <topic>/gazebo/frc/simulator/pwm/4</topic>
      <multiplier>10</multiplier>
    </plugin>
    <plugin name="Frame-Climber1_motor" filename="libgz_dc_motor.so">
      <joint>Frame-Climber1</joint>
      <topic>/gazebo/frc/simulator/pwm/6</topic>
      <multiplier>100</multiplier>
    </plugin>
    <plugin name="Climber1-Climber2_motor" filename="libgz_dc_motor.so">
      <joint>Climber1-Climber2</joint>
      <topic>/gazebo/frc/simulator/pwm/6</topic>
      <multiplier>100</multiplier>
    </plugin>
    <model name='Elevator'>
        <pose frame=''>-0.61 -0.265 0.03 3.14159 -0.003567 3.14159</pose>
        <plugin name='clock' filename='libgz_clock.so'>
          <topic>/gazebo/frc/time</topic>
        </plugin>
        <link name='FrameBase'>
          <gravity>1</gravity>
          <self_collide>0</self_collide>
          <pose frame=''>-0.069233 0.266711 -0.01355 -1.5708 0 0</pose>
          <must_be_base_link>0</must_be_base_link>
          <velocity_decay>
            <linear>0</linear>
            <angular>0</angular>
          </velocity_decay>
          <inertial>
            <mass>0.967597</mass>
            <pose frame=''>0 0 0 0 -0 0</pose>
            <inertia>
              <ixx>0.00430893</ixx>
              <ixy>8.21392e-06</ixy>
              <ixz>2.89565e-07</ixz>
              <iyy>0.0187849</iyy>
              <iyz>1.69755e-08</iyz>
              <izz>0.0144998</izz>
            </inertia>
          </inertial>
          <collision name='FrameBase_collision'>
            <pose frame=''>0.031133 -0.00085 -1.1e-05 0 -0 0</pose>
            <geometry>
              <mesh>
                <scale>1 1 1</scale>
                <uri>model://Elevator/meshes/FrameBase_col.STL</uri>
              </mesh>
            </geometry>
            <surface>
              <contact>
                <ode/>
              </contact>
              <friction>
                <ode>
                  <mu>0</mu>
                  <mu2>0</mu2>
                </ode>
                <torsional>
                  <ode/>
                </torsional>
              </friction>
              <bounce/>
            </surface>
            <max_contacts>10</max_contacts>
          </collision>
          <visual name='FrameBase_visual'>
            <pose frame=''>0.031133 -0.00085 -1.1e-05 0 -0 0</pose>
            <material>
              <ambient>0.501961 0.501961 0.501961 1</ambient>
              <diffuse>0.501961 0.501961 0.501961 1</diffuse>
            </material>
            <geometry>
              <mesh>
                <scale>1 1 1</scale>
                <uri>model://Elevator/meshes/FrameBase.STL</uri>
              </mesh>
            </geometry>
          </visual>
          <enable_wind>0</enable_wind>
          <kinematic>0</kinematic>
        </link>
        <link name='ElevatorBase'>
          <gravity>1</gravity>
          <self_collide>0</self_collide>
          <pose frame=''>-0.048922 0.266697 -0.597377 -1.5708 0 0</pose>
          <must_be_base_link>0</must_be_base_link>
          <velocity_decay>
            <linear>0</linear>
            <angular>0</angular>
          </velocity_decay>
          <inertial>
            <mass>6.18862</mass>
            <pose frame=''>0 0 0 0 -0 0</pose>
            <inertia>
              <ixx>0.815372</ixx>
              <ixy>0.00115872</ixy>
              <ixz>3.38872e-06</ixz>
              <iyy>0.276563</iyy>
              <iyz>4.87362e-05</iyz>
              <izz>0.575488</izz>
            </inertia>
          </inertial>
          <collision name='ElevatorBase_collision'>
            <pose frame=''>0.010822 -0.584677 3e-06 0 -0 0</pose>
            <geometry>
              <mesh>
                <scale>1 1 1</scale>
                <uri>model://Elevator/meshes/ElevatorBase_col.STL</uri>
              </mesh>
            </geometry>
            <surface>
              <contact>
                <ode/>
              </contact>
              <friction>
                <ode>
                  <mu>0</mu>
                  <mu2>0</mu2>
                </ode>
                <torsional>
                  <ode/>
                </torsional>
              </friction>
              <bounce/>
            </surface>
            <max_contacts>10</max_contacts>
          </collision>
          <visual name='ElevatorBase_visual'>
            <pose frame=''>0.010822 -0.584677 3e-06 0 -0 0</pose>
            <material>
              <ambient>0.501961 0.501961 0.501961 1</ambient>
              <diffuse>0.501961 0.501961 0.501961 1</diffuse>
            </material>
            <geometry>
              <mesh>
                <scale>1 1 1</scale>
                <uri>model://Elevator/meshes/ElevatorBase.STL</uri>
              </mesh>
            </geometry>
          </visual>
          <enable_wind>0</enable_wind>
          <kinematic>0</kinematic>
        </link>
        <joint name='FrameBase-ElevatorBase' type='revolute'>
          <parent>FrameBase</parent>
          <child>ElevatorBase</child>
          <pose frame=''>-0.039673 -0.568802 0 0 -0 0</pose>
          <axis>
            <xyz>-0 -0 1</xyz>
            <dynamics>
              <damping>1</damping>
              <friction>1</friction>
              <spring_reference>0</spring_reference>
              <spring_stiffness>0</spring_stiffness>
            </dynamics>
            <limit>
              <upper>0</upper>
              <lower>0</lower>
              <effort>1</effort>
            </limit>
            <use_parent_model_frame>0</use_parent_model_frame>
          </axis>
        </joint>
        <link name='Stage1'>
          <gravity>1</gravity>
          <self_collide>0</self_collide>
          <pose frame=''>-0.044951 0.268157 -0.614138 -1.5708 0 0</pose>
          <must_be_base_link>0</must_be_base_link>
          <velocity_decay>
            <linear>0</linear>
            <angular>0</angular>
          </velocity_decay>
          <inertial>
            <mass>5.14333</mass>
            <pose frame=''>0 0 0 0 -0 0</pose>
            <inertia>
              <ixx>0.481772</ixx>
              <ixy>0.0174063</ixy>
              <ixz>0.00037574</ixz>
              <iyy>0.106616</iyy>
              <iyz>0.00366235</iyz>
              <izz>0.379693</izz>
            </inertia>
          </inertial>
          <collision name='Stage1_collision'>
            <pose frame=''>0.006851 -0.601438 -0.001457 0 -0 0</pose>
            <geometry>
              <mesh>
                <scale>1 1 1</scale>
                <uri>model://Elevator/meshes/Stage1_col.STL</uri>
              </mesh>
            </geometry>
            <surface>
              <contact>
                <ode/>
              </contact>
              <friction>
                <ode>
                  <mu>0</mu>
                  <mu2>0</mu2>
                </ode>
                <torsional>
                  <ode/>
                </torsional>
              </friction>
              <bounce/>
            </surface>
            <max_contacts>10</max_contacts>
          </collision>
          <visual name='Stage1_visual'>
            <pose frame=''>0.006851 -0.601438 -0.001457 0 -0 0</pose>
            <material>
              <ambient>0.501961 0.501961 0.501961 1</ambient>
              <diffuse>0.501961 0.501961 0.501961 1</diffuse>
            </material>
            <geometry>
              <mesh>
                <scale>1 1 1</scale>
                <uri>model://Elevator/meshes/Stage1.STL</uri>
              </mesh>
            </geometry>
          </visual>
          <enable_wind>0</enable_wind>
          <kinematic>0</kinematic>
        </link>
        <joint name='ElevatorBase-Stage1' type='prismatic'>
          <parent>ElevatorBase</parent>
          <child>Stage1</child>
          <pose frame=''>0.006851 -0 0.230369 0 -0 -1.5708</pose>
          <axis>
            <xyz>1 0 0</xyz>
            <dynamics>
              <damping>1</damping>
              <friction>1</friction>
              <spring_reference>0</spring_reference>
              <spring_stiffness>0</spring_stiffness>
            </dynamics>
            <limit>
              <upper>0</upper>
              <lower>0</lower>
              <effort>1</effort>
            </limit>
            <use_parent_model_frame>0</use_parent_model_frame>
          </axis>
        </joint>
        <link name='Stage2'>
          <gravity>1</gravity>
          <self_collide>0</self_collide>
          <pose frame=''>-0.0381 0.266705 -0.630865 -1.5708 0 0</pose>
          <must_be_base_link>0</must_be_base_link>
          <velocity_decay>
            <linear>0</linear>
            <angular>0</angular>
          </velocity_decay>
          <inertial>
            <mass>4.28523</mass>
            <pose frame=''>0 0 0 0 -0 0</pose>
            <inertia>
              <ixx>0.17601</ixx>
              <ixy>2.36116e-09</ixy>
              <ixz>5.79863e-13</ixz>
              <iyy>0.0234279</iyy>
              <iyz>9.4653e-06</iyz>
              <izz>0.152582</izz>
            </inertia>
          </inertial>
          <collision name='Stage2_collision'>
            <pose frame=''>0 -0.618165 -5e-06 0 -0 0</pose>
            <geometry>
              <mesh>
                <scale>1 1 1</scale>
                <uri>model://Elevator/meshes/Stage2_col.STL</uri>
              </mesh>
            </geometry>
            <surface>
              <contact>
                <ode/>
              </contact>
              <friction>
                <ode>
                  <mu>0</mu>
                  <mu2>0</mu2>
                </ode>
                <torsional>
                  <ode/>
                </torsional>
              </friction>
              <bounce/>
            </surface>
            <max_contacts>10</max_contacts>
          </collision>
          <visual name='Stage2_visual'>
            <pose frame=''>0 -0.618165 -5e-06 0 -0 0</pose>
            <material>
              <ambient>0.501961 0.501961 0.501961 1</ambient>
              <diffuse>0.501961 0.501961 0.501961 1</diffuse>
            </material>
            <geometry>
              <mesh>
                <scale>1 1 1</scale>
                <uri>model://Elevator/meshes/Stage2.STL</uri>
              </mesh>
            </geometry>
          </visual>
          <enable_wind>0</enable_wind>
          <kinematic>0</kinematic>
        </link>
        <joint name='Stage1-Stage2' type='prismatic'>
          <parent>Stage1</parent>
          <child>Stage2</child>
          <pose frame=''>0 -0 0.231821 0 -0 1.5708</pose>
          <axis>
            <xyz>-1 -0 0</xyz>
            <dynamics>
              <damping>1</damping>
              <friction>1</friction>
              <spring_reference>0</spring_reference>
              <spring_stiffness>0</spring_stiffness>
            </dynamics>
            <limit>
              <upper>0</upper>
              <lower>0</lower>
              <effort>1</effort>
            </limit>
            <use_parent_model_frame>0</use_parent_model_frame>
          </axis>
        </joint>
        <link name='Carriage'>
          <gravity>1</gravity>
          <self_collide>0</self_collide>
          <pose frame=''>-0.0381 0.2667 -0.281063 -1.5708 0 0</pose>
          <must_be_base_link>0</must_be_base_link>
          <velocity_decay>
            <linear>0</linear>
            <angular>0</angular>
          </velocity_decay>
          <inertial>
            <mass>0.952467</mass>
            <pose frame=''>0 0 0 0 -0 0</pose>
            <inertia>
              <ixx>0.00444645</ixx>
              <ixy>1.5081e-11</ixy>
              <ixz>1.27972e-11</ixz>
              <iyy>0.00123828</iyy>
              <iyz>2.46468e-11</iyz>
              <izz>0.00368569</izz>
            </inertia>
          </inertial>
          <collision name='Carriage_collision'>
            <pose frame=''>-0 -0.268363 -0 0 -0 0</pose>
            <geometry>
              <mesh>
                <scale>1 1 1</scale>
                <uri>model://Elevator/meshes/Carriage_col.STL</uri>
              </mesh>
            </geometry>
            <surface>
              <contact>
                <ode/>
              </contact>
              <friction>
                <ode>
                  <mu>0</mu>
                  <mu2>0</mu2>
                </ode>
                <torsional>
                  <ode/>
                </torsional>
              </friction>
              <bounce/>
            </surface>
            <max_contacts>10</max_contacts>
          </collision>
          <visual name='Carriage_visual'>
            <pose frame=''>-0 -0.268363 -0 0 -0 0</pose>
            <material>
              <ambient>0.25098 0.501961 0.501961 1</ambient>
              <diffuse>0.25098 0.501961 0.501961 1</diffuse>
            </material>
            <geometry>
              <mesh>
                <scale>1 1 1</scale>
                <uri>model://Elevator/meshes/Carriage.STL</uri>
              </mesh>
            </geometry>
          </visual>
          <sensor name='CarriageCamera' type='camera'>
            <visualize>1</visualize>
            <always_on>1</always_on>
            <pose frame=''>0.0381 -0.085832 -0 1.5708 -0 0</pose>
            <camera name='Carriagecamera'>
              <horizontal_fov>1.5708</horizontal_fov>
              <image>
                <width>320</width>
                <height>240</height>
              </image>
              <clip>
                <near>0.1</near>
                <far>100</far>
              </clip>
            </camera>
          </sensor>
          <enable_wind>0</enable_wind>
          <kinematic>0</kinematic>
        </link>
        <joint name='Stage2-Carriage' type='prismatic'>
          <parent>Stage2</parent>
          <child>Carriage</child>
          <pose frame=''>-0 -0 0.231826 0 -0 1.5708</pose>
          <axis>
            <xyz>-1 -0 0</xyz>
            <dynamics>
              <damping>1</damping>
              <friction>1</friction>
              <spring_reference>0</spring_reference>
              <spring_stiffness>0</spring_stiffness>
            </dynamics>
            <limit>
              <upper>0</upper>
              <lower>0</lower>
              <effort>1</effort>
            </limit>
            <use_parent_model_frame>0</use_parent_model_frame>
          </axis>
        </joint>
        <link name='TilterBaseArm'>
          <gravity>1</gravity>
          <self_collide>0</self_collide>
          <pose frame=''>-0.39609 0.261767 -0.206919 -1.5708 0 0</pose>
          <must_be_base_link>0</must_be_base_link>
          <velocity_decay>
            <linear>0</linear>
            <angular>0</angular>
          </velocity_decay>
          <inertial>
            <mass>0.414124</mass>
            <pose frame=''>0 0 0 0 -0 0</pose>
            <inertia>
              <ixx>0.0131141</ixx>
              <ixy>0.00161299</ixy>
              <ixz>0.000129718</ixz>
              <iyy>0.0131182</iyy>
              <iyz>0.000129552</iyz>
              <izz>0.00322598</izz>
            </inertia>
          </inertial>
          <collision name='TilterBaseArm_collision'>
            <pose frame=''>0.35799 -0.194219 0.004933 0 -0 0</pose>
            <geometry>
              <mesh>
                <scale>1 1 1</scale>
                <uri>model://Elevator/meshes/TilterBaseArm_col.STL</uri>
              </mesh>
            </geometry>
            <surface>
              <contact>
                <ode/>
              </contact>
              <friction>
                <ode>
                  <mu>0</mu>
                  <mu2>0</mu2>
                </ode>
                <torsional>
                  <ode/>
                </torsional>
              </friction>
              <bounce/>
            </surface>
            <max_contacts>10</max_contacts>
          </collision>
          <visual name='TilterBaseArm_visual'>
            <pose frame=''>0.35799 -0.194219 0.004933 0 -0 0</pose>
            <material>
              <ambient>0.501961 0.501961 0.501961 1</ambient>
              <diffuse>0.501961 0.501961 0.501961 1</diffuse>
            </material>
            <geometry>
              <mesh>
                <scale>1 1 1</scale>
                <uri>model://Elevator/meshes/TilterBaseArm.STL</uri>
              </mesh>
            </geometry>
          </visual>
          <enable_wind>0</enable_wind>
          <kinematic>0</kinematic>
        </link>
        <joint name='ElevatorBase-TilterBaseArm' type='fixed'>
          <parent>ElevatorBase</parent>
          <child>TilterBaseArm</child>
          <pose frame=''>-0.18811 -0.187869 0 0 -0 0</pose>
          <axis>
            <xyz>0 0 -1</xyz>
            <dynamics>
              <damping>1</damping>
              <friction>1</friction>
              <spring_reference>0</spring_reference>
              <spring_stiffness>0</spring_stiffness>
            </dynamics>
            <limit>
              <upper>0</upper>
              <lower>0</lower>
              <effort>1</effort>
            </limit>
            <use_parent_model_frame>0</use_parent_model_frame>
          </axis>
        </joint>
        <link name='TilterEleArm'>
          <gravity>1</gravity>
          <self_collide>0</self_collide>
          <pose frame=''>-0.185346 0.2667 -0.369993 -1.5708 0 0</pose>
          <must_be_base_link>0</must_be_base_link>
          <velocity_decay>
            <linear>0</linear>
            <angular>0</angular>
          </velocity_decay>
          <inertial>
            <mass>0.514276</mass>
            <pose frame=''>0 0 0 0 -0 0</pose>
            <inertia>
              <ixx>0.159756</ixx>
              <ixy>0</ixy>
              <ixz>0</ixz>
              <iyy>0.159756</iyy>
              <iyz>0</iyz>
              <izz>0</izz>
            </inertia>
          </inertial>
          <collision name='TilterEleArm_collision'>
            <pose frame=''>0.147246 -0.357293 0 0 -0 0</pose>
            <geometry>
              <mesh>
                <scale>1 1 1</scale>
                <uri>model://Elevator/meshes/TilterEleArm_col.STL</uri>
              </mesh>
            </geometry>
            <surface>
              <contact>
                <ode/>
              </contact>
              <friction>
                <ode>
                  <mu>0</mu>
                  <mu2>0</mu2>
                </ode>
                <torsional>
                  <ode/>
                </torsional>
              </friction>
              <bounce/>
            </surface>
            <max_contacts>10</max_contacts>
          </collision>
          <visual name='TilterEleArm_visual'>
            <pose frame=''>0.147246 -0.357293 0 0 -0 0</pose>
            <material>
              <ambient>0.501961 0.501961 0.501961 1</ambient>
              <diffuse>0.501961 0.501961 0.501961 1</diffuse>
            </material>
            <geometry>
              <mesh>
                <scale>1 1 1</scale>
                <uri>model://Elevator/meshes/TilterEleArm.STL</uri>
              </mesh>
            </geometry>
          </visual>
          <enable_wind>0</enable_wind>
          <kinematic>0</kinematic>
        </link>
        <joint name='ElevatorBase-TilterEleArm' type='fixed'>
          <parent>ElevatorBase</parent>
          <child>TilterEleArm</child>
          <pose frame=''>0.147246 0.099657 0 0 -0 0</pose>
          <axis>
            <xyz>0 0 1</xyz>
            <dynamics>
              <damping>1</damping>
              <friction>1</friction>
              <spring_reference>0</spring_reference>
              <spring_stiffness>0</spring_stiffness>
            </dynamics>
            <limit>
              <upper>0</upper>
              <lower>0</lower>
              <effort>1</effort>
            </limit>
            <use_parent_model_frame>0</use_parent_model_frame>
          </axis>
        </joint>
        <plugin name='ElevatorBase-Stage1_motor' filename='libgz_dc_motor.so'>
          <joint>ElevatorBase-Stage1</joint>
          <topic>/gazebo/frc/simulator/pwm/5</topic>
          <multiplier>20</multiplier>
        </plugin>
        <plugin name='Stage1-Stage2_motor' filename='libgz_dc_motor.so'>
          <joint>Stage1-Stage2</joint>
          <topic>/gazebo/frc/simulator/pwm/5</topic>
          <multiplier>20</multiplier>
        </plugin>
        <plugin name='Stage2-Carriage_motor' filename='libgz_dc_motor.so'>
          <joint>Stage2-Carriage</joint>
          <topic>/gazebo/frc/simulator/pwm/5</topic>
          <multiplier>20</multiplier>
        </plugin>
      </model>
      <joint name="model1-model2" type="fixed">
      <parent>Frame</parent>
      <child>FrameBase</child>
    </joint>
  </model>
</sdf>