<?xml version="1.0" encoding="utf-8"?>
<sdf version="1.5">
  <model name="2015-Robot">
    <pose>0 0 -0.205244741154153 0 0 0</pose>
    <plugin name="clock" filename="libclock.so">
      <topic>/gazebo/frc/time</topic>
    </plugin>
    <link name="Chassis">
      <gravity>1</gravity>
      <self_collide>0</self_collide>
      <pose>-0.401025500465737 0.230776991603709 0.286644381625399 0 0 0</pose>
      <must_be_base_link>1</must_be_base_link>
      <velocity_decay>
        <linear>0</linear>
        <angular>0</angular>
      </velocity_decay>
      <inertial>
        <mass>63.5665306425937</mass>
        <pose>0 0 0 0 0 0</pose>
        <inertia>
          <ixx>12.3422869983664</ixx>
          <ixy>0.144478033171119</ixy>
          <ixz>0.0351416687291587</ixz>
          <iyy>9.97756819183086</iyy>
          <iyz>0.0194041878028764</iyz>
          <izz>15.7849892429057</izz>
        </inertia>
      </inertial>
      <collision name="Chassis_collision">
        <pose>-0.582059564363616 -0.323087667293095 0.371697829264734 0 0 0</pose>
        <geometry>
          <mesh>
            <scale>1 1 1</scale>
            <uri>model://2015-Robot/meshes/Chassis_col.STL</uri>
          </mesh>
        </geometry>
        <surface>
          <contact>
            <ode />
          </contact>
          <friction>
            <ode>
              <mu>0</mu>
              <mu2>0</mu2>
            </ode>
          </friction>
        </surface>
      </collision>
      <visual name="Chassis_visual">
        <pose>-0.582059564363616 -0.323087667293095 0.371697829264734 0 0 0</pose>
        <material>
          <ambient>0 0 1 1</ambient>
          <diffuse>0 0 1 1</diffuse>
        </material>
        <geometry>
          <mesh>
            <scale>1 1 1</scale>
            <uri>model://2015-Robot/meshes/Chassis.STL</uri>
          </mesh>
        </geometry>
      </visual>
      <sensor name="ChassisUltrasonic" type="sonar">
        <always_on>1</always_on>
        <visualize>1</visualize>
        <pose>-0.625093566490494 -0.216338403469202 0.0121117011848754 1.57079632679492 0 1.5707963267949</pose>
        <sonar>
          <min>0</min>
          <max>2</max>
          <radius>0.12</radius>
        </sonar>
      </sensor>
    </link>
    <link name="LFPivot">
      <gravity>1</gravity>
      <self_collide>0</self_collide>
      <pose>-0.95870454858405 -0.0736713957466903 0.512629032997598 0 0 0</pose>
      <must_be_base_link>0</must_be_base_link>
      <velocity_decay>
        <linear>0</linear>
        <angular>0</angular>
      </velocity_decay>
      <inertial>
        <mass>1.44739278538339</mass>
        <pose>0 0 0 0 0 0</pose>
        <inertia>
          <ixx>0.00233676058796664</ixx>
          <ixy>6.15567615603567E-07</ixy>
          <ixz>7.63616124093722E-06</ixz>
          <iyy>0.00181599181965529</iyy>
          <iyz>6.17355468187915E-05</iyz>
          <izz>0.00157703325312505</izz>
        </inertia>
      </inertial>
      <collision name="LFPivot_collision">
        <pose>-0.0243805162453027 -0.0186392799426959 0.145713177892535 0 0 0</pose>
        <geometry>
          <mesh>
            <scale>1 1 1</scale>
            <uri>model://2015-Robot/meshes/LFPivot_col.STL</uri>
          </mesh>
        </geometry>
        <surface>
          <contact>
            <ode />
          </contact>
          <friction>
            <ode>
              <mu>0</mu>
              <mu2>0</mu2>
            </ode>
          </friction>
        </surface>
      </collision>
      <visual name="LFPivot_visual">
        <pose>-0.0243805162453027 -0.0186392799426959 0.145713177892535 0 0 0</pose>
        <material>
          <ambient>0 0 0 1</ambient>
          <diffuse>0 0 0 1</diffuse>
        </material>
        <geometry>
          <mesh>
            <scale>1 1 1</scale>
            <uri>model://2015-Robot/meshes/LFPivot.STL</uri>
          </mesh>
        </geometry>
      </visual>
    </link>
    <joint name="Chassis-LFPivot" type="revolute">
      <parent>Chassis</parent>
      <child>LFPivot</child>
      <pose>-0.000145451415950387 0.0438263957466912 0.0144209670024015 0 0 1.5707963267949</pose>
      <axis>
        <xyz>1 -3.85032727000361E-16 0</xyz>
        <dynamics>
          <damping>2</damping>
          <friction>1</friction>
        </dynamics>
        <limit>
          <effort>200</effort>
        </limit>
      </axis>
    </joint>
    <link name="LFWheel">
      <gravity>1</gravity>
      <self_collide>0</self_collide>
      <pose>-0.958861217170619 -0.127825222544386 0.528166733571689 0 0 0</pose>
      <must_be_base_link>0</must_be_base_link>
      <velocity_decay>
        <linear>0</linear>
        <angular>0</angular>
      </velocity_decay>
      <inertial>
        <mass>1.8555319646432</mass>
        <pose>0 0 0 0 0 0</pose>
        <inertia>
          <ixx>0.00118622871860514</ixx>
          <ixy>6.74556798881706E-10</ixy>
          <ixz>7.21215725396255E-06</ixz>
          <iyy>0.00118617044109406</iyy>
          <iyz>3.52253400263471E-08</iyz>
          <izz>0.00190657662977929</izz>
        </inertia>
      </inertial>
      <collision name="LFWheel_collision">
        <pose>-0.0242238476587333 0.0355145468549995 0.130175477318445 0 0 0</pose>
        <geometry>
          <mesh>
            <scale>1 1 1</scale>
            <uri>model://2015-Robot/meshes/LFWheel_col.STL</uri>
          </mesh>
        </geometry>
        <surface>
          <contact>
            <ode />
          </contact>
          <friction>
            <ode>
              <mu>1</mu>
              <mu2>1</mu2>
            </ode>
          </friction>
        </surface>
      </collision>
      <visual name="LFWheel_visual">
        <pose>-0.0242238476587333 0.0355145468549995 0.130175477318445 0 0 0</pose>
        <material>
          <ambient>0.501960784313725 0.501960784313725 0.501960784313725 1</ambient>
          <diffuse>0.501960784313725 0.501960784313725 0.501960784313725 1</diffuse>
        </material>
        <geometry>
          <mesh>
            <scale>1 1 1</scale>
            <uri>model://2015-Robot/meshes/LFWheel.STL</uri>
          </mesh>
        </geometry>
      </visual>
    </link>
    <joint name="LFPivot-LFWheel" type="revolute">
      <parent>LFPivot</parent>
      <child>LFWheel</child>
      <pose>-2.69362340808363E-06 -2.77455613595379E-07 0.000273096813577206 0 1.56078767417446 3.14159265358979</pose>
      <axis>
        <xyz>0.999799660435128 1.09617717515883E-15 -0.0200159684702737</xyz>
        <dynamics>
          <damping>1</damping>
          <friction>1</friction>
        </dynamics>
        <limit>
          <effort>100</effort>
        </limit>
      </axis>
    </joint>
    <link name="RFPivot">
      <gravity>1</gravity>
      <self_collide>0</self_collide>
      <pose>-0.958995053722582 -0.0736748369935368 0.0588735140965105 0 0 0</pose>
      <must_be_base_link>0</must_be_base_link>
      <velocity_decay>
        <linear>0</linear>
        <angular>0</angular>
      </velocity_decay>
      <inertial>
        <mass>1.4475795191339</mass>
        <pose>0 0 0 0 0 0</pose>
        <inertia>
          <ixx>0.0023369686508179</ixx>
          <ixy>6.30923439869121E-07</ixy>
          <ixz>7.62480866374576E-06</ixz>
          <iyy>0.00181606645789441</iyy>
          <iyz>6.16372020802289E-05</iyz>
          <izz>0.00157717026566569</izz>
        </inertia>
      </inertial>
      <collision name="RFPivot_collision">
        <pose>-0.0240900111067707 -0.0186358386958493 0.599468696793623 0 0 0</pose>
        <geometry>
          <mesh>
            <scale>1 1 1</scale>
            <uri>model://2015-Robot/meshes/RFPivot_col.STL</uri>
          </mesh>
        </geometry>
        <surface>
          <contact>
            <ode />
          </contact>
          <friction>
            <ode>
              <mu>0</mu>
              <mu2>0</mu2>
            </ode>
          </friction>
        </surface>
      </collision>
      <visual name="RFPivot_visual">
        <pose>-0.0240900111067707 -0.0186358386958493 0.599468696793623 0 0 0</pose>
        <material>
          <ambient>0 0 0 1</ambient>
          <diffuse>0 0 0 1</diffuse>
        </material>
        <geometry>
          <mesh>
            <scale>1 1 1</scale>
            <uri>model://2015-Robot/meshes/RFPivot.STL</uri>
          </mesh>
        </geometry>
      </visual>
    </link>
    <joint name="Chassis-RFPivot" type="revolute">
      <parent>Chassis</parent>
      <child>RFPivot</child>
      <pose>0.000145053722581917 0.0438298369935367 -0.0144235140965107 0 0 1.5707963267949</pose>
      <axis>
        <xyz>1 2.22044604925031E-16 0</xyz>
        <dynamics>
          <damping>2</damping>
          <friction>1</friction>
        </dynamics>
        <limit>
          <effort>200</effort>
        </limit>
      </axis>
    </joint>
    <link name="RFWheel">
      <gravity>1</gravity>
      <self_collide>0</self_collide>
      <pose>-0.958838782829381 -0.127825222544386 0.0433332664283111 0 0 0</pose>
      <must_be_base_link>0</must_be_base_link>
      <velocity_decay>
        <linear>0</linear>
        <angular>0</angular>
      </velocity_decay>
      <inertial>
        <mass>1.8555319646432</mass>
        <pose>0 0 0 0 0 0</pose>
        <inertia>
          <ixx>0.00118622871860514</ixx>
          <ixy>6.74556799077305E-10</ixy>
          <ixz>7.21215725396224E-06</ixz>
          <iyy>0.00118617044109405</iyy>
          <iyz>3.52253400264321E-08</iyz>
          <izz>0.00190657662977929</izz>
        </inertia>
      </inertial>
      <collision name="RFWheel_collision">
        <pose>-0.0242462819999717 0.0355145468550003 0.615008944461822 0 0 0</pose>
        <geometry>
          <mesh>
            <scale>1 1 1</scale>
            <uri>model://2015-Robot/meshes/RFWheel_col.STL</uri>
          </mesh>
        </geometry>
        <surface>
          <contact>
            <ode />
          </contact>
          <friction>
            <ode>
              <mu>1</mu>
              <mu2>1</mu2>
            </ode>
          </friction>
        </surface>
      </collision>
      <visual name="RFWheel_visual">
        <pose>-0.0242462819999717 0.0355145468550003 0.615008944461822 0 0 0</pose>
        <material>
          <ambient>0.501960784313725 0.501960784313725 0.501960784313725 1</ambient>
          <diffuse>0.501960784313725 0.501960784313725 0.501960784313725 1</diffuse>
        </material>
        <geometry>
          <mesh>
            <scale>1 1 1</scale>
            <uri>model://2015-Robot/meshes/RFWheel.STL</uri>
          </mesh>
        </geometry>
      </visual>
    </link>
    <joint name="RFPivot-RFWheel" type="revolute">
      <parent>RFPivot</parent>
      <child>RFWheel</child>
      <pose>2.69362340823281E-06 -2.77455613546806E-07 -0.000273096813577234 0 4.72239763300511 6.28318530717959</pose>
      <axis>
        <xyz>0.999799660435128 -1.10429877207449E-15 0.0200159684702621</xyz>
        <dynamics>
          <damping>1</damping>
          <friction>1</friction>
        </dynamics>
        <limit>
          <effort>100</effort>
        </limit>
      </axis>
    </joint>
    <link name="LRPivot">
      <gravity>1</gravity>
      <self_collide>0</self_collide>
      <pose>-0.0697049462774184 -0.0736748369935357 0.512626485903489 0 0 0</pose>
      <must_be_base_link>0</must_be_base_link>
      <velocity_decay>
        <linear>0</linear>
        <angular>0</angular>
      </velocity_decay>
      <inertial>
        <mass>1.4475795191339</mass>
        <pose>0 0 0 0 0 0</pose>
        <inertia>
          <ixx>0.0023369686508179</ixx>
          <ixy>6.30923439866244E-07</ixy>
          <ixz>7.6248086637477E-06</ixz>
          <iyy>0.00181606645789441</iyy>
          <iyz>6.16372020802319E-05</iyz>
          <izz>0.00157717026566569</izz>
        </inertia>
      </inertial>
      <collision name="LRPivot_collision">
        <pose>-0.913380118551934 -0.0186358386958504 0.145715724986644 0 0 0</pose>
        <geometry>
          <mesh>
            <scale>1 1 1</scale>
            <uri>model://2015-Robot/meshes/LRPivot_col.STL</uri>
          </mesh>
        </geometry>
        <surface>
          <contact>
            <ode />
          </contact>
          <friction>
            <ode>
              <mu>0</mu>
              <mu2>0</mu2>
            </ode>
          </friction>
        </surface>
      </collision>
      <visual name="LRPivot_visual">
        <pose>-0.913380118551934 -0.0186358386958504 0.145715724986644 0 0 0</pose>
        <material>
          <ambient>0 0 0 1</ambient>
          <diffuse>0 0 0 1</diffuse>
        </material>
        <geometry>
          <mesh>
            <scale>1 1 1</scale>
            <uri>model://2015-Robot/meshes/LRPivot.STL</uri>
          </mesh>
        </geometry>
      </visual>
    </link>
    <joint name="Chassis-LRPivot" type="revolute">
      <parent>Chassis</parent>
      <child>LRPivot</child>
      <pose>-0.000145053722581889 0.0531643369935366 0.0144235140965104 0 0 1.5707963267949</pose>
      <axis>
        <xyz>1 2.22044604925031E-16 0</xyz>
        <dynamics>
          <damping>2</damping>
          <friction>1</friction>
        </dynamics>
        <limit>
          <effort>200</effort>
        </limit>
      </axis>
    </joint>
    <link name="LRWheel">
      <gravity>1</gravity>
      <self_collide>0</self_collide>
      <pose>-0.0698612171706193 -0.127825222544386 0.528166733571689 0 0 0</pose>
      <must_be_base_link>0</must_be_base_link>
      <velocity_decay>
        <linear>0</linear>
        <angular>0</angular>
      </velocity_decay>
      <inertial>
        <mass>1.85553196464319</mass>
        <pose>0 0 0 0 0 0</pose>
        <inertia>
          <ixx>0.00118622871860513</ixx>
          <ixy>6.7455680023538E-10</ixy>
          <ixz>7.21215725396253E-06</ixz>
          <iyy>0.00118617044109405</iyy>
          <iyz>3.52253400263866E-08</iyz>
          <izz>0.00190657662977928</izz>
        </inertia>
      </inertial>
      <collision name="LRWheel_collision">
        <pose>-0.913223847658733 0.0355145468549996 0.130175477318445 0 0 0</pose>
        <geometry>
          <mesh>
            <scale>1 1 1</scale>
            <uri>model://2015-Robot/meshes/LRWheel_col.STL</uri>
          </mesh>
        </geometry>
        <surface>
          <contact>
            <ode />
          </contact>
          <friction>
            <ode>
              <mu>1</mu>
              <mu2>1</mu2>
            </ode>
          </friction>
        </surface>
      </collision>
      <visual name="LRWheel_visual">
        <pose>-0.913223847658733 0.0355145468549996 0.130175477318445 0 0 0</pose>
        <material>
          <ambient>0.501960784313725 0.501960784313725 0.501960784313725 1</ambient>
          <diffuse>0.501960784313725 0.501960784313725 0.501960784313725 1</diffuse>
        </material>
        <geometry>
          <mesh>
            <scale>1 1 1</scale>
            <uri>model://2015-Robot/meshes/LRWheel.STL</uri>
          </mesh>
        </geometry>
      </visual>
    </link>
    <joint name="LRPivot-LRWheel" type="revolute">
      <parent>LRPivot</parent>
      <child>LRWheel</child>
      <pose>-2.69362340865609E-06 -2.7745561408804E-07 0.000273096813577484 0 1.56078767417446 3.14159265358979</pose>
      <axis>
        <xyz>0.999799660435128 1.09617717515883E-15 -0.0200159684702739</xyz>
        <dynamics>
          <damping>1</damping>
          <friction>1</friction>
        </dynamics>
        <limit>
          <effort>100</effort>
        </limit>
      </axis>
    </joint>
    <link name="RRPivot">
      <gravity>1</gravity>
      <self_collide>0</self_collide>
      <pose>-0.0699950537225819 -0.0743653184534709 0.0588735140965106 0 0 0</pose>
      <must_be_base_link>0</must_be_base_link>
      <velocity_decay>
        <linear>0</linear>
        <angular>0</angular>
      </velocity_decay>
      <inertial>
        <mass>1.44757951913391</mass>
        <pose>0 0 0 0 0 0</pose>
        <inertia>
          <ixx>0.00233696865081792</ixx>
          <ixy>6.30923439868601E-07</ixy>
          <ixz>7.62480866374975E-06</ixz>
          <iyy>0.00181606645789442</iyy>
          <iyz>6.16372020802251E-05</iyz>
          <izz>0.0015771702656657</izz>
        </inertia>
      </inertial>
      <collision name="RRPivot_collision">
        <pose>-0.913090011106771 -0.0179453572359152 0.599468696793623 0 0 0</pose>
        <geometry>
          <mesh>
            <scale>1 1 1</scale>
            <uri>model://2015-Robot/meshes/RRPivot_col.STL</uri>
          </mesh>
        </geometry>
        <surface>
          <contact>
            <ode />
          </contact>
          <friction>
            <ode>
              <mu>0</mu>
              <mu2>0</mu2>
            </ode>
          </friction>
        </surface>
      </collision>
      <visual name="RRPivot_visual">
        <pose>-0.913090011106771 -0.0179453572359152 0.599468696793623 0 0 0</pose>
        <material>
          <ambient>0 0 0 1</ambient>
          <diffuse>0 0 0 1</diffuse>
        </material>
        <geometry>
          <mesh>
            <scale>1 1 1</scale>
            <uri>model://2015-Robot/meshes/RRPivot.STL</uri>
          </mesh>
        </geometry>
      </visual>
    </link>
    <joint name="Chassis-RRPivot" type="revolute">
      <parent>Chassis</parent>
      <child>RRPivot</child>
      <pose>0.000145053722581889 0.0438298369935369 -0.0144235140965108 0 0 1.5707963267949</pose>
      <axis>
        <xyz>1 2.22044604925031E-16 0</xyz>
        <dynamics>
          <damping>2</damping>
          <friction>1</friction>
        </dynamics>
        <limit>
          <effort>200</effort>
        </limit>
      </axis>
    </joint>
    <link name="RRWheel">
      <gravity>1</gravity>
      <self_collide>0</self_collide>
      <pose>-0.0698387828293809 -0.12851570400432 0.043333266428311 0 0 0</pose>
      <must_be_base_link>0</must_be_base_link>
      <velocity_decay>
        <linear>0</linear>
        <angular>0</angular>
      </velocity_decay>
      <inertial>
        <mass>1.8555319646432</mass>
        <pose>0 0 0 0 0 0</pose>
        <inertia>
          <ixx>0.00118622871860513</ixx>
          <ixy>6.74556797103717E-10</ixy>
          <ixz>7.21215725396294E-06</ixz>
          <iyy>0.00118617044109406</iyy>
          <iyz>3.52253400268494E-08</iyz>
          <izz>0.00190657662977928</izz>
        </inertia>
      </inertial>
      <collision name="RRWheel_collision">
        <pose>-0.913246281999972 0.0362050283149341 0.615008944461822 0 0 0</pose>
        <geometry>
          <mesh>
            <scale>1 1 1</scale>
            <uri>model://2015-Robot/meshes/RRWheel_col.STL</uri>
          </mesh>
        </geometry>
        <surface>
          <contact>
            <ode />
          </contact>
          <friction>
            <ode>
              <mu>1</mu>
              <mu2>1</mu2>
            </ode>
          </friction>
        </surface>
      </collision>
      <visual name="RRWheel_visual">
        <pose>-0.913246281999972 0.0362050283149341 0.615008944461822 0 0 0</pose>
        <material>
          <ambient>0.501960784313725 0.501960784313725 0.501960784313725 1</ambient>
          <diffuse>0.501960784313725 0.501960784313725 0.501960784313725 1</diffuse>
        </material>
        <geometry>
          <mesh>
            <scale>1 1 1</scale>
            <uri>model://2015-Robot/meshes/RRWheel.STL</uri>
          </mesh>
        </geometry>
      </visual>
    </link>
    <joint name="RRPivot-RRWheel" type="revolute">
      <parent>RRPivot</parent>
      <child>RRWheel</child>
      <pose>2.69362340810098E-06 -2.77455613782729E-07 -0.000273096813577345 0 4.72239763300511 6.28318530717959</pose>
      <axis>
        <xyz>0.999799660435128 -1.10429877207449E-15 0.0200159684702625</xyz>
        <dynamics>
          <damping>1</damping>
          <friction>1</friction>
        </dynamics>
        <limit>
          <effort>100</effort>
        </limit>
      </axis>
    </joint>
    <link name="Lifter">
      <gravity>1</gravity>
      <self_collide>0</self_collide>
      <pose>-0.778431631238913 0.167442853370672 0.285191434881006 0 0 0</pose>
      <must_be_base_link>0</must_be_base_link>
      <velocity_decay>
        <linear>0</linear>
        <angular>0</angular>
      </velocity_decay>
      <inertial>
        <mass>9.51516761753436</mass>
        <pose>0 0 0 0 0 0</pose>
        <inertia>
          <ixx>0.366432066309504</ixx>
          <ixy>0.0224471545650555</ixy>
          <ixz>0.000354531949222565</ixz>
          <iyy>0.509257457339072</iyy>
          <iyz>0.000268897304813689</iyz>
          <izz>0.183457975180987</izz>
        </inertia>
      </inertial>
      <collision name="Lifter_collision">
        <pose>-0.20465343359044 -0.259753529060058 0.373150776009127 0 0 0</pose>
        <geometry>
          <mesh>
            <scale>1 1 1</scale>
            <uri>model://2015-Robot/meshes/Lifter_col.STL</uri>
          </mesh>
        </geometry>
        <surface>
          <contact>
            <ode />
          </contact>
          <friction>
            <ode>
              <mu>1</mu>
              <mu2>1</mu2>
            </ode>
          </friction>
        </surface>
      </collision>
      <visual name="Lifter_visual">
        <pose>-0.20465343359044 -0.259753529060058 0.373150776009127 0 0 0</pose>
        <material>
          <ambient>1 0 0 1</ambient>
          <diffuse>1 0 0 1</diffuse>
        </material>
        <geometry>
          <mesh>
            <scale>1 1 1</scale>
            <uri>model://2015-Robot/meshes/Lifter.STL</uri>
          </mesh>
        </geometry>
      </visual>
      <sensor name="LifterCamera" type="camera">
        <visualize>1</visualize>
        <always_on>1</always_on>
        <pose>-0.208993368761087 -0.029242708536449 0.000558565119000154 1.5707963267949 0 3.14159265358979</pose>
        <camera name="Liftercamera">
          <horizontal_fov>1.5707963267949</horizontal_fov>
          <image>
            <width>320</width>
            <height>240</height>
          </image>
          <clip>
            <near>0.1</near>
            <far>100</far>
          </clip>
          <save enabled="true">
              <path>/tmp/shooter-camera</path>
          </save>
        </camera>
      </sensor>
    </link>
    <joint name="Chassis-Lifter" type="prismatic">
      <parent>Chassis</parent>
      <child>Lifter</child>
      <pose>0.143431631238934 -0.091242853370672 -0.265238202122385 0 0 1.5707963267949</pose>
      <axis>
        <xyz>1 2.22044604925031E-16 0</xyz>
        <dynamics>
          <damping>100</damping>
          <friction>5</friction>
        </dynamics>
        <limit>
          <upper>1.5</upper>
          <lower>0</lower>
          <effort>200</effort>
        </limit>
      </axis>
    </joint>
    <link name="LeftArm">
      <gravity>1</gravity>
      <self_collide>0</self_collide>
      <pose>-1.34324627354824 0.13446315869893 0.543380507029937 0 0 0</pose>
      <must_be_base_link>0</must_be_base_link>
      <velocity_decay>
        <linear>0</linear>
        <angular>0</angular>
      </velocity_decay>
      <inertial>
        <mass>1.11345618276179</mass>
        <pose>0 0 0 0 0 0</pose>
        <inertia>
          <ixx>0.00432018256891324</ixx>
          <ixy>0.00022411717574954</ixy>
          <ixz>0.0161290230269331</ixz>
          <iyy>0.0877261629901876</iyy>
          <iyz>2.53556399443232E-05</iyz>
          <izz>0.0839126397533981</izz>
        </inertia>
      </inertial>
      <collision name="LeftArm_collision">
        <pose>0.36016120871889 -0.226773834388316 0.114961703860196 0 0 0</pose>
        <geometry>
          <mesh>
            <scale>1 1 1</scale>
            <uri>model://2015-Robot/meshes/LeftArm_col.STL</uri>
          </mesh>
        </geometry>
        <surface>
          <contact>
            <ode />
          </contact>
          <friction>
            <ode>
              <mu>1</mu>
              <mu2>1</mu2>
            </ode>
          </friction>
        </surface>
      </collision>
      <visual name="LeftArm_visual">
        <pose>0.36016120871889 -0.226773834388316 0.114961703860196 0 0 0</pose>
        <material>
          <ambient>0 0 0 1</ambient>
          <diffuse>0 0 0 1</diffuse>
        </material>
        <geometry>
          <mesh>
            <scale>1 1 1</scale>
            <uri>model://2015-Robot/meshes/LeftArm.STL</uri>
          </mesh>
        </geometry>
      </visual>
    </link>
    <joint name="Lifter-LeftArm" type="revolute">
      <parent>Lifter</parent>
      <child>LeftArm</child>
      <pose>0.378046273548243 -0.0273780138647068 -0.0885719385781383 0 6.28318530717959 1.5707963267949</pose>
      <axis>
        <xyz>1 3.91279831349304E-16 4.22475028006071E-16</xyz>
        <dynamics>
          <damping>0</damping>
          <friction>0</friction>
        </dynamics>
        <limit>
          <upper>0.2</upper>
          <lower>-0.1</lower>
          <effort>200</effort>
        </limit>
      </axis>
    </joint>
    <link name="RightArm">
      <gravity>1</gravity>
      <self_collide>0</self_collide>
      <pose>-1.3524125718207 0.13453340179875 0.0630423931521605 0 0 0</pose>
      <must_be_base_link>0</must_be_base_link>
      <velocity_decay>
        <linear>0</linear>
        <angular>0</angular>
      </velocity_decay>
      <inertial>
        <mass>1.11319136820711</mass>
        <pose>0 0 0 0 0 0</pose>
        <inertia>
          <ixx>0.00227926764450931</ixx>
          <ixy>0.00021118413406714</ixy>
          <ixz>0.0103876838867992</ixz>
          <iyy>0.0868096234739407</iyy>
          <iyz>7.41904465918707E-06</iyz>
          <izz>0.0850385930782833</izz>
        </inertia>
      </inertial>
      <collision name="RightArm_collision">
        <pose>0.369327506991351 -0.226844077488136 0.595299817737973 0 0 0</pose>
        <geometry>
          <mesh>
            <scale>1 1 1</scale>
            <uri>model://2015-Robot/meshes/RightArm_col.STL</uri>
          </mesh>
        </geometry>
        <surface>
          <contact>
            <ode />
          </contact>
          <friction>
            <ode>
              <mu>1</mu>
              <mu2>1</mu2>
            </ode>
          </friction>
        </surface>
      </collision>
      <visual name="RightArm_visual">
        <pose>0.369327506991351 -0.226844077488136 0.595299817737973 0 0 0</pose>
        <material>
          <ambient>0 0 0 1</ambient>
          <diffuse>0 0 0 1</diffuse>
        </material>
        <geometry>
          <mesh>
            <scale>1 1 1</scale>
            <uri>model://2015-Robot/meshes/RightArm.STL</uri>
          </mesh>
        </geometry>
      </visual>
    </link>
    <joint name="Lifter-RightArm" type="revolute">
      <parent>Lifter</parent>
      <child>RightArm</child>
      <pose>0.387212571820704 -0.0274482569645268 0.0615661752996385 0 0 4.71238898038469</pose>
      <axis>
        <xyz>1 2.22044604925031E-16 0</xyz>
        <dynamics>
          <damping>0</damping>
          <friction>0</friction>
        </dynamics>
        <limit>
          <upper>0.2</upper>
          <lower>-0.1</lower>
          <effort>200</effort>
        </limit>
      </axis>
    </joint>
    <plugin name="Chassis_rangefinder" filename="librangefinder.so">
      <topic>/gazebo/frc/simulator/analog/6</topic>
      <sensor>ChassisUltrasonic</sensor>
    </plugin>
    <plugin name="Chassis-LFPivot_motor" filename="libdc_motor.so">
      <joint>Chassis-LFPivot</joint>
      <topic>/gazebo/frc/simulator/pwm/5</topic>
      <multiplier>25</multiplier>
    </plugin>
    <plugin name="Chassis-LFPivot_encoder" filename="libencoder.so">
      <joint>Chassis-LFPivot</joint>
      <topic>/gazebo/frc/simulator/dio/9/10</topic>
      <units>degrees</units>
    </plugin>
    <plugin name="LFPivot-LFWheel_motor" filename="libdc_motor.so">
      <joint>LFPivot-LFWheel</joint>
      <topic>/gazebo/frc/simulator/pwm/1</topic>
      <multiplier>25</multiplier>
    </plugin>
    <plugin name="LFPivot-LFWheel_encoder" filename="libencoder.so">
      <joint>LFPivot-LFWheel</joint>
      <topic>/gazebo/frc/simulator/dio/1/2</topic>
      <units>degrees</units>
    </plugin>
    <plugin name="Chassis-RFPivot_motor" filename="libdc_motor.so">
      <joint>Chassis-RFPivot</joint>
      <topic>/gazebo/frc/simulator/pwm/7</topic>
      <multiplier>25</multiplier>
    </plugin>
    <plugin name="Chassis-RFPivot_encoder" filename="libencoder.so">
      <joint>Chassis-RFPivot</joint>
      <topic>/gazebo/frc/simulator/dio/13/14</topic>
      <units>degrees</units>
    </plugin>
    <plugin name="RFPivot-RFWheel_motor" filename="libdc_motor.so">
      <joint>RFPivot-RFWheel</joint>
      <topic>/gazebo/frc/simulator/pwm/3</topic>
      <multiplier>25</multiplier>
    </plugin>
    <plugin name="RFPivot-RFWheel_encoder" filename="libencoder.so">
      <joint>RFPivot-RFWheel</joint>
      <topic>/gazebo/frc/simulator/dio/5/6</topic>
      <units>degrees</units>
    </plugin>
    <plugin name="Chassis-LRPivot_motor" filename="libdc_motor.so">
      <joint>Chassis-LRPivot</joint>
      <topic>/gazebo/frc/simulator/pwm/6</topic>
      <multiplier>25</multiplier>
    </plugin>
    <plugin name="Chassis-LRPivot_encoder" filename="libencoder.so">
      <joint>Chassis-LRPivot</joint>
      <topic>/gazebo/frc/simulator/dio/11/12</topic>
      <units>degrees</units>
    </plugin>
    <plugin name="LRPivot-LRWheel_motor" filename="libdc_motor.so">
      <joint>LRPivot-LRWheel</joint>
      <topic>/gazebo/frc/simulator/pwm/2</topic>
      <multiplier>25</multiplier>
    </plugin>
    <plugin name="LRPivot-LRWheel_encoder" filename="libencoder.so">
      <joint>LRPivot-LRWheel</joint>
      <topic>/gazebo/frc/simulator/dio/3/4</topic>
      <units>degrees</units>
    </plugin>
    <plugin name="Chassis-RRPivot_motor" filename="libdc_motor.so">
      <joint>Chassis-RRPivot</joint>
      <topic>/gazebo/frc/simulator/pwm/8</topic>
      <multiplier>25</multiplier>
    </plugin>
    <plugin name="Chassis-RRPivot_encoder" filename="libencoder.so">
      <joint>Chassis-RRPivot</joint>
      <topic>/gazebo/frc/simulator/dio/15/16</topic>
      <units>degrees</units>
    </plugin>
    <plugin name="RRPivot-RRWheel_motor" filename="libdc_motor.so">
      <joint>RRPivot-RRWheel</joint>
      <topic>/gazebo/frc/simulator/pwm/4</topic>
      <multiplier>25</multiplier>
    </plugin>
    <plugin name="RRPivot-RRWheel_encoder" filename="libencoder.so">
      <joint>RRPivot-RRWheel</joint>
      <topic>/gazebo/frc/simulator/dio/7/8</topic>
      <units>degrees</units>
    </plugin>
    <plugin name="Chassis-Lifter_motor" filename="libdc_motor.so">
      <joint>Chassis-Lifter</joint>
      <topic>/gazebo/frc/simulator/pwm/9</topic>
      <multiplier>400</multiplier>
    </plugin>
    <plugin name="Chassis-Lifter_encoder" filename="libencoder.so">
      <joint>Chassis-Lifter</joint>
      <topic>/gazebo/frc/simulator/dio/17/18</topic>
      <units>degrees</units>
    </plugin>
    <plugin name="Lifter-LeftArm_motor" filename="libdc_motor.so">
      <joint>Lifter-LeftArm</joint>
      <topic>/gazebo/frc/simulator/pwm/10</topic>
      <multiplier>200</multiplier>
    </plugin>
    <plugin name="Lifter-RightArm_motor" filename="libdc_motor.so">
      <joint>Lifter-RightArm</joint>
      <topic>/gazebo/frc/simulator/pwm/10</topic>
      <multiplier>200</multiplier>
    </plugin>
  </model>
</sdf>
