<sdf version='1.6'>
  <world name='default'>
    <gui fullscreen='0'>
      <camera name='user_camera'>
        <pose frame=''>-4.95338 -6.6728 6.45539 -0 1.3058 0.46818</pose>
        <view_controller>orbit</view_controller>
        <projection_type>perspective</projection_type>
      </camera>
    </gui>
    <light name='sun' type='directional'>
      <cast_shadows>1</cast_shadows>
      <pose frame=''>0 0 10 0 -0 0</pose>
      <diffuse>0.8 0.8 0.8 1</diffuse>
      <specular>0.1 0.1 0.1 1</specular>
      <attenuation>
        <range>1000</range>
        <constant>0.9</constant>
        <linear>0.01</linear>
        <quadratic>0.001</quadratic>
      </attenuation>
      <direction>-0.5 0.5 -1</direction>
    </light>
    <model name='ground_plane'>
      <static>1</static>
      <link name='link'>
        <collision name='collision'>
          <geometry>
            <plane>
              <normal>0 0 1</normal>
              <size>100 100</size>
            </plane>
          </geometry>
          <surface>
            <friction>
              <ode>
                <mu>100</mu>
                <mu2>50</mu2>
              </ode>
              <torsional>
                <ode/>
              </torsional>
            </friction>
            <contact>
              <ode/>
            </contact>
            <bounce/>
          </surface>
          <max_contacts>10</max_contacts>
        </collision>
        <visual name='visual'>
          <cast_shadows>0</cast_shadows>
          <geometry>
            <plane>
              <normal>0 0 1</normal>
              <size>100 100</size>
            </plane>
          </geometry>
          <material>
            <script>
              <uri>file://media/materials/scripts/gazebo.material</uri>
              <name>Gazebo/Grey</name>
            </script>
          </material>
        </visual>
        <self_collide>0</self_collide>
        <kinematic>0</kinematic>
      </link>
    </model>
    <model name='FRC2017'>
      <pose frame=''>0 0 -0.927 0 -0 0</pose>
      <static>1</static>
      <link name='Field'>
        <gravity>0</gravity>
        <self_collide>0</self_collide>
        <pose frame=''>0 0.066233 1.9717 1.5707 -0 0</pose>
        <must_be_base_link>1</must_be_base_link>
        <velocity_decay>
          <linear>0</linear>
          <angular>0</angular>
        </velocity_decay>
        <visual name='Field_visual'>
          <pose frame=''>-0.821548 0.928908 0.089052 0 -0 0</pose>
          <material>
            <ambient>0.752941 0.752941 0.752941 1</ambient>
            <diffuse>0.752941 0.752941 0.752941 1</diffuse>
          </material>
          <geometry>
            <mesh>
              <scale>1 1 1</scale>
              <uri>model://FRC2017/meshes/Field.STL</uri>
            </mesh>
          </geometry>
        </visual>
        <kinematic>0</kinematic>
      </link>
    </model>
    <model name='SimBot'>
      <pose frame=''>-3.46933 -7.37274 0.022039 2.4e-05 0.000319 1.5851</pose>
      <plugin name='clock' filename='libclock.so'>
        <topic>/gazebo/frc/time</topic>
      </plugin>
      <link name='Chassis'>
        <gravity>1</gravity>
        <self_collide>0</self_collide>
        <pose frame=''>-0.417788 -0.370901 0.109796 1.5708 0 -1.5708</pose>
        <must_be_base_link>1</must_be_base_link>
        <velocity_decay>
          <linear>0</linear>
          <angular>0</angular>
        </velocity_decay>
        <inertial>
          <mass>48.6161</mass>
          <pose frame=''>0 0 0 0 -0 0</pose>
          <inertia>
            <ixx>6.85956</ixx>
            <ixy>0.0505958</ixy>
            <ixz>0.0454905</ixz>
            <iyy>11.068</iyy>
            <iyz>0.0206055</iyz>
            <izz>5.66912</izz>
          </inertia>
        </inertial>
        <collision name='Chassis_collision'>
          <pose frame=''>0.003749 -0.143686 -0.417788 0 -0 0</pose>
          <geometry>
            <mesh>
              <scale>1 1 1</scale>
              <uri>model://SimBot/meshes/Chassis_col.STL</uri>
            </mesh>
          </geometry>
          <surface>
            <contact>
              <ode/>
            </contact>
            <friction>
              <ode>
                <mu>0</mu>
                <mu2>0</mu2>
              </ode>
              <torsional>
                <ode/>
              </torsional>
            </friction>
            <bounce/>
          </surface>
          <max_contacts>10</max_contacts>
        </collision>
        <visual name='Chassis_visual'>
          <pose frame=''>0.003749 -0.143686 -0.417788 0 -0 0</pose>
          <material>
            <ambient>0 0.25098 1 1</ambient>
            <diffuse>0 0.25098 1 1</diffuse>
          </material>
          <geometry>
            <mesh>
              <scale>1 1 1</scale>
              <uri>model://SimBot/meshes/Chassis.STL</uri>
            </mesh>
          </geometry>
        </visual>
        <sensor name='ChassisCamera' type='camera'>
          <visualize>1</visualize>
          <always_on>1</always_on>
          <pose frame=''>0.17 0.23 -0.369812 -1.57 1.57 0</pose>
          <camera name='Chassiscamera'>
            <horizontal_fov>0.66</horizontal_fov>
            <image>
              <width>320</width>
              <height>240</height>
            </image>
            <clip>
              <near>0.1</near>
              <far>30</far>
            </clip>
            <save enabled='1'>
              <path>/tmp/target-camera</path>
            </save>
          </camera>
        </sensor>
        <sensor name='DriverCamera' type='camera'>
          <visualize>0</visualize>
          <always_on>1</always_on>
          <pose frame=''>-0.05 0.23 -0.3 -1.57 1.57 -0</pose>
          <camera name='Bodycamera'>
            <horizontal_fov>1.0472</horizontal_fov>
            <image>
              <width>320</width>
              <height>240</height>
            </image>
            <clip>
              <near>0.01</near>
              <far>30</far>
            </clip>
            <save enabled='1'>
              <path>/tmp/driver-camera</path>
            </save>
          </camera>
        </sensor>
        <sensor name='ChassisUltrasonic' type='sonar'>
          <always_on>1</always_on>
          <visualize>0</visualize>
          <pose frame=''>0.17 0.318096 -0.369812 -0.2 0.2 -0</pose>
          <sonar>
            <min>0.1</min>
            <max>2</max>
            <radius>0.2</radius>
          </sonar>
        </sensor>
        <kinematic>0</kinematic>
      </link>
      <link name='L1Wheel'>
        <gravity>1</gravity>
        <self_collide>0</self_collide>
        <pose frame=''>-0.1143 -0.04318 0.034925 1.5708 0 -1.5708</pose>
        <must_be_base_link>0</must_be_base_link>
        <velocity_decay>
          <linear>0</linear>
          <angular>0</angular>
        </velocity_decay>
        <inertial>
          <mass>0.408395</mass>
          <pose frame=''>0 0 0 0 -0 0</pose>
          <inertia>
            <ixx>0.00522886</ixx>
            <ixy>0</ixy>
            <ixz>0</ixz>
            <iyy>0.00347976</iyy>
            <iyz>0</iyz>
            <izz>0.00347976</izz>
          </inertia>
        </inertial>
        <collision name='L1Wheel_collision'>
          <pose frame=''>0.33147 -0.068814 -0.1143 0 -0 0</pose>
          <geometry>
            <mesh>
              <scale>1 1 1</scale>
              <uri>model://SimBot/meshes/L1Wheel_col.STL</uri>
            </mesh>
          </geometry>
          <surface>
            <contact>
              <ode/>
            </contact>
            <friction>
              <ode>
                <mu>1</mu>
                <mu2>1</mu2>
              </ode>
              <torsional>
                <ode/>
              </torsional>
            </friction>
            <bounce/>
          </surface>
          <max_contacts>10</max_contacts>
        </collision>
        <visual name='L1Wheel_visual'>
          <pose frame=''>0.33147 -0.068814 -0.1143 0 -0 0</pose>
          <material>
            <ambient>0.752941 0.752941 0.752941 1</ambient>
            <diffuse>0.752941 0.752941 0.752941 1</diffuse>
          </material>
          <geometry>
            <mesh>
              <scale>1 1 1</scale>
              <uri>model://SimBot/meshes/L1Wheel.STL</uri>
            </mesh>
          </geometry>
        </visual>
        <kinematic>0</kinematic>
      </link>
      <joint name='Chassis-L1Wheel' type='revolute'>
        <parent>Chassis</parent>
        <child>L1Wheel</child>
        <pose frame=''>0.02286 0 0 0 -0 0</pose>
        <axis>
          <xyz>-1 0 0</xyz>
          <dynamics>
            <damping>1</damping>
            <friction>1</friction>
            <spring_reference>0</spring_reference>
            <spring_stiffness>0</spring_stiffness>
          </dynamics>
          <limit>
            <effort>100</effort>
            <lower>-1e+16</lower>
            <upper>1e+16</upper>
          </limit>
          <use_parent_model_frame>0</use_parent_model_frame>
        </axis>
      </joint>
      <link name='L2Wheel'>
        <gravity>1</gravity>
        <self_collide>0</self_collide>
        <pose frame=''>-0.315134 -0.04318 0.028575 1.5708 0 -1.5708</pose>
        <must_be_base_link>0</must_be_base_link>
        <velocity_decay>
          <linear>0</linear>
          <angular>0</angular>
        </velocity_decay>
        <inertial>
          <mass>0.408395</mass>
          <pose frame=''>0 0 0 0 -0 0</pose>
          <inertia>
            <ixx>0.00522886</ixx>
            <ixy>0</ixy>
            <ixz>0</ixz>
            <iyy>0.00347976</iyy>
            <iyz>0</iyz>
            <izz>0.00347976</izz>
          </inertia>
        </inertial>
        <collision name='L2Wheel_collision'>
          <pose frame=''>0.33147 -0.062464 -0.315134 0 -0 0</pose>
          <geometry>
            <mesh>
              <scale>1 1 1</scale>
              <uri>model://SimBot/meshes/L2Wheel_col.STL</uri>
            </mesh>
          </geometry>
          <surface>
            <contact>
              <ode/>
            </contact>
            <friction>
              <ode>
                <mu>1</mu>
                <mu2>1</mu2>
              </ode>
              <torsional>
                <ode/>
              </torsional>
            </friction>
            <bounce/>
          </surface>
          <max_contacts>10</max_contacts>
        </collision>
        <visual name='L2Wheel_visual'>
          <pose frame=''>0.33147 -0.062464 -0.315134 0 -0 0</pose>
          <material>
            <ambient>0.752941 0.752941 0.752941 1</ambient>
            <diffuse>0.752941 0.752941 0.752941 1</diffuse>
          </material>
          <geometry>
            <mesh>
              <scale>1 1 1</scale>
              <uri>model://SimBot/meshes/L2Wheel.STL</uri>
            </mesh>
          </geometry>
        </visual>
        <kinematic>0</kinematic>
      </link>
      <joint name='Chassis-L2Wheel' type='revolute'>
        <parent>Chassis</parent>
        <child>L2Wheel</child>
        <pose frame=''>0.02286 0 0 0 -0 0</pose>
        <axis>
          <xyz>-1 0 0</xyz>
          <dynamics>
            <damping>1</damping>
            <friction>1</friction>
            <spring_reference>0</spring_reference>
            <spring_stiffness>0</spring_stiffness>
          </dynamics>
          <limit>
            <effort>100</effort>
            <lower>-1e+16</lower>
            <upper>1e+16</upper>
          </limit>
          <use_parent_model_frame>0</use_parent_model_frame>
        </axis>
      </joint>
      <link name='L3Wheel'>
        <gravity>1</gravity>
        <self_collide>0</self_collide>
        <pose frame=''>-0.535766 -0.04318 0.028575 1.5708 0 -1.5708</pose>
        <must_be_base_link>0</must_be_base_link>
        <velocity_decay>
          <linear>0</linear>
          <angular>0</angular>
        </velocity_decay>
        <inertial>
          <mass>0.408395</mass>
          <pose frame=''>0 0 0 0 -0 0</pose>
          <inertia>
            <ixx>0.00522886</ixx>
            <ixy>0</ixy>
            <ixz>0</ixz>
            <iyy>0.00347976</iyy>
            <iyz>0</iyz>
            <izz>0.00347976</izz>
          </inertia>
        </inertial>
        <collision name='L3Wheel_collision'>
          <pose frame=''>0.33147 -0.062464 -0.535766 0 -0 0</pose>
          <geometry>
            <mesh>
              <scale>1 1 1</scale>
              <uri>model://SimBot/meshes/L3Wheel_col.STL</uri>
            </mesh>
          </geometry>
          <surface>
            <contact>
              <ode/>
            </contact>
            <friction>
              <ode>
                <mu>1</mu>
                <mu2>1</mu2>
              </ode>
              <torsional>
                <ode/>
              </torsional>
            </friction>
            <bounce/>
          </surface>
          <max_contacts>10</max_contacts>
        </collision>
        <visual name='L3Wheel_visual'>
          <pose frame=''>0.33147 -0.062464 -0.535766 0 -0 0</pose>
          <material>
            <ambient>0.752941 0.752941 0.752941 1</ambient>
            <diffuse>0.752941 0.752941 0.752941 1</diffuse>
          </material>
          <geometry>
            <mesh>
              <scale>1 1 1</scale>
              <uri>model://SimBot/meshes/L3Wheel.STL</uri>
            </mesh>
          </geometry>
        </visual>
        <kinematic>0</kinematic>
      </link>
      <joint name='Chassis-L3Wheel' type='revolute'>
        <parent>Chassis</parent>
        <child>L3Wheel</child>
        <pose frame=''>0.02286 0 0 0 -0 0</pose>
        <axis>
          <xyz>-1 0 0</xyz>
          <dynamics>
            <damping>1</damping>
            <friction>1</friction>
            <spring_reference>0</spring_reference>
            <spring_stiffness>0</spring_stiffness>
          </dynamics>
          <limit>
            <effort>100</effort>
            <lower>-1e+16</lower>
            <upper>1e+16</upper>
          </limit>
          <use_parent_model_frame>0</use_parent_model_frame>
        </axis>
      </joint>
      <link name='L4Wheel'>
        <gravity>1</gravity>
        <self_collide>0</self_collide>
        <pose frame=''>-0.7366 -0.04318 0.034925 1.5708 0 -1.5708</pose>
        <must_be_base_link>0</must_be_base_link>
        <velocity_decay>
          <linear>0</linear>
          <angular>0</angular>
        </velocity_decay>
        <inertial>
          <mass>0.408395</mass>
          <pose frame=''>0 0 0 0 -0 0</pose>
          <inertia>
            <ixx>0.00522886</ixx>
            <ixy>0</ixy>
            <ixz>0</ixz>
            <iyy>0.00347976</iyy>
            <iyz>0</iyz>
            <izz>0.00347976</izz>
          </inertia>
        </inertial>
        <collision name='L4Wheel_collision'>
          <pose frame=''>0.33147 -0.068814 -0.7366 0 -0 0</pose>
          <geometry>
            <mesh>
              <scale>1 1 1</scale>
              <uri>model://SimBot/meshes/L4Wheel_col.STL</uri>
            </mesh>
          </geometry>
          <surface>
            <contact>
              <ode/>
            </contact>
            <friction>
              <ode>
                <mu>1</mu>
                <mu2>1</mu2>
              </ode>
              <torsional>
                <ode/>
              </torsional>
            </friction>
            <bounce/>
          </surface>
          <max_contacts>10</max_contacts>
        </collision>
        <visual name='L4Wheel_visual'>
          <pose frame=''>0.33147 -0.068814 -0.7366 0 -0 0</pose>
          <material>
            <ambient>0.752941 0.752941 0.752941 1</ambient>
            <diffuse>0.752941 0.752941 0.752941 1</diffuse>
          </material>
          <geometry>
            <mesh>
              <scale>1 1 1</scale>
              <uri>model://SimBot/meshes/L4Wheel.STL</uri>
            </mesh>
          </geometry>
        </visual>
        <kinematic>0</kinematic>
      </link>
      <joint name='Chassis-L4Wheel' type='revolute'>
        <parent>Chassis</parent>
        <child>L4Wheel</child>
        <pose frame=''>0.02286 0 0 0 -0 0</pose>
        <axis>
          <xyz>-1 0 0</xyz>
          <dynamics>
            <damping>1</damping>
            <friction>1</friction>
            <spring_reference>0</spring_reference>
            <spring_stiffness>0</spring_stiffness>
          </dynamics>
          <limit>
            <effort>100</effort>
            <lower>-1e+16</lower>
            <upper>1e+16</upper>
          </limit>
          <use_parent_model_frame>0</use_parent_model_frame>
        </axis>
      </joint>
      <link name='R1Wheel'>
        <gravity>1</gravity>
        <self_collide>0</self_collide>
        <pose frame=''>-0.1143 -0.70612 0.034925 1.5708 0 -1.5708</pose>
        <must_be_base_link>0</must_be_base_link>
        <velocity_decay>
          <linear>0</linear>
          <angular>0</angular>
        </velocity_decay>
        <inertial>
          <mass>0.408395</mass>
          <pose frame=''>0 0 0 0 -0 0</pose>
          <inertia>
            <ixx>0.00522886</ixx>
            <ixy>0</ixy>
            <ixz>0</ixz>
            <iyy>0.00347976</iyy>
            <iyz>0</iyz>
            <izz>0.00347976</izz>
          </inertia>
        </inertial>
        <collision name='R1Wheel_collision'>
          <pose frame=''>-0.33147 -0.068814 -0.1143 0 -0 0</pose>
          <geometry>
            <mesh>
              <scale>1 1 1</scale>
              <uri>model://SimBot/meshes/R1Wheel_col.STL</uri>
            </mesh>
          </geometry>
          <surface>
            <contact>
              <ode/>
            </contact>
            <friction>
              <ode>
                <mu>1</mu>
                <mu2>1</mu2>
              </ode>
              <torsional>
                <ode/>
              </torsional>
            </friction>
            <bounce/>
          </surface>
          <max_contacts>10</max_contacts>
        </collision>
        <visual name='R1Wheel_visual'>
          <pose frame=''>-0.33147 -0.068814 -0.1143 0 -0 0</pose>
          <material>
            <ambient>0.752941 0.752941 0.752941 1</ambient>
            <diffuse>0.752941 0.752941 0.752941 1</diffuse>
          </material>
          <geometry>
            <mesh>
              <scale>1 1 1</scale>
              <uri>model://SimBot/meshes/R1Wheel.STL</uri>
            </mesh>
          </geometry>
        </visual>
        <kinematic>0</kinematic>
      </link>
      <joint name='Chassis-R1Wheel' type='revolute'>
        <parent>Chassis</parent>
        <child>R1Wheel</child>
        <pose frame=''>-0.02286 0 0 0 -0 0</pose>
        <axis>
          <xyz>1 0 0</xyz>
          <dynamics>
            <damping>1</damping>
            <friction>1</friction>
            <spring_reference>0</spring_reference>
            <spring_stiffness>0</spring_stiffness>
          </dynamics>
          <limit>
            <effort>100</effort>
            <lower>-1e+16</lower>
            <upper>1e+16</upper>
          </limit>
          <use_parent_model_frame>0</use_parent_model_frame>
        </axis>
      </joint>
      <link name='R2Wheel'>
        <gravity>1</gravity>
        <self_collide>0</self_collide>
        <pose frame=''>-0.315134 -0.70612 0.028575 1.5708 0 -1.5708</pose>
        <must_be_base_link>0</must_be_base_link>
        <velocity_decay>
          <linear>0</linear>
          <angular>0</angular>
        </velocity_decay>
        <inertial>
          <mass>0.408395</mass>
          <pose frame=''>0 0 0 0 -0 0</pose>
          <inertia>
            <ixx>0.00522886</ixx>
            <ixy>0</ixy>
            <ixz>0</ixz>
            <iyy>0.00347976</iyy>
            <iyz>0</iyz>
            <izz>0.00347976</izz>
          </inertia>
        </inertial>
        <collision name='R2Wheel_collision'>
          <pose frame=''>-0.33147 -0.062464 -0.315134 0 -0 0</pose>
          <geometry>
            <mesh>
              <scale>1 1 1</scale>
              <uri>model://SimBot/meshes/R2Wheel_col.STL</uri>
            </mesh>
          </geometry>
          <surface>
            <contact>
              <ode/>
            </contact>
            <friction>
              <ode>
                <mu>1</mu>
                <mu2>1</mu2>
              </ode>
              <torsional>
                <ode/>
              </torsional>
            </friction>
            <bounce/>
          </surface>
          <max_contacts>10</max_contacts>
        </collision>
        <visual name='R2Wheel_visual'>
          <pose frame=''>-0.33147 -0.062464 -0.315134 0 -0 0</pose>
          <material>
            <ambient>0.752941 0.752941 0.752941 1</ambient>
            <diffuse>0.752941 0.752941 0.752941 1</diffuse>
          </material>
          <geometry>
            <mesh>
              <scale>1 1 1</scale>
              <uri>model://SimBot/meshes/R2Wheel.STL</uri>
            </mesh>
          </geometry>
        </visual>
        <kinematic>0</kinematic>
      </link>
      <joint name='Chassis-R2Wheel' type='revolute'>
        <parent>Chassis</parent>
        <child>R2Wheel</child>
        <pose frame=''>-0.02286 0 0 0 -0 0</pose>
        <axis>
          <xyz>1 0 0</xyz>
          <dynamics>
            <damping>1</damping>
            <friction>1</friction>
            <spring_reference>0</spring_reference>
            <spring_stiffness>0</spring_stiffness>
          </dynamics>
          <limit>
            <effort>100</effort>
            <lower>-1e+16</lower>
            <upper>1e+16</upper>
          </limit>
          <use_parent_model_frame>0</use_parent_model_frame>
        </axis>
      </joint>
      <link name='R3Wheel'>
        <gravity>1</gravity>
        <self_collide>0</self_collide>
        <pose frame=''>-0.535766 -0.70612 0.028575 1.5708 0 -1.5708</pose>
        <must_be_base_link>0</must_be_base_link>
        <velocity_decay>
          <linear>0</linear>
          <angular>0</angular>
        </velocity_decay>
        <inertial>
          <mass>0.408395</mass>
          <pose frame=''>0 0 0 0 -0 0</pose>
          <inertia>
            <ixx>0.00522886</ixx>
            <ixy>0</ixy>
            <ixz>0</ixz>
            <iyy>0.00347976</iyy>
            <iyz>0</iyz>
            <izz>0.00347976</izz>
          </inertia>
        </inertial>
        <collision name='R3Wheel_collision'>
          <pose frame=''>-0.33147 -0.062464 -0.535766 0 -0 0</pose>
          <geometry>
            <mesh>
              <scale>1 1 1</scale>
              <uri>model://SimBot/meshes/R3Wheel_col.STL</uri>
            </mesh>
          </geometry>
          <surface>
            <contact>
              <ode/>
            </contact>
            <friction>
              <ode>
                <mu>1</mu>
                <mu2>1</mu2>
              </ode>
              <torsional>
                <ode/>
              </torsional>
            </friction>
            <bounce/>
          </surface>
          <max_contacts>10</max_contacts>
        </collision>
        <visual name='R3Wheel_visual'>
          <pose frame=''>-0.33147 -0.062464 -0.535766 0 -0 0</pose>
          <material>
            <ambient>0.752941 0.752941 0.752941 1</ambient>
            <diffuse>0.752941 0.752941 0.752941 1</diffuse>
          </material>
          <geometry>
            <mesh>
              <scale>1 1 1</scale>
              <uri>model://SimBot/meshes/R3Wheel.STL</uri>
            </mesh>
          </geometry>
        </visual>
        <kinematic>0</kinematic>
      </link>
      <joint name='Chassis-R3Wheel' type='revolute'>
        <parent>Chassis</parent>
        <child>R3Wheel</child>
        <pose frame=''>-0.02286 0 0 0 -0 0</pose>
        <axis>
          <xyz>1 0 0</xyz>
          <dynamics>
            <damping>1</damping>
            <friction>1</friction>
            <spring_reference>0</spring_reference>
            <spring_stiffness>0</spring_stiffness>
          </dynamics>
          <limit>
            <effort>100</effort>
            <lower>-1e+16</lower>
            <upper>1e+16</upper>
          </limit>
          <use_parent_model_frame>0</use_parent_model_frame>
        </axis>
      </joint>
      <link name='R4Wheel'>
        <gravity>1</gravity>
        <self_collide>0</self_collide>
        <pose frame=''>-0.7366 -0.70612 0.034925 1.5708 0 -1.5708</pose>
        <must_be_base_link>0</must_be_base_link>
        <velocity_decay>
          <linear>0</linear>
          <angular>0</angular>
        </velocity_decay>
        <inertial>
          <mass>0.408395</mass>
          <pose frame=''>0 0 0 0 -0 0</pose>
          <inertia>
            <ixx>0.00522886</ixx>
            <ixy>0</ixy>
            <ixz>0</ixz>
            <iyy>0.00347976</iyy>
            <iyz>0</iyz>
            <izz>0.00347976</izz>
          </inertia>
        </inertial>
        <collision name='R4Wheel_collision'>
          <pose frame=''>-0.33147 -0.068814 -0.7366 0 -0 0</pose>
          <geometry>
            <mesh>
              <scale>1 1 1</scale>
              <uri>model://SimBot/meshes/R4Wheel_col.STL</uri>
            </mesh>
          </geometry>
          <surface>
            <contact>
              <ode/>
            </contact>
            <friction>
              <ode>
                <mu>1</mu>
                <mu2>1</mu2>
              </ode>
              <torsional>
                <ode/>
              </torsional>
            </friction>
            <bounce/>
          </surface>
          <max_contacts>10</max_contacts>
        </collision>
        <visual name='R4Wheel_visual'>
          <pose frame=''>-0.33147 -0.068814 -0.7366 0 -0 0</pose>
          <material>
            <ambient>0.752941 0.752941 0.752941 1</ambient>
            <diffuse>0.752941 0.752941 0.752941 1</diffuse>
          </material>
          <geometry>
            <mesh>
              <scale>1 1 1</scale>
              <uri>model://SimBot/meshes/R4Wheel.STL</uri>
            </mesh>
          </geometry>
        </visual>
        <kinematic>0</kinematic>
      </link>
      <joint name='Chassis-R4Wheel' type='revolute'>
        <parent>Chassis</parent>
        <child>R4Wheel</child>
        <pose frame=''>-0.02286 0 0 0 -0 0</pose>
        <axis>
          <xyz>1 0 0</xyz>
          <dynamics>
            <damping>1</damping>
            <friction>1</friction>
            <spring_reference>0</spring_reference>
            <spring_stiffness>0</spring_stiffness>
          </dynamics>
          <limit>
            <effort>100</effort>
            <lower>-1e+16</lower>
            <upper>1e+16</upper>
          </limit>
          <use_parent_model_frame>0</use_parent_model_frame>
        </axis>
      </joint>
      <link name='BallPusher'>
        <gravity>1</gravity>
        <self_collide>0</self_collide>
        <pose frame=''>-0.23857 -0.37545 0.193772 1.5708 0 -1.5708</pose>
        <must_be_base_link>0</must_be_base_link>
        <velocity_decay>
          <linear>0</linear>
          <angular>0</angular>
        </velocity_decay>
        <inertial>
          <mass>0.355128</mass>
          <pose frame=''>0 0 0 0 -0 0</pose>
          <inertia>
            <ixx>0.00398094</ixx>
            <ixy>3.1169e-17</ixy>
            <ixz>2.20178e-17</ixz>
            <iyy>0.0516966</iyy>
            <iyz>0.00161224</iyz>
            <izz>0.05358</izz>
          </inertia>
        </inertial>
        <collision name='BallPusher_collision'>
          <pose frame=''>-0.0008 -0.227662 -0.23857 0 -0 0</pose>
          <geometry>
            <mesh>
              <scale>1 1 1</scale>
              <uri>model://SimBot/meshes/BallPusher_col.STL</uri>
            </mesh>
          </geometry>
          <surface>
            <contact>
              <ode/>
            </contact>
            <friction>
              <ode>
                <mu>1</mu>
                <mu2>1</mu2>
              </ode>
              <torsional>
                <ode/>
              </torsional>
            </friction>
            <bounce/>
          </surface>
          <max_contacts>10</max_contacts>
        </collision>
        <visual name='BallPusher_visual'>
          <pose frame=''>-0.0008 -0.227662 -0.23857 0 -0 0</pose>
          <material>
            <ambient>1 0.752941 0.501961 1</ambient>
            <diffuse>1 0.752941 0.501961 1</diffuse>
          </material>
          <geometry>
            <mesh>
              <scale>1 1 1</scale>
              <uri>model://SimBot/meshes/BallPusher.STL</uri>
            </mesh>
          </geometry>
        </visual>
        <kinematic>0</kinematic>
      </link>
      <joint name='Chassis-BallPusher' type='prismatic'>
        <parent>Chassis</parent>
        <child>BallPusher</child>
        <pose frame=''>0 0 0 0 -0 0</pose>
        <axis>
          <xyz>0 0.5 1</xyz>
          <dynamics>
            <damping>1</damping>
            <friction>1</friction>
            <spring_reference>0</spring_reference>
            <spring_stiffness>0</spring_stiffness>
          </dynamics>
          <limit>
            <upper>0.5</upper>
            <lower>0</lower>
            <effort>100</effort>
          </limit>
          <use_parent_model_frame>0</use_parent_model_frame>
        </axis>
      </joint>
      <link name='GearPlate'>
        <gravity>1</gravity>
        <self_collide>0</self_collide>
        <pose frame=''>-0.034925 -0.37465 0.225425 1.5708 0 -1.5708</pose>
        <must_be_base_link>0</must_be_base_link>
        <velocity_decay>
          <linear>0</linear>
          <angular>0</angular>
        </velocity_decay>
        <inertial>
          <mass>0.0286774</mass>
          <pose frame=''>0 0 0 0 -0 0</pose>
          <inertia>
            <ixx>0.001</ixx>
            <ixy>0</ixy>
            <ixz>0</ixz>
            <iyy>0.003</iyy>
            <iyz>0</iyz>
            <izz>0.001</izz>
          </inertia>
        </inertial>
        <collision name='GearPlate_collision'>
          <pose frame=''>-0 -0.259314 -0.034925 0 -0 0</pose>
          <geometry>
            <mesh>
              <scale>1 1 1</scale>
              <uri>model://SimBot/meshes/GearPlate_col.STL</uri>
            </mesh>
          </geometry>
          <surface>
            <contact>
              <ode/>
            </contact>
            <friction>
              <ode>
                <mu>1</mu>
                <mu2>1</mu2>
              </ode>
              <torsional>
                <ode/>
              </torsional>
            </friction>
            <bounce/>
          </surface>
          <max_contacts>10</max_contacts>
        </collision>
        <visual name='GearPlate_visual'>
          <pose frame=''>-0 -0.259314 -0.034925 0 -0 0</pose>
          <material>
            <ambient>1 0 0 1</ambient>
            <diffuse>1 0 0 1</diffuse>
          </material>
          <geometry>
            <mesh>
              <scale>1 1 1</scale>
              <uri>model://SimBot/meshes/GearPlate.STL</uri>
            </mesh>
          </geometry>
        </visual>
        <kinematic>0</kinematic>
      </link>
      <joint name='Chassis-GearPlate' type='prismatic'>
        <parent>Chassis</parent>
        <child>GearPlate</child>
        <pose frame=''>-0.04445 0.003175 -0.0254 0 -0 0</pose>
        <axis>
          <xyz>0 0 1</xyz>
          <dynamics>
            <damping>0.2</damping>
            <friction>0.2</friction>
            <spring_reference>0</spring_reference>
            <spring_stiffness>0</spring_stiffness>
          </dynamics>
          <limit>
            <upper>0.05</upper>
            <lower>0</lower>
            <effort>100</effort>
          </limit>
          <use_parent_model_frame>0</use_parent_model_frame>
        </axis>
      </joint>
      <plugin name='Chassis_rangefinder' filename='librangefinder.so'>
        <topic>/gazebo/frc/simulator/analog/0</topic>
        <sensor>ChassisUltrasonic</sensor>
      </plugin>
      <plugin name='Chassis-L1Wheel_motor' filename='libdc_motor.so'>
        <joint>Chassis-L1Wheel</joint>
        <topic>/gazebo/frc/simulator/pwm/2</topic>
        <multiplier>25</multiplier>
      </plugin>
      <plugin name='Chassis-L2Wheel_motor' filename='libdc_motor.so'>
        <joint>Chassis-L2Wheel</joint>
        <topic>/gazebo/frc/simulator/pwm/2</topic>
        <multiplier>25</multiplier>
      </plugin>
      <plugin name='Chassis-L2Wheel_encoder' filename='libencoder.so'>
        <joint>Chassis-L2Wheel</joint>
        <topic>/gazebo/frc/simulator/dio/3/4</topic>
        <units>degrees</units>
      </plugin>
      <plugin name='Chassis-L3Wheel_motor' filename='libdc_motor.so'>
        <joint>Chassis-L3Wheel</joint>
        <topic>/gazebo/frc/simulator/pwm/2</topic>
        <multiplier>25</multiplier>
      </plugin>
      <plugin name='Chassis-L4Wheel_motor' filename='libdc_motor.so'>
        <joint>Chassis-L4Wheel</joint>
        <topic>/gazebo/frc/simulator/pwm/2</topic>
        <multiplier>25</multiplier>
      </plugin>
      <plugin name='Chassis-R1Wheel_motor' filename='libdc_motor.so'>
        <joint>Chassis-R1Wheel</joint>
        <topic>/gazebo/frc/simulator/pwm/4</topic>
        <multiplier>25</multiplier>
      </plugin>
      <plugin name='Chassis-R2Wheel_motor' filename='libdc_motor.so'>
        <joint>Chassis-R2Wheel</joint>
        <topic>/gazebo/frc/simulator/pwm/4</topic>
        <multiplier>25</multiplier>
      </plugin>
      <plugin name='Chassis-R2Wheel_encoder' filename='libencoder.so'>
        <joint>Chassis-R2Wheel</joint>
        <topic>/gazebo/frc/simulator/dio/7/8</topic>
        <units>degrees</units>
      </plugin>
      <plugin name='Chassis-R3Wheel_motor' filename='libdc_motor.so'>
        <joint>Chassis-R3Wheel</joint>
        <topic>/gazebo/frc/simulator/pwm/4</topic>
        <multiplier>25</multiplier>
      </plugin>
      <plugin name='Chassis-R4Wheel_motor' filename='libdc_motor.so'>
        <joint>Chassis-R4Wheel</joint>
        <topic>/gazebo/frc/simulator/pwm/4</topic>
        <multiplier>25</multiplier>
      </plugin>
      <plugin name='Chassis-BallPusher_motor' filename='libdc_motor.so'>
        <joint>Chassis-BallPusher</joint>
        <topic>/gazebo/frc/simulator/pwm/5</topic>
        <multiplier>25</multiplier>
      </plugin>
      <plugin name='Chassis-Gearplate' filename='libpneumatic_piston.so'>
        <joint>Chassis-GearPlate</joint>
        <direction>forward</direction>
        <forward-force>1</forward-force>
        <reverse-force>1</reverse-force>
        <topic>/gazebo/frc/simulator/pneumatic/1/1</topic>
      </plugin>
    </model>
    <model name='spike1'>
      <pose frame=''>-0.25793 -4.9648 0.002057 -0.0185 -0.007 -0.5244</pose>
      <static>1</static>
      <link name='Body'>
        <gravity>1</gravity>
        <self_collide>0</self_collide>
        <pose frame=''>0.015957 2e-06 0.440048 1.5708 -0 1.5708</pose>
        <must_be_base_link>1</must_be_base_link>
        <velocity_decay>
          <linear>0</linear>
          <angular>0</angular>
        </velocity_decay>
        <inertial>
          <mass>10</mass>
          <pose frame=''>0 0 0 0 -0 0</pose>
          <inertia>
            <ixx>1</ixx>
            <ixy>0</ixy>
            <ixz>0</ixz>
            <iyy>1</iyy>
            <iyz>0</iyz>
            <izz>1</izz>
          </inertia>
        </inertial>
        <collision name='Body_collision'>
          <pose frame=''>-2e-06 -0.440048 -0.91566 0 -0 0</pose>
          <geometry>
            <mesh>
              <scale>1 1 1</scale>
              <uri>model://SpikePanel/meshes/Body.STL</uri>
            </mesh>
          </geometry>
          <surface>
            <friction>
              <ode>
                <mu>0</mu>
                <mu2>0</mu2>
              </ode>
              <torsional>
                <ode/>
              </torsional>
            </friction>
            <contact>
              <ode>
                <kd>120000</kd>
                <kp>1e+07</kp>
              </ode>
            </contact>
            <bounce/>
          </surface>
          <max_contacts>10</max_contacts>
        </collision>
        <kinematic>0</kinematic>
      </link>
    </model>
    <model name='spike2'>
      <pose frame=''>-1.037 -5.412 0.00523 0 0 -1.56</pose>
      <static>1</static>
      <link name='Body'>
        <gravity>1</gravity>
        <self_collide>0</self_collide>
        <pose frame=''>0.015957 2e-06 0.440048 1.5708 -0 1.5708</pose>
        <must_be_base_link>1</must_be_base_link>
        <velocity_decay>
          <linear>0</linear>
          <angular>0</angular>
        </velocity_decay>
        <inertial>
          <mass>10</mass>
          <pose frame=''>0 0 0 0 -0 0</pose>
          <inertia>
            <ixx>1</ixx>
            <ixy>0</ixy>
            <ixz>0</ixz>
            <iyy>1</iyy>
            <iyz>0</iyz>
            <izz>1</izz>
          </inertia>
        </inertial>
        <collision name='Body_collision'>
          <pose frame=''>-2e-06 -0.440048 -0.91566 0 -0 0</pose>
          <geometry>
            <mesh>
              <scale>1 1 1</scale>
              <uri>model://SpikePanel/meshes/Body.STL</uri>
            </mesh>
          </geometry>
          <surface>
            <friction>
              <ode>
                <mu>0</mu>
                <mu2>0</mu2>
              </ode>
              <torsional>
                <ode/>
              </torsional>
            </friction>
            <contact>
              <ode>
                <kd>120000</kd>
                <kp>1e+07</kp>
              </ode>
            </contact>
            <bounce/>
          </surface>
          <max_contacts>10</max_contacts>
        </collision>
        <kinematic>0</kinematic>
      </link>
    </model>
    <model name='spike3'>
      <pose frame=''>-1.844 -5.009 0.026 0 0 -2.61</pose>
      <static>1</static>
      <link name='Body'>
        <gravity>1</gravity>
        <self_collide>0</self_collide>
        <pose frame=''>0.015957 2e-06 0.440048 1.5708 -0 1.5708</pose>
        <must_be_base_link>1</must_be_base_link>
        <velocity_decay>
          <linear>0</linear>
          <angular>0</angular>
        </velocity_decay>
        <inertial>
          <mass>10</mass>
          <pose frame=''>0 0 0 0 -0 0</pose>
          <inertia>
            <ixx>1</ixx>
            <ixy>0</ixy>
            <ixz>0</ixz>
            <iyy>1</iyy>
            <iyz>0</iyz>
            <izz>1</izz>
          </inertia>
        </inertial>
        <collision name='Body_collision'>
          <pose frame=''>-2e-06 -0.440048 -0.91566 0 -0 0</pose>
          <geometry>
            <mesh>
              <scale>1 1 1</scale>
              <uri>model://SpikePanel/meshes/Body.STL</uri>
            </mesh>
          </geometry>
          <surface>
            <friction>
              <ode>
                <mu>0</mu>
                <mu2>0</mu2>
              </ode>
              <torsional>
                <ode/>
              </torsional>
            </friction>
            <contact>
              <ode>
                <kd>120000</kd>
                <kp>1e+07</kp>
              </ode>
            </contact>
            <bounce/>
          </surface>
          <max_contacts>10</max_contacts>
        </collision>
        <kinematic>0</kinematic>
      </link>
    </model>
    <model name='tape1'>
      <link name='Tape'>
        <gravity>0</gravity>
        <self_collide>0</self_collide>
        <pose frame=''>0.00127 -0.13037 -0.064619 -1.5708 0 1.5708</pose>
        <must_be_base_link>1</must_be_base_link>
        <velocity_decay>
          <linear>0</linear>
          <angular>0</angular>
        </velocity_decay>
        <visual name='Tape_visual'>
          <pose frame=''>-0.006897 0.026776 -0.00127 0 -0 0</pose>
          <material>
            <ambient>0 1 1 1</ambient>
            <diffuse>0 1 1 1</diffuse>
            <emissive>0.2 1 1 1</emissive>
          </material>
          <geometry>
            <mesh>
              <scale>1 1 1</scale>
              <uri>model://TAPE2017/meshes/Tape.STL</uri>
            </mesh>
          </geometry>
        </visual>
        <inertial>
          <inertia>
            <ixx>1</ixx>
            <ixy>0</ixy>
            <ixz>0</ixz>
            <iyy>1</iyy>
            <iyz>0</iyz>
            <izz>1</izz>
          </inertia>
          <mass>1</mass>
        </inertial>
        <kinematic>0</kinematic>
      </link>
      <pose frame=''>-0.18536 -4.85795 0.41079 0.0116 -0.001119 -0.54</pose>
    </model>
    <model name='tape2'>
      <link name='Tape'>
        <gravity>0</gravity>
        <self_collide>0</self_collide>
        <pose frame=''>0.00127 -0.13037 -0.064619 -1.5708 0 1.5708</pose>
        <must_be_base_link>1</must_be_base_link>
        <velocity_decay>
          <linear>0</linear>
          <angular>0</angular>
        </velocity_decay>
        <visual name='Tape_visual'>
          <pose frame=''>-0.006897 0.026776 -0.00127 0 -0 0</pose>
          <material>
            <ambient>0 1 1 1</ambient>
            <diffuse>0 1 1 1</diffuse>
            <emissive>0.2 1 1 1</emissive>
          </material>
          <geometry>
            <mesh>
              <scale>1 1 1</scale>
              <uri>model://TAPE2017/meshes/Tape.STL</uri>
            </mesh>
          </geometry>
        </visual>
        <inertial>
          <inertia>
            <ixx>1</ixx>
            <ixy>0</ixy>
            <ixz>0</ixz>
            <iyy>1</iyy>
            <iyz>0</iyz>
            <izz>1</izz>
          </inertia>
          <mass>1</mass>
        </inertial>
        <kinematic>0</kinematic>
      </link>
      <pose frame=''>-0.902837 -5.42368 0.4133 0 0 -1.56235</pose>
    </model>
    <model name='tape3'>
      <link name='Tape'>
        <gravity>0</gravity>
        <self_collide>0</self_collide>
        <pose frame=''>0.00127 -0.13037 -0.064619 -1.5708 0 1.5708</pose>
        <must_be_base_link>1</must_be_base_link>
        <velocity_decay>
          <linear>0</linear>
          <angular>0</angular>
        </velocity_decay>
        <visual name='Tape_visual'>
          <pose frame=''>-0.006897 0.026776 -0.00127 0 -0 0</pose>
          <material>
            <ambient>0 1 1 1</ambient>
            <diffuse>0 1 1 1</diffuse>
            <emissive>0.2 1 1 1</emissive>
          </material>
          <geometry>
            <mesh>
              <scale>1 1 1</scale>
              <uri>model://TAPE2017/meshes/Tape.STL</uri>
            </mesh>
          </geometry>
        </visual>
        <inertial>
          <inertia>
            <ixx>1</ixx>
            <ixy>0</ixy>
            <ixz>0</ixz>
            <iyy>1</iyy>
            <iyz>0</iyz>
            <izz>1</izz>
          </inertia>
          <mass>1</mass>
        </inertial>
        <kinematic>0</kinematic>
      </link>
      <pose frame=''>-1.885 -4.858 0.41 0 -0 0.51715</pose>
    </model>
    <model name='gear'>
      <pose frame=''>-3.07483 -7.42411 0.386712 1.56178 -0.29245 0.008741</pose>
      <plugin name='clock' filename='libgz_clock.so'>
        <topic>/gazebo/frc/time</topic>
      </plugin>
      <link name='Body'>
        <gravity>1</gravity>
        <self_collide>0</self_collide>
        <pose frame=''>-0.000248 0 -0.023813 0 0 -2.82392</pose>
        <must_be_base_link>1</must_be_base_link>
        <velocity_decay>
          <linear>0</linear>
          <angular>0</angular>
        </velocity_decay>
        <inertial>
          <mass>1.06857</mass>
          <pose frame=''>0 0 0 0 -0 0</pose>
          <inertia>
            <ixx>0.02</ixx>
            <ixy>0</ixy>
            <ixz>0</ixz>
            <iyy>0.02</iyy>
            <iyz>0</iyz>
            <izz>0.02</izz>
          </inertia>
        </inertial>
        <collision name='Body_collision'>
          <pose frame=''>-0.000236 7.8e-05 0 0 -0 0</pose>
          <geometry>
            <mesh>
              <scale>1 1 1</scale>
              <uri>model://Gear/meshes/Body_col.STL</uri>
            </mesh>
          </geometry>
          <surface>
            <friction>
              <ode>
                <mu>0</mu>
                <mu2>0</mu2>
              </ode>
              <torsional>
                <ode/>
              </torsional>
            </friction>
            <contact>
              <ode>
                <kd>10000</kd>
                <kp>2e+07</kp>
              </ode>
            </contact>
            <bounce/>
          </surface>
          <max_contacts>10</max_contacts>
        </collision>
        <visual name='Body_visual'>
          <pose frame=''>-0.000236 7.8e-05 0 0 -0 0</pose>
          <material>
            <ambient>0.8 0.8 0.2 1</ambient>
            <diffuse>0.8 0.8 0.2 1</diffuse>
          </material>
          <geometry>
            <mesh>
              <scale>1 1 1</scale>
              <uri>model://Gear/meshes/Body.STL</uri>
            </mesh>
          </geometry>
        </visual>
        <kinematic>0</kinematic>
      </link>
    </model>
    <gravity>0 0 -9.8</gravity>
    <magnetic_field>6e-06 2.3e-05 -4.2e-05</magnetic_field>
    <atmosphere type='adiabatic'/>
    <physics name='default_physics' default='0' type='ode'>
      <max_step_size>0.001</max_step_size>
      <real_time_factor>1</real_time_factor>
      <real_time_update_rate>1000</real_time_update_rate>
    </physics>
    <scene>
      <ambient>0.4 0.4 0.4 1</ambient>
      <background>0.7 0.7 0.7 1</background>
      <shadows>1</shadows>
    </scene>
    <spherical_coordinates>
      <surface_model>EARTH_WGS84</surface_model>
      <latitude_deg>0</latitude_deg>
      <longitude_deg>0</longitude_deg>
      <elevation>0</elevation>
      <heading_deg>0</heading_deg>
    </spherical_coordinates>
    <state world_name='default'>
      <sim_time>356 314000000</sim_time>
      <real_time>156 800375148</real_time>
      <wall_time>1487200535 34943562</wall_time>
      <iterations>93712</iterations>
      <model name='FRC2017'>
        <pose frame=''>0 0 -0.927 0 -0 0</pose>
        <scale>1 1 1</scale>
        <link name='Field'>
          <pose frame=''>0 0.066233 1.0447 1.5707 -0 0</pose>
          <velocity>0 0 0 0 -0 0</velocity>
          <acceleration>0 0 0 0 -0 0</acceleration>
          <wrench>0 0 0 0 -0 0</wrench>
        </link>
      </model>
      <model name='SimBot'>
        <pose frame=''>-3.46933 -7.37274 0.022039 2.4e-05 0.000319 1.5851</pose>
        <scale>1 1 1</scale>
        <link name='BallPusher'>
          <pose frame=''>-3.0905 -7.60586 0.215878 1.57048 2.4e-05 0.014301</pose>
          <velocity>0.000135 0.000144 -0.002643 -0.0024 -0.007405 3.9e-05</velocity>
          <acceleration>-1.53348 0.497425 -5.21959 2.29598 -1.09709 2.34851</acceleration>
          <wrench>-0.54458 0.176649 -1.85362 0 -0 0</wrench>
        </link>
        <link name='Chassis'>
          <pose frame=''>-3.09248 -7.78515 0.131959 1.57048 2.4e-05 0.014301</pose>
          <velocity>0.00076 -6.1e-05 -0.002212 -0.002704 -0.007489 4.6e-05</velocity>
          <acceleration>-0.279204 0.108864 -4.40386 -2.25447 0.956565 3.13721</acceleration>
          <wrench>-13.5738 5.29255 -214.099 0 -0 0</wrench>
        </link>
        <link name='GearPlate'>
          <pose frame=''>-3.09418 -7.40404 0.247453 1.57037 1.7e-05 0.014301</pose>
          <velocity>9.4e-05 -0.000113 -0.000926 0.00322 -0.006886 -0.000227</velocity>
          <acceleration>-1.82995 -0.434206 0.264911 -0.966971 -1.31643 3.09958</acceleration>
          <wrench>-0.052478 -0.012452 0.007597 0 -0 0</wrench>
        </link>
        <link name='L1Wheel'>
          <pose frame=''>-3.42451 -7.4864 0.056999 -0.268741 2.4e-05 0.014301</pose>
          <velocity>0.001309 -0.000279 -0.005521 -0.002717 -0.007559 4.5e-05</velocity>
          <acceleration>0.801293 -0.322989 -10.9335 -1.98128 -0.674144 -3.00832</acceleration>
          <wrench>0.327244 -0.131907 -4.46518 0 -0 0</wrench>
        </link>
        <link name='L2Wheel'>
          <pose frame=''>-3.42164 -7.68722 0.050726 -0.00818 3.6e-05 0.014301</pose>
          <velocity>0.001257 -0.000108 -0.008191 -0.002674 -0.010612 0.000185</velocity>
          <acceleration>0.711557 0.007258 -16.3816 -1.68282 -0.652218 -2.74531</acceleration>
          <wrench>0.290596 0.002964 -6.69015 0 -0 0</wrench>
        </link>
        <link name='L3Wheel'>
          <pose frame=''>-3.41849 -7.90783 0.050783 -2.45354 1.7e-05 0.014301</pose>
          <velocity>0.001493 -0.000145 -0.004086 -0.002741 -0.005879 7.9e-05</velocity>
          <acceleration>1.19382 -0.068066 -8.20515 2.10368 0.834381 0.188841</acceleration>
          <wrench>0.487551 -0.027798 -3.35094 0 -0 0</wrench>
        </link>
        <link name='L4Wheel'>
          <pose frame=''>-3.41561 -8.10864 0.057198 -2.72871 2.3e-05 0.014301</pose>
          <velocity>0.001329 -0.000279 -0.003709 -0.002719 -0.007443 4.8e-05</velocity>
          <acceleration>0.867652 -0.322236 -7.46017 -1.94459 -0.908593 -3.00433</acceleration>
          <wrench>0.354345 -0.131599 -3.0467 0 -0 0</wrench>
        </link>
        <link name='R1Wheel'>
          <pose frame=''>-2.76164 -7.47692 0.056984 0.124601 2.3e-05 0.014301</pose>
          <velocity>0.001301 -0.000249 -0.000565 -0.00272 -0.007415 4.6e-05</velocity>
          <acceleration>0.78462 -0.234104 -1.04961 -1.94463 -0.966211 -3.00638</acceleration>
          <wrench>0.320435 -0.095607 -0.428657 0 -0 0</wrench>
        </link>
        <link name='R2Wheel'>
          <pose frame=''>-2.75877 -7.67774 0.050709 -0.474085 3.9e-05 0.014301</pose>
          <velocity>0.001209 -0.000115 -0.002913 -0.002659 -0.011569 0.000126</velocity>
          <acceleration>0.599473 0.008504 -5.92124 -1.84806 1.55944 -2.81182</acceleration>
          <wrench>0.244822 0.003473 -2.4182 0 -0 0</wrench>
        </link>
        <link name='R3Wheel'>
          <pose frame=''>-2.75562 -7.89834 0.050785 -2.93028 8.7e-05 0.0143</pose>
          <velocity>0.00027 5.9e-05 0.004063 -0.00117 0.005309 -9e-05</velocity>
          <acceleration>-1.24609 0.381143 8.12424 -0.660164 -1.24611 3.00689</acceleration>
          <wrench>-0.508898 0.155657 3.3179 0 -0 0</wrench>
        </link>
        <link name='R4Wheel'>
          <pose frame=''>-2.75274 -8.09916 0.057182 -1.84917 2.4e-05 0.014301</pose>
          <velocity>0.001334 -0.000247 0.001153 -0.002662 -0.007432 4.5e-05</velocity>
          <acceleration>0.877378 -0.230512 2.23672 -1.84804 -0.927305 -3.01016</acceleration>
          <wrench>0.358317 -0.09414 0.913467 0 -0 0</wrench>
        </link>
      </model>
      <model name='gear'>
        <pose frame=''>-3.07483 -7.42411 0.386712 1.56178 -0.29245 0.008741</pose>
        <scale>1 1 1</scale>
        <link name='Body'>
          <pose frame=''>-3.07522 -7.40031 0.386434 -1.56027 0.610108 -3.12942</pose>
          <velocity>0.002503 4.7e-05 0.000131 -0.000354 -0.006261 0.000189</velocity>
          <acceleration>2.50253 0.04695 0.131165 -0.354348 0.02188 0.188733</acceleration>
          <wrench>2.67413 0.050169 0.140159 0 -0 0</wrench>
        </link>
      </model>
      <model name='ground_plane'>
        <pose frame=''>0 0 0 0 -0 0</pose>
        <scale>1 1 1</scale>
        <link name='link'>
          <pose frame=''>0 0 0 0 -0 0</pose>
          <velocity>0 0 0 0 -0 0</velocity>
          <acceleration>0 0 0 0 -0 0</acceleration>
          <wrench>0 0 0 0 -0 0</wrench>
        </link>
      </model>
      <model name='spike1'>
        <pose frame=''>-0.257931 -4.9648 0.002057 -0.0185 -0.006999 -0.524401</pose>
        <scale>1 1 1</scale>
        <link name='Body'>
          <pose frame=''>-0.242707 -4.9642 0.442131 1.5638 0.0185 1.04627</pose>
          <velocity>0 0 0 0 -0 0</velocity>
          <acceleration>0 0 0 0 -0 0</acceleration>
          <wrench>0 0 0 0 -0 0</wrench>
        </link>
      </model>
      <model name='spike2'>
        <pose frame=''>-1.037 -5.412 0.00523 0 0 -1.56</pose>
        <scale>1 1 1</scale>
        <link name='Body'>
          <pose frame=''>-1.03683 -5.42796 0.445278 1.5708 0 0.0108</pose>
          <velocity>0 0 0 0 -0 0</velocity>
          <acceleration>0 0 0 0 -0 0</acceleration>
          <wrench>0 0 0 0 -0 0</wrench>
        </link>
      </model>
      <model name='spike3'>
        <pose frame=''>-1.844 -5.009 0.026 0 0 -2.61</pose>
        <scale>1 1 1</scale>
        <link name='Body'>
          <pose frame=''>-1.85775 -5.01709 0.466048 1.5708 -0 -1.0392</pose>
          <velocity>0 0 0 0 -0 0</velocity>
          <acceleration>0 0 0 0 -0 0</acceleration>
          <wrench>0 0 0 0 -0 0</wrench>
        </link>
      </model>
      <model name='tape1'>
        <pose frame=''>-0.185359 -4.85795 0.41079 0.0116 -0.00112 -0.540003</pose>
        <scale>1 1 1</scale>
        <link name='Tape'>
          <pose frame=''>-0.250845 -4.96981 0.344665 -1.57192 -0.0116 1.03081</pose>
          <velocity>0 0 0 0 -0 0</velocity>
          <acceleration>0 0 0 0 -0 0</acceleration>
          <wrench>0 0 0 0 -0 0</wrench>
        </link>
      </model>
      <model name='tape2'>
        <pose frame=''>-0.902835 -5.42368 0.4133 0 0 -1.56235</pose>
        <scale>1 1 1</scale>
        <link name='Tape'>
          <pose frame=''>-1.03319 -5.42605 0.348681 -1.5708 -0 0.00845</pose>
          <velocity>0 0 0 0 -0 0</velocity>
          <acceleration>0 0 0 0 -0 0</acceleration>
          <wrench>0 0 0 0 -0 0</wrench>
        </link>
      </model>
      <model name='tape3'>
        <pose frame=''>-1.885 -4.858 0.41 0 -0 0.51715</pose>
        <scale>1 1 1</scale>
        <link name='Tape'>
          <pose frame=''>-1.81944 -4.97069 0.345381 -1.5708 0 2.08795</pose>
          <velocity>0 0 0 0 -0 0</velocity>
          <acceleration>0 0 0 0 -0 0</acceleration>
          <wrench>0 0 0 0 -0 0</wrench>
        </link>
      </model>
      <light name='sun'>
        <pose frame=''>0 0 10 0 -0 0</pose>
      </light>
    </state>
  </world>
</sdf>
