<sdf version='1.6'>
  <world name='default'>
    <gui fullscreen='0'>
      <camera name='user_camera'>
        <pose frame=''>0.821739 -6.99642 4.81856 1e-06 1.4978 1.26421</pose>
        <view_controller>orbit</view_controller>
        <projection_type>perspective</projection_type>
      </camera>
    </gui>
    <light name='sun' type='directional'>
      <cast_shadows>1</cast_shadows>
      <pose frame=''>0 0 10 0 -0 0</pose>
      <diffuse>0.8 0.8 0.8 1</diffuse>
      <specular>0.1 0.1 0.1 1</specular>
      <attenuation>
        <range>1000</range>
        <constant>0.9</constant>
        <linear>0.01</linear>
        <quadratic>0.001</quadratic>
      </attenuation>
      <direction>-0.5 0.5 -1</direction>
    </light>
    <model name='ground_plane'>
      <static>1</static>
      <link name='link'>
        <collision name='collision'>
          <geometry>
            <plane>
              <normal>0 0 1</normal>
              <size>100 100</size>
            </plane>
          </geometry>
          <surface>
            <friction>
              <ode>
                <mu>100</mu>
                <mu2>50</mu2>
              </ode>
              <torsional>
                <ode/>
              </torsional>
            </friction>
            <contact>
              <ode/>
            </contact>
            <bounce/>
          </surface>
          <max_contacts>10</max_contacts>
        </collision>
        <visual name='visual'>
          <cast_shadows>0</cast_shadows>
          <geometry>
            <plane>
              <normal>0 0 1</normal>
              <size>100 100</size>
            </plane>
          </geometry>
          <material>
            <script>
              <uri>file://media/materials/scripts/gazebo.material</uri>
              <name>Gazebo/Grey</name>
            </script>
          </material>
        </visual>
        <self_collide>0</self_collide>
        <kinematic>0</kinematic>
      </link>
    </model>
    <model name='FRC2017'>
      <pose frame=''>0 0 -0.927 0 -0 0</pose>
      <static>1</static>
      <link name='Field'>
        <gravity>0</gravity>
        <self_collide>0</self_collide>
        <pose frame=''>0 0.066233 1.9717 1.5707 -0 0</pose>
        <must_be_base_link>1</must_be_base_link>
        <velocity_decay>
          <linear>0</linear>
          <angular>0</angular>
        </velocity_decay>
        <visual name='Field_visual'>
          <pose frame=''>-0.821548 0.928908 0.089052 0 -0 0</pose>
          <material>
            <ambient>0.752941 0.752941 0.752941 1</ambient>
            <diffuse>0.752941 0.752941 0.752941 1</diffuse>
          </material>
          <geometry>
            <mesh>
              <scale>1 1 1</scale>
              <uri>model://FRC2017/meshes/Field.STL</uri>
            </mesh>
          </geometry>
        </visual>
        <kinematic>0</kinematic>
      </link>
    </model>
    <model name='SimBot'>
      <pose frame=''>0.3256 -7.36 0.022 0 -0 1.579</pose>
      <plugin name='clock' filename='libclock.so'>
        <topic>/gazebo/frc/time</topic>
      </plugin>
      <link name='Chassis'>
        <gravity>1</gravity>
        <self_collide>0</self_collide>
        <pose frame=''>-0.417788 -0.370901 0.109796 1.5708 0 -1.5708</pose>
        <must_be_base_link>1</must_be_base_link>
        <velocity_decay>
          <linear>0</linear>
          <angular>0</angular>
        </velocity_decay>
        <inertial>
          <mass>48.6161</mass>
          <pose frame=''>0 0 0 0 -0 0</pose>
          <inertia>
            <ixx>6.85956</ixx>
            <ixy>0.0505958</ixy>
            <ixz>0.0454905</ixz>
            <iyy>11.068</iyy>
            <iyz>0.0206055</iyz>
            <izz>5.66912</izz>
          </inertia>
        </inertial>
        <collision name='Chassis_collision'>
          <pose frame=''>0.003749 -0.143686 -0.417788 0 -0 0</pose>
          <geometry>
            <mesh>
              <scale>1 1 1</scale>
              <uri>model://SimBot/meshes/Chassis_col.STL</uri>
            </mesh>
          </geometry>
          <surface>
            <contact>
              <ode/>
            </contact>
            <friction>
              <ode>
                <mu>0</mu>
                <mu2>0</mu2>
              </ode>
              <torsional>
                <ode/>
              </torsional>
            </friction>
            <bounce/>
          </surface>
          <max_contacts>10</max_contacts>
        </collision>
        <visual name='Chassis_visual'>
          <pose frame=''>0.003749 -0.143686 -0.417788 0 -0 0</pose>
          <material>
            <ambient>0 0.25098 1 1</ambient>
            <diffuse>0 0.25098 1 1</diffuse>
          </material>
          <geometry>
            <mesh>
              <scale>1 1 1</scale>
              <uri>model://SimBot/meshes/Chassis.STL</uri>
            </mesh>
          </geometry>
        </visual>
        <sensor name='ChassisCamera' type='camera'>
          <visualize>1</visualize>
          <always_on>1</always_on>
          <pose frame=''>0.17 0.23 -0.37 1.57159 1.57159 3.14159</pose>
          <camera name='Chassiscamera'>
            <horizontal_fov>0.66</horizontal_fov>
            <image>
              <width>320</width>
              <height>240</height>
            </image>
            <clip>
              <near>0.1</near>
              <far>30</far>
            </clip>
            <save enabled='1'>
              <path>/tmp/target-camera</path>
            </save>
          </camera>
        </sensor>
        <sensor name='DriverCamera' type='camera'>
          <visualize>0</visualize>
          <always_on>1</always_on>
          <pose frame=''>-0.05 0.23 -0.3 -1.57 1.57 -0</pose>
          <camera name='Bodycamera'>
            <horizontal_fov>1.0472</horizontal_fov>
            <image>
              <width>320</width>
              <height>240</height>
            </image>
            <clip>
              <near>0.01</near>
              <far>30</far>
            </clip>
            <save enabled='1'>
              <path>/tmp/driver-camera</path>
            </save>
          </camera>
        </sensor>
        <sensor name='ChassisUltrasonic' type='sonar'>
          <always_on>1</always_on>
          <visualize>0</visualize>
          <pose frame=''>0.17 0.318096 -0.369812 -0.2 0.2 -0</pose>
          <sonar>
            <min>0.1</min>
            <max>2</max>
            <radius>0.2</radius>
          </sonar>
        </sensor>
        <kinematic>0</kinematic>
      </link>
      <link name='L1Wheel'>
        <gravity>1</gravity>
        <self_collide>0</self_collide>
        <pose frame=''>-0.1143 -0.04318 0.034925 1.5708 0 -1.5708</pose>
        <must_be_base_link>0</must_be_base_link>
        <velocity_decay>
          <linear>0</linear>
          <angular>0</angular>
        </velocity_decay>
        <inertial>
          <mass>0.408395</mass>
          <pose frame=''>0 0 0 0 -0 0</pose>
          <inertia>
            <ixx>0.00522886</ixx>
            <ixy>0</ixy>
            <ixz>0</ixz>
            <iyy>0.00347976</iyy>
            <iyz>0</iyz>
            <izz>0.00347976</izz>
          </inertia>
        </inertial>
        <collision name='L1Wheel_collision'>
          <pose frame=''>0.33147 -0.068814 -0.1143 0 -0 0</pose>
          <geometry>
            <mesh>
              <scale>1 1 1</scale>
              <uri>model://SimBot/meshes/L1Wheel_col.STL</uri>
            </mesh>
          </geometry>
          <surface>
            <contact>
              <ode/>
            </contact>
            <friction>
              <ode>
                <mu>1</mu>
                <mu2>1</mu2>
              </ode>
              <torsional>
                <ode/>
              </torsional>
            </friction>
            <bounce/>
          </surface>
          <max_contacts>10</max_contacts>
        </collision>
        <visual name='L1Wheel_visual'>
          <pose frame=''>0.33147 -0.068814 -0.1143 0 -0 0</pose>
          <material>
            <ambient>0.752941 0.752941 0.752941 1</ambient>
            <diffuse>0.752941 0.752941 0.752941 1</diffuse>
          </material>
          <geometry>
            <mesh>
              <scale>1 1 1</scale>
              <uri>model://SimBot/meshes/L1Wheel.STL</uri>
            </mesh>
          </geometry>
        </visual>
        <kinematic>0</kinematic>
      </link>
      <joint name='Chassis-L1Wheel' type='revolute'>
        <parent>Chassis</parent>
        <child>L1Wheel</child>
        <pose frame=''>0.02286 0 0 0 -0 0</pose>
        <axis>
          <xyz>-1 0 0</xyz>
          <dynamics>
            <damping>1</damping>
            <friction>1</friction>
            <spring_reference>0</spring_reference>
            <spring_stiffness>0</spring_stiffness>
          </dynamics>
          <limit>
            <effort>100</effort>
            <lower>-1e+16</lower>
            <upper>1e+16</upper>
          </limit>
          <use_parent_model_frame>0</use_parent_model_frame>
        </axis>
      </joint>
      <link name='L2Wheel'>
        <gravity>1</gravity>
        <self_collide>0</self_collide>
        <pose frame=''>-0.315134 -0.04318 0.028575 1.5708 0 -1.5708</pose>
        <must_be_base_link>0</must_be_base_link>
        <velocity_decay>
          <linear>0</linear>
          <angular>0</angular>
        </velocity_decay>
        <inertial>
          <mass>0.408395</mass>
          <pose frame=''>0 0 0 0 -0 0</pose>
          <inertia>
            <ixx>0.00522886</ixx>
            <ixy>0</ixy>
            <ixz>0</ixz>
            <iyy>0.00347976</iyy>
            <iyz>0</iyz>
            <izz>0.00347976</izz>
          </inertia>
        </inertial>
        <collision name='L2Wheel_collision'>
          <pose frame=''>0.33147 -0.062464 -0.315134 0 -0 0</pose>
          <geometry>
            <mesh>
              <scale>1 1 1</scale>
              <uri>model://SimBot/meshes/L2Wheel_col.STL</uri>
            </mesh>
          </geometry>
          <surface>
            <contact>
              <ode/>
            </contact>
            <friction>
              <ode>
                <mu>1</mu>
                <mu2>1</mu2>
              </ode>
              <torsional>
                <ode/>
              </torsional>
            </friction>
            <bounce/>
          </surface>
          <max_contacts>10</max_contacts>
        </collision>
        <visual name='L2Wheel_visual'>
          <pose frame=''>0.33147 -0.062464 -0.315134 0 -0 0</pose>
          <material>
            <ambient>0.752941 0.752941 0.752941 1</ambient>
            <diffuse>0.752941 0.752941 0.752941 1</diffuse>
          </material>
          <geometry>
            <mesh>
              <scale>1 1 1</scale>
              <uri>model://SimBot/meshes/L2Wheel.STL</uri>
            </mesh>
          </geometry>
        </visual>
        <kinematic>0</kinematic>
      </link>
      <joint name='Chassis-L2Wheel' type='revolute'>
        <parent>Chassis</parent>
        <child>L2Wheel</child>
        <pose frame=''>0.02286 0 0 0 -0 0</pose>
        <axis>
          <xyz>-1 0 0</xyz>
          <dynamics>
            <damping>1</damping>
            <friction>1</friction>
            <spring_reference>0</spring_reference>
            <spring_stiffness>0</spring_stiffness>
          </dynamics>
          <limit>
            <effort>100</effort>
            <lower>-1e+16</lower>
            <upper>1e+16</upper>
          </limit>
          <use_parent_model_frame>0</use_parent_model_frame>
        </axis>
      </joint>
      <link name='L3Wheel'>
        <gravity>1</gravity>
        <self_collide>0</self_collide>
        <pose frame=''>-0.535766 -0.04318 0.028575 1.5708 0 -1.5708</pose>
        <must_be_base_link>0</must_be_base_link>
        <velocity_decay>
          <linear>0</linear>
          <angular>0</angular>
        </velocity_decay>
        <inertial>
          <mass>0.408395</mass>
          <pose frame=''>0 0 0 0 -0 0</pose>
          <inertia>
            <ixx>0.00522886</ixx>
            <ixy>0</ixy>
            <ixz>0</ixz>
            <iyy>0.00347976</iyy>
            <iyz>0</iyz>
            <izz>0.00347976</izz>
          </inertia>
        </inertial>
        <collision name='L3Wheel_collision'>
          <pose frame=''>0.33147 -0.062464 -0.535766 0 -0 0</pose>
          <geometry>
            <mesh>
              <scale>1 1 1</scale>
              <uri>model://SimBot/meshes/L3Wheel_col.STL</uri>
            </mesh>
          </geometry>
          <surface>
            <contact>
              <ode/>
            </contact>
            <friction>
              <ode>
                <mu>1</mu>
                <mu2>1</mu2>
              </ode>
              <torsional>
                <ode/>
              </torsional>
            </friction>
            <bounce/>
          </surface>
          <max_contacts>10</max_contacts>
        </collision>
        <visual name='L3Wheel_visual'>
          <pose frame=''>0.33147 -0.062464 -0.535766 0 -0 0</pose>
          <material>
            <ambient>0.752941 0.752941 0.752941 1</ambient>
            <diffuse>0.752941 0.752941 0.752941 1</diffuse>
          </material>
          <geometry>
            <mesh>
              <scale>1 1 1</scale>
              <uri>model://SimBot/meshes/L3Wheel.STL</uri>
            </mesh>
          </geometry>
        </visual>
        <kinematic>0</kinematic>
      </link>
      <joint name='Chassis-L3Wheel' type='revolute'>
        <parent>Chassis</parent>
        <child>L3Wheel</child>
        <pose frame=''>0.02286 0 0 0 -0 0</pose>
        <axis>
          <xyz>-1 0 0</xyz>
          <dynamics>
            <damping>1</damping>
            <friction>1</friction>
            <spring_reference>0</spring_reference>
            <spring_stiffness>0</spring_stiffness>
          </dynamics>
          <limit>
            <effort>100</effort>
            <lower>-1e+16</lower>
            <upper>1e+16</upper>
          </limit>
          <use_parent_model_frame>0</use_parent_model_frame>
        </axis>
      </joint>
      <link name='L4Wheel'>
        <gravity>1</gravity>
        <self_collide>0</self_collide>
        <pose frame=''>-0.7366 -0.04318 0.034925 1.5708 0 -1.5708</pose>
        <must_be_base_link>0</must_be_base_link>
        <velocity_decay>
          <linear>0</linear>
          <angular>0</angular>
        </velocity_decay>
        <inertial>
          <mass>0.408395</mass>
          <pose frame=''>0 0 0 0 -0 0</pose>
          <inertia>
            <ixx>0.00522886</ixx>
            <ixy>0</ixy>
            <ixz>0</ixz>
            <iyy>0.00347976</iyy>
            <iyz>0</iyz>
            <izz>0.00347976</izz>
          </inertia>
        </inertial>
        <collision name='L4Wheel_collision'>
          <pose frame=''>0.33147 -0.068814 -0.7366 0 -0 0</pose>
          <geometry>
            <mesh>
              <scale>1 1 1</scale>
              <uri>model://SimBot/meshes/L4Wheel_col.STL</uri>
            </mesh>
          </geometry>
          <surface>
            <contact>
              <ode/>
            </contact>
            <friction>
              <ode>
                <mu>1</mu>
                <mu2>1</mu2>
              </ode>
              <torsional>
                <ode/>
              </torsional>
            </friction>
            <bounce/>
          </surface>
          <max_contacts>10</max_contacts>
        </collision>
        <visual name='L4Wheel_visual'>
          <pose frame=''>0.33147 -0.068814 -0.7366 0 -0 0</pose>
          <material>
            <ambient>0.752941 0.752941 0.752941 1</ambient>
            <diffuse>0.752941 0.752941 0.752941 1</diffuse>
          </material>
          <geometry>
            <mesh>
              <scale>1 1 1</scale>
              <uri>model://SimBot/meshes/L4Wheel.STL</uri>
            </mesh>
          </geometry>
        </visual>
        <kinematic>0</kinematic>
      </link>
      <joint name='Chassis-L4Wheel' type='revolute'>
        <parent>Chassis</parent>
        <child>L4Wheel</child>
        <pose frame=''>0.02286 0 0 0 -0 0</pose>
        <axis>
          <xyz>-1 0 0</xyz>
          <dynamics>
            <damping>1</damping>
            <friction>1</friction>
            <spring_reference>0</spring_reference>
            <spring_stiffness>0</spring_stiffness>
          </dynamics>
          <limit>
            <effort>100</effort>
            <lower>-1e+16</lower>
            <upper>1e+16</upper>
          </limit>
          <use_parent_model_frame>0</use_parent_model_frame>
        </axis>
      </joint>
      <link name='R1Wheel'>
        <gravity>1</gravity>
        <self_collide>0</self_collide>
        <pose frame=''>-0.1143 -0.70612 0.034925 1.5708 0 -1.5708</pose>
        <must_be_base_link>0</must_be_base_link>
        <velocity_decay>
          <linear>0</linear>
          <angular>0</angular>
        </velocity_decay>
        <inertial>
          <mass>0.408395</mass>
          <pose frame=''>0 0 0 0 -0 0</pose>
          <inertia>
            <ixx>0.00522886</ixx>
            <ixy>0</ixy>
            <ixz>0</ixz>
            <iyy>0.00347976</iyy>
            <iyz>0</iyz>
            <izz>0.00347976</izz>
          </inertia>
        </inertial>
        <collision name='R1Wheel_collision'>
          <pose frame=''>-0.33147 -0.068814 -0.1143 0 -0 0</pose>
          <geometry>
            <mesh>
              <scale>1 1 1</scale>
              <uri>model://SimBot/meshes/R1Wheel_col.STL</uri>
            </mesh>
          </geometry>
          <surface>
            <contact>
              <ode/>
            </contact>
            <friction>
              <ode>
                <mu>1</mu>
                <mu2>1</mu2>
              </ode>
              <torsional>
                <ode/>
              </torsional>
            </friction>
            <bounce/>
          </surface>
          <max_contacts>10</max_contacts>
        </collision>
        <visual name='R1Wheel_visual'>
          <pose frame=''>-0.33147 -0.068814 -0.1143 0 -0 0</pose>
          <material>
            <ambient>0.752941 0.752941 0.752941 1</ambient>
            <diffuse>0.752941 0.752941 0.752941 1</diffuse>
          </material>
          <geometry>
            <mesh>
              <scale>1 1 1</scale>
              <uri>model://SimBot/meshes/R1Wheel.STL</uri>
            </mesh>
          </geometry>
        </visual>
        <kinematic>0</kinematic>
      </link>
      <joint name='Chassis-R1Wheel' type='revolute'>
        <parent>Chassis</parent>
        <child>R1Wheel</child>
        <pose frame=''>-0.02286 0 0 0 -0 0</pose>
        <axis>
          <xyz>1 0 0</xyz>
          <dynamics>
            <damping>1</damping>
            <friction>1</friction>
            <spring_reference>0</spring_reference>
            <spring_stiffness>0</spring_stiffness>
          </dynamics>
          <limit>
            <effort>100</effort>
            <lower>-1e+16</lower>
            <upper>1e+16</upper>
          </limit>
          <use_parent_model_frame>0</use_parent_model_frame>
        </axis>
      </joint>
      <link name='R2Wheel'>
        <gravity>1</gravity>
        <self_collide>0</self_collide>
        <pose frame=''>-0.315134 -0.70612 0.028575 1.5708 0 -1.5708</pose>
        <must_be_base_link>0</must_be_base_link>
        <velocity_decay>
          <linear>0</linear>
          <angular>0</angular>
        </velocity_decay>
        <inertial>
          <mass>0.408395</mass>
          <pose frame=''>0 0 0 0 -0 0</pose>
          <inertia>
            <ixx>0.00522886</ixx>
            <ixy>0</ixy>
            <ixz>0</ixz>
            <iyy>0.00347976</iyy>
            <iyz>0</iyz>
            <izz>0.00347976</izz>
          </inertia>
        </inertial>
        <collision name='R2Wheel_collision'>
          <pose frame=''>-0.33147 -0.062464 -0.315134 0 -0 0</pose>
          <geometry>
            <mesh>
              <scale>1 1 1</scale>
              <uri>model://SimBot/meshes/R2Wheel_col.STL</uri>
            </mesh>
          </geometry>
          <surface>
            <contact>
              <ode/>
            </contact>
            <friction>
              <ode>
                <mu>1</mu>
                <mu2>1</mu2>
              </ode>
              <torsional>
                <ode/>
              </torsional>
            </friction>
            <bounce/>
          </surface>
          <max_contacts>10</max_contacts>
        </collision>
        <visual name='R2Wheel_visual'>
          <pose frame=''>-0.33147 -0.062464 -0.315134 0 -0 0</pose>
          <material>
            <ambient>0.752941 0.752941 0.752941 1</ambient>
            <diffuse>0.752941 0.752941 0.752941 1</diffuse>
          </material>
          <geometry>
            <mesh>
              <scale>1 1 1</scale>
              <uri>model://SimBot/meshes/R2Wheel.STL</uri>
            </mesh>
          </geometry>
        </visual>
        <kinematic>0</kinematic>
      </link>
      <joint name='Chassis-R2Wheel' type='revolute'>
        <parent>Chassis</parent>
        <child>R2Wheel</child>
        <pose frame=''>-0.02286 0 0 0 -0 0</pose>
        <axis>
          <xyz>1 0 0</xyz>
          <dynamics>
            <damping>1</damping>
            <friction>1</friction>
            <spring_reference>0</spring_reference>
            <spring_stiffness>0</spring_stiffness>
          </dynamics>
          <limit>
            <effort>100</effort>
            <lower>-1e+16</lower>
            <upper>1e+16</upper>
          </limit>
          <use_parent_model_frame>0</use_parent_model_frame>
        </axis>
      </joint>
      <link name='R3Wheel'>
        <gravity>1</gravity>
        <self_collide>0</self_collide>
        <pose frame=''>-0.535766 -0.70612 0.028575 1.5708 0 -1.5708</pose>
        <must_be_base_link>0</must_be_base_link>
        <velocity_decay>
          <linear>0</linear>
          <angular>0</angular>
        </velocity_decay>
        <inertial>
          <mass>0.408395</mass>
          <pose frame=''>0 0 0 0 -0 0</pose>
          <inertia>
            <ixx>0.00522886</ixx>
            <ixy>0</ixy>
            <ixz>0</ixz>
            <iyy>0.00347976</iyy>
            <iyz>0</iyz>
            <izz>0.00347976</izz>
          </inertia>
        </inertial>
        <collision name='R3Wheel_collision'>
          <pose frame=''>-0.33147 -0.062464 -0.535766 0 -0 0</pose>
          <geometry>
            <mesh>
              <scale>1 1 1</scale>
              <uri>model://SimBot/meshes/R3Wheel_col.STL</uri>
            </mesh>
          </geometry>
          <surface>
            <contact>
              <ode/>
            </contact>
            <friction>
              <ode>
                <mu>1</mu>
                <mu2>1</mu2>
              </ode>
              <torsional>
                <ode/>
              </torsional>
            </friction>
            <bounce/>
          </surface>
          <max_contacts>10</max_contacts>
        </collision>
        <visual name='R3Wheel_visual'>
          <pose frame=''>-0.33147 -0.062464 -0.535766 0 -0 0</pose>
          <material>
            <ambient>0.752941 0.752941 0.752941 1</ambient>
            <diffuse>0.752941 0.752941 0.752941 1</diffuse>
          </material>
          <geometry>
            <mesh>
              <scale>1 1 1</scale>
              <uri>model://SimBot/meshes/R3Wheel.STL</uri>
            </mesh>
          </geometry>
        </visual>
        <kinematic>0</kinematic>
      </link>
      <joint name='Chassis-R3Wheel' type='revolute'>
        <parent>Chassis</parent>
        <child>R3Wheel</child>
        <pose frame=''>-0.02286 0 0 0 -0 0</pose>
        <axis>
          <xyz>1 0 0</xyz>
          <dynamics>
            <damping>1</damping>
            <friction>1</friction>
            <spring_reference>0</spring_reference>
            <spring_stiffness>0</spring_stiffness>
          </dynamics>
          <limit>
            <effort>100</effort>
            <lower>-1e+16</lower>
            <upper>1e+16</upper>
          </limit>
          <use_parent_model_frame>0</use_parent_model_frame>
        </axis>
      </joint>
      <link name='R4Wheel'>
        <gravity>1</gravity>
        <self_collide>0</self_collide>
        <pose frame=''>-0.7366 -0.70612 0.034925 1.5708 0 -1.5708</pose>
        <must_be_base_link>0</must_be_base_link>
        <velocity_decay>
          <linear>0</linear>
          <angular>0</angular>
        </velocity_decay>
        <inertial>
          <mass>0.408395</mass>
          <pose frame=''>0 0 0 0 -0 0</pose>
          <inertia>
            <ixx>0.00522886</ixx>
            <ixy>0</ixy>
            <ixz>0</ixz>
            <iyy>0.00347976</iyy>
            <iyz>0</iyz>
            <izz>0.00347976</izz>
          </inertia>
        </inertial>
        <collision name='R4Wheel_collision'>
          <pose frame=''>-0.33147 -0.068814 -0.7366 0 -0 0</pose>
          <geometry>
            <mesh>
              <scale>1 1 1</scale>
              <uri>model://SimBot/meshes/R4Wheel_col.STL</uri>
            </mesh>
          </geometry>
          <surface>
            <contact>
              <ode/>
            </contact>
            <friction>
              <ode>
                <mu>1</mu>
                <mu2>1</mu2>
              </ode>
              <torsional>
                <ode/>
              </torsional>
            </friction>
            <bounce/>
          </surface>
          <max_contacts>10</max_contacts>
        </collision>
        <visual name='R4Wheel_visual'>
          <pose frame=''>-0.33147 -0.068814 -0.7366 0 -0 0</pose>
          <material>
            <ambient>0.752941 0.752941 0.752941 1</ambient>
            <diffuse>0.752941 0.752941 0.752941 1</diffuse>
          </material>
          <geometry>
            <mesh>
              <scale>1 1 1</scale>
              <uri>model://SimBot/meshes/R4Wheel.STL</uri>
            </mesh>
          </geometry>
        </visual>
        <kinematic>0</kinematic>
      </link>
      <joint name='Chassis-R4Wheel' type='revolute'>
        <parent>Chassis</parent>
        <child>R4Wheel</child>
        <pose frame=''>-0.02286 0 0 0 -0 0</pose>
        <axis>
          <xyz>1 0 0</xyz>
          <dynamics>
            <damping>1</damping>
            <friction>1</friction>
            <spring_reference>0</spring_reference>
            <spring_stiffness>0</spring_stiffness>
          </dynamics>
          <limit>
            <effort>100</effort>
            <lower>-1e+16</lower>
            <upper>1e+16</upper>
          </limit>
          <use_parent_model_frame>0</use_parent_model_frame>
        </axis>
      </joint>
      <link name='BallPusher'>
        <gravity>1</gravity>
        <self_collide>0</self_collide>
        <pose frame=''>-0.23857 -0.37545 0.193772 1.5708 0 -1.5708</pose>
        <must_be_base_link>0</must_be_base_link>
        <velocity_decay>
          <linear>0</linear>
          <angular>0</angular>
        </velocity_decay>
        <inertial>
          <mass>0.355128</mass>
          <pose frame=''>0 0 0 0 -0 0</pose>
          <inertia>
            <ixx>0.00398094</ixx>
            <ixy>3.1169e-17</ixy>
            <ixz>2.20178e-17</ixz>
            <iyy>0.0516966</iyy>
            <iyz>0.00161224</iyz>
            <izz>0.05358</izz>
          </inertia>
        </inertial>
        <collision name='BallPusher_collision'>
          <pose frame=''>-0.0008 -0.227662 -0.23857 0 -0 0</pose>
          <geometry>
            <mesh>
              <scale>1 1 1</scale>
              <uri>model://SimBot/meshes/BallPusher_col.STL</uri>
            </mesh>
          </geometry>
          <surface>
            <contact>
              <ode/>
            </contact>
            <friction>
              <ode>
                <mu>1</mu>
                <mu2>1</mu2>
              </ode>
              <torsional>
                <ode/>
              </torsional>
            </friction>
            <bounce/>
          </surface>
          <max_contacts>10</max_contacts>
        </collision>
        <visual name='BallPusher_visual'>
          <pose frame=''>-0.0008 -0.227662 -0.23857 0 -0 0</pose>
          <material>
            <ambient>1 0.752941 0.501961 1</ambient>
            <diffuse>1 0.752941 0.501961 1</diffuse>
          </material>
          <geometry>
            <mesh>
              <scale>1 1 1</scale>
              <uri>model://SimBot/meshes/BallPusher.STL</uri>
            </mesh>
          </geometry>
        </visual>
        <kinematic>0</kinematic>
      </link>
      <joint name='Chassis-BallPusher' type='prismatic'>
        <parent>Chassis</parent>
        <child>BallPusher</child>
        <pose frame=''>0 0 0 0 -0 0</pose>
        <axis>
          <xyz>0 0.5 1</xyz>
          <dynamics>
            <damping>1</damping>
            <friction>1</friction>
            <spring_reference>0</spring_reference>
            <spring_stiffness>0</spring_stiffness>
          </dynamics>
          <limit>
            <upper>0.5</upper>
            <lower>0</lower>
            <effort>100</effort>
          </limit>
          <use_parent_model_frame>0</use_parent_model_frame>
        </axis>
      </joint>
      <link name='GearPlate'>
        <gravity>1</gravity>
        <self_collide>0</self_collide>
        <pose frame=''>-0.034925 -0.37465 0.225425 1.5708 0 -1.5708</pose>
        <must_be_base_link>0</must_be_base_link>
        <velocity_decay>
          <linear>0</linear>
          <angular>0</angular>
        </velocity_decay>
        <inertial>
          <mass>0.0286774</mass>
          <pose frame=''>0 0 0 0 -0 0</pose>
          <inertia>
            <ixx>0.001</ixx>
            <ixy>0</ixy>
            <ixz>0</ixz>
            <iyy>0.003</iyy>
            <iyz>0</iyz>
            <izz>0.001</izz>
          </inertia>
        </inertial>
        <collision name='GearPlate_collision'>
          <pose frame=''>-0 -0.259314 -0.034925 0 -0 0</pose>
          <geometry>
            <mesh>
              <scale>1 1 1</scale>
              <uri>model://SimBot/meshes/GearPlate_col.STL</uri>
            </mesh>
          </geometry>
          <surface>
            <contact>
              <ode/>
            </contact>
            <friction>
              <ode>
                <mu>1</mu>
                <mu2>1</mu2>
              </ode>
              <torsional>
                <ode/>
              </torsional>
            </friction>
            <bounce/>
          </surface>
          <max_contacts>10</max_contacts>
        </collision>
        <visual name='GearPlate_visual'>
          <pose frame=''>-0 -0.259314 -0.034925 0 -0 0</pose>
          <material>
            <ambient>1 0 0 1</ambient>
            <diffuse>1 0 0 1</diffuse>
          </material>
          <geometry>
            <mesh>
              <scale>1 1 1</scale>
              <uri>model://SimBot/meshes/GearPlate.STL</uri>
            </mesh>
          </geometry>
        </visual>
        <kinematic>0</kinematic>
      </link>
      <joint name='Chassis-GearPlate' type='prismatic'>
        <parent>Chassis</parent>
        <child>GearPlate</child>
        <pose frame=''>-0.04445 0.003175 -0.0254 0 -0 0</pose>
        <axis>
          <xyz>0 0 1</xyz>
          <dynamics>
            <damping>0.2</damping>
            <friction>0.2</friction>
            <spring_reference>0</spring_reference>
            <spring_stiffness>0</spring_stiffness>
          </dynamics>
          <limit>
            <upper>0.05</upper>
            <lower>0</lower>
            <effort>100</effort>
          </limit>
          <use_parent_model_frame>0</use_parent_model_frame>
        </axis>
      </joint>
      <plugin name='Chassis_rangefinder' filename='librangefinder.so'>
        <topic>/gazebo/frc/simulator/analog/0</topic>
        <sensor>ChassisUltrasonic</sensor>
      </plugin>
      <plugin name='Chassis-L1Wheel_motor' filename='libdc_motor.so'>
        <joint>Chassis-L1Wheel</joint>
        <topic>/gazebo/frc/simulator/pwm/2</topic>
        <multiplier>25</multiplier>
      </plugin>
      <plugin name='Chassis-L2Wheel_motor' filename='libdc_motor.so'>
        <joint>Chassis-L2Wheel</joint>
        <topic>/gazebo/frc/simulator/pwm/2</topic>
        <multiplier>25</multiplier>
      </plugin>
      <plugin name='Chassis-L2Wheel_encoder' filename='libencoder.so'>
        <joint>Chassis-L2Wheel</joint>
        <topic>/gazebo/frc/simulator/dio/3/4</topic>
        <units>degrees</units>
      </plugin>
      <plugin name='Chassis-L3Wheel_motor' filename='libdc_motor.so'>
        <joint>Chassis-L3Wheel</joint>
        <topic>/gazebo/frc/simulator/pwm/2</topic>
        <multiplier>25</multiplier>
      </plugin>
      <plugin name='Chassis-L4Wheel_motor' filename='libdc_motor.so'>
        <joint>Chassis-L4Wheel</joint>
        <topic>/gazebo/frc/simulator/pwm/2</topic>
        <multiplier>25</multiplier>
      </plugin>
      <plugin name='Chassis-R1Wheel_motor' filename='libdc_motor.so'>
        <joint>Chassis-R1Wheel</joint>
        <topic>/gazebo/frc/simulator/pwm/4</topic>
        <multiplier>25</multiplier>
      </plugin>
      <plugin name='Chassis-R2Wheel_motor' filename='libdc_motor.so'>
        <joint>Chassis-R2Wheel</joint>
        <topic>/gazebo/frc/simulator/pwm/4</topic>
        <multiplier>25</multiplier>
      </plugin>
      <plugin name='Chassis-R2Wheel_encoder' filename='libencoder.so'>
        <joint>Chassis-R2Wheel</joint>
        <topic>/gazebo/frc/simulator/dio/7/8</topic>
        <units>degrees</units>
      </plugin>
      <plugin name='Chassis-R3Wheel_motor' filename='libdc_motor.so'>
        <joint>Chassis-R3Wheel</joint>
        <topic>/gazebo/frc/simulator/pwm/4</topic>
        <multiplier>25</multiplier>
      </plugin>
      <plugin name='Chassis-R4Wheel_motor' filename='libdc_motor.so'>
        <joint>Chassis-R4Wheel</joint>
        <topic>/gazebo/frc/simulator/pwm/4</topic>
        <multiplier>25</multiplier>
      </plugin>
      <plugin name='Chassis-Gearplate' filename='libpneumatic_piston.so'>
        <joint>Chassis-GearPlate</joint>
        <direction>forward</direction>
        <forward-force>1</forward-force>
        <reverse-force>1</reverse-force>
        <topic>/gazebo/frc/simulator/pneumatic/1/1</topic>
      </plugin>
      <plugin name='Chassis-BallPusher_motor' filename='libdc_motor.so'>
        <joint>Chassis-BallPusher</joint>
        <topic>/gazebo/frc/simulator/pwm/5</topic>
        <multiplier>25</multiplier>
      </plugin>
      <plugin name='BallPusher_fwdlimit' filename='liblimit_switch.so'>
        <joint>Chassis-BallPusher</joint>
        <topic>/gazebo/frc/simulator/dio/10</topic>
        <units>radians</units>
        <type>internal</type>
        <min>0.45</min>
        <max>0.5</max>
      </plugin>
      <plugin name='BallPusher_revlimit' filename='liblimit_switch.so'>
        <joint>Chassis-BallPusher</joint>
        <topic>/gazebo/frc/simulator/dio/9</topic>
        <units>radians</units>
        <type>internal</type>
        <min>0</min>
        <max>0.1</max>
      </plugin>
    </model>
    <model name='spike1'>
      <pose frame=''>-0.25793 -4.9648 0.002057 -0.0185 -0.007 -0.5244</pose>
      <static>1</static>
      <link name='Body'>
        <gravity>1</gravity>
        <self_collide>0</self_collide>
        <pose frame=''>0.015957 2e-06 0.440048 1.5708 -0 1.5708</pose>
        <must_be_base_link>1</must_be_base_link>
        <velocity_decay>
          <linear>0</linear>
          <angular>0</angular>
        </velocity_decay>
        <inertial>
          <mass>10</mass>
          <pose frame=''>0 0 0 0 -0 0</pose>
          <inertia>
            <ixx>1</ixx>
            <ixy>0</ixy>
            <ixz>0</ixz>
            <iyy>1</iyy>
            <iyz>0</iyz>
            <izz>1</izz>
          </inertia>
        </inertial>
        <collision name='Body_collision'>
          <pose frame=''>-2e-06 -0.440048 -0.91566 0 -0 0</pose>
          <geometry>
            <mesh>
              <scale>1 1 1</scale>
              <uri>model://SpikePanel/meshes/Body.STL</uri>
            </mesh>
          </geometry>
          <surface>
            <friction>
              <ode>
                <mu>0</mu>
                <mu2>0</mu2>
              </ode>
              <torsional>
                <ode/>
              </torsional>
            </friction>
            <contact>
              <ode>
                <kd>120000</kd>
                <kp>1e+07</kp>
              </ode>
            </contact>
            <bounce/>
          </surface>
          <max_contacts>10</max_contacts>
        </collision>
        <kinematic>0</kinematic>
      </link>
    </model>
    <model name='spike2'>
      <pose frame=''>-1.037 -5.412 0.00523 0 0 -1.56</pose>
      <static>1</static>
      <link name='Body'>
        <gravity>1</gravity>
        <self_collide>0</self_collide>
        <pose frame=''>0.015957 2e-06 0.440048 1.5708 -0 1.5708</pose>
        <must_be_base_link>1</must_be_base_link>
        <velocity_decay>
          <linear>0</linear>
          <angular>0</angular>
        </velocity_decay>
        <inertial>
          <mass>10</mass>
          <pose frame=''>0 0 0 0 -0 0</pose>
          <inertia>
            <ixx>1</ixx>
            <ixy>0</ixy>
            <ixz>0</ixz>
            <iyy>1</iyy>
            <iyz>0</iyz>
            <izz>1</izz>
          </inertia>
        </inertial>
        <collision name='Body_collision'>
          <pose frame=''>-2e-06 -0.440048 -0.91566 0 -0 0</pose>
          <geometry>
            <mesh>
              <scale>1 1 1</scale>
              <uri>model://SpikePanel/meshes/Body.STL</uri>
            </mesh>
          </geometry>
          <surface>
            <friction>
              <ode>
                <mu>0</mu>
                <mu2>0</mu2>
              </ode>
              <torsional>
                <ode/>
              </torsional>
            </friction>
            <contact>
              <ode>
                <kd>120000</kd>
                <kp>1e+07</kp>
              </ode>
            </contact>
            <bounce/>
          </surface>
          <max_contacts>10</max_contacts>
        </collision>
        <kinematic>0</kinematic>
      </link>
    </model>
    <model name='spike3'>
      <pose frame=''>-1.844 -5.009 0.026 0 0 -2.61</pose>
      <static>1</static>
      <link name='Body'>
        <gravity>1</gravity>
        <self_collide>0</self_collide>
        <pose frame=''>0.015957 2e-06 0.440048 1.5708 -0 1.5708</pose>
        <must_be_base_link>1</must_be_base_link>
        <velocity_decay>
          <linear>0</linear>
          <angular>0</angular>
        </velocity_decay>
        <inertial>
          <mass>10</mass>
          <pose frame=''>0 0 0 0 -0 0</pose>
          <inertia>
            <ixx>1</ixx>
            <ixy>0</ixy>
            <ixz>0</ixz>
            <iyy>1</iyy>
            <iyz>0</iyz>
            <izz>1</izz>
          </inertia>
        </inertial>
        <collision name='Body_collision'>
          <pose frame=''>-2e-06 -0.440048 -0.91566 0 -0 0</pose>
          <geometry>
            <mesh>
              <scale>1 1 1</scale>
              <uri>model://SpikePanel/meshes/Body.STL</uri>
            </mesh>
          </geometry>
          <surface>
            <friction>
              <ode>
                <mu>0</mu>
                <mu2>0</mu2>
              </ode>
              <torsional>
                <ode/>
              </torsional>
            </friction>
            <contact>
              <ode>
                <kd>120000</kd>
                <kp>1e+07</kp>
              </ode>
            </contact>
            <bounce/>
          </surface>
          <max_contacts>10</max_contacts>
        </collision>
        <kinematic>0</kinematic>
      </link>
    </model>
    <model name='tape1'>
      <link name='Tape'>
        <gravity>0</gravity>
        <self_collide>0</self_collide>
        <pose frame=''>0.00127 -0.13037 -0.064619 -1.5708 0 1.5708</pose>
        <must_be_base_link>1</must_be_base_link>
        <velocity_decay>
          <linear>0</linear>
          <angular>0</angular>
        </velocity_decay>
        <visual name='Tape_visual'>
          <pose frame=''>-0.006897 0.026776 -0.00127 0 -0 0</pose>
          <material>
            <ambient>0 1 1 1</ambient>
            <diffuse>0 1 1 1</diffuse>
            <emissive>0.2 1 1 1</emissive>
          </material>
          <geometry>
            <mesh>
              <scale>1 1 1</scale>
              <uri>model://TAPE2017/meshes/Tape.STL</uri>
            </mesh>
          </geometry>
        </visual>
        <inertial>
          <inertia>
            <ixx>1</ixx>
            <ixy>0</ixy>
            <ixz>0</ixz>
            <iyy>1</iyy>
            <iyz>0</iyz>
            <izz>1</izz>
          </inertia>
          <mass>1</mass>
        </inertial>
        <kinematic>0</kinematic>
      </link>
      <pose frame=''>-0.18536 -4.85795 0.41079 0.0116 -0.001119 -0.54</pose>
    </model>
    <model name='tape2'>
      <link name='Tape'>
        <gravity>0</gravity>
        <self_collide>0</self_collide>
        <pose frame=''>0.00127 -0.13037 -0.064619 -1.5708 0 1.5708</pose>
        <must_be_base_link>1</must_be_base_link>
        <velocity_decay>
          <linear>0</linear>
          <angular>0</angular>
        </velocity_decay>
        <visual name='Tape_visual'>
          <pose frame=''>-0.006897 0.026776 -0.00127 0 -0 0</pose>
          <material>
            <ambient>0 1 1 1</ambient>
            <diffuse>0 1 1 1</diffuse>
            <emissive>0.2 1 1 1</emissive>
          </material>
          <geometry>
            <mesh>
              <scale>1 1 1</scale>
              <uri>model://TAPE2017/meshes/Tape.STL</uri>
            </mesh>
          </geometry>
        </visual>
        <inertial>
          <inertia>
            <ixx>1</ixx>
            <ixy>0</ixy>
            <ixz>0</ixz>
            <iyy>1</iyy>
            <iyz>0</iyz>
            <izz>1</izz>
          </inertia>
          <mass>1</mass>
        </inertial>
        <kinematic>0</kinematic>
      </link>
      <pose frame=''>-0.902837 -5.42368 0.4133 0 0 -1.56235</pose>
    </model>
    <model name='tape3'>
      <link name='Tape'>
        <gravity>0</gravity>
        <self_collide>0</self_collide>
        <pose frame=''>0.00127 -0.13037 -0.064619 -1.5708 0 1.5708</pose>
        <must_be_base_link>1</must_be_base_link>
        <velocity_decay>
          <linear>0</linear>
          <angular>0</angular>
        </velocity_decay>
        <visual name='Tape_visual'>
          <pose frame=''>-0.006897 0.026776 -0.00127 0 -0 0</pose>
          <material>
            <ambient>0 1 1 1</ambient>
            <diffuse>0 1 1 1</diffuse>
            <emissive>0.2 1 1 1</emissive>
          </material>
          <geometry>
            <mesh>
              <scale>1 1 1</scale>
              <uri>model://TAPE2017/meshes/Tape.STL</uri>
            </mesh>
          </geometry>
        </visual>
        <inertial>
          <inertia>
            <ixx>1</ixx>
            <ixy>0</ixy>
            <ixz>0</ixz>
            <iyy>1</iyy>
            <iyz>0</iyz>
            <izz>1</izz>
          </inertia>
          <mass>1</mass>
        </inertial>
        <kinematic>0</kinematic>
      </link>
      <pose frame=''>-1.885 -4.858 0.41 0 -0 0.51715</pose>
    </model>
    <model name='gear'>
      <pose frame=''>0.692 -7.414 0.395 1.562 -0.042 0.0059</pose>
      <plugin name='clock' filename='libgz_clock.so'>
        <topic>/gazebo/frc/time</topic>
      </plugin>
      <link name='Body'>
        <gravity>1</gravity>
        <self_collide>0</self_collide>
        <pose frame=''>-0.000248 0 -0.023813 0 0 -2.82392</pose>
        <must_be_base_link>1</must_be_base_link>
        <velocity_decay>
          <linear>0</linear>
          <angular>0</angular>
        </velocity_decay>
        <inertial>
          <mass>1.06857</mass>
          <pose frame=''>0 0 0 0 -0 0</pose>
          <inertia>
            <ixx>0.02</ixx>
            <ixy>0</ixy>
            <ixz>0</ixz>
            <iyy>0.02</iyy>
            <iyz>0</iyz>
            <izz>0.02</izz>
          </inertia>
        </inertial>
        <collision name='Body_collision'>
          <pose frame=''>-0.000236 7.8e-05 0 0 -0 0</pose>
          <geometry>
            <mesh>
              <scale>1 1 1</scale>
              <uri>model://Gear/meshes/Body_col.STL</uri>
            </mesh>
          </geometry>
          <surface>
            <friction>
              <ode>
                <mu>0</mu>
                <mu2>0</mu2>
              </ode>
              <torsional>
                <ode/>
              </torsional>
            </friction>
            <contact>
              <ode>
                <kd>10000</kd>
                <kp>2e+07</kp>
              </ode>
            </contact>
            <bounce/>
          </surface>
          <max_contacts>10</max_contacts>
        </collision>
        <visual name='Body_visual'>
          <pose frame=''>-0.000236 7.8e-05 0 0 -0 0</pose>
          <material>
            <ambient>0.8 0.8 0.2 1</ambient>
            <diffuse>0.8 0.8 0.2 1</diffuse>
          </material>
          <geometry>
            <mesh>
              <scale>1 1 1</scale>
              <uri>model://Gear/meshes/Body.STL</uri>
            </mesh>
          </geometry>
        </visual>
        <kinematic>0</kinematic>
      </link>
    </model>
    <gravity>0 0 -9.8</gravity>
    <magnetic_field>6e-06 2.3e-05 -4.2e-05</magnetic_field>
    <atmosphere type='adiabatic'/>
    <physics name='default_physics' default='0' type='ode'>
      <max_step_size>0.001</max_step_size>
      <real_time_factor>1</real_time_factor>
      <real_time_update_rate>1000</real_time_update_rate>
    </physics>
    <scene>
      <ambient>0.4 0.4 0.4 1</ambient>
      <background>0.7 0.7 0.7 1</background>
      <shadows>1</shadows>
    </scene>
    <spherical_coordinates>
      <surface_model>EARTH_WGS84</surface_model>
      <latitude_deg>0</latitude_deg>
      <longitude_deg>0</longitude_deg>
      <elevation>0</elevation>
      <heading_deg>0</heading_deg>
    </spherical_coordinates>
    <state world_name='default'>
      <sim_time>34 522000000</sim_time>
      <real_time>55 516700853</real_time>
      <wall_time>1487438133 464654850</wall_time>
      <iterations>34522</iterations>
      <model name='FRC2017'>
        <pose frame=''>0 0 -0.927 0 -0 0</pose>
        <scale>1 1 1</scale>
        <link name='Field'>
          <pose frame=''>0 0.066233 1.0447 1.5707 -0 0</pose>
          <velocity>0 0 0 0 -0 0</velocity>
          <acceleration>0 0 0 0 -0 0</acceleration>
          <wrench>0 0 0 0 -0 0</wrench>
        </link>
      </model>
      <model name='SimBot'>
        <pose frame=''>0.343098 -7.35839 0.02199 -5e-06 0.000403 1.57671</pose>
        <scale>1 1 1</scale>
        <link name='BallPusher'>
          <pose frame=''>0.71995 -7.59465 0.21586 1.57039 -5e-06 0.005909</pose>
          <velocity>0.000572 -0.000507 0.001386 0.00403 0.000836 2.2e-05</velocity>
          <acceleration>0.159295 -0.76932 2.6713 0.919551 1.00471 0.046265</acceleration>
          <wrench>0.05657 -0.273207 0.948654 0 -0 0</wrench>
        </link>
        <link name='Chassis'>
          <pose frame=''>0.716462 -7.77393 0.131957 1.5704 -5e-06 0.005909</pose>
          <velocity>0.000506 -0.000165 0.000647 0.004394 0.000854 2.2e-05</velocity>
          <acceleration>0.062786 -0.163496 1.35857 -1.56509 0.765498 3.13494</acceleration>
          <wrench>3.05243 -7.94855 66.0483 0 -0 0</wrench>
        </link>
        <link name='GearPlate'>
          <pose frame=''>0.717981 -7.39686 0.247417 1.57026 -7e-06 0.005909</pose>
          <velocity>0.000581 -0.000286 8e-06 -0.003516 0.001428 2.3e-05</velocity>
          <acceleration>0.184428 -0.461111 0.886839 0.307966 0.283744 3.13707</acceleration>
          <wrench>0.005289 -0.013223 0.025432 0 -0 0</wrench>
        </link>
        <link name='L1Wheel'>
          <pose frame=''>0.386953 -7.47241 0.056962 1.5704 -5e-06 0.005909</pose>
          <velocity>0.000435 0.000158 0.002265 0.004412 0.000895 2.1e-05</velocity>
          <acceleration>-0.019668 0.430837 4.12608 1.58872 1.21938 -0.018621</acceleration>
          <wrench>-0.008032 0.175952 1.68507 0 -0 0</wrench>
        </link>
        <link name='L2Wheel'>
          <pose frame=''>0.388139 -7.67325 0.050713 1.54173 4e-06 0.005908</pose>
          <velocity>0.000121 -0.000141 0.005217 0.002777 0.002377 -0.000215</velocity>
          <acceleration>-0.608872 -0.135985 10.4257 3.07676 -1.39781 2.68454</acceleration>
          <wrench>-0.24866 -0.055536 4.25782 0 -0 0</wrench>
        </link>
        <link name='L3Wheel'>
          <pose frame=''>0.389444 -7.89387 0.05079 1.58173 1.1e-05 0.005906</pose>
          <velocity>0.000641 -0.000173 -0.001768 0.004388 -0.003383 0.000797</velocity>
          <acceleration>0.411427 -0.215525 -3.65073 -0.556494 -1.47099 1.48913</acceleration>
          <wrench>0.168025 -0.088019 -1.49094 0 -0 0</wrench>
        </link>
        <link name='L4Wheel'>
          <pose frame=''>0.390632 -8.0947 0.057212 1.57023 -6e-06 0.005909</pose>
          <velocity>0.000452 0.000158 -0.000503 0.004362 0.000813 1.6e-05</velocity>
          <acceleration>-0.023585 0.430048 -0.819039 1.50879 1.04989 -0.02802</acceleration>
          <wrench>-0.009632 0.17563 -0.334492 0 -0 0</wrench>
        </link>
        <link name='R1Wheel'>
          <pose frame=''>1.04988 -7.46849 0.056965 1.57017 -6e-06 0.005909</pose>
          <velocity>0.000441 0.00017 0.0017 0.004361 0.000781 1.8e-05</velocity>
          <acceleration>-0.0071 0.414509 3.356 1.50918 0.99127 -0.024481</acceleration>
          <wrench>-0.0029 0.169284 1.37058 0 -0 0</wrench>
        </link>
        <link name='R2Wheel'>
          <pose frame=''>1.05107 -7.66933 0.050712 1.54125 3.6e-05 0.005909</pose>
          <velocity>0.000487 -0.000159 0.004037 0.003139 0.009598 -4.4e-05</velocity>
          <acceleration>0.084396 -0.195877 8.02927 0.202693 -0.630239 -0.029729</acceleration>
          <wrench>0.034467 -0.079995 3.27912 0 -0 0</wrench>
        </link>
        <link name='R3Wheel'>
          <pose frame=''>1.05237 -7.88995 0.050794 1.58743 2.3e-05 0.005907</pose>
          <velocity>0.000693 -0.000154 -0.002393 0.004363 -0.006427 0.000581</velocity>
          <acceleration>0.204531 -0.187908 -4.78874 2.6148 0.2554 -1.34766</acceleration>
          <wrench>0.08353 -0.076741 -1.9557 0 -0 0</wrench>
        </link>
        <link name='R4Wheel'>
          <pose frame=''>1.05356 -8.09078 0.057216 1.57009 -6e-06 0.005909</pose>
          <velocity>0.00045 0.00017 -0.001027 0.00432 0.000843 2.2e-05</velocity>
          <acceleration>-0.025557 0.413674 -1.49192 1.4275 1.10179 -0.016201</acceleration>
          <wrench>-0.010437 0.168942 -0.609292 0 -0 0</wrench>
        </link>
      </model>
      <model name='gear'>
        <pose frame=''>0.711352 -7.41366 0.390807 1.56217 -0.042506 0.005929</pose>
        <scale>1 1 1</scale>
        <link name='Body'>
          <pose frame=''>0.710972 -7.38985 0.390592 -1.56159 0.360166 -3.13279</pose>
          <velocity>0.000797 1.4e-05 0.001847 -0.000693 -0.002874 -3.2e-05</velocity>
          <acceleration>0.797173 0.014067 1.84706 2.44812 -0.267122 3.10939</acceleration>
          <wrench>0.851832 0.015031 1.97371 0 -0 0</wrench>
        </link>
      </model>
      <model name='ground_plane'>
        <pose frame=''>0 0 0 0 -0 0</pose>
        <scale>1 1 1</scale>
        <link name='link'>
          <pose frame=''>0 0 0 0 -0 0</pose>
          <velocity>0 0 0 0 -0 0</velocity>
          <acceleration>0 0 0 0 -0 0</acceleration>
          <wrench>0 0 0 0 -0 0</wrench>
        </link>
      </model>
      <model name='spike1'>
        <pose frame=''>-0.25793 -4.9648 0.002057 -0.0185 -0.007 -0.5244</pose>
        <scale>1 1 1</scale>
        <link name='Body'>
          <pose frame=''>-0.242707 -4.9642 0.442131 1.5638 0.0185 1.04627</pose>
          <velocity>0 0 0 0 -0 0</velocity>
          <acceleration>0 0 0 0 -0 0</acceleration>
          <wrench>0 0 0 0 -0 0</wrench>
        </link>
      </model>
      <model name='spike2'>
        <pose frame=''>-1.037 -5.412 0.00523 0 0 -1.56</pose>
        <scale>1 1 1</scale>
        <link name='Body'>
          <pose frame=''>-1.03683 -5.42796 0.445278 1.5708 0 0.0108</pose>
          <velocity>0 0 0 0 -0 0</velocity>
          <acceleration>0 0 0 0 -0 0</acceleration>
          <wrench>0 0 0 0 -0 0</wrench>
        </link>
      </model>
      <model name='spike3'>
        <pose frame=''>-1.844 -5.009 0.026 0 0 -2.61</pose>
        <scale>1 1 1</scale>
        <link name='Body'>
          <pose frame=''>-1.85775 -5.01709 0.466048 1.5708 -0 -1.0392</pose>
          <velocity>0 0 0 0 -0 0</velocity>
          <acceleration>0 0 0 0 -0 0</acceleration>
          <wrench>0 0 0 0 -0 0</wrench>
        </link>
      </model>
      <model name='tape1'>
        <pose frame=''>-0.18536 -4.85795 0.41079 0.0116 -0.001119 -0.54</pose>
        <scale>1 1 1</scale>
        <link name='Tape'>
          <pose frame=''>-0.250845 -4.96981 0.344665 -1.57192 -0.0116 1.03081</pose>
          <velocity>0 0 0 0 -0 0</velocity>
          <acceleration>0 0 0 0 -0 0</acceleration>
          <wrench>0 0 0 0 -0 0</wrench>
        </link>
      </model>
      <model name='tape2'>
        <pose frame=''>-0.902837 -5.42368 0.4133 0 0 -1.56235</pose>
        <scale>1 1 1</scale>
        <link name='Tape'>
          <pose frame=''>-1.03319 -5.42605 0.348681 -1.5708 -0 0.00845</pose>
          <velocity>0 0 0 0 -0 0</velocity>
          <acceleration>0 0 0 0 -0 0</acceleration>
          <wrench>0 0 0 0 -0 0</wrench>
        </link>
      </model>
      <model name='tape3'>
        <pose frame=''>-1.885 -4.858 0.41 0 -0 0.51715</pose>
        <scale>1 1 1</scale>
        <link name='Tape'>
          <pose frame=''>-1.81944 -4.97069 0.345381 -1.5708 0 2.08795</pose>
          <velocity>0 0 0 0 -0 0</velocity>
          <acceleration>0 0 0 0 -0 0</acceleration>
          <wrench>0 0 0 0 -0 0</wrench>
        </link>
      </model>
      <light name='sun'>
        <pose frame=''>0 0 10 0 -0 0</pose>
      </light>
    </state>
  </world>
</sdf>
