<sdf version='1.6'>
  <world name='default'>
    <light name='sun' type='directional'>
      <cast_shadows>1</cast_shadows>
      <pose frame=''>0 0 10 0 -0 0</pose>
      <diffuse>0.8 0.8 0.8 1</diffuse>
      <specular>0.1 0.1 0.1 1</specular>
      <attenuation>
        <range>1000</range>
        <constant>0.9</constant>
        <linear>0.01</linear>
        <quadratic>0.001</quadratic>
      </attenuation>
      <direction>-0.5 0.5 -1</direction>
    </light>
    <model name='ground_plane'>
      <static>1</static>
      <link name='link'>
        <collision name='collision'>
          <geometry>
            <plane>
              <normal>0 0 1</normal>
              <size>100 100</size>
            </plane>
          </geometry>
          <surface>
            <friction>
              <ode>
                <mu>100</mu>
                <mu2>50</mu2>
              </ode>
              <torsional>
                <ode/>
              </torsional>
            </friction>
            <contact>
              <ode/>
            </contact>
            <bounce/>
          </surface>
          <max_contacts>10</max_contacts>
        </collision>
        <visual name='visual'>
          <cast_shadows>0</cast_shadows>
          <geometry>
            <plane>
              <normal>0 0 1</normal>
              <size>100 100</size>
            </plane>
          </geometry>
          <material>
            <script>
              <uri>file://media/materials/scripts/gazebo.material</uri>
              <name>Gazebo/Grey</name>
            </script>
          </material>
        </visual>
        <self_collide>0</self_collide>
        <kinematic>0</kinematic>
      </link>
    </model>
    <model name='FRC2017'>
      <pose frame=''>0 0 -0.9 0 -0 0</pose>
      <plugin name='clock' filename='libgz_clock.so'>
        <topic>/gazebo/frc/time</topic>
      </plugin>
      <link name='Field'>
        <gravity>1</gravity>
        <self_collide>0</self_collide>
        <pose frame=''>0 0.066233 1.9717 1.5707 -0 0</pose>
        <must_be_base_link>1</must_be_base_link>
        <velocity_decay>
          <linear>0</linear>
          <angular>0</angular>
        </velocity_decay>
        <inertial>
          <mass>1897.51</mass>
          <pose frame=''>0 0 0 0 -0 0</pose>
          <inertia>
            <ixx>86097.9</ixx>
            <ixy>712.771</ixy>
            <ixz>612.448</ixz>
            <iyy>102903</iyy>
            <iyz>5.36823</iyz>
            <izz>18938.6</izz>
          </inertia>
        </inertial>
        <collision name='Field_collision'>
          <pose frame=''>-0.821548 0.928908 0.089052 0 -0 0</pose>
          <geometry>
            <mesh>
              <scale>1 1 1</scale>
              <uri>model://FRC2017/meshes/Field.STL</uri>
            </mesh>
          </geometry>
          <surface>
            <contact>
              <ode/>
            </contact>
            <friction>
              <ode>
                <mu>0</mu>
                <mu2>0</mu2>
              </ode>
              <torsional>
                <ode/>
              </torsional>
            </friction>
            <bounce/>
          </surface>
          <max_contacts>10</max_contacts>
        </collision>
        <visual name='Field_visual'>
          <pose frame=''>-0.821548 0.928908 0.089052 0 -0 0</pose>
          <material>
            <ambient>0.752941 0.752941 0.752941 1</ambient>
            <diffuse>0.752941 0.752941 0.752941 1</diffuse>
          </material>
          <geometry>
            <mesh>
              <scale>1 1 1</scale>
              <uri>model://FRC2017/meshes/Field.STL</uri>
            </mesh>
          </geometry>
        </visual>
        <kinematic>0</kinematic>
      </link>
    </model>
    <model name='Tank8'>
      <pose frame=''>2.07 -7.94 0.065 0 0 -0.972</pose>
      <plugin name='clock' filename='libgz_clock.so'>
        <topic>/gazebo/frc/time</topic>
      </plugin>
      <link name='Frame'>
        <gravity>1</gravity>
        <self_collide>0</self_collide>
        <pose frame=''>-0.41396 -0.247077 0.04124 1.5708 -0 1.5708</pose>
        <must_be_base_link>1</must_be_base_link>
        <velocity_decay>
          <linear>0</linear>
          <angular>0</angular>
        </velocity_decay>
        <inertial>
          <mass>5.61518</mass>
          <pose frame=''>0 0 0 0 -0 0</pose>
          <inertia>
            <ixx>0.535687</ixx>
            <ixy>0.0014173</ixy>
            <ixz>0.00156371</ixz>
            <iyy>0.763663</iyy>
            <iyz>2.75596e-05</iyz>
            <izz>0.237196</izz>
          </inertia>
        </inertial>
        <collision name='Frame_collision'>
          <pose frame=''>-0.580324 -0.679492 -0.973196 0 -0 0</pose>
          <geometry>
            <mesh>
              <scale>1 1 1</scale>
              <uri>model://Tank8/meshes/Frame_col.STL</uri>
            </mesh>
          </geometry>
          <surface>
            <contact>
              <ode/>
            </contact>
            <friction>
              <ode>
                <mu>0</mu>
                <mu2>0</mu2>
              </ode>
              <torsional>
                <ode/>
              </torsional>
            </friction>
            <bounce/>
          </surface>
          <max_contacts>10</max_contacts>
        </collision>
        <visual name='Frame_visual'>
          <pose frame=''>-0.580324 -0.679492 -0.973196 0 -0 0</pose>
          <material>
            <ambient>0 0.25098 1 1</ambient>
            <diffuse>0 0.25098 1 1</diffuse>
          </material>
          <geometry>
            <mesh>
              <scale>1 1 1</scale>
              <uri>model://Tank8/meshes/Frame.STL</uri>
            </mesh>
          </geometry>
        </visual>
        <sensor name='FrameCamera' type='camera'>
          <visualize>1</visualize>
          <always_on>1</always_on>
          <pose frame=''>-0.000573 0.038135 -0.39249 -0.015383 1.57079 1.55541</pose>
          <camera name='Framecamera'>
            <horizontal_fov>1.5708</horizontal_fov>
            <image>
              <width>320</width>
              <height>240</height>
            </image>
            <clip>
              <near>0.1</near>
              <far>100</far>
            </clip>
          </camera>
        </sensor>
        <kinematic>0</kinematic>
      </link>
      <link name='L1Wheel'>
        <gravity>1</gravity>
        <self_collide>0</self_collide>
        <pose frame=''>-0.723265 -0.537083 0.047625 1.5708 -0 1.5708</pose>
        <must_be_base_link>0</must_be_base_link>
        <velocity_decay>
          <linear>0</linear>
          <angular>0</angular>
        </velocity_decay>
        <inertial>
          <mass>1.3252</mass>
          <pose frame=''>0 0 0 0 -0 0</pose>
          <inertia>
            <ixx>0.00636122</ixx>
            <ixy>1.36307e-19</ixy>
            <ixz>3.70169e-19</ixz>
            <iyy>0.00340889</iyy>
            <iyz>2.8197e-19</iyz>
            <izz>0.00340889</izz>
          </inertia>
        </inertial>
        <collision name='L1Wheel_collision'>
          <pose frame=''>-0.290317 -0.685878 -0.663891 0 -0 0</pose>
          <geometry>
            <mesh>
              <scale>1 1 1</scale>
              <uri>model://Tank8/meshes/L1Wheel_col.STL</uri>
            </mesh>
          </geometry>
          <surface>
            <contact>
              <ode/>
            </contact>
            <friction>
              <ode>
                <mu>1</mu>
                <mu2>1</mu2>
              </ode>
              <torsional>
                <ode/>
              </torsional>
            </friction>
            <bounce/>
          </surface>
          <max_contacts>10</max_contacts>
        </collision>
        <visual name='L1Wheel_visual'>
          <pose frame=''>-0.290317 -0.685878 -0.663891 0 -0 0</pose>
          <material>
            <ambient>0.501961 0.501961 0.501961 1</ambient>
            <diffuse>0.501961 0.501961 0.501961 1</diffuse>
          </material>
          <geometry>
            <mesh>
              <scale>1 1 1</scale>
              <uri>model://Tank8/meshes/L1Wheel.STL</uri>
            </mesh>
          </geometry>
        </visual>
        <kinematic>0</kinematic>
      </link>
      <joint name='Frame-L1Wheel' type='revolute'>
        <parent>Frame</parent>
        <child>L1Wheel</child>
        <pose frame=''>0 -0 0 0 -0 0</pose>
        <axis>
          <xyz>-1 0 0</xyz>
          <dynamics>
            <damping>1</damping>
            <friction>1</friction>
            <spring_reference>0</spring_reference>
            <spring_stiffness>0</spring_stiffness>
          </dynamics>
          <limit>
            <effort>50</effort>
            <lower>-1e+16</lower>
            <upper>1e+16</upper>
          </limit>
          <use_parent_model_frame>0</use_parent_model_frame>
        </axis>
      </joint>
      <link name='L2Wheel'>
        <gravity>1</gravity>
        <self_collide>0</self_collide>
        <pose frame=''>-0.516255 -0.537083 0.03175 1.5708 -0 1.5708</pose>
        <must_be_base_link>0</must_be_base_link>
        <velocity_decay>
          <linear>0</linear>
          <angular>0</angular>
        </velocity_decay>
        <inertial>
          <mass>1.3252</mass>
          <pose frame=''>0 0 0 0 -0 0</pose>
          <inertia>
            <ixx>0.00636122</ixx>
            <ixy>5.85274e-36</ixy>
            <ixz>1.07917e-37</ixz>
            <iyy>0.00340889</iyy>
            <iyz>1.2077e-35</iyz>
            <izz>0.00340889</izz>
          </inertia>
        </inertial>
        <collision name='L2Wheel_collision'>
          <pose frame=''>-0.290317 -0.670003 -0.870901 0 -0 0</pose>
          <geometry>
            <mesh>
              <scale>1 1 1</scale>
              <uri>model://Tank8/meshes/L2Wheel_col.STL</uri>
            </mesh>
          </geometry>
          <surface>
            <contact>
              <ode/>
            </contact>
            <friction>
              <ode>
                <mu>1</mu>
                <mu2>1</mu2>
              </ode>
              <torsional>
                <ode/>
              </torsional>
            </friction>
            <bounce/>
          </surface>
          <max_contacts>10</max_contacts>
        </collision>
        <visual name='L2Wheel_visual'>
          <pose frame=''>-0.290317 -0.670003 -0.870901 0 -0 0</pose>
          <material>
            <ambient>0.501961 0.501961 0.501961 1</ambient>
            <diffuse>0.501961 0.501961 0.501961 1</diffuse>
          </material>
          <geometry>
            <mesh>
              <scale>1 1 1</scale>
              <uri>model://Tank8/meshes/L2Wheel.STL</uri>
            </mesh>
          </geometry>
        </visual>
        <kinematic>0</kinematic>
      </link>
      <joint name='Frame-L2Wheel' type='revolute'>
        <parent>Frame</parent>
        <child>L2Wheel</child>
        <pose frame=''>0 0 -0 0 -0 0</pose>
        <axis>
          <xyz>-1 0 0</xyz>
          <dynamics>
            <damping>1</damping>
            <friction>1</friction>
            <spring_reference>0</spring_reference>
            <spring_stiffness>0</spring_stiffness>
          </dynamics>
          <limit>
            <effort>50</effort>
            <lower>-1e+16</lower>
            <upper>1e+16</upper>
          </limit>
          <use_parent_model_frame>0</use_parent_model_frame>
        </axis>
      </joint>
      <link name='L3Wheel'>
        <gravity>1</gravity>
        <self_collide>0</self_collide>
        <pose frame=''>-0.309245 -0.537083 0.03175 1.5708 -0 1.5708</pose>
        <must_be_base_link>0</must_be_base_link>
        <velocity_decay>
          <linear>0</linear>
          <angular>0</angular>
        </velocity_decay>
        <inertial>
          <mass>1.3252</mass>
          <pose frame=''>0 0 0 0 -0 0</pose>
          <inertia>
            <ixx>0.00636122</ixx>
            <ixy>7.97907e-20</ixy>
            <ixz>1.02387e-19</ixz>
            <iyy>0.00340889</iyy>
            <iyz>3.68262e-19</iyz>
            <izz>0.00340889</izz>
          </inertia>
        </inertial>
        <collision name='L3Wheel_collision'>
          <pose frame=''>-0.290317 -0.670003 -1.07791 0 -0 0</pose>
          <geometry>
            <mesh>
              <scale>1 1 1</scale>
              <uri>model://Tank8/meshes/L3Wheel_col.STL</uri>
            </mesh>
          </geometry>
          <surface>
            <contact>
              <ode/>
            </contact>
            <friction>
              <ode>
                <mu>1</mu>
                <mu2>1</mu2>
              </ode>
              <torsional>
                <ode/>
              </torsional>
            </friction>
            <bounce/>
          </surface>
          <max_contacts>10</max_contacts>
        </collision>
        <visual name='L3Wheel_visual'>
          <pose frame=''>-0.290317 -0.670003 -1.07791 0 -0 0</pose>
          <material>
            <ambient>0.501961 0.501961 0.501961 1</ambient>
            <diffuse>0.501961 0.501961 0.501961 1</diffuse>
          </material>
          <geometry>
            <mesh>
              <scale>1 1 1</scale>
              <uri>model://Tank8/meshes/L3Wheel.STL</uri>
            </mesh>
          </geometry>
        </visual>
        <kinematic>0</kinematic>
      </link>
      <joint name='Frame-L3Wheel' type='revolute'>
        <parent>Frame</parent>
        <child>L3Wheel</child>
        <pose frame=''>0 0 0 0 -0 0</pose>
        <axis>
          <xyz>-1 0 0</xyz>
          <dynamics>
            <damping>1</damping>
            <friction>1</friction>
            <spring_reference>0</spring_reference>
            <spring_stiffness>0</spring_stiffness>
          </dynamics>
          <limit>
            <effort>50</effort>
            <lower>-1e+16</lower>
            <upper>1e+16</upper>
          </limit>
          <use_parent_model_frame>0</use_parent_model_frame>
        </axis>
      </joint>
      <link name='L4Wheel'>
        <gravity>1</gravity>
        <self_collide>0</self_collide>
        <pose frame=''>-0.102235 -0.537083 0.047625 1.5708 -0 1.5708</pose>
        <must_be_base_link>0</must_be_base_link>
        <velocity_decay>
          <linear>0</linear>
          <angular>0</angular>
        </velocity_decay>
        <inertial>
          <mass>1.3252</mass>
          <pose frame=''>0 0 0 0 -0 0</pose>
          <inertia>
            <ixx>0.00636122</ixx>
            <ixy>6.86348e-20</ixy>
            <ixz>1.38577e-19</ixz>
            <iyy>0.00340889</iyy>
            <iyz>1.89655e-33</iyz>
            <izz>0.00340889</izz>
          </inertia>
        </inertial>
        <collision name='L4Wheel_collision'>
          <pose frame=''>-0.290317 -0.685878 -1.28492 0 -0 0</pose>
          <geometry>
            <mesh>
              <scale>1 1 1</scale>
              <uri>model://Tank8/meshes/L4Wheel_col.STL</uri>
            </mesh>
          </geometry>
          <surface>
            <contact>
              <ode/>
            </contact>
            <friction>
              <ode>
                <mu>1</mu>
                <mu2>1</mu2>
              </ode>
              <torsional>
                <ode/>
              </torsional>
            </friction>
            <bounce/>
          </surface>
          <max_contacts>10</max_contacts>
        </collision>
        <visual name='L4Wheel_visual'>
          <pose frame=''>-0.290317 -0.685878 -1.28492 0 -0 0</pose>
          <material>
            <ambient>0.501961 0.501961 0.501961 1</ambient>
            <diffuse>0.501961 0.501961 0.501961 1</diffuse>
          </material>
          <geometry>
            <mesh>
              <scale>1 1 1</scale>
              <uri>model://Tank8/meshes/L4Wheel.STL</uri>
            </mesh>
          </geometry>
        </visual>
        <kinematic>0</kinematic>
      </link>
      <joint name='Frame-L4Wheel' type='revolute'>
        <parent>Frame</parent>
        <child>L4Wheel</child>
        <pose frame=''>0 -0 0 0 -0 0</pose>
        <axis>
          <xyz>-1 0 0</xyz>
          <dynamics>
            <damping>1</damping>
            <friction>1</friction>
            <spring_reference>0</spring_reference>
            <spring_stiffness>0</spring_stiffness>
          </dynamics>
          <limit>
            <effort>50</effort>
            <lower>-1e+16</lower>
            <upper>1e+16</upper>
          </limit>
          <use_parent_model_frame>0</use_parent_model_frame>
        </axis>
      </joint>
      <link name='R1Wheel'>
        <gravity>1</gravity>
        <self_collide>0</self_collide>
        <pose frame=''>-0.723265 0.041783 0.047625 1.5708 -0 1.5708</pose>
        <must_be_base_link>0</must_be_base_link>
        <velocity_decay>
          <linear>0</linear>
          <angular>0</angular>
        </velocity_decay>
        <inertial>
          <mass>1.3252</mass>
          <pose frame=''>0 0 0 0 -0 0</pose>
          <inertia>
            <ixx>0.00636122</ixx>
            <ixy>1.12324e-21</ixy>
            <ixz>4.49297e-21</ixz>
            <iyy>0.00340889</iyy>
            <iyz>1.02506e-19</iyz>
            <izz>0.00340889</izz>
          </inertia>
        </inertial>
        <collision name='R1Wheel_collision'>
          <pose frame=''>-0.869183 -0.685878 -0.663891 0 -0 0</pose>
          <geometry>
            <mesh>
              <scale>1 1 1</scale>
              <uri>model://Tank8/meshes/R1Wheel_col.STL</uri>
            </mesh>
          </geometry>
          <surface>
            <contact>
              <ode/>
            </contact>
            <friction>
              <ode>
                <mu>1</mu>
                <mu2>1</mu2>
              </ode>
              <torsional>
                <ode/>
              </torsional>
            </friction>
            <bounce/>
          </surface>
          <max_contacts>10</max_contacts>
        </collision>
        <visual name='R1Wheel_visual'>
          <pose frame=''>-0.869183 -0.685878 -0.663891 0 -0 0</pose>
          <material>
            <ambient>0.501961 0.501961 0.501961 1</ambient>
            <diffuse>0.501961 0.501961 0.501961 1</diffuse>
          </material>
          <geometry>
            <mesh>
              <scale>1 1 1</scale>
              <uri>model://Tank8/meshes/R1Wheel.STL</uri>
            </mesh>
          </geometry>
        </visual>
        <kinematic>0</kinematic>
      </link>
      <joint name='Frame-R1Wheel' type='revolute'>
        <parent>Frame</parent>
        <child>R1Wheel</child>
        <pose frame=''>-0 0 0 0 -0 0</pose>
        <axis>
          <xyz>1 0 0</xyz>
          <dynamics>
            <damping>1</damping>
            <friction>1</friction>
            <spring_reference>0</spring_reference>
            <spring_stiffness>0</spring_stiffness>
          </dynamics>
          <limit>
            <effort>50</effort>
            <lower>-1e+16</lower>
            <upper>1e+16</upper>
          </limit>
          <use_parent_model_frame>0</use_parent_model_frame>
        </axis>
      </joint>
      <link name='R2Wheel'>
        <gravity>1</gravity>
        <self_collide>0</self_collide>
        <pose frame=''>-0.516255 0.041783 0.03175 1.5708 -0 1.5708</pose>
        <must_be_base_link>0</must_be_base_link>
        <velocity_decay>
          <linear>0</linear>
          <angular>0</angular>
        </velocity_decay>
        <inertial>
          <mass>1.3252</mass>
          <pose frame=''>0 0 0 0 -0 0</pose>
          <inertia>
            <ixx>0.00636122</ixx>
            <ixy>2.14529e-20</ixy>
            <ixz>4.16955e-21</ixz>
            <iyy>0.00340889</iyy>
            <iyz>4.95999e-20</iyz>
            <izz>0.00340889</izz>
          </inertia>
        </inertial>
        <collision name='R2Wheel_collision'>
          <pose frame=''>-0.869183 -0.670003 -0.870901 0 -0 0</pose>
          <geometry>
            <mesh>
              <scale>1 1 1</scale>
              <uri>model://Tank8/meshes/R2Wheel_col.STL</uri>
            </mesh>
          </geometry>
          <surface>
            <contact>
              <ode/>
            </contact>
            <friction>
              <ode>
                <mu>1</mu>
                <mu2>1</mu2>
              </ode>
              <torsional>
                <ode/>
              </torsional>
            </friction>
            <bounce/>
          </surface>
          <max_contacts>10</max_contacts>
        </collision>
        <visual name='R2Wheel_visual'>
          <pose frame=''>-0.869183 -0.670003 -0.870901 0 -0 0</pose>
          <material>
            <ambient>0.501961 0.501961 0.501961 1</ambient>
            <diffuse>0.501961 0.501961 0.501961 1</diffuse>
          </material>
          <geometry>
            <mesh>
              <scale>1 1 1</scale>
              <uri>model://Tank8/meshes/R2Wheel.STL</uri>
            </mesh>
          </geometry>
        </visual>
        <kinematic>0</kinematic>
      </link>
      <joint name='Frame-R2Wheel' type='revolute'>
        <parent>Frame</parent>
        <child>R2Wheel</child>
        <pose frame=''>0 0 -0 0 -0 0</pose>
        <axis>
          <xyz>1 0 0</xyz>
          <dynamics>
            <damping>1</damping>
            <friction>1</friction>
            <spring_reference>0</spring_reference>
            <spring_stiffness>0</spring_stiffness>
          </dynamics>
          <limit>
            <effort>50</effort>
            <lower>-1e+16</lower>
            <upper>1e+16</upper>
          </limit>
          <use_parent_model_frame>0</use_parent_model_frame>
        </axis>
      </joint>
      <link name='R3Wheel'>
        <gravity>1</gravity>
        <self_collide>0</self_collide>
        <pose frame=''>-0.309245 0.041783 0.03175 1.5708 -0 1.5708</pose>
        <must_be_base_link>0</must_be_base_link>
        <velocity_decay>
          <linear>0</linear>
          <angular>0</angular>
        </velocity_decay>
        <inertial>
          <mass>1.3252</mass>
          <pose frame=''>0 0 0 0 -0 0</pose>
          <inertia>
            <ixx>0.00636122</ixx>
            <ixy>7.83061e-20</ixy>
            <ixz>2.36683e-21</ixz>
            <iyy>0.00340889</iyy>
            <iyz>1.60821e-20</iyz>
            <izz>0.00340889</izz>
          </inertia>
        </inertial>
        <collision name='R3Wheel_collision'>
          <pose frame=''>-0.869183 -0.670003 -1.07791 0 -0 0</pose>
          <geometry>
            <mesh>
              <scale>1 1 1</scale>
              <uri>model://Tank8/meshes/R3Wheel_col.STL</uri>
            </mesh>
          </geometry>
          <surface>
            <contact>
              <ode/>
            </contact>
            <friction>
              <ode>
                <mu>1</mu>
                <mu2>1</mu2>
              </ode>
              <torsional>
                <ode/>
              </torsional>
            </friction>
            <bounce/>
          </surface>
          <max_contacts>10</max_contacts>
        </collision>
        <visual name='R3Wheel_visual'>
          <pose frame=''>-0.869183 -0.670003 -1.07791 0 -0 0</pose>
          <material>
            <ambient>0.501961 0.501961 0.501961 1</ambient>
            <diffuse>0.501961 0.501961 0.501961 1</diffuse>
          </material>
          <geometry>
            <mesh>
              <scale>1 1 1</scale>
              <uri>model://Tank8/meshes/R3Wheel.STL</uri>
            </mesh>
          </geometry>
        </visual>
        <kinematic>0</kinematic>
      </link>
      <joint name='Frame-R3Wheel' type='revolute'>
        <parent>Frame</parent>
        <child>R3Wheel</child>
        <pose frame=''>0 0 0 0 -0 0</pose>
        <axis>
          <xyz>1 0 0</xyz>
          <dynamics>
            <damping>1</damping>
            <friction>1</friction>
            <spring_reference>0</spring_reference>
            <spring_stiffness>0</spring_stiffness>
          </dynamics>
          <limit>
            <effort>50</effort>
            <lower>-1e+16</lower>
            <upper>1e+16</upper>
          </limit>
          <use_parent_model_frame>0</use_parent_model_frame>
        </axis>
      </joint>
      <link name='R4Wheel'>
        <gravity>1</gravity>
        <self_collide>0</self_collide>
        <pose frame=''>-0.102235 0.041783 0.047625 1.5708 -0 1.5708</pose>
        <must_be_base_link>0</must_be_base_link>
        <velocity_decay>
          <linear>0</linear>
          <angular>0</angular>
        </velocity_decay>
        <inertial>
          <mass>1.3252</mass>
          <pose frame=''>0 0 0 0 -0 0</pose>
          <inertia>
            <ixx>0.00636122</ixx>
            <ixy>1.28371e-21</ixy>
            <ixz>6.41853e-22</ixz>
            <iyy>0.00340889</iyy>
            <iyz>5.60757e-19</iyz>
            <izz>0.00340889</izz>
          </inertia>
        </inertial>
        <collision name='R4Wheel_collision'>
          <pose frame=''>-0.869183 -0.685878 -1.28492 0 -0 0</pose>
          <geometry>
            <mesh>
              <scale>1 1 1</scale>
              <uri>model://Tank8/meshes/R4Wheel_col.STL</uri>
            </mesh>
          </geometry>
          <surface>
            <contact>
              <ode/>
            </contact>
            <friction>
              <ode>
                <mu>1</mu>
                <mu2>1</mu2>
              </ode>
              <torsional>
                <ode/>
              </torsional>
            </friction>
            <bounce/>
          </surface>
          <max_contacts>10</max_contacts>
        </collision>
        <visual name='R4Wheel_visual'>
          <pose frame=''>-0.869183 -0.685878 -1.28492 0 -0 0</pose>
          <material>
            <ambient>0.501961 0.501961 0.501961 1</ambient>
            <diffuse>0.501961 0.501961 0.501961 1</diffuse>
          </material>
          <geometry>
            <mesh>
              <scale>1 1 1</scale>
              <uri>model://Tank8/meshes/R4Wheel.STL</uri>
            </mesh>
          </geometry>
        </visual>
        <kinematic>0</kinematic>
      </link>
      <joint name='Frame-R4Wheel' type='revolute'>
        <parent>Frame</parent>
        <child>R4Wheel</child>
        <pose frame=''>-0 -0 0 0 -0 0</pose>
        <axis>
          <xyz>1 0 0</xyz>
          <dynamics>
            <damping>1</damping>
            <friction>1</friction>
            <spring_reference>0</spring_reference>
            <spring_stiffness>0</spring_stiffness>
          </dynamics>
          <limit>
            <effort>50</effort>
            <lower>-1e+16</lower>
            <upper>1e+16</upper>
          </limit>
          <use_parent_model_frame>0</use_parent_model_frame>
        </axis>
      </joint>
      <plugin name='Frame-L1Wheel_motor' filename='libgz_dc_motor.so'>
        <joint>Frame-L1Wheel</joint>
        <topic>/gazebo/frc/simulator/pwm/1</topic>
        <multiplier>25</multiplier>
      </plugin>
      <plugin name='Frame-L1Wheel_encoder' filename='libgz_encoder.so'>
        <joint>Frame-L1Wheel</joint>
        <topic>/gazebo/frc/simulator/dio/1/2</topic>
        <units>degrees</units>
      </plugin>
      <plugin name='Frame-L2Wheel_motor' filename='libgz_dc_motor.so'>
        <joint>Frame-L2Wheel</joint>
        <topic>/gazebo/frc/simulator/pwm/1</topic>
        <multiplier>24</multiplier>
      </plugin>
      <plugin name='Frame-L3Wheel_motor' filename='libgz_dc_motor.so'>
        <joint>Frame-L3Wheel</joint>
        <topic>/gazebo/frc/simulator/pwm/1</topic>
        <multiplier>25</multiplier>
      </plugin>
      <plugin name='Frame-L4Wheel_motor' filename='libgz_dc_motor.so'>
        <joint>Frame-L4Wheel</joint>
        <topic>/gazebo/frc/simulator/pwm/1</topic>
        <multiplier>25</multiplier>
      </plugin>
      <plugin name='Frame-R1Wheel_motor' filename='libgz_dc_motor.so'>
        <joint>Frame-R1Wheel</joint>
        <topic>/gazebo/frc/simulator/pwm/2</topic>
        <multiplier>25</multiplier>
      </plugin>
      <plugin name='Frame-R1Wheel_encoder' filename='libgz_encoder.so'>
        <joint>Frame-R1Wheel</joint>
        <topic>/gazebo/frc/simulator/dio/2/3</topic>
        <units>degrees</units>
      </plugin>
      <plugin name='Frame-R2Wheel_motor' filename='libgz_dc_motor.so'>
        <joint>Frame-R2Wheel</joint>
        <topic>/gazebo/frc/simulator/pwm/2</topic>
        <multiplier>25</multiplier>
      </plugin>
      <plugin name='Frame-R3Wheel_motor' filename='libgz_dc_motor.so'>
        <joint>Frame-R3Wheel</joint>
        <topic>/gazebo/frc/simulator/pwm/2</topic>
        <multiplier>25</multiplier>
      </plugin>
      <plugin name='Frame-R4Wheel_motor' filename='libgz_dc_motor.so'>
        <joint>Frame-R4Wheel</joint>
        <topic>/gazebo/frc/simulator/pwm/2</topic>
        <multiplier>25</multiplier>
      </plugin>
    </model>
    <gravity>0 0 -9.8</gravity>
    <magnetic_field>6e-06 2.3e-05 -4.2e-05</magnetic_field>
    <atmosphere type='adiabatic'/>
    <physics name='default_physics' default='0' type='ode'>
      <max_step_size>0.001</max_step_size>
      <real_time_factor>1</real_time_factor>
      <real_time_update_rate>1000</real_time_update_rate>
    </physics>
    <scene>
      <ambient>0.4 0.4 0.4 1</ambient>
      <background>0.7 0.7 0.7 1</background>
      <shadows>1</shadows>
    </scene>
    <spherical_coordinates>
      <surface_model>EARTH_WGS84</surface_model>
      <latitude_deg>0</latitude_deg>
      <longitude_deg>0</longitude_deg>
      <elevation>0</elevation>
      <heading_deg>0</heading_deg>
    </spherical_coordinates>
    <state world_name='default'>
      <sim_time>98 714000000</sim_time>
      <real_time>300 601951936</real_time>
      <wall_time>1485836328 914350808</wall_time>
      <iterations>98714</iterations>
      <model name='FRC2017'>
        <pose frame=''>-0.001177 4.4e-05 -0.929357 2.2e-05 0.000597 1e-06</pose>
        <scale>1 1 1</scale>
        <link name='Field'>
          <pose frame=''>0 0.066233 1.04234 1.57072 0.000597 1e-06</pose>
          <velocity>0 0 0 0 -0 0</velocity>
          <acceleration>0 0 5.53399 -0.973398 0.53431 0.002549</acceleration>
          <wrench>0 0 10500.8 0 -0 0</wrench>
        </link>
      </model>
      <model name='Tank8'>
        <pose frame=''>2.07203 -7.92942 0.065332 -0.000184 -0.000108 -0.969408</pose>
        <scale>1 1 1</scale>
        <link name='Frame'>
          <pose frame=''>1.63409 -7.72787 0.106573 1.57069 0.000184 0.601392</pose>
          <velocity>0.000202 0.000575 -0.004071 -0.010431 0.012828 -0.000215</velocity>
          <acceleration>0.077566 0.019087 -9.8179 0.087092 -0.267892 -0.007494</acceleration>
          <wrench>0.435548 0.10718 -55.1293 0 -0 0</wrench>
        </link>
        <link name='L1Wheel'>
          <pose frame=''>1.21996 -7.63691 0.112978 1.571 0.000184 0.601392</pose>
          <velocity>0.000303 0.000734 0.000288 -0.010429 0.012824 -0.000213</velocity>
          <acceleration>0.063195 0.019809 -9.86656 0.018534 -0.093356 -0.02524</acceleration>
          <wrench>0.083746 0.026251 -13.0752 0 -0 0</wrench>
        </link>
        <link name='L2Wheel'>
          <pose frame=''>1.33709 -7.80761 0.097126 1.55655 0.00016 0.60139</pose>
          <velocity>-5.9e-05 0.000526 0.00038 -0.01382 0.017767 0.000335</velocity>
          <acceleration>-0.315664 -0.095078 -10.1604 2.62306 -0.090944 -1.67872</acceleration>
          <wrench>-0.418318 -0.125998 -13.4645 0 -0 0</wrench>
        </link>
        <link name='L3Wheel'>
          <pose frame=''>1.45421 -7.9783 0.097147 1.5868 0.000163 0.60139</pose>
          <velocity>-0.000135 0.000471 0.00115 -0.013421 0.017185 0.000272</velocity>
          <acceleration>-0.372892 -0.144828 -9.42425 -3.06937 0.379947 -1.83365</acceleration>
          <wrench>-0.494157 -0.191926 -12.489 0 -0 0</wrench>
        </link>
        <link name='L4Wheel'>
          <pose frame=''>1.57133 -8.14898 0.113046 1.56895 0.000185 0.601392</pose>
          <velocity>0.000233 0.000683 0.001057 -0.010369 0.012738 -0.000203</velocity>
          <acceleration>0.138692 0.040641 -9.88663 0.258079 -0.188571 0.043247</acceleration>
          <wrench>0.183794 0.053857 -13.1018 0 -0 0</wrench>
        </link>
        <link name='R1Wheel'>
          <pose frame=''>1.69727 -7.3094 0.112871 1.5691 0.000185 0.601392</pose>
          <velocity>0.000401 0.00066 -0.009174 -0.010363 0.012729 -0.000203</velocity>
          <acceleration>0.105017 0.036795 -9.71084 0.215191 -0.159648 0.008606</acceleration>
          <wrench>0.139169 0.048761 -12.8688 0 -0 0</wrench>
        </link>
        <link name='R2Wheel'>
          <pose frame=''>1.81439 -7.48009 0.097019 1.51283 0.000195 0.601391</pose>
          <velocity>0.000181 0.000512 -0.008851 -0.008878 0.010564 0.000143</velocity>
          <acceleration>-0.153899 -0.028071 -9.58071 0.442574 1.12327 0.270858</acceleration>
          <wrench>-0.203947 -0.0372 -12.6964 0 -0 0</wrench>
        </link>
        <link name='R3Wheel'>
          <pose frame=''>1.93151 -7.65078 0.097042 1.55302 0.000191 0.601391</pose>
          <velocity>0.000151 0.000481 -0.008898 -0.009421 0.011356 0.000215</velocity>
          <acceleration>0.084467 0.044581 -9.87712 1.36098 1.29319 -3.02846</acceleration>
          <wrench>0.111936 0.059078 -13.0892 0 -0 0</wrench>
        </link>
        <link name='R4Wheel'>
          <pose frame=''>2.04864 -7.82147 0.112939 1.56929 0.000184 0.601392</pose>
          <velocity>0.000265 0.00054 -0.008434 -0.010456 0.012864 -0.000222</velocity>
          <acceleration>0.122418 0.045273 -9.8177 0.025989 -0.023002 0.004246</acceleration>
          <wrench>0.162229 0.059996 -13.0104 0 -0 0</wrench>
        </link>
      </model>
      <model name='ground_plane'>
        <pose frame=''>0 0 0 0 -0 0</pose>
        <scale>1 1 1</scale>
        <link name='link'>
          <pose frame=''>0 0 0 0 -0 0</pose>
          <velocity>0 0 0 0 -0 0</velocity>
          <acceleration>0 0 0 0 -0 0</acceleration>
          <wrench>0 0 0 0 -0 0</wrench>
        </link>
      </model>
      <light name='sun'>
        <pose frame=''>0 0 10 0 -0 0</pose>
      </light>
    </state>
    <gui fullscreen='0'>
      <camera name='user_camera'>
        <pose frame=''>0.821739 -6.99642 4.81856 0 1.4978 1.26421</pose>
        <view_controller>orbit</view_controller>
        <projection_type>perspective</projection_type>
      </camera>
    </gui>
  </world>
</sdf>
