<sdf version='1.6'>
  <world name='default'>
    <gui fullscreen='0'>
      <camera name='user_camera'>
        <pose frame=''>0.220883 -5.05341 0.940032 -0 0.9778 2.97621</pose>
        <view_controller>orbit</view_controller>
        <projection_type>perspective</projection_type>
      </camera>
    </gui>
    <light name='sun' type='directional'>
      <cast_shadows>1</cast_shadows>
      <pose frame=''>0 0 10 0 -0 0</pose>
      <diffuse>0.8 0.8 0.8 1</diffuse>
      <specular>0.1 0.1 0.1 1</specular>
      <attenuation>
        <range>1000</range>
        <constant>0.9</constant>
        <linear>0.01</linear>
        <quadratic>0.001</quadratic>
      </attenuation>
      <direction>-0.5 0.5 -1</direction>
    </light>
    <model name='ground_plane'>
      <static>1</static>
      <link name='link'>
        <collision name='collision'>
          <geometry>
            <plane>
              <normal>0 0 1</normal>
              <size>100 100</size>
            </plane>
          </geometry>
          <surface>
            <friction>
              <ode>
                <mu>100</mu>
                <mu2>50</mu2>
              </ode>
              <torsional>
                <ode/>
              </torsional>
            </friction>
            <contact>
              <ode/>
            </contact>
            <bounce/>
          </surface>
          <max_contacts>10</max_contacts>
        </collision>
        <visual name='visual'>
          <cast_shadows>0</cast_shadows>
          <geometry>
            <plane>
              <normal>0 0 1</normal>
              <size>100 100</size>
            </plane>
          </geometry>
          <material>
            <script>
              <uri>file://media/materials/scripts/gazebo.material</uri>
              <name>Gazebo/Grey</name>
            </script>
          </material>
        </visual>
        <self_collide>0</self_collide>
        <kinematic>0</kinematic>
      </link>
    </model>
    <model name='FRC2017'>
      <pose frame=''>0 0 -0.9 0 -0 0</pose>
      <plugin name='clock' filename='libgz_clock.so'>
        <topic>/gazebo/frc/time</topic>
      </plugin>
      <link name='Field'>
        <gravity>1</gravity>
        <self_collide>0</self_collide>
        <pose frame=''>0 0.066233 1.9717 1.5707 -0 0</pose>
        <must_be_base_link>1</must_be_base_link>
        <velocity_decay>
          <linear>0</linear>
          <angular>0</angular>
        </velocity_decay>
        <inertial>
          <mass>1897.51</mass>
          <pose frame=''>0 0 0 0 -0 0</pose>
          <inertia>
            <ixx>86097.9</ixx>
            <ixy>712.771</ixy>
            <ixz>612.448</ixz>
            <iyy>102903</iyy>
            <iyz>5.36823</iyz>
            <izz>18938.6</izz>
          </inertia>
        </inertial>
        <collision name='Field_collision'>
          <pose frame=''>-0.821548 0.928908 0.089052 0 -0 0</pose>
          <geometry>
            <mesh>
              <scale>1 1 1</scale>
              <uri>model://FRC2017/meshes/Field.STL</uri>
            </mesh>
          </geometry>
          <surface>
            <contact>
              <ode/>
            </contact>
            <friction>
              <ode>
                <mu>0</mu>
                <mu2>0</mu2>
              </ode>
              <torsional>
                <ode/>
              </torsional>
            </friction>
            <bounce/>
          </surface>
          <max_contacts>10</max_contacts>
        </collision>
        <visual name='Field_visual'>
          <pose frame=''>-0.821548 0.928908 0.089052 0 -0 0</pose>
          <material>
            <ambient>0.752941 0.752941 0.752941 1</ambient>
            <diffuse>0.752941 0.752941 0.752941 1</diffuse>
          </material>
          <geometry>
            <mesh>
              <scale>1 1 1</scale>
              <uri>model://FRC2017/meshes/Field.STL</uri>
            </mesh>
          </geometry>
        </visual>
        <kinematic>0</kinematic>
      </link>
    </model>
    <model name='Tank8'>
      <pose frame=''>2.07 -7.94 0.065 0 0 -0.972</pose>
      <plugin name='clock' filename='libclock.so'>
        <topic>/gazebo/frc/time</topic>
      </plugin>
      <link name='Frame'>
        <gravity>1</gravity>
        <self_collide>0</self_collide>
        <pose frame=''>-0.41396 -0.247077 0.04124 1.5708 -0 1.5708</pose>
        <must_be_base_link>1</must_be_base_link>
        <velocity_decay>
          <linear>0</linear>
          <angular>0</angular>
        </velocity_decay>
        <inertial>
          <mass>5.61518</mass>
          <pose frame=''>0 0 0 0 -0 0</pose>
          <inertia>
            <ixx>0.535687</ixx>
            <ixy>0.0014173</ixy>
            <ixz>0.00156371</ixz>
            <iyy>0.763663</iyy>
            <iyz>2.75596e-05</iyz>
            <izz>0.237196</izz>
          </inertia>
        </inertial>
        <collision name='Frame_collision'>
          <pose frame=''>-0.580324 -0.679492 -0.973196 0 -0 0</pose>
          <geometry>
            <mesh>
              <scale>1 1 1</scale>
              <uri>model://Tank8/meshes/Frame_col.STL</uri>
            </mesh>
          </geometry>
          <surface>
            <contact>
              <ode/>
            </contact>
            <friction>
              <ode>
                <mu>0</mu>
                <mu2>0</mu2>
              </ode>
              <torsional>
                <ode/>
              </torsional>
            </friction>
            <bounce/>
          </surface>
          <max_contacts>10</max_contacts>
        </collision>
        <visual name='Frame_visual'>
          <pose frame=''>-0.580324 -0.679492 -0.973196 0 -0 0</pose>
          <material>
            <ambient>0 0.25098 1 1</ambient>
            <diffuse>0 0.25098 1 1</diffuse>
          </material>
          <geometry>
            <mesh>
              <scale>1 1 1</scale>
              <uri>model://Tank8/meshes/Frame.STL</uri>
            </mesh>
          </geometry>
        </visual>
        <sensor name='FrameCamera' type='camera'>
          <visualize>1</visualize>
          <always_on>1</always_on>
          <update_rate>100</update_rate>
          <pose frame=''>-0.000573 0.3 -0.39249 -0.015383 1.57079 1.55541</pose>
          <camera name='Framecamera'>
            <horizontal_fov>1.05</horizontal_fov>
            <image>
              <width>320</width>
              <height>240</height>
            </image>
            <clip>
              <near>0.1</near>
              <far>100</far>
            </clip>
            <save enabled='1'>
              <path>/tmp/shooter-camera</path>
            </save>
          </camera>
        </sensor>
        <kinematic>0</kinematic>
      </link>
      <link name='L1Wheel'>
        <gravity>1</gravity>
        <self_collide>0</self_collide>
        <pose frame=''>-0.723265 -0.537083 0.047625 1.5708 -0 1.5708</pose>
        <must_be_base_link>0</must_be_base_link>
        <velocity_decay>
          <linear>0</linear>
          <angular>0</angular>
        </velocity_decay>
        <inertial>
          <mass>1.3252</mass>
          <pose frame=''>0 0 0 0 -0 0</pose>
          <inertia>
            <ixx>0.00636122</ixx>
            <ixy>1.36307e-19</ixy>
            <ixz>3.70169e-19</ixz>
            <iyy>0.00340889</iyy>
            <iyz>2.8197e-19</iyz>
            <izz>0.00340889</izz>
          </inertia>
        </inertial>
        <collision name='L1Wheel_collision'>
          <pose frame=''>-0.290317 -0.685878 -0.663891 0 -0 0</pose>
          <geometry>
            <mesh>
              <scale>1 1 1</scale>
              <uri>model://Tank8/meshes/L1Wheel_col.STL</uri>
            </mesh>
          </geometry>
          <surface>
            <contact>
              <ode/>
            </contact>
            <friction>
              <ode>
                <mu>1</mu>
                <mu2>1</mu2>
              </ode>
              <torsional>
                <ode/>
              </torsional>
            </friction>
            <bounce/>
          </surface>
          <max_contacts>10</max_contacts>
        </collision>
        <visual name='L1Wheel_visual'>
          <pose frame=''>-0.290317 -0.685878 -0.663891 0 -0 0</pose>
          <material>
            <ambient>0.501961 0.501961 0.501961 1</ambient>
            <diffuse>0.501961 0.501961 0.501961 1</diffuse>
          </material>
          <geometry>
            <mesh>
              <scale>1 1 1</scale>
              <uri>model://Tank8/meshes/L1Wheel.STL</uri>
            </mesh>
          </geometry>
        </visual>
        <kinematic>0</kinematic>
      </link>
      <joint name='Frame-L1Wheel' type='revolute'>
        <parent>Frame</parent>
        <child>L1Wheel</child>
        <pose frame=''>0 -0 0 0 -0 0</pose>
        <axis>
          <xyz>-1 0 0</xyz>
          <dynamics>
            <damping>1</damping>
            <friction>1</friction>
            <spring_reference>0</spring_reference>
            <spring_stiffness>0</spring_stiffness>
          </dynamics>
          <limit>
            <effort>50</effort>
            <lower>-1e+16</lower>
            <upper>1e+16</upper>
          </limit>
          <use_parent_model_frame>0</use_parent_model_frame>
        </axis>
      </joint>
      <link name='L2Wheel'>
        <gravity>1</gravity>
        <self_collide>0</self_collide>
        <pose frame=''>-0.516255 -0.537083 0.03175 1.5708 -0 1.5708</pose>
        <must_be_base_link>0</must_be_base_link>
        <velocity_decay>
          <linear>0</linear>
          <angular>0</angular>
        </velocity_decay>
        <inertial>
          <mass>1.3252</mass>
          <pose frame=''>0 0 0 0 -0 0</pose>
          <inertia>
            <ixx>0.00636122</ixx>
            <ixy>5.85274e-36</ixy>
            <ixz>1.07917e-37</ixz>
            <iyy>0.00340889</iyy>
            <iyz>1.2077e-35</iyz>
            <izz>0.00340889</izz>
          </inertia>
        </inertial>
        <collision name='L2Wheel_collision'>
          <pose frame=''>-0.290317 -0.670003 -0.870901 0 -0 0</pose>
          <geometry>
            <mesh>
              <scale>1 1 1</scale>
              <uri>model://Tank8/meshes/L2Wheel_col.STL</uri>
            </mesh>
          </geometry>
          <surface>
            <contact>
              <ode/>
            </contact>
            <friction>
              <ode>
                <mu>1</mu>
                <mu2>1</mu2>
              </ode>
              <torsional>
                <ode/>
              </torsional>
            </friction>
            <bounce/>
          </surface>
          <max_contacts>10</max_contacts>
        </collision>
        <visual name='L2Wheel_visual'>
          <pose frame=''>-0.290317 -0.670003 -0.870901 0 -0 0</pose>
          <material>
            <ambient>0.501961 0.501961 0.501961 1</ambient>
            <diffuse>0.501961 0.501961 0.501961 1</diffuse>
          </material>
          <geometry>
            <mesh>
              <scale>1 1 1</scale>
              <uri>model://Tank8/meshes/L2Wheel.STL</uri>
            </mesh>
          </geometry>
        </visual>
        <kinematic>0</kinematic>
      </link>
      <joint name='Frame-L2Wheel' type='revolute'>
        <parent>Frame</parent>
        <child>L2Wheel</child>
        <pose frame=''>0 0 -0 0 -0 0</pose>
        <axis>
          <xyz>-1 0 0</xyz>
          <dynamics>
            <damping>1</damping>
            <friction>1</friction>
            <spring_reference>0</spring_reference>
            <spring_stiffness>0</spring_stiffness>
          </dynamics>
          <limit>
            <effort>50</effort>
            <lower>-1e+16</lower>
            <upper>1e+16</upper>
          </limit>
          <use_parent_model_frame>0</use_parent_model_frame>
        </axis>
      </joint>
      <link name='L3Wheel'>
        <gravity>1</gravity>
        <self_collide>0</self_collide>
        <pose frame=''>-0.309245 -0.537083 0.03175 1.5708 -0 1.5708</pose>
        <must_be_base_link>0</must_be_base_link>
        <velocity_decay>
          <linear>0</linear>
          <angular>0</angular>
        </velocity_decay>
        <inertial>
          <mass>1.3252</mass>
          <pose frame=''>0 0 0 0 -0 0</pose>
          <inertia>
            <ixx>0.00636122</ixx>
            <ixy>7.97907e-20</ixy>
            <ixz>1.02387e-19</ixz>
            <iyy>0.00340889</iyy>
            <iyz>3.68262e-19</iyz>
            <izz>0.00340889</izz>
          </inertia>
        </inertial>
        <collision name='L3Wheel_collision'>
          <pose frame=''>-0.290317 -0.670003 -1.07791 0 -0 0</pose>
          <geometry>
            <mesh>
              <scale>1 1 1</scale>
              <uri>model://Tank8/meshes/L3Wheel_col.STL</uri>
            </mesh>
          </geometry>
          <surface>
            <contact>
              <ode/>
            </contact>
            <friction>
              <ode>
                <mu>1</mu>
                <mu2>1</mu2>
              </ode>
              <torsional>
                <ode/>
              </torsional>
            </friction>
            <bounce/>
          </surface>
          <max_contacts>10</max_contacts>
        </collision>
        <visual name='L3Wheel_visual'>
          <pose frame=''>-0.290317 -0.670003 -1.07791 0 -0 0</pose>
          <material>
            <ambient>0.501961 0.501961 0.501961 1</ambient>
            <diffuse>0.501961 0.501961 0.501961 1</diffuse>
          </material>
          <geometry>
            <mesh>
              <scale>1 1 1</scale>
              <uri>model://Tank8/meshes/L3Wheel.STL</uri>
            </mesh>
          </geometry>
        </visual>
        <kinematic>0</kinematic>
      </link>
      <joint name='Frame-L3Wheel' type='revolute'>
        <parent>Frame</parent>
        <child>L3Wheel</child>
        <pose frame=''>0 0 0 0 -0 0</pose>
        <axis>
          <xyz>-1 0 0</xyz>
          <dynamics>
            <damping>1</damping>
            <friction>1</friction>
            <spring_reference>0</spring_reference>
            <spring_stiffness>0</spring_stiffness>
          </dynamics>
          <limit>
            <effort>50</effort>
            <lower>-1e+16</lower>
            <upper>1e+16</upper>
          </limit>
          <use_parent_model_frame>0</use_parent_model_frame>
        </axis>
      </joint>
      <link name='L4Wheel'>
        <gravity>1</gravity>
        <self_collide>0</self_collide>
        <pose frame=''>-0.102235 -0.537083 0.047625 1.5708 -0 1.5708</pose>
        <must_be_base_link>0</must_be_base_link>
        <velocity_decay>
          <linear>0</linear>
          <angular>0</angular>
        </velocity_decay>
        <inertial>
          <mass>1.3252</mass>
          <pose frame=''>0 0 0 0 -0 0</pose>
          <inertia>
            <ixx>0.00636122</ixx>
            <ixy>6.86348e-20</ixy>
            <ixz>1.38577e-19</ixz>
            <iyy>0.00340889</iyy>
            <iyz>1.89655e-33</iyz>
            <izz>0.00340889</izz>
          </inertia>
        </inertial>
        <collision name='L4Wheel_collision'>
          <pose frame=''>-0.290317 -0.685878 -1.28492 0 -0 0</pose>
          <geometry>
            <mesh>
              <scale>1 1 1</scale>
              <uri>model://Tank8/meshes/L4Wheel_col.STL</uri>
            </mesh>
          </geometry>
          <surface>
            <contact>
              <ode/>
            </contact>
            <friction>
              <ode>
                <mu>1</mu>
                <mu2>1</mu2>
              </ode>
              <torsional>
                <ode/>
              </torsional>
            </friction>
            <bounce/>
          </surface>
          <max_contacts>10</max_contacts>
        </collision>
        <visual name='L4Wheel_visual'>
          <pose frame=''>-0.290317 -0.685878 -1.28492 0 -0 0</pose>
          <material>
            <ambient>0.501961 0.501961 0.501961 1</ambient>
            <diffuse>0.501961 0.501961 0.501961 1</diffuse>
          </material>
          <geometry>
            <mesh>
              <scale>1 1 1</scale>
              <uri>model://Tank8/meshes/L4Wheel.STL</uri>
            </mesh>
          </geometry>
        </visual>
        <kinematic>0</kinematic>
      </link>
      <joint name='Frame-L4Wheel' type='revolute'>
        <parent>Frame</parent>
        <child>L4Wheel</child>
        <pose frame=''>0 -0 0 0 -0 0</pose>
        <axis>
          <xyz>-1 0 0</xyz>
          <dynamics>
            <damping>1</damping>
            <friction>1</friction>
            <spring_reference>0</spring_reference>
            <spring_stiffness>0</spring_stiffness>
          </dynamics>
          <limit>
            <effort>50</effort>
            <lower>-1e+16</lower>
            <upper>1e+16</upper>
          </limit>
          <use_parent_model_frame>0</use_parent_model_frame>
        </axis>
      </joint>
      <link name='R1Wheel'>
        <gravity>1</gravity>
        <self_collide>0</self_collide>
        <pose frame=''>-0.723265 0.041783 0.047625 1.5708 -0 1.5708</pose>
        <must_be_base_link>0</must_be_base_link>
        <velocity_decay>
          <linear>0</linear>
          <angular>0</angular>
        </velocity_decay>
        <inertial>
          <mass>1.3252</mass>
          <pose frame=''>0 0 0 0 -0 0</pose>
          <inertia>
            <ixx>0.00636122</ixx>
            <ixy>1.12324e-21</ixy>
            <ixz>4.49297e-21</ixz>
            <iyy>0.00340889</iyy>
            <iyz>1.02506e-19</iyz>
            <izz>0.00340889</izz>
          </inertia>
        </inertial>
        <collision name='R1Wheel_collision'>
          <pose frame=''>-0.869183 -0.685878 -0.663891 0 -0 0</pose>
          <geometry>
            <mesh>
              <scale>1 1 1</scale>
              <uri>model://Tank8/meshes/R1Wheel_col.STL</uri>
            </mesh>
          </geometry>
          <surface>
            <contact>
              <ode/>
            </contact>
            <friction>
              <ode>
                <mu>1</mu>
                <mu2>1</mu2>
              </ode>
              <torsional>
                <ode/>
              </torsional>
            </friction>
            <bounce/>
          </surface>
          <max_contacts>10</max_contacts>
        </collision>
        <visual name='R1Wheel_visual'>
          <pose frame=''>-0.869183 -0.685878 -0.663891 0 -0 0</pose>
          <material>
            <ambient>0.501961 0.501961 0.501961 1</ambient>
            <diffuse>0.501961 0.501961 0.501961 1</diffuse>
          </material>
          <geometry>
            <mesh>
              <scale>1 1 1</scale>
              <uri>model://Tank8/meshes/R1Wheel.STL</uri>
            </mesh>
          </geometry>
        </visual>
        <kinematic>0</kinematic>
      </link>
      <joint name='Frame-R1Wheel' type='revolute'>
        <parent>Frame</parent>
        <child>R1Wheel</child>
        <pose frame=''>-0 0 0 0 -0 0</pose>
        <axis>
          <xyz>1 0 0</xyz>
          <dynamics>
            <damping>1</damping>
            <friction>1</friction>
            <spring_reference>0</spring_reference>
            <spring_stiffness>0</spring_stiffness>
          </dynamics>
          <limit>
            <effort>50</effort>
            <lower>-1e+16</lower>
            <upper>1e+16</upper>
          </limit>
          <use_parent_model_frame>0</use_parent_model_frame>
        </axis>
      </joint>
      <link name='R2Wheel'>
        <gravity>1</gravity>
        <self_collide>0</self_collide>
        <pose frame=''>-0.516255 0.041783 0.03175 1.5708 -0 1.5708</pose>
        <must_be_base_link>0</must_be_base_link>
        <velocity_decay>
          <linear>0</linear>
          <angular>0</angular>
        </velocity_decay>
        <inertial>
          <mass>1.3252</mass>
          <pose frame=''>0 0 0 0 -0 0</pose>
          <inertia>
            <ixx>0.00636122</ixx>
            <ixy>2.14529e-20</ixy>
            <ixz>4.16955e-21</ixz>
            <iyy>0.00340889</iyy>
            <iyz>4.95999e-20</iyz>
            <izz>0.00340889</izz>
          </inertia>
        </inertial>
        <collision name='R2Wheel_collision'>
          <pose frame=''>-0.869183 -0.670003 -0.870901 0 -0 0</pose>
          <geometry>
            <mesh>
              <scale>1 1 1</scale>
              <uri>model://Tank8/meshes/R2Wheel_col.STL</uri>
            </mesh>
          </geometry>
          <surface>
            <contact>
              <ode/>
            </contact>
            <friction>
              <ode>
                <mu>1</mu>
                <mu2>1</mu2>
              </ode>
              <torsional>
                <ode/>
              </torsional>
            </friction>
            <bounce/>
          </surface>
          <max_contacts>10</max_contacts>
        </collision>
        <visual name='R2Wheel_visual'>
          <pose frame=''>-0.869183 -0.670003 -0.870901 0 -0 0</pose>
          <material>
            <ambient>0.501961 0.501961 0.501961 1</ambient>
            <diffuse>0.501961 0.501961 0.501961 1</diffuse>
          </material>
          <geometry>
            <mesh>
              <scale>1 1 1</scale>
              <uri>model://Tank8/meshes/R2Wheel.STL</uri>
            </mesh>
          </geometry>
        </visual>
        <kinematic>0</kinematic>
      </link>
      <joint name='Frame-R2Wheel' type='revolute'>
        <parent>Frame</parent>
        <child>R2Wheel</child>
        <pose frame=''>0 0 -0 0 -0 0</pose>
        <axis>
          <xyz>1 0 0</xyz>
          <dynamics>
            <damping>1</damping>
            <friction>1</friction>
            <spring_reference>0</spring_reference>
            <spring_stiffness>0</spring_stiffness>
          </dynamics>
          <limit>
            <effort>50</effort>
            <lower>-1e+16</lower>
            <upper>1e+16</upper>
          </limit>
          <use_parent_model_frame>0</use_parent_model_frame>
        </axis>
      </joint>
      <link name='R3Wheel'>
        <gravity>1</gravity>
        <self_collide>0</self_collide>
        <pose frame=''>-0.309245 0.041783 0.03175 1.5708 -0 1.5708</pose>
        <must_be_base_link>0</must_be_base_link>
        <velocity_decay>
          <linear>0</linear>
          <angular>0</angular>
        </velocity_decay>
        <inertial>
          <mass>1.3252</mass>
          <pose frame=''>0 0 0 0 -0 0</pose>
          <inertia>
            <ixx>0.00636122</ixx>
            <ixy>7.83061e-20</ixy>
            <ixz>2.36683e-21</ixz>
            <iyy>0.00340889</iyy>
            <iyz>1.60821e-20</iyz>
            <izz>0.00340889</izz>
          </inertia>
        </inertial>
        <collision name='R3Wheel_collision'>
          <pose frame=''>-0.869183 -0.670003 -1.07791 0 -0 0</pose>
          <geometry>
            <mesh>
              <scale>1 1 1</scale>
              <uri>model://Tank8/meshes/R3Wheel_col.STL</uri>
            </mesh>
          </geometry>
          <surface>
            <contact>
              <ode/>
            </contact>
            <friction>
              <ode>
                <mu>1</mu>
                <mu2>1</mu2>
              </ode>
              <torsional>
                <ode/>
              </torsional>
            </friction>
            <bounce/>
          </surface>
          <max_contacts>10</max_contacts>
        </collision>
        <visual name='R3Wheel_visual'>
          <pose frame=''>-0.869183 -0.670003 -1.07791 0 -0 0</pose>
          <material>
            <ambient>0.501961 0.501961 0.501961 1</ambient>
            <diffuse>0.501961 0.501961 0.501961 1</diffuse>
          </material>
          <geometry>
            <mesh>
              <scale>1 1 1</scale>
              <uri>model://Tank8/meshes/R3Wheel.STL</uri>
            </mesh>
          </geometry>
        </visual>
        <kinematic>0</kinematic>
      </link>
      <joint name='Frame-R3Wheel' type='revolute'>
        <parent>Frame</parent>
        <child>R3Wheel</child>
        <pose frame=''>0 0 0 0 -0 0</pose>
        <axis>
          <xyz>1 0 0</xyz>
          <dynamics>
            <damping>1</damping>
            <friction>1</friction>
            <spring_reference>0</spring_reference>
            <spring_stiffness>0</spring_stiffness>
          </dynamics>
          <limit>
            <effort>50</effort>
            <lower>-1e+16</lower>
            <upper>1e+16</upper>
          </limit>
          <use_parent_model_frame>0</use_parent_model_frame>
        </axis>
      </joint>
      <link name='R4Wheel'>
        <gravity>1</gravity>
        <self_collide>0</self_collide>
        <pose frame=''>-0.102235 0.041783 0.047625 1.5708 -0 1.5708</pose>
        <must_be_base_link>0</must_be_base_link>
        <velocity_decay>
          <linear>0</linear>
          <angular>0</angular>
        </velocity_decay>
        <inertial>
          <mass>1.3252</mass>
          <pose frame=''>0 0 0 0 -0 0</pose>
          <inertia>
            <ixx>0.00636122</ixx>
            <ixy>1.28371e-21</ixy>
            <ixz>6.41853e-22</ixz>
            <iyy>0.00340889</iyy>
            <iyz>5.60757e-19</iyz>
            <izz>0.00340889</izz>
          </inertia>
        </inertial>
        <collision name='R4Wheel_collision'>
          <pose frame=''>-0.869183 -0.685878 -1.28492 0 -0 0</pose>
          <geometry>
            <mesh>
              <scale>1 1 1</scale>
              <uri>model://Tank8/meshes/R4Wheel_col.STL</uri>
            </mesh>
          </geometry>
          <surface>
            <contact>
              <ode/>
            </contact>
            <friction>
              <ode>
                <mu>1</mu>
                <mu2>1</mu2>
              </ode>
              <torsional>
                <ode/>
              </torsional>
            </friction>
            <bounce/>
          </surface>
          <max_contacts>10</max_contacts>
        </collision>
        <visual name='R4Wheel_visual'>
          <pose frame=''>-0.869183 -0.685878 -1.28492 0 -0 0</pose>
          <material>
            <ambient>0.501961 0.501961 0.501961 1</ambient>
            <diffuse>0.501961 0.501961 0.501961 1</diffuse>
          </material>
          <geometry>
            <mesh>
              <scale>1 1 1</scale>
              <uri>model://Tank8/meshes/R4Wheel.STL</uri>
            </mesh>
          </geometry>
        </visual>
        <kinematic>0</kinematic>
      </link>
      <joint name='Frame-R4Wheel' type='revolute'>
        <parent>Frame</parent>
        <child>R4Wheel</child>
        <pose frame=''>-0 -0 0 0 -0 0</pose>
        <axis>
          <xyz>1 0 0</xyz>
          <dynamics>
            <damping>1</damping>
            <friction>1</friction>
            <spring_reference>0</spring_reference>
            <spring_stiffness>0</spring_stiffness>
          </dynamics>
          <limit>
            <effort>50</effort>
            <lower>-1e+16</lower>
            <upper>1e+16</upper>
          </limit>
          <use_parent_model_frame>0</use_parent_model_frame>
        </axis>
      </joint>
      <plugin name='Frame-L1Wheel_motor' filename='libdc_motor.so'>
        <joint>Frame-L1Wheel</joint>
        <topic>/gazebo/frc/simulator/pwm/1</topic>
        <multiplier>25</multiplier>
      </plugin>
      <plugin name='Frame-L1Wheel_encoder' filename='libencoder.so'>
        <joint>Frame-L1Wheel</joint>
        <topic>/gazebo/frc/simulator/dio/1/2</topic>
        <units>degrees</units>
      </plugin>
      <plugin name='Frame-L2Wheel_motor' filename='libdc_motor.so'>
        <joint>Frame-L2Wheel</joint>
        <topic>/gazebo/frc/simulator/pwm/1</topic>
        <multiplier>24</multiplier>
      </plugin>
      <plugin name='Frame-L3Wheel_motor' filename='libdc_motor.so'>
        <joint>Frame-L3Wheel</joint>
        <topic>/gazebo/frc/simulator/pwm/1</topic>
        <multiplier>25</multiplier>
      </plugin>
      <plugin name='Frame-L4Wheel_motor' filename='libdc_motor.so'>
        <joint>Frame-L4Wheel</joint>
        <topic>/gazebo/frc/simulator/pwm/1</topic>
        <multiplier>25</multiplier>
      </plugin>
      <plugin name='Frame-R1Wheel_motor' filename='libdc_motor.so'>
        <joint>Frame-R1Wheel</joint>
        <topic>/gazebo/frc/simulator/pwm/2</topic>
        <multiplier>25</multiplier>
      </plugin>
      <plugin name='Frame-R1Wheel_encoder' filename='libencoder.so'>
        <joint>Frame-R1Wheel</joint>
        <topic>/gazebo/frc/simulator/dio/2/3</topic>
        <units>degrees</units>
      </plugin>
      <plugin name='Frame-R2Wheel_motor' filename='libdc_motor.so'>
        <joint>Frame-R2Wheel</joint>
        <topic>/gazebo/frc/simulator/pwm/2</topic>
        <multiplier>25</multiplier>
      </plugin>
      <plugin name='Frame-R3Wheel_motor' filename='libdc_motor.so'>
        <joint>Frame-R3Wheel</joint>
        <topic>/gazebo/frc/simulator/pwm/2</topic>
        <multiplier>25</multiplier>
      </plugin>
      <plugin name='Frame-R4Wheel_motor' filename='libdc_motor.so'>
        <joint>Frame-R4Wheel</joint>
        <topic>/gazebo/frc/simulator/pwm/2</topic>
        <multiplier>25</multiplier>
      </plugin>
    </model>
    <gravity>0 0 -9.8</gravity>
    <magnetic_field>6e-06 2.3e-05 -4.2e-05</magnetic_field>
    <atmosphere type='adiabatic'/>
    <physics name='default_physics' default='0' type='ode'>
      <max_step_size>0.001</max_step_size>
      <real_time_factor>1</real_time_factor>
      <real_time_update_rate>1000</real_time_update_rate>
    </physics>
    <scene>
      <ambient>0.4 0.4 0.4 1</ambient>
      <background>0.7 0.7 0.7 1</background>
      <shadows>1</shadows>
    </scene>
    <spherical_coordinates>
      <surface_model>EARTH_WGS84</surface_model>
      <latitude_deg>0</latitude_deg>
      <longitude_deg>0</longitude_deg>
      <elevation>0</elevation>
      <heading_deg>0</heading_deg>
    </spherical_coordinates>
    <model name='TAPE2017'>
      <pose frame=''>-0.177995 -5.16225 0.000302 0 -0 0</pose>
      <plugin name='clock' filename='libgz_clock.so'>
        <topic>/gazebo/frc/time</topic>
      </plugin>
      <link name='Tape'>
        <gravity>1</gravity>
        <self_collide>0</self_collide>
        <pose frame=''>0.00127 -0.13037 -0.064619 -1.5708 0 1.5708</pose>
        <must_be_base_link>1</must_be_base_link>
        <velocity_decay>
          <linear>0</linear>
          <angular>0</angular>
        </velocity_decay>
        <inertial>
          <mass>0.0327741</mass>
          <pose frame=''>0 0 0 0 -0 0</pose>
          <inertia>
            <ixx>4.41098e-05</ixx>
            <ixy>3.85007e-06</ixy>
            <ixz>8.50284e-24</ixz>
            <iyy>0.000368193</iyy>
            <iyz>3.69783e-23</iyz>
            <izz>0.000412268</izz>
          </inertia>
        </inertial>
        <collision name='Tape_collision'>
          <pose frame=''>-0.006897 0.026776 -0.00127 0 -0 0</pose>
          <geometry>
            <mesh>
              <scale>1 1 1</scale>
              <uri>model://TAPE2017/meshes/Tape_col.STL</uri>
            </mesh>
          </geometry>
          <surface>
            <contact>
              <ode/>
            </contact>
            <friction>
              <ode>
                <mu>0</mu>
                <mu2>0</mu2>
              </ode>
              <torsional>
                <ode/>
              </torsional>
            </friction>
            <bounce/>
          </surface>
          <max_contacts>10</max_contacts>
        </collision>
        <visual name='Tape_visual'>
          <pose frame=''>-0.006897 0.026776 -0.00127 0 -0 0</pose>
          <material>
            <ambient>0 1 1 1</ambient>
            <diffuse>0 1 1 1</diffuse>
          </material>
          <geometry>
            <mesh>
              <scale>1 1 1</scale>
              <uri>model://TAPE2017/meshes/Tape.STL</uri>
            </mesh>
          </geometry>
        </visual>
        <kinematic>0</kinematic>
      </link>
    </model>
    <state world_name='default'>
      <sim_time>9 2000000</sim_time>
      <real_time>55 76241223</real_time>
      <wall_time>1485896714 346878140</wall_time>
      <iterations>9002</iterations>
      <model name='FRC2017'>
        <pose frame=''>-0.001177 4.4e-05 -0.929357 2.2e-05 0.000597 1e-06</pose>
        <scale>1 1 1</scale>
        <link name='Field'>
          <pose frame=''>0 0.066233 1.04234 1.57072 0.000597 1e-06</pose>
          <velocity>0 0 0.005199 -0.000802 -0.000402 6e-06</velocity>
          <acceleration>0 0 10.4077 1.50341 1.28891 -3.13753</acceleration>
          <wrench>0 0 19748.7 0 -0 0</wrench>
        </link>
      </model>
      <model name='TAPE2017'>
        <pose frame=''>-0.185361 -4.85795 0.41079 0.011603 -0.00112 -0.540051</pose>
        <scale>1 1 1</scale>
        <link name='Tape'>
          <pose frame=''>-0.250852 -4.96981 0.344664 -1.57192 -0.011603 1.03076</pose>
          <velocity>0 0 0.006778 0.040491 0.000304 -0.0108</velocity>
          <acceleration>0 0 10.1283 0.070943 1.2335 0.886922</acceleration>
          <wrench>0 0 0.331947 0 -0 0</wrench>
        </link>
      </model>
      <model name='Tank8'>
        <pose frame=''>2.06997 -7.94093 0.065326 -4.5e-05 0.000161 -0.973891</pose>
        <scale>1 1 1</scale>
        <link name='Frame'>
          <pose frame=''>1.63294 -7.73744 0.106643 1.57096 4.5e-05 0.596909</pose>
          <velocity>-0.000194 -0.000838 0.00563 -0.008895 0.014593 0.000514</velocity>
          <acceleration>0.793889 1.43389 7.54634 -0.722561 0.058023 3.06636</acceleration>
          <wrench>4.45783 8.05153 42.3741 0 -0 0</wrench>
        </link>
        <link name='L1Wheel'>
          <pose frame=''>1.21923 -7.64463 0.113091 1.57096 4.5e-05 0.596909</pose>
          <velocity>-0.000136 -0.00098 0.010841 -0.008896 0.014594 0.000512</velocity>
          <acceleration>1.00894 1.76563 15.2861 2.12241 0.818287 3.02777</acceleration>
          <wrench>1.33705 2.33982 20.2572 0 -0 0</wrench>
        </link>
        <link name='L2Wheel'>
          <pose frame=''>1.33558 -7.81584 0.097183 1.57097 4.5e-05 0.596909</pose>
          <velocity>-0.000279 -0.001044 0.010665 -0.008896 0.014592 0.000479</velocity>
          <acceleration>0.550731 1.14425 18.9837 2.12121 0.819885 2.95944</acceleration>
          <wrench>0.729829 1.51636 25.1572 0 -0 0</wrench>
        </link>
        <link name='L3Wheel'>
          <pose frame=''>1.45194 -7.98705 0.09715 1.58149 -2e-06 0.596912</pose>
          <velocity>0.000123 -0.000577 0.010571 0.005462 0.001165 0.001787</velocity>
          <acceleration>0.955515 1.69019 22.7834 -2.16224 -0.873519 -1.66577</acceleration>
          <wrench>1.26625 2.23985 30.1925 0 -0 0</wrench>
        </link>
        <link name='L4Wheel'>
          <pose frame=''>1.5683 -8.15827 0.112991 1.57098 4.5e-05 0.596909</pose>
          <velocity>9.4e-05 -0.000814 0.010296 -0.008894 0.014589 0.000462</velocity>
          <acceleration>0.905947 1.72 26.366 2.10584 0.804035 2.92837</acceleration>
          <wrench>1.20056 2.27935 34.9402 0 -0 0</wrench>
        </link>
        <link name='R1Wheel'>
          <pose frame=''>1.69799 -7.31926 0.113065 1.57097 4.5e-05 0.596909</pose>
          <velocity>-0.000291 -0.000744 0.000939 -0.008898 0.014591 0.000478</velocity>
          <acceleration>1.0898 1.71199 -11.2277 2.09694 0.797468 2.95952</acceleration>
          <wrench>1.44421 2.26873 -14.879 0 -0 0</wrench>
        </link>
        <link name='R2Wheel'>
          <pose frame=''>1.81435 -7.49047 0.097157 1.56449 4.2e-05 0.59691</pose>
          <velocity>1.4e-05 -0.0004 0.000667 0.003721 3.8e-05 0.001666</velocity>
          <acceleration>1.53536 1.68652 -7.6402 2.08218 0.823322 -1.79259</acceleration>
          <wrench>2.03465 2.23497 -10.1248 0 -0 0</wrench>
        </link>
        <link name='R3Wheel'>
          <pose frame=''>1.9307 -7.66168 0.097124 1.57088 4.5e-05 0.596909</pose>
          <velocity>-0.000408 -0.000819 0.000615 -0.008888 0.014587 0.000481</velocity>
          <acceleration>0.455162 0.942099 -3.78804 2.1451 0.837844 3.0067</acceleration>
          <wrench>0.603182 1.24847 -5.01991 0 -0 0</wrench>
        </link>
        <link name='R4Wheel'>
          <pose frame=''>2.04706 -7.8329 0.112965 1.57097 4.5e-05 0.596909</pose>
          <velocity>-8.2e-05 -0.000608 0.000438 -0.008888 0.014589 0.000493</velocity>
          <acceleration>0.896384 1.58809 -0.092959 2.14286 0.834195 3.02344</acceleration>
          <wrench>1.18789 2.10453 -0.123189 0 -0 0</wrench>
        </link>
      </model>
      <model name='ground_plane'>
        <pose frame=''>0 0 0 0 -0 0</pose>
        <scale>1 1 1</scale>
        <link name='link'>
          <pose frame=''>0 0 0 0 -0 0</pose>
          <velocity>0 0 0 0 -0 0</velocity>
          <acceleration>0 0 0 0 -0 0</acceleration>
          <wrench>0 0 0 0 -0 0</wrench>
        </link>
      </model>
      <light name='sun'>
        <pose frame=''>0 0 10 0 -0 0</pose>
      </light>
    </state>
  </world>
</sdf>
