<?xml version="1.0" encoding="utf-8"?>
<sdf version="1.5">
  <model name="2018RobotElevator">
    <pose>0 0 0.07612 0 0 0</pose>
    <plugin name="clock" filename="libclock.so">
      <topic>/gazebo/frc/time</topic>
    </plugin>
    <link name="Body">
      <gravity>1</gravity>
      <self_collide>0</self_collide>
      <pose>0.0757570464740847 -0.00766407941753125 0.137726754371528 1.5707963267949 0 1.5707963267949</pose>
      <must_be_base_link>1</must_be_base_link>
      <velocity_decay>
        <linear>0</linear>
        <angular>0</angular>
      </velocity_decay>
      <inertial>
        <mass>40</mass>
        <pose>0 -0.15 -0.1 0 0 0</pose>
        <inertia>
          <ixx>1.40287896</ixx>
          <ixy>0.06862777</ixy>
          <ixz>0.02446668</ixz>
          <iyy>0.18210418</iyy>
          <iyz>0.24909937</iyz>
          <izz>1.34266984</izz>
        </inertia>
      </inertial>
      <collision name="Body_collision">
        <pose>0.00759376246486691 -0.136328157591616 -0.0242947917100101 0 0 0</pose>
        <geometry>
          <mesh>
            <scale>1 1 1</scale>
            <uri>model://2018RobotElevator/meshes/Body_col.STL</uri>
          </mesh>
        </geometry>
        <surface>
          <contact>
            <ode />
          </contact>
          <friction>
            <ode>
              <mu>1</mu>
              <mu2>1</mu2>
            </ode>
          </friction>
        </surface>
      </collision>
      <visual name="Body_visual">
        <pose>0.00759376246486691 -0.136328157591616 -0.0242947917100101 0 0 0</pose>
        <material>
          <ambient>0 0 1 1</ambient>
          <diffuse>0 0 1 1</diffuse>
        </material>
        <geometry>
          <mesh>
            <scale>1 1 1</scale>
            <uri>model://2018RobotElevator/meshes/Body.STL</uri>
          </mesh>
        </geometry>
      </visual>
    </link>
    <link name="Bumpers">
      <gravity>1</gravity>
      <self_collide>0</self_collide>
      <pose>0.0468968962464854 -3.51584763100226E-05 0.0504398952900915 1.5707963267949 0 1.5707963267949</pose>
      <must_be_base_link>0</must_be_base_link>
      <velocity_decay>
        <linear>0</linear>
        <angular>0</angular>
      </velocity_decay>
      <inertial>
        <mass>0.398486040545588</mass>
        <pose>-4.06575814682064E-20 2.08166817117217E-17 4.33680868994202E-18 0 0 0</pose>
        <inertia>
          <ixx>0.01</ixx>
          <ixy>1.03639166087484E-14</ixy>
          <ixz>2.06E-06</ixz>
          <iyy>0.05</iyy>
          <iyz>4.06737867734918E-19</iyz>
          <izz>0.05</izz>
        </inertia>
      </inertial>
      <collision name="Bumpers_collision">
        <pose>-3.51584763543176E-05 -0.04904129851018 0.00456535851758919 0 0 0</pose>
        <geometry>
          <mesh>
            <scale>1 1 1</scale>
            <uri>model://2018RobotElevator/meshes/Bumpers_col.STL</uri>
          </mesh>
        </geometry>
        <surface>
          <contact>
            <ode>
              <kp>10000</kp>
              <kd>100</kd>
            </ode>
          </contact>
          <friction>
            <ode>
              <mu>1</mu>
              <mu2>1</mu2>
            </ode>
          </friction>
        </surface>
      </collision>
      <visual name="Bumpers_visual">
        <pose>-3.51584763543176E-05 -0.04904129851018 0.00456535851758919 0 0 0</pose>
        <material>
          <ambient>1 0 0 1</ambient>
          <diffuse>1 0 0 1</diffuse>
        </material>
        <geometry>
          <mesh>
            <scale>1 1 1</scale>
            <uri>model://2018RobotElevator/meshes/Bumpers.STL</uri>
          </mesh>
        </geometry>
      </visual>
    </link>
    <joint name="Body-Bumpers" type="prismatic">
      <parent>Body</parent>
      <child>Bumpers</child>
      <pose>0.146583619805358 4.16333634234434E-17 0.254630684340466 0 0 1.5707963267949</pose>
      <axis>
        <xyz>1 2.22044604925031E-16 0</xyz>
        <dynamics>
          <damping>0</damping>
          <friction>0</friction>
        </dynamics>
        <limit>
          <upper>0.001</upper>
          <lower>0</lower>
          <effort>1</effort>
        </limit>
      </axis>
    </joint>
    <link name="LFWheel">
      <gravity>1</gravity>
      <self_collide>0</self_collide>
      <pose>0.345346896246474 0.328549000000001 0.026924 1.5707963267949 0 1.5707963267949</pose>
      <must_be_base_link>0</must_be_base_link>
      <velocity_decay>
        <linear>0</linear>
        <angular>0</angular>
      </velocity_decay>
      <inertial>
        <mass>0.593273105209116</mass>
        <pose>0 0 0 0 0 0</pose>
        <inertia>
          <ixx>0</ixx>
          <ixy>0</ixy>
          <ixz>0</ixz>
          <iyy>0</iyy>
          <iyz>0</iyz>
          <izz>0</izz>
        </inertia>
      </inertial>
      <collision name="LFWheel_collision">
        <pose>-0.328619316952665 -0.0255254032200884 -0.2938846414824 0 0 0</pose>
        <geometry>
          <mesh>
            <scale>1 1 1</scale>
            <uri>model://2018RobotElevator/meshes/LFWheel_col.STL</uri>
          </mesh>
        </geometry>
        <surface>
          <contact>
            <ode>
              <kp>1000000</kp>
              <kd>10</kd>
            </ode>
          </contact>
          <friction>
            <ode>
              <mu>1</mu>
              <mu2>1</mu2>
            </ode>
          </friction>
        </surface>
      </collision>
      <visual name="LFWheel_visual">
        <pose>-0.328619316952665 -0.0255254032200884 -0.2938846414824 0 0 0</pose>
        <material>
          <ambient>0.501960784313725 0.501960784313725 0.501960784313725 1</ambient>
          <diffuse>0.501960784313725 0.501960784313725 0.501960784313725 1</diffuse>
        </material>
        <geometry>
          <mesh>
            <scale>1 1 1</scale>
            <uri>model://2018RobotElevator/meshes/LFWheel.STL</uri>
          </mesh>
        </geometry>
      </visual>
    </link>
    <joint name="Body-LFWheel" type="revolute">
      <parent>Body</parent>
      <child>LFWheel</child>
      <pose>-3.88578058618805E-16 2.42861286636753E-17 -5.55111512312578E-17 0 0 3.14159265358979</pose>
      <axis>
        <xyz>-1 -1.22460635382238E-16 0</xyz>
        <dynamics>
          <damping>1</damping>
          <friction>1</friction>
        </dynamics>
        <limit>
          <effort>50</effort>
        </limit>
      </axis>
    </joint>
    <link name="LCWheel">
      <gravity>1</gravity>
      <self_collide>0</self_collide>
      <pose>0.0468968962464743 0.328549000000001 0.0220472 1.5707963267949 0 1.5707963267949</pose>
      <must_be_base_link>0</must_be_base_link>
      <velocity_decay>
        <linear>0</linear>
        <angular>0</angular>
      </velocity_decay>
      <inertial>
        <mass>0.593273105209116</mass>
        <pose>0 0 0 0 0 0</pose>
        <inertia>
          <ixx>0</ixx>
          <ixy>0</ixy>
          <ixz>0</ixz>
          <iyy>0</iyy>
          <iyz>0</iyz>
          <izz>0</izz>
        </inertia>
      </inertial>
      <collision name="LCWheel_collision">
        <pose>-0.328619316952665 -0.0206486032200884 0.00456535851760044 0 0 0</pose>
        <geometry>
          <mesh>
            <scale>1 1 1</scale>
            <uri>model://2018RobotElevator/meshes/LCWheel_col.STL</uri>
          </mesh>
        </geometry>
        <surface>
          <contact>
            <ode>
              <kp>1000000</kp>
              <kd>10</kd>
            </ode>
          </contact>
          <friction>
            <ode>
              <mu>1</mu>
              <mu2>1</mu2>
            </ode>
          </friction>
        </surface>
      </collision>
      <visual name="LCWheel_visual">
        <pose>-0.328619316952665 -0.0206486032200884 0.00456535851760044 0 0 0</pose>
        <material>
          <ambient>0.501960784313725 0.501960784313725 0.501960784313725 1</ambient>
          <diffuse>0.501960784313725 0.501960784313725 0.501960784313725 1</diffuse>
        </material>
        <geometry>
          <mesh>
            <scale>1 1 1</scale>
            <uri>model://2018RobotElevator/meshes/LCWheel.STL</uri>
          </mesh>
        </geometry>
      </visual>
    </link>
    <joint name="Body-LCWheel" type="revolute">
      <parent>Body</parent>
      <child>LCWheel</child>
      <pose>0 6.93889390390723E-18 -3.46944695195361E-18 0 0 3.14159265358979</pose>
      <axis>
        <xyz>-1 -1.22460635382238E-16 0</xyz>
        <dynamics>
          <damping>1</damping>
          <friction>1</friction>
        </dynamics>
        <limit>
          <effort>50</effort>
        </limit>
      </axis>
    </joint>
    <link name="LBWheel">
      <gravity>1</gravity>
      <self_collide>0</self_collide>
      <pose>-0.251553103753526 0.328549000000001 0.0269239999999999 1.5707963267949 0 1.5707963267949</pose>
      <must_be_base_link>0</must_be_base_link>
      <velocity_decay>
        <linear>0</linear>
        <angular>0</angular>
      </velocity_decay>
      <inertial>
        <mass>0.593273105209116</mass>
        <pose>0 0 0 0 0 0</pose>
        <inertia>
          <ixx>0</ixx>
          <ixy>0</ixy>
          <ixz>0</ixz>
          <iyy>0</iyy>
          <iyz>0</iyz>
          <izz>0</izz>
        </inertia>
      </inertial>
      <collision name="LBWheel_collision">
        <pose>-0.328619316952665 -0.0255254032200885 0.3030153585176 0 0 0</pose>
        <geometry>
          <mesh>
            <scale>1 1 1</scale>
            <uri>model://2018RobotElevator/meshes/LBWheel_col.STL</uri>
          </mesh>
        </geometry>
        <surface>
          <contact>
            <ode>
              <kp>1000000</kp>
              <kd>10</kd>
            </ode>
          </contact>
          <friction>
            <ode>
              <mu>1</mu>
              <mu2>1</mu2>
            </ode>
          </friction>
        </surface>
      </collision>
      <visual name="LBWheel_visual">
        <pose>-0.328619316952665 -0.0255254032200885 0.3030153585176 0 0 0</pose>
        <material>
          <ambient>0.501960784313725 0.501960784313725 0.501960784313725 1</ambient>
          <diffuse>0.501960784313725 0.501960784313725 0.501960784313725 1</diffuse>
        </material>
        <geometry>
          <mesh>
            <scale>1 1 1</scale>
            <uri>model://2018RobotElevator/meshes/LBWheel.STL</uri>
          </mesh>
        </geometry>
      </visual>
    </link>
    <joint name="Body-LBWheel" type="revolute">
      <parent>Body</parent>
      <child>LBWheel</child>
      <pose>0 -1.73472347597681E-17 5.55111512312578E-17 0 0 3.14159265358979</pose>
      <axis>
        <xyz>-1 -1.22460635382238E-16 0</xyz>
        <dynamics>
          <damping>1</damping>
          <friction>1</friction>
        </dynamics>
        <limit>
          <effort>50</effort>
        </limit>
      </axis>
    </joint>
    <link name="RFWheel">
      <gravity>1</gravity>
      <self_collide>0</self_collide>
      <pose>0.347862527162241 -0.328548999999999 0.0280925888899449 1.5707963267949 0 1.5707963267949</pose>
      <must_be_base_link>0</must_be_base_link>
      <velocity_decay>
        <linear>0</linear>
        <angular>0</angular>
      </velocity_decay>
      <inertial>
        <mass>0.593273105209116</mass>
        <pose>0 0 0 0 0 0</pose>
        <inertia>
          <ixx>0</ixx>
          <ixy>0</ixy>
          <ixz>0</ixz>
          <iyy>0</iyy>
          <iyz>0</iyz>
          <izz>0</izz>
        </inertia>
      </inertial>
      <collision name="RFWheel_collision">
        <pose>0.328478683047335 -0.0266939921100333 -0.296400272398166 0 0 0</pose>
        <geometry>
          <mesh>
            <scale>1 1 1</scale>
            <uri>model://2018RobotElevator/meshes/RFWheel_col.STL</uri>
          </mesh>
        </geometry>
        <surface>
          <contact>
            <ode>
              <kp>1000000</kp>
              <kd>10</kd>
            </ode>
          </contact>
          <friction>
            <ode>
              <mu>1</mu>
              <mu2>1</mu2>
            </ode>
          </friction>
        </surface>
      </collision>
      <visual name="RFWheel_visual">
        <pose>0.328478683047335 -0.0266939921100333 -0.296400272398166 0 0 0</pose>
        <material>
          <ambient>0.501960784313725 0.501960784313725 0.501960784313725 1</ambient>
          <diffuse>0.501960784313725 0.501960784313725 0.501960784313725 1</diffuse>
        </material>
        <geometry>
          <mesh>
            <scale>1 1 1</scale>
            <uri>model://2018RobotElevator/meshes/RFWheel.STL</uri>
          </mesh>
        </geometry>
      </visual>
    </link>
    <joint name="Body-RFWheel" type="revolute">
      <parent>Body</parent>
      <child>RFWheel</child>
      <pose>0 -6.93889390390723E-18 0 0 0 0</pose>
      <axis>
        <xyz>1 0 0</xyz>
        <dynamics>
          <damping>1</damping>
          <friction>1</friction>
        </dynamics>
        <limit>
          <effort>50</effort>
        </limit>
      </axis>
    </joint>
    <link name="RCWheel">
      <gravity>1</gravity>
      <self_collide>0</self_collide>
      <pose>0.0494125271622406 -0.328548999999999 0.0232157888899448 1.5707963267949 0 1.5707963267949</pose>
      <must_be_base_link>0</must_be_base_link>
      <velocity_decay>
        <linear>0</linear>
        <angular>0</angular>
      </velocity_decay>
      <inertial>
        <mass>0.593273105209116</mass>
        <pose>0 0 0 0 0 0</pose>
        <inertia>
          <ixx>0</ixx>
          <ixy>0</ixy>
          <ixz>0</ixz>
          <iyy>0</iyy>
          <iyz>0</iyz>
          <izz>0</izz>
        </inertia>
      </inertial>
      <collision name="RCWheel_collision">
        <pose>0.328478683047335 -0.0218171921100333 0.00204972760183393 0 0 0</pose>
        <geometry>
          <mesh>
            <scale>1 1 1</scale>
            <uri>model://2018RobotElevator/meshes/RCWheel_col.STL</uri>
          </mesh>
        </geometry>
        <surface>
          <contact>
            <ode>
              <kp>1000000</kp>
              <kd>10</kd>
            </ode>
          </contact>
          <friction>
            <ode>
              <mu>1</mu>
              <mu2>1</mu2>
            </ode>
          </friction>
        </surface>
      </collision>
      <visual name="RCWheel_visual">
        <pose>0.328478683047335 -0.0218171921100333 0.00204972760183393 0 0 0</pose>
        <material>
          <ambient>0.501960784313725 0.501960784313725 0.501960784313725 1</ambient>
          <diffuse>0.501960784313725 0.501960784313725 0.501960784313725 1</diffuse>
        </material>
        <geometry>
          <mesh>
            <scale>1 1 1</scale>
            <uri>model://2018RobotElevator/meshes/RCWheel.STL</uri>
          </mesh>
        </geometry>
      </visual>
    </link>
    <joint name="Body-RCWheel" type="revolute">
      <parent>Body</parent>
      <child>RCWheel</child>
      <pose>0 6.93889390390723E-18 -3.46944695195361E-18 0 0 0</pose>
      <axis>
        <xyz>1 0 0</xyz>
        <dynamics>
          <damping>1</damping>
          <friction>1</friction>
        </dynamics>
        <limit>
          <effort>50</effort>
        </limit>
      </axis>
    </joint>
    <link name="RBWheel">
      <gravity>1</gravity>
      <self_collide>0</self_collide>
      <pose>-0.249037472837759 -0.328548999999999 0.0280925888899448 1.5707963267949 0 1.5707963267949</pose>
      <must_be_base_link>0</must_be_base_link>
      <velocity_decay>
        <linear>0</linear>
        <angular>0</angular>
      </velocity_decay>
      <inertial>
        <mass>0.593273105209116</mass>
        <pose>0 0 0 0 0 0</pose>
        <inertia>
          <ixx>0</ixx>
          <ixy>0</ixy>
          <ixz>0</ixz>
          <iyy>0</iyy>
          <iyz>0</iyz>
          <izz>0</izz>
        </inertia>
      </inertial>
      <collision name="RBWheel_collision">
        <pose>0.328478683047335 -0.0266939921100333 0.300499727601834 0 0 0</pose>
        <geometry>
          <mesh>
            <scale>1 1 1</scale>
            <uri>model://2018RobotElevator/meshes/RBWheel_col.STL</uri>
          </mesh>
        </geometry>
        <surface>
          <contact>
            <ode>
              <kp>1000000</kp>
              <kd>10</kd>
            </ode>
          </contact>
          <friction>
            <ode>
              <mu>1</mu>
              <mu2>1</mu2>
            </ode>
          </friction>
        </surface>
      </collision>
      <visual name="RBWheel_visual">
        <pose>0.328478683047335 -0.0266939921100333 0.300499727601834 0 0 0</pose>
        <material>
          <ambient>0.501960784313725 0.501960784313725 0.501960784313725 1</ambient>
          <diffuse>0.501960784313725 0.501960784313725 0.501960784313725 1</diffuse>
        </material>
        <geometry>
          <mesh>
            <scale>1 1 1</scale>
            <uri>model://2018RobotElevator/meshes/RBWheel.STL</uri>
          </mesh>
        </geometry>
      </visual>
    </link>
    <joint name="Body-RBWheel" type="revolute">
      <parent>Body</parent>
      <child>RBWheel</child>
      <pose>0 3.46944695195361E-18 -5.55111512312578E-17 0 0 0</pose>
      <axis>
        <xyz>1 0 0</xyz>
        <dynamics>
          <damping>1</damping>
          <friction>1</friction>
        </dynamics>
        <limit>
          <effort>50</effort>
        </limit>
      </axis>
    </joint>
    <link name="Elevator">
      <gravity>1</gravity>
      <self_collide>0</self_collide>
      <pose>0.273084449678101 -0.000136538670951696 0.682521554774599 1.5707963267949 0 1.5707963267949</pose>
      <must_be_base_link>0</must_be_base_link>
      <velocity_decay>
        <linear>0</linear>
        <angular>0</angular>
      </velocity_decay>
      <inertial>
        <mass>3.0105647270352</mass>
        <pose>0 0 0 0 0 0</pose>
        <inertia>
          <ixx>0.312365172579047</ixx>
          <ixy>5.03971217549906E-17</ixy>
          <ixz>4.34846172939816E-07</ixz>
          <iyy>0.0310790228334829</iyy>
          <iyz>5.94465968109679E-05</iyz>
          <izz>0.342860898116179</izz>
        </inertia>
      </inertial>
      <collision name="Elevator_collision">
        <pose>6.62217182873051E-05 -0.681122957994687 -0.221622194914027 0 0 0</pose>
        <geometry>
          <mesh>
            <scale>1 1 1</scale>
            <uri>model://2018RobotElevator/meshes/Elevator_col.STL</uri>
          </mesh>
        </geometry>
        <surface>
          <contact>
            <ode />
          </contact>
          <friction>
            <ode>
              <mu>1</mu>
              <mu2>1</mu2>
            </ode>
          </friction>
        </surface>
      </collision>
      <visual name="Elevator_visual">
        <pose>6.62217182873051E-05 -0.681122957994687 -0.221622194914027 0 0 0</pose>
        <material>
          <ambient>0 0.752941176470588 0.501960784313725 1</ambient>
          <diffuse>0 0.752941176470588 0.501960784313725 1</diffuse>
        </material>
        <geometry>
          <mesh>
            <scale>1 1 1</scale>
            <uri>model://2018RobotElevator/meshes/Elevator.STL</uri>
          </mesh>
        </geometry>
      </visual>
    </link>
    <joint name="Body-Elevator" type="prismatic">
      <parent>Body</parent>
      <child>Elevator</child>
      <pose>0.146685 -9.99200722162641E-16 0.02844313090885 0 0 4.71238898038469</pose>
      <axis>
        <xyz>-1 -2.22044604925031E-16 0</xyz>
        <dynamics>
          <damping>1</damping>
          <friction>1</friction>
        </dynamics>
        <limit>
          <upper>0.5</upper>
          <lower>0</lower>
          <effort>100</effort>
        </limit>
      </axis>
    </joint>
    <link name="Carriage">
      <gravity>1</gravity>
      <self_collide>0</self_collide>
      <pose>0.278225666243566 -0.000136534850968466 0.216624887328579 1.5707963267949 0 1.5707963267949</pose>
      <must_be_base_link>0</must_be_base_link>
      <velocity_decay>
        <linear>0</linear>
        <angular>0</angular>
      </velocity_decay>
      <inertial>
        <mass>0.42919741300587</mass>
        <pose>0 0 0 0 0 0</pose>
        <inertia>
          <ixx>0.000699681875856221</ixx>
          <ixy>7.820428868358E-11</ixy>
          <ixz>3.06918450564483E-11</ixz>
          <iyy>0.00185142502331105</iyy>
          <iyz>2.51721352903904E-10</iyz>
          <izz>0.00251499734652645</izz>
        </inertia>
      </inertial>
      <collision name="Carriage_collision">
        <pose>6.6217898304074E-05 -0.215226290548668 -0.226763411479492 0 0 0</pose>
        <geometry>
          <mesh>
            <scale>1 1 1</scale>
            <uri>model://2018RobotElevator/meshes/Carriage_col.STL</uri>
          </mesh>
        </geometry>
        <surface>
          <contact>
            <ode />
          </contact>
          <friction>
            <ode>
              <mu>1</mu>
              <mu2>1</mu2>
            </ode>
          </friction>
        </surface>
      </collision>
      <visual name="Carriage_visual">
        <pose>6.6217898304074E-05 -0.215226290548668 -0.226763411479492 0 0 0</pose>
        <material>
          <ambient>1 0 0.501960784313725 1</ambient>
          <diffuse>1 0 0.501960784313725 1</diffuse>
        </material>
        <geometry>
          <mesh>
            <scale>1 1 1</scale>
            <uri>model://2018RobotElevator/meshes/Carriage.STL</uri>
          </mesh>
        </geometry>
      </visual>
      <sensor name="CarriageCamera" type="camera">
        <visualize>1</visualize>
        <always_on>1</always_on>
        <pose>-3.81998218116058E-09 0.0507999686701436 0.0106019143433852 4.71 4.71238898038469 0</pose>
        <camera name="Carriagecamera">
          <horizontal_fov>1.5707963267949</horizontal_fov>
          <image>
            <width>320</width>
            <height>240</height>
          </image>
          <clip>
            <near>0.1</near>
            <far>100</far>
          </clip>
          <save enabled="true">
              <path>/tmp/driver-camera</path>
          </save>
        </camera>
      </sensor>
    </link>
    <joint name="Elevator-Carriage" type="prismatic">
      <parent>Elevator</parent>
      <child>Carriage</child>
      <pose>0.102234996180017 1.11022302462516E-16 0.0233019143433853 0 0 1.5707963267949</pose>
      <axis>
        <xyz>1 2.22044604925031E-16 0</xyz>
        <dynamics>
          <damping>1</damping>
          <friction>1</friction>
        </dynamics>
        <limit>
          <upper>0.5</upper>
          <lower>0</lower>
          <effort>100</effort>
        </limit>
      </axis>
    </joint>
    <plugin name="Body_gyro" filename="libgyro.so">
      <link>Body</link>
      <topic>/gazebo/frc/simulator/analog/3</topic>
      <units>degrees</units>
      <axis>yaw</axis>
    </plugin>
    <plugin name="Body-LFWheel_motor" filename="libdc_motor.so">
      <joint>Body-LFWheel</joint>
      <topic>/gazebo/frc/simulator/pwm/2</topic>
      <multiplier>20</multiplier>
    </plugin>
    <plugin name="Body-LCWheel_motor" filename="libdc_motor.so">
      <joint>Body-LCWheel</joint>
      <topic>/gazebo/frc/simulator/pwm/2</topic>
      <multiplier>20</multiplier>
    </plugin>
    <plugin name="Body-LCWheel_encoder" filename="libencoder.so">
      <joint>Body-LCWheel</joint>
      <topic>/gazebo/frc/simulator/dio/3/4</topic>
      <units>degrees</units>
    </plugin>
    <plugin name="Body-LBWheel_motor" filename="libdc_motor.so">
      <joint>Body-LBWheel</joint>
      <topic>/gazebo/frc/simulator/pwm/2</topic>
      <multiplier>20</multiplier>
    </plugin>
    <plugin name="Body-RFWheel_motor" filename="libdc_motor.so">
      <joint>Body-RFWheel</joint>
      <topic>/gazebo/frc/simulator/pwm/4</topic>
      <multiplier>20</multiplier>
    </plugin>
    <plugin name="Body-RCWheel_motor" filename="libdc_motor.so">
      <joint>Body-RCWheel</joint>
      <topic>/gazebo/frc/simulator/pwm/4</topic>
      <multiplier>20</multiplier>
    </plugin>
    <plugin name="Body-RCWheel_encoder" filename="libencoder.so">
      <joint>Body-RCWheel</joint>
      <topic>/gazebo/frc/simulator/dio/7/8</topic>
      <units>degrees</units>
    </plugin>
    <plugin name="Body-RBWheel_motor" filename="libdc_motor.so">
      <joint>Body-RBWheel</joint>
      <topic>/gazebo/frc/simulator/pwm/4</topic>
      <multiplier>20</multiplier>
    </plugin>
    <plugin name="Body-Elevator_motor" filename="libdc_motor.so">
      <joint>Body-Elevator</joint>
      <topic>/gazebo/frc/simulator/pwm/7</topic>
      <multiplier>50</multiplier>
    </plugin>
    <plugin name="Elevator-Carriage_motor" filename="libdc_motor.so">
      <joint>Elevator-Carriage</joint>
      <topic>/gazebo/frc/simulator/pwm/7</topic>
      <multiplier>50</multiplier>
    </plugin>
  </model>
</sdf>
