<?xml version="1.0" encoding="utf-8"?>
<sdf version="1.5">
  <model name="Scale">
    <pose>0 0 -1.21310977876712E-19 0 0 0</pose>
    <plugin name="clock" filename="libclock.so">
      <topic>/gazebo/frc/time</topic>
    </plugin>
    <link name="ScaleBase">
      <gravity>1</gravity>
      <self_collide>0</self_collide>
      <pose>1.64620715512013 0.218437394875832 0.385903951485867 1.5707963267949 -8.88178419700125E-16 -1.5707963267949</pose>
      <must_be_base_link>1</must_be_base_link>
      <velocity_decay>
        <linear>0</linear>
        <angular>0</angular>
      </velocity_decay>
      <inertial>
        <mass>2001.03145742486</mass>
        <pose>0 0 0 0 0 0</pose>
        <inertia>
          <ixx>250.1847798276473</ixx>
          <ixy>0.00210790674326739</ixy>
          <ixz>110.3860287376259</ixz>
          <iyy>720.9963221587105</iyy>
          <iyz>20.17805590048165E-07</iyz>
          <izz>570.0320707385587</izz>
        </inertia>
      </inertial>
      <collision name="ScaleBase_collision">
        <pose>0.00253739487582736 -0.388742698481816 1.62388813618477E-08 0 0 0</pose>
        <geometry>
          <mesh>
            <scale>1 1 1</scale>
            <uri>model://Scale/meshes/ScaleBase_col.STL</uri>
          </mesh>
        </geometry>
        <surface>
          <contact>
            <ode />
          </contact>
          <friction>
            <ode>
              <mu>1</mu>
              <mu2>1</mu2>
            </ode>
          </friction>
        </surface>
      </collision>
      <visual name="ScaleBase_visual">
        <pose>0.00253739487582736 -0.388742698481816 1.62388813618477E-08 0 0 0</pose>
        <material>
          <ambient>0 0.627450980392157 0 1</ambient>
          <diffuse>0 0.627450980392157 0 1</diffuse>
        </material>
        <geometry>
          <mesh>
            <scale>1 1 1</scale>
            <uri>model://Scale/meshes/ScaleBase.STL</uri>
          </mesh>
        </geometry>
      </visual>
    </link>
    <joint name="ScaleBase-World" type="fixed">
      <parent>world</parent>
      <child>ScaleBase</child>
   </joint>

    <link name="ScaleArm">
      <gravity>1</gravity>
      <self_collide>0</self_collide>
      <pose>1.64700336504853 0.213606627472934 1.57887880341548 1.5707963267949 -8.88178419700125E-16 -1.5707963267949</pose>
      <must_be_base_link>0</must_be_base_link>
      <velocity_decay>
        <linear>0</linear>
        <angular>0</angular>
      </velocity_decay>
      <inertial>
        <mass>67.1881352871921</mass>
        <pose>0 0 0 0 0 0</pose>
        <inertia>
          <ixx>122.288700229871</ixx>
          <ixy>0.000816148995356533</ixy>
          <ixz>3.02941853255745E-07</ixz>
          <iyy>124.108034329393</iyy>
          <iyz>0.164394634252998</iyz>
          <izz>2.02882625831945</izz>
        </inertia>
      </inertial>
      <collision name="ScaleArm_collision">
        <pose>-0.00229337252707149 -1.58171755041143 0.000796226167280495 0 0 0</pose>
        <geometry>
          <mesh>
            <scale>1 1 1</scale>
            <uri>model://Scale/meshes/ScaleArm_col.STL</uri>
          </mesh>
        </geometry>
        <surface>
          <contact>
            <ode />
          </contact>
          <friction>
            <ode>
              <mu>1</mu>
              <mu2>1</mu2>
            </ode>
          </friction>
        </surface>
      </collision>
      <visual name="ScaleArm_visual">
        <pose>-0.00229337252707149 -1.58171755041143 0.000796226167280495 0 0 0</pose>
        <material>
          <ambient>1 0 0.501960784313725 1</ambient>
          <diffuse>1 0 0.501960784313725 1</diffuse>
        </material>
        <geometry>
          <mesh>
            <scale>1 1 1</scale>
            <uri>model://Scale/meshes/ScaleArm.STL</uri>
          </mesh>
        </geometry>
      </visual>
    </link>
    <joint name="ScaleBase-ScaleArm" type="revolute">
      <parent>ScaleBase</parent>
      <child>ScaleArm</child>
      <pose>2.08166817117217E-17 0.131052303592442 0.000176481707091244 0 0 0</pose>
      <axis>
        <xyz>1 0 3.88581826685001E-16</xyz>
        <dynamics>
          <damping>1</damping>
          <friction>1</friction>
        </dynamics>
        <limit>
          <upper>0.1</upper>
          <lower>-0.10</lower>
          <effort>1</effort>
        </limit>
      </axis>
    </joint>
  </model>
</sdf>
