<?xml version="1.0" encoding="utf-8"?>
<sdf version="1.5">
  <model name="Elevator">
    <pose>0 0 0.00254 3.14159 -0.003567 3.14159</pose>
    <plugin name="clock" filename="libgz_clock.so">
      <topic>/gazebo/frc/time</topic>
    </plugin>
    <link name="FrameBase">
      <gravity>1</gravity>
      <self_collide>0</self_collide>
      <pose>-0.0692332840636431 0.266711468696946 -0.0135500056389031 -1.5707963267949 0 0</pose>
      <must_be_base_link>1</must_be_base_link>
      <velocity_decay>
        <linear>0</linear>
        <angular>0</angular>
      </velocity_decay>
      <inertial>
        <mass>0.967597258478304</mass>
        <pose>0 0 0 0 0 0</pose>
        <inertia>
          <ixx>0.00430893297758607</ixx>
          <ixy>8.2139190539863E-06</ixy>
          <ixz>2.89564781925441E-07</ixz>
          <iyy>0.0187848870575196</iyy>
          <iyz>1.69755410866169E-08</iyz>
          <izz>0.0144997646753308</izz>
        </inertia>
      </inertial>
      <collision name="FrameBase_collision">
        <pose>0.0311332840636431 -0.000850005638903144 -1.14686969464102E-05 0 0 0</pose>
        <geometry>
          <mesh>
            <scale>1 1 1</scale>
            <uri>model://Elevator/meshes/FrameBase_col.STL</uri>
          </mesh>
        </geometry>
        <surface>
          <contact>
            <ode />
          </contact>
          <friction>
            <ode>
              <mu>0</mu>
              <mu2>0</mu2>
            </ode>
          </friction>
        </surface>
      </collision>
      <visual name="FrameBase_visual">
        <pose>0.0311332840636431 -0.000850005638903144 -1.14686969464102E-05 0 0 0</pose>
        <material>
          <ambient>0.501960784313725 0.501960784313725 0.501960784313725 1</ambient>
          <diffuse>0.501960784313725 0.501960784313725 0.501960784313725 1</diffuse>
        </material>
        <geometry>
          <mesh>
            <scale>1 1 1</scale>
            <uri>model://Elevator/meshes/FrameBase.STL</uri>
          </mesh>
        </geometry>
      </visual>
    </link>
    <link name="ElevatorBase">
      <gravity>1</gravity>
      <self_collide>0</self_collide>
      <pose>-0.0489224631738407 0.266697147126975 -0.597377393685777 -1.5707963267949 0 0</pose>
      <must_be_base_link>0</must_be_base_link>
      <velocity_decay>
        <linear>0</linear>
        <angular>0</angular>
      </velocity_decay>
      <inertial>
        <mass>6.18862194274529</mass>
        <pose>0 0 0 0 0 0</pose>
        <inertia>
          <ixx>0.815371582005532</ixx>
          <ixy>0.00115872360120666</ixy>
          <ixz>3.38872009620446E-06</ixz>
          <iyy>0.27656283423519</iyy>
          <iyz>4.87362429240248E-05</iyz>
          <izz>0.575488048079503</izz>
        </inertia>
      </inertial>
      <collision name="ElevatorBase_collision">
        <pose>0.0108224631738407 -0.584677393685777 2.85287302557384E-06 0 0 0</pose>
        <geometry>
          <mesh>
            <scale>1 1 1</scale>
            <uri>model://Elevator/meshes/ElevatorBase_col.STL</uri>
          </mesh>
        </geometry>
        <surface>
          <contact>
            <ode />
          </contact>
          <friction>
            <ode>
              <mu>0</mu>
              <mu2>0</mu2>
            </ode>
          </friction>
        </surface>
      </collision>
      <visual name="ElevatorBase_visual">
        <pose>0.0108224631738407 -0.584677393685777 2.85287302557384E-06 0 0 0</pose>
        <material>
          <ambient>0.501960784313725 0.501960784313725 0.501960784313725 1</ambient>
          <diffuse>0.501960784313725 0.501960784313725 0.501960784313725 1</diffuse>
        </material>
        <geometry>
          <mesh>
            <scale>1 1 1</scale>
            <uri>model://Elevator/meshes/ElevatorBase.STL</uri>
          </mesh>
        </geometry>
      </visual>
    </link>
    <joint name="FrameBase-ElevatorBase" type="revolute">
      <parent>FrameBase</parent>
      <child>ElevatorBase</child>
      <pose>-0.0396732278936056 -0.568802393685777 7.7012235564361E-18 0 0 0</pose>
      <axis>
        <xyz>-1.62319783125387E-32 -1.46852158259527E-33 1</xyz>
        <dynamics>
          <damping>1</damping>
          <friction>1</friction>
        </dynamics>
        <limit>
          <upper>0</upper>
          <lower>0</lower>
          <effort>1</effort>
        </limit>
      </axis>
    </joint>
    <link name="Stage1">
      <gravity>1</gravity>
      <self_collide>0</self_collide>
      <pose>-0.044951484506086 0.268157125772729 -0.614137876940995 -1.5707963267949 0 0</pose>
      <must_be_base_link>0</must_be_base_link>
      <velocity_decay>
        <linear>0</linear>
        <angular>0</angular>
      </velocity_decay>
      <inertial>
        <mass>5.14333379372811</mass>
        <pose>0 0 0 0 0 0</pose>
        <inertia>
          <ixx>0.481771673218427</ixx>
          <ixy>0.0174062674878509</ixy>
          <ixz>0.000375739832185117</ixz>
          <iyy>0.106616123645562</iyy>
          <iyz>0.0036623539597195</iyz>
          <izz>0.37969270586102</izz>
        </inertia>
      </inertial>
      <collision name="Stage1_collision">
        <pose>0.00685148450608597 -0.601437876940995 -0.00145712577272882 0 0 0</pose>
        <geometry>
          <mesh>
            <scale>1 1 1</scale>
            <uri>model://Elevator/meshes/Stage1_col.STL</uri>
          </mesh>
        </geometry>
        <surface>
          <contact>
            <ode />
          </contact>
          <friction>
            <ode>
              <mu>0</mu>
              <mu2>0</mu2>
            </ode>
          </friction>
        </surface>
      </collision>
      <visual name="Stage1_visual">
        <pose>0.00685148450608597 -0.601437876940995 -0.00145712577272882 0 0 0</pose>
        <material>
          <ambient>0.501960784313725 0.501960784313725 0.501960784313725 1</ambient>
          <diffuse>0.501960784313725 0.501960784313725 0.501960784313725 1</diffuse>
        </material>
        <geometry>
          <mesh>
            <scale>1 1 1</scale>
            <uri>model://Elevator/meshes/Stage1.STL</uri>
          </mesh>
        </geometry>
      </visual>
    </link>
    <joint name="ElevatorBase-Stage1" type="prismatic">
      <parent>ElevatorBase</parent>
      <child>Stage1</child>
      <pose>0.00685148450608597 -1.11022302462516E-16 0.230368674227266 0 0 4.71238898038469</pose>
      <axis>
        <xyz>1 2.22044604925031E-16 0</xyz>
        <dynamics>
          <damping>1</damping>
          <friction>1</friction>
        </dynamics>
        <limit>
          <upper>0</upper>
          <lower>0</lower>
          <effort>1</effort>
        </limit>
      </axis>
    </joint>
    <link name="Stage2">
      <gravity>1</gravity>
      <self_collide>0</self_collide>
      <pose>-0.0381000259334506 0.266705219918479 -0.630865467570375 -1.5707963267949 0 0</pose>
      <must_be_base_link>0</must_be_base_link>
      <velocity_decay>
        <linear>0</linear>
        <angular>0</angular>
      </velocity_decay>
      <inertial>
        <mass>4.28522513417582</mass>
        <pose>0 0 0 0 0 0</pose>
        <inertia>
          <ixx>0.176009586432212</ixx>
          <ixy>2.36115592357987E-09</ixy>
          <ixz>5.79862963880284E-13</ixz>
          <iyy>0.0234279109967537</iyy>
          <iyz>9.4652964310782E-06</iyz>
          <izz>0.15258167543546</izz>
        </inertia>
      </inertial>
      <collision name="Stage2_collision">
        <pose>2.59334506020675E-08 -0.618165467570375 -5.21991847892455E-06 0 0 0</pose>
        <geometry>
          <mesh>
            <scale>1 1 1</scale>
            <uri>model://Elevator/meshes/Stage2_col.STL</uri>
          </mesh>
        </geometry>
        <surface>
          <contact>
            <ode />
          </contact>
          <friction>
            <ode>
              <mu>0</mu>
              <mu2>0</mu2>
            </ode>
          </friction>
        </surface>
      </collision>
      <visual name="Stage2_visual">
        <pose>2.59334506020675E-08 -0.618165467570375 -5.21991847892455E-06 0 0 0</pose>
        <material>
          <ambient>0.501960784313725 0.501960784313725 0.501960784313725 1</ambient>
          <diffuse>0.501960784313725 0.501960784313725 0.501960784313725 1</diffuse>
        </material>
        <geometry>
          <mesh>
            <scale>1 1 1</scale>
            <uri>model://Elevator/meshes/Stage2.STL</uri>
          </mesh>
        </geometry>
      </visual>
    </link>
    <joint name="Stage1-Stage2" type="prismatic">
      <parent>Stage1</parent>
      <child>Stage2</child>
      <pose>2.59334506020675E-08 -4.44089209850063E-16 0.231820580081516 0 0 1.5707963267949</pose>
      <axis>
        <xyz>-1 -2.22044604925031E-16 0</xyz>
        <dynamics>
          <damping>1</damping>
          <friction>1</friction>
        </dynamics>
        <limit>
          <upper>0</upper>
          <lower>0</lower>
          <effort>1</effort>
        </limit>
      </axis>
    </joint>
    <link name="Carriage">
      <gravity>1</gravity>
      <self_collide>0</self_collide>
      <pose>-0.0380999999163021 0.266700000266276 -0.281063339012714 -1.5707963267949 0 0</pose>
      <must_be_base_link>0</must_be_base_link>
      <velocity_decay>
        <linear>0</linear>
        <angular>0</angular>
      </velocity_decay>
      <inertial>
        <mass>0.952467113073436</mass>
        <pose>0 0 0 0 0 0</pose>
        <inertia>
          <ixx>0.00444644500613112</ixx>
          <ixy>1.50809618250805E-11</ixy>
          <ixz>1.27972245383596E-11</ixz>
          <iyy>0.00123828433448723</iyy>
          <iyz>2.46468190637488E-11</iyz>
          <izz>0.00368568713416048</izz>
        </inertia>
      </inertial>
      <collision name="Carriage_collision">
        <pose>-8.36978548987117E-11 -0.268363339012714 -2.66276181522724E-10 0 0 0</pose>
        <geometry>
          <mesh>
            <scale>1 1 1</scale>
            <uri>model://Elevator/meshes/Carriage_col.STL</uri>
          </mesh>
        </geometry>
        <surface>
          <contact>
            <ode />
          </contact>
          <friction>
            <ode>
              <mu>0</mu>
              <mu2>0</mu2>
            </ode>
          </friction>
        </surface>
      </collision>
      <visual name="Carriage_visual">
        <pose>-8.36978548987117E-11 -0.268363339012714 -2.66276181522724E-10 0 0 0</pose>
        <material>
          <ambient>0.250980392156863 0.501960784313725 0.501960784313725 1</ambient>
          <diffuse>0.250980392156863 0.501960784313725 0.501960784313725 1</diffuse>
        </material>
        <geometry>
          <mesh>
            <scale>1 1 1</scale>
            <uri>model://Elevator/meshes/Carriage.STL</uri>
          </mesh>
        </geometry>
      </visual>
      <sensor name="CarriageCamera" type="camera">
        <visualize>1</visualize>
        <always_on>1</always_on>
        <pose>0.0380999999163022 -0.0858317431545866 -2.6627613988936E-10 1.5707963267949 0 0</pose>
        <camera name="Carriagecamera">
          <horizontal_fov>1.5707963267949</horizontal_fov>
          <image>
            <width>320</width>
            <height>240</height>
          </image>
          <clip>
            <near>0.1</near>
            <far>100</far>
          </clip>
        </camera>
      </sensor>
    </link>
    <joint name="Stage2-Carriage" type="prismatic">
      <parent>Stage2</parent>
      <child>Carriage</child>
      <pose>-8.36978548987117E-11 -3.8746783559418E-14 0.231825799733719 0 0 1.5707963267949</pose>
      <axis>
        <xyz>-1 -2.22044604925031E-16 0</xyz>
        <dynamics>
          <damping>1</damping>
          <friction>1</friction>
        </dynamics>
        <limit>
          <upper>0</upper>
          <lower>0</lower>
          <effort>1</effort>
        </limit>
      </axis>
    </joint>
    <!-- -->
    <link name="TilterBaseArm">
      <gravity>1</gravity>
      <self_collide>0</self_collide>
      <pose>-0.3960903732572 0.261767047417281 -0.206919257830928 -1.5707963267949 0 0</pose>
      <must_be_base_link>0</must_be_base_link>
      <velocity_decay>
        <linear>0</linear>
        <angular>0</angular>
      </velocity_decay>
      <inertial>
        <mass>0.414123580721828</mass>
        <pose>0 0 0 0 0 0</pose>
        <inertia>
          <ixx>0.0131140860742016</ixx>
          <ixy>0.00161298697097021</ixy>
          <ixz>0.000129717520381681</ixz>
          <iyy>0.0131182109024561</iyy>
          <iyz>0.000129551765657884</iyz>
          <izz>0.00322597657900468</izz>
        </inertia>
      </inertial>
      <collision name="TilterBaseArm_collision">
        <pose>0.3579903732572 -0.194219257830928 0.00493295258271862 0 0 0</pose>
        <geometry>
          <mesh>
            <scale>1 1 1</scale>
            <uri>model://Elevator/meshes/TilterBaseArm_col.STL</uri>
          </mesh>
        </geometry>
        <surface>
          <contact>
            <ode />
          </contact>
          <friction>
            <ode>
              <mu>0</mu>
              <mu2>0</mu2>
            </ode>
          </friction>
        </surface>
      </collision>
      <visual name="TilterBaseArm_visual">
        <pose>0.3579903732572 -0.194219257830928 0.00493295258271862 0 0 0</pose>
        <material>
          <ambient>0.501960784313725 0.501960784313725 0.501960784313725 1</ambient>
          <diffuse>0.501960784313725 0.501960784313725 0.501960784313725 1</diffuse>
        </material>
        <geometry>
          <mesh>
            <scale>1 1 1</scale>
            <uri>model://Elevator/meshes/TilterBaseArm.STL</uri>
          </mesh>
        </geometry>
      </visual>
    </link>
    <joint name="ElevatorBase-TilterBaseArm" type="fixed">
      <parent>ElevatorBase</parent>
      <child>TilterBaseArm</child>
      <pose>-0.188109626742797 -0.187869257830928 3.69454822637949E-11 0 0 0</pose>
      <axis>
        <xyz>0 0 -1</xyz>
        <dynamics>
          <damping>1</damping>
          <friction>1</friction>
        </dynamics>
        <limit>
          <upper>0</upper>
          <lower>0</lower>
          <effort>1</effort>
        </limit>
      </axis>
    </joint>
       <joint name="TilterEleArm-TilterBaseArm" type="revolute">
      <parent>TilterEleArm</parent>
      <child>TilterBaseArm</child>
      <pose>0.0634982471572795 0.0634171082765121 -1.24379673227537E-15 0 0 0</pose>
      <axis>
        <xyz>5.02893531012506E-16 -2.79217922287273E-18 1</xyz>
        <dynamics>
          <damping>1</damping>
          <friction>1</friction>
        </dynamics>
        <limit>
          <effort>1</effort>
        </limit>
      </axis>
    </joint>
    <link name="TilterEleArm">
      <gravity>1</gravity>
      <self_collide>0</self_collide>
      <pose>-0.185346063049962 0.266699999999998 -0.36999296105372 -1.5707963267949 0 0</pose>
      <must_be_base_link>0</must_be_base_link>
      <velocity_decay>
        <linear>0</linear>
        <angular>0</angular>
      </velocity_decay>
      <inertial>
        <mass>0.514275816876933</mass>
        <pose>0 0 0 0 0 0</pose>
        <inertia>
          <ixx>0.159756126215111</ixx>
          <ixy>0</ixy>
          <ixz>0</ixz>
          <iyy>0.159756126215111</iyy>
          <iyz>0</iyz>
          <izz>0</izz>
        </inertia>
      </inertial>
      <collision name="TilterEleArm_collision">
        <pose>0.147246063049962 -0.35729296105372 2.34776754262571E-15 0 0 0</pose>
        <geometry>
          <mesh>
            <scale>1 1 1</scale>
            <uri>model://Elevator/meshes/TilterEleArm_col.STL</uri>
          </mesh>
        </geometry>
        <surface>
          <contact>
            <ode />
          </contact>
          <friction>
            <ode>
              <mu>0</mu>
              <mu2>0</mu2>
            </ode>
          </friction>
        </surface>
      </collision>
      <visual name="TilterEleArm_visual">
        <pose>0.147246063049962 -0.35729296105372 2.34776754262571E-15 0 0 0</pose>
        <material>
          <ambient>0.501960784313725 0.501960784313725 0.501960784313725 1</ambient>
          <diffuse>0.501960784313725 0.501960784313725 0.501960784313725 1</diffuse>
        </material>
        <geometry>
          <mesh>
            <scale>1 1 1</scale>
            <uri>model://Elevator/meshes/TilterEleArm.STL</uri>
          </mesh>
        </geometry>
      </visual>
    </link>
    <joint name="ElevatorBase-TilterEleArm" type="fixed">
      <parent>ElevatorBase</parent>
      <child>TilterEleArm</child>
      <pose>0.147246063049962 0.0996565949462797 2.38343795837915E-16 0 0 0</pose>
      <axis>
        <xyz>0 0 1</xyz>
        <dynamics>
          <damping>1</damping>
          <friction>1</friction>
        </dynamics>
        <limit>
          <upper>0</upper>
          <lower>0</lower>
          <effort>1</effort>
        </limit>
      </axis>
    </joint>
   
    <plugin name="ElevatorBase-Stage1_motor" filename="libgz_dc_motor.so">
      <joint>ElevatorBase-Stage1</joint>
      <topic>/gazebo/frc/simulator/pwm/7</topic>
      <multiplier>20</multiplier>
    </plugin>
    <plugin name="Body-Elevator_encoder" filename="libencoder.so">
      <joint>ElevatorBase-Stage1</joint>
      <topic>/gazebo/frc/simulator/dio/13/14</topic>
    </plugin>
    <plugin name="Stage1-Stage2_motor" filename="libgz_dc_motor.so">
      <joint>Stage1-Stage2</joint>
      <topic>/gazebo/frc/simulator/pwm/8</topic>
      <multiplier>20</multiplier>
    </plugin>
    <plugin name="Stage2-Carriage_motor" filename="libgz_dc_motor.so">
      <joint>Stage2-Carriage</joint>
      <topic>/gazebo/frc/simulator/pwm/9</topic>
      <multiplier>20</multiplier>
    </plugin>
  </model>
</sdf>