<sdf version='1.5'>
  <world name='default'>
    <light name='sun' type='directional'>
      <cast_shadows>1</cast_shadows>
      <pose frame=''>0 0 10 0 -0 0</pose>
      <diffuse>0.8 0.8 0.8 1</diffuse>
      <specular>0.2 0.2 0.2 1</specular>
      <attenuation>
        <range>1000</range>
        <constant>0.9</constant>
        <linear>0.01</linear>
        <quadratic>0.001</quadratic>
      </attenuation>
      <direction>-0.5 0.1 -0.9</direction>
    </light>
    <model name='Tank8Wedge'>
      <pose frame=''>0 0 0 0 -0 0</pose>
      <plugin name='clock' filename='libgz_clock.so'>
        <topic>/gazebo/frc/time</topic>
      </plugin>
      <link name='Chassis'>
        <gravity>1</gravity>
        <self_collide>0</self_collide>
        <pose frame=''>0.354317 0.310939 0.045987 1.5708 -0 1.5708</pose>
        <must_be_base_link>1</must_be_base_link>
        <velocity_decay>
          <linear>0</linear>
          <angular>0</angular>
        </velocity_decay>
        <inertial>
          <mass>23.0274</mass>
          <pose frame=''>0 0 0 0 -0 0</pose>
          <inertia>
            <ixx>1.93952</ixx>
            <ixy>0.000392609</ixy>
            <ixz>0.0016172</ixz>
            <iyy>3.27373</iyy>
            <iyz>0.0393884</iyz>
            <izz>1.37827</izz>
          </inertia>
        </inertial>
        <collision name='Chassis_collision'>
          <pose frame=''>-0.643353 -0.680077 -0.954771 0 -0 0</pose>
          <geometry>
            <mesh>
              <scale>1 1 1</scale>
              <uri>model://Tank8Wedge/meshes/Chassis_col.STL</uri>
            </mesh>
          </geometry>
          <surface>
            <contact>
              <ode/>
            </contact>
            <friction>
              <ode>
                <mu>0</mu>
                <mu2>0</mu2>
              </ode>
            </friction>
            <bounce/>
          </surface>
          <max_contacts>10</max_contacts>
        </collision>
        <visual name='Chassis_visual'>
          <pose frame=''>-0.643353 -0.680077 -0.954771 0 -0 0</pose>
          <material>
            <ambient>0 0.25098 1 1</ambient>
            <diffuse>0 0.25098 1 1</diffuse>
          </material>
          <geometry>
            <mesh>
              <scale>1 1 1</scale>
              <uri>model://Tank8Wedge/meshes/Chassis.STL</uri>
            </mesh>
          </geometry>
        </visual>
        <sensor name='ChassisCamera' type='camera'>
          <visualize>1</visualize>
          <always_on>1</always_on>
          <pose frame=''>0.000608 -0.006311 -0.376972 -0.015383 1.57079 1.55541</pose>
          <camera name='Chassiscamera'>
            <horizontal_fov>1.5708</horizontal_fov>
            <image>
              <width>320</width>
              <height>240</height>
            </image>
            <clip>
              <near>0.1</near>
              <far>100</far>
            </clip>
          </camera>
        </sensor>
        <kinematic>0</kinematic>
      </link>
      <link name='L1Wheel'>
        <gravity>1</gravity>
        <self_collide>0</self_collide>
        <pose frame=''>0.063437 -0.042097 0.051788 1.5708 -0 1.5708</pose>
        <must_be_base_link>0</must_be_base_link>
        <velocity_decay>
          <linear>0</linear>
          <angular>0</angular>
        </velocity_decay>
        <inertial>
          <mass>1.32264</mass>
          <pose frame=''>0 0 0 0 -0 0</pose>
          <inertia>
            <ixx>0.00613217</ixx>
            <ixy>2.27955e-19</ixy>
            <ixz>3.68884e-19</ixz>
            <iyy>0.00328751</iyy>
            <iyz>4.36247e-20</iyz>
            <izz>0.00328751</izz>
          </inertia>
        </inertial>
        <collision name='L1Wheel_collision'>
          <pose frame=''>-0.290317 -0.685878 -0.663891 0 -0 0</pose>
          <geometry>
            <mesh>
              <scale>1 1 1</scale>
              <uri>model://Tank8Wedge/meshes/L1Wheel_col.STL</uri>
            </mesh>
          </geometry>
          <surface>
            <contact>
              <ode/>
            </contact>
            <friction>
              <ode>
                <mu>1</mu>
                <mu2>1</mu2>
              </ode>
            </friction>
            <bounce/>
          </surface>
          <max_contacts>10</max_contacts>
        </collision>
        <visual name='L1Wheel_visual'>
          <pose frame=''>-0.290317 -0.685878 -0.663891 0 -0 0</pose>
          <material>
            <ambient>0.25098 0.501961 0.501961 1</ambient>
            <diffuse>0.25098 0.501961 0.501961 1</diffuse>
          </material>
          <geometry>
            <mesh>
              <scale>1 1 1</scale>
              <uri>model://Tank8Wedge/meshes/L1Wheel.STL</uri>
            </mesh>
          </geometry>
        </visual>
        <kinematic>0</kinematic>
      </link>
      <joint name='Chassis-L1Wheel' type='revolute'>
        <parent>Chassis</parent>
        <child>L1Wheel</child>
        <pose frame=''>0.009525 0 0 0 -0 0</pose>
        <axis>
          <xyz>-1 0 0</xyz>
          <dynamics>
            <damping>1</damping>
            <friction>1</friction>
            <spring_reference>0</spring_reference>
            <spring_stiffness>0</spring_stiffness>
          </dynamics>
          <limit>
            <effort>20</effort>
            <lower>-1e+16</lower>
            <upper>1e+16</upper>
          </limit>
          <use_parent_model_frame>0</use_parent_model_frame>
        </axis>
      </joint>
      <link name='L2Wheel'>
        <gravity>1</gravity>
        <self_collide>0</self_collide>
        <pose frame=''>0.270447 -0.042097 0.035913 1.5708 -0 1.5708</pose>
        <must_be_base_link>0</must_be_base_link>
        <velocity_decay>
          <linear>0</linear>
          <angular>0</angular>
        </velocity_decay>
        <inertial>
          <mass>1.32264</mass>
          <pose frame=''>0 0 0 0 -0 0</pose>
          <inertia>
            <ixx>0.00613217</ixx>
            <ixy>4.15415e-36</ixy>
            <ixz>4.4081e-36</ixz>
            <iyy>0.00328751</iyy>
            <iyz>0</iyz>
            <izz>0.00328751</izz>
          </inertia>
        </inertial>
        <collision name='L2Wheel_collision'>
          <pose frame=''>-0.290317 -0.670003 -0.870901 0 -0 0</pose>
          <geometry>
            <mesh>
              <scale>1 1 1</scale>
              <uri>model://Tank8Wedge/meshes/L2Wheel_col.STL</uri>
            </mesh>
          </geometry>
          <surface>
            <contact>
              <ode/>
            </contact>
            <friction>
              <ode>
                <mu>1</mu>
                <mu2>1</mu2>
              </ode>
            </friction>
            <bounce/>
          </surface>
          <max_contacts>10</max_contacts>
        </collision>
        <visual name='L2Wheel_visual'>
          <pose frame=''>-0.290317 -0.670003 -0.870901 0 -0 0</pose>
          <material>
            <ambient>0.501961 0.501961 0.501961 1</ambient>
            <diffuse>0.501961 0.501961 0.501961 1</diffuse>
          </material>
          <geometry>
            <mesh>
              <scale>1 1 1</scale>
              <uri>model://Tank8Wedge/meshes/L2Wheel.STL</uri>
            </mesh>
          </geometry>
        </visual>
        <kinematic>0</kinematic>
      </link>
      <joint name='Chassis-L2Wheel' type='revolute'>
        <parent>Chassis</parent>
        <child>L2Wheel</child>
        <pose frame=''>0.009525 -0 0 0 -0 0</pose>
        <axis>
          <xyz>-1 0 0</xyz>
          <dynamics>
            <damping>1</damping>
            <friction>1</friction>
            <spring_reference>0</spring_reference>
            <spring_stiffness>0</spring_stiffness>
          </dynamics>
          <limit>
            <effort>20</effort>
            <lower>-1e+16</lower>
            <upper>1e+16</upper>
          </limit>
          <use_parent_model_frame>0</use_parent_model_frame>
        </axis>
      </joint>
      <link name='L3Wheel'>
        <gravity>1</gravity>
        <self_collide>0</self_collide>
        <pose frame=''>0.477457 -0.042097 0.035913 1.5708 -0 1.5708</pose>
        <must_be_base_link>0</must_be_base_link>
        <velocity_decay>
          <linear>0</linear>
          <angular>0</angular>
        </velocity_decay>
        <inertial>
          <mass>1.32264</mass>
          <pose frame=''>0 0 0 0 -0 0</pose>
          <inertia>
            <ixx>0.00613217</ixx>
            <ixy>5.8152e-20</ixy>
            <ixz>1.15038e-19</ixz>
            <iyy>0.00328751</iyy>
            <iyz>2.25932e-19</iyz>
            <izz>0.00328751</izz>
          </inertia>
        </inertial>
        <collision name='L3Wheel_collision'>
          <pose frame=''>-0.290317 -0.670003 -1.07791 0 -0 0</pose>
          <geometry>
            <mesh>
              <scale>1 1 1</scale>
              <uri>model://Tank8Wedge/meshes/L3Wheel_col.STL</uri>
            </mesh>
          </geometry>
          <surface>
            <contact>
              <ode/>
            </contact>
            <friction>
              <ode>
                <mu>1</mu>
                <mu2>1</mu2>
              </ode>
            </friction>
            <bounce/>
          </surface>
          <max_contacts>10</max_contacts>
        </collision>
        <visual name='L3Wheel_visual'>
          <pose frame=''>-0.290317 -0.670003 -1.07791 0 -0 0</pose>
          <material>
            <ambient>0.501961 0.501961 0.501961 1</ambient>
            <diffuse>0.501961 0.501961 0.501961 1</diffuse>
          </material>
          <geometry>
            <mesh>
              <scale>1 1 1</scale>
              <uri>model://Tank8Wedge/meshes/L3Wheel.STL</uri>
            </mesh>
          </geometry>
        </visual>
        <kinematic>0</kinematic>
      </link>
      <joint name='Chassis-L3Wheel' type='revolute'>
        <parent>Chassis</parent>
        <child>L3Wheel</child>
        <pose frame=''>0.009525 0 0 0 -0 0</pose>
        <axis>
          <xyz>-1 0 0</xyz>
          <dynamics>
            <damping>1</damping>
            <friction>1</friction>
            <spring_reference>0</spring_reference>
            <spring_stiffness>0</spring_stiffness>
          </dynamics>
          <limit>
            <effort>20</effort>
            <lower>-1e+16</lower>
            <upper>1e+16</upper>
          </limit>
          <use_parent_model_frame>0</use_parent_model_frame>
        </axis>
      </joint>
      <link name='L4Wheel'>
        <gravity>1</gravity>
        <self_collide>0</self_collide>
        <pose frame=''>0.684467 -0.042097 0.051788 1.5708 -0 1.5708</pose>
        <must_be_base_link>0</must_be_base_link>
        <velocity_decay>
          <linear>0</linear>
          <angular>0</angular>
        </velocity_decay>
        <inertial>
          <mass>1.32264</mass>
          <pose frame=''>0 0 0 0 -0 0</pose>
          <inertia>
            <ixx>0.00613217</ixx>
            <ixy>6.76665e-20</ixy>
            <ixz>1.47041e-19</ixz>
            <iyy>0.00328751</iyy>
            <iyz>2.93129e-34</iyz>
            <izz>0.00328751</izz>
          </inertia>
        </inertial>
        <collision name='L4Wheel_collision'>
          <pose frame=''>-0.290317 -0.685878 -1.28492 0 -0 0</pose>
          <geometry>
            <mesh>
              <scale>1 1 1</scale>
              <uri>model://Tank8Wedge/meshes/L4Wheel_col.STL</uri>
            </mesh>
          </geometry>
          <surface>
            <contact>
              <ode/>
            </contact>
            <friction>
              <ode>
                <mu>1</mu>
                <mu2>1</mu2>
              </ode>
            </friction>
            <bounce/>
          </surface>
          <max_contacts>10</max_contacts>
        </collision>
        <visual name='L4Wheel_visual'>
          <pose frame=''>-0.290317 -0.685878 -1.28492 0 -0 0</pose>
          <material>
            <ambient>0.501961 0.501961 0.501961 1</ambient>
            <diffuse>0.501961 0.501961 0.501961 1</diffuse>
          </material>
          <geometry>
            <mesh>
              <scale>1 1 1</scale>
              <uri>model://Tank8Wedge/meshes/L4Wheel.STL</uri>
            </mesh>
          </geometry>
        </visual>
        <kinematic>0</kinematic>
      </link>
      <joint name='Chassis-L4Wheel' type='revolute'>
        <parent>Chassis</parent>
        <child>L4Wheel</child>
        <pose frame=''>0.009525 0 0 0 -0 0</pose>
        <axis>
          <xyz>-1 0 0</xyz>
          <dynamics>
            <damping>1</damping>
            <friction>1</friction>
            <spring_reference>0</spring_reference>
            <spring_stiffness>0</spring_stiffness>
          </dynamics>
          <limit>
            <effort>20</effort>
            <lower>-1e+16</lower>
            <upper>1e+16</upper>
          </limit>
          <use_parent_model_frame>0</use_parent_model_frame>
        </axis>
      </joint>
      <link name='R1Wheel'>
        <gravity>1</gravity>
        <self_collide>0</self_collide>
        <pose frame=''>0.063437 0.663769 0.051788 1.5708 -0 1.5708</pose>
        <must_be_base_link>0</must_be_base_link>
        <velocity_decay>
          <linear>0</linear>
          <angular>0</angular>
        </velocity_decay>
        <inertial>
          <mass>1.32264</mass>
          <pose frame=''>0 0 0 0 -0 0</pose>
          <inertia>
            <ixx>0.00613217</ixx>
            <ixy>2.81894e-20</ixy>
            <ixz>3.89249e-20</ixz>
            <iyy>0.00328751</iyy>
            <iyz>1.25782e-19</iyz>
            <izz>0.00328751</izz>
          </inertia>
        </inertial>
        <collision name='R1Wheel_collision'>
          <pose frame=''>-0.996183 -0.685878 -0.663891 0 -0 0</pose>
          <geometry>
            <mesh>
              <scale>1 1 1</scale>
              <uri>model://Tank8Wedge/meshes/R1Wheel_col.STL</uri>
            </mesh>
          </geometry>
          <surface>
            <contact>
              <ode/>
            </contact>
            <friction>
              <ode>
                <mu>1</mu>
                <mu2>1</mu2>
              </ode>
            </friction>
            <bounce/>
          </surface>
          <max_contacts>10</max_contacts>
        </collision>
        <visual name='R1Wheel_visual'>
          <pose frame=''>-0.996183 -0.685878 -0.663891 0 -0 0</pose>
          <material>
            <ambient>0.25098 0.501961 0.501961 1</ambient>
            <diffuse>0.25098 0.501961 0.501961 1</diffuse>
          </material>
          <geometry>
            <mesh>
              <scale>1 1 1</scale>
              <uri>model://Tank8Wedge/meshes/R1Wheel.STL</uri>
            </mesh>
          </geometry>
        </visual>
        <kinematic>0</kinematic>
      </link>
      <joint name='Chassis-R1Wheel' type='revolute'>
        <parent>Chassis</parent>
        <child>R1Wheel</child>
        <pose frame=''>-0.009525 0 0 0 -0 0</pose>
        <axis>
          <xyz>1 0 0</xyz>
          <dynamics>
            <damping>1</damping>
            <friction>1</friction>
            <spring_reference>0</spring_reference>
            <spring_stiffness>0</spring_stiffness>
          </dynamics>
          <limit>
            <effort>20</effort>
            <lower>-1e+16</lower>
            <upper>1e+16</upper>
          </limit>
          <use_parent_model_frame>0</use_parent_model_frame>
        </axis>
      </joint>
      <link name='R2Wheel'>
        <gravity>1</gravity>
        <self_collide>0</self_collide>
        <pose frame=''>0.270447 0.663769 0.035913 1.5708 -0 1.5708</pose>
        <must_be_base_link>0</must_be_base_link>
        <velocity_decay>
          <linear>0</linear>
          <angular>0</angular>
        </velocity_decay>
        <inertial>
          <mass>1.32264</mass>
          <pose frame=''>0 0 0 0 -0 0</pose>
          <inertia>
            <ixx>0.00613217</ixx>
            <ixy>2.12477e-20</ixy>
            <ixz>5.53282e-21</ixz>
            <iyy>0.00328751</iyy>
            <iyz>1.86084e-20</iyz>
            <izz>0.00328751</izz>
          </inertia>
        </inertial>
        <collision name='R2Wheel_collision'>
          <pose frame=''>-0.996183 -0.670003 -0.870901 0 -0 0</pose>
          <geometry>
            <mesh>
              <scale>1 1 1</scale>
              <uri>model://Tank8Wedge/meshes/R2Wheel_col.STL</uri>
            </mesh>
          </geometry>
          <surface>
            <contact>
              <ode/>
            </contact>
            <friction>
              <ode>
                <mu>1</mu>
                <mu2>1</mu2>
              </ode>
            </friction>
            <bounce/>
          </surface>
          <max_contacts>10</max_contacts>
        </collision>
        <visual name='R2Wheel_visual'>
          <pose frame=''>-0.996183 -0.670003 -0.870901 0 -0 0</pose>
          <material>
            <ambient>0.501961 0.501961 0.501961 1</ambient>
            <diffuse>0.501961 0.501961 0.501961 1</diffuse>
          </material>
          <geometry>
            <mesh>
              <scale>1 1 1</scale>
              <uri>model://Tank8Wedge/meshes/R2Wheel.STL</uri>
            </mesh>
          </geometry>
        </visual>
        <kinematic>0</kinematic>
      </link>
      <joint name='Chassis-R2Wheel' type='revolute'>
        <parent>Chassis</parent>
        <child>R2Wheel</child>
        <pose frame=''>-0.009525 -0 0 0 -0 0</pose>
        <axis>
          <xyz>1 0 0</xyz>
          <dynamics>
            <damping>1</damping>
            <friction>1</friction>
            <spring_reference>0</spring_reference>
            <spring_stiffness>0</spring_stiffness>
          </dynamics>
          <limit>
            <effort>20</effort>
            <lower>-1e+16</lower>
            <upper>1e+16</upper>
          </limit>
          <use_parent_model_frame>0</use_parent_model_frame>
        </axis>
      </joint>
      <link name='R3Wheel'>
        <gravity>1</gravity>
        <self_collide>0</self_collide>
        <pose frame=''>0.477457 0.663769 0.035913 1.5708 -0 1.5708</pose>
        <must_be_base_link>0</must_be_base_link>
        <velocity_decay>
          <linear>0</linear>
          <angular>0</angular>
        </velocity_decay>
        <inertial>
          <mass>1.32264</mass>
          <pose frame=''>0 0 0 0 -0 0</pose>
          <inertia>
            <ixx>0.00613217</ixx>
            <ixy>4.10337e-24</ixy>
            <ixz>8.0265e-23</ixz>
            <iyy>0.00328751</iyy>
            <iyz>2.05393e-20</iyz>
            <izz>0.00328751</izz>
          </inertia>
        </inertial>
        <collision name='R3Wheel_collision'>
          <pose frame=''>-0.996183 -0.670003 -1.07791 0 -0 0</pose>
          <geometry>
            <mesh>
              <scale>1 1 1</scale>
              <uri>model://Tank8Wedge/meshes/R3Wheel_col.STL</uri>
            </mesh>
          </geometry>
          <surface>
            <contact>
              <ode/>
            </contact>
            <friction>
              <ode>
                <mu>1</mu>
                <mu2>1</mu2>
              </ode>
            </friction>
            <bounce/>
          </surface>
          <max_contacts>10</max_contacts>
        </collision>
        <visual name='R3Wheel_visual'>
          <pose frame=''>-0.996183 -0.670003 -1.07791 0 -0 0</pose>
          <material>
            <ambient>0.501961 0.501961 0.501961 1</ambient>
            <diffuse>0.501961 0.501961 0.501961 1</diffuse>
          </material>
          <geometry>
            <mesh>
              <scale>1 1 1</scale>
              <uri>model://Tank8Wedge/meshes/R3Wheel.STL</uri>
            </mesh>
          </geometry>
        </visual>
        <kinematic>0</kinematic>
      </link>
      <joint name='Chassis-R3Wheel' type='revolute'>
        <parent>Chassis</parent>
        <child>R3Wheel</child>
        <pose frame=''>-0.009525 0 0 0 -0 0</pose>
        <axis>
          <xyz>1 0 0</xyz>
          <dynamics>
            <damping>1</damping>
            <friction>1</friction>
            <spring_reference>0</spring_reference>
            <spring_stiffness>0</spring_stiffness>
          </dynamics>
          <limit>
            <effort>20</effort>
            <lower>-1e+16</lower>
            <upper>1e+16</upper>
          </limit>
          <use_parent_model_frame>0</use_parent_model_frame>
        </axis>
      </joint>
      <link name='R4Wheel'>
        <gravity>1</gravity>
        <self_collide>0</self_collide>
        <pose frame=''>0.684467 0.663769 0.051788 1.5708 -0 1.5708</pose>
        <must_be_base_link>0</must_be_base_link>
        <velocity_decay>
          <linear>0</linear>
          <angular>0</angular>
        </velocity_decay>
        <inertial>
          <mass>1.32264</mass>
          <pose frame=''>0 0 0 0 -0 0</pose>
          <inertia>
            <ixx>0.00613217</ixx>
            <ixy>5.50452e-21</ixy>
            <ixz>1.59694e-20</ixz>
            <iyy>0.00328751</iyy>
            <iyz>3.85325e-20</iyz>
            <izz>0.00328751</izz>
          </inertia>
        </inertial>
        <collision name='R4Wheel_collision'>
          <pose frame=''>-0.996183 -0.685878 -1.28492 0 -0 0</pose>
          <geometry>
            <mesh>
              <scale>1 1 1</scale>
              <uri>model://Tank8Wedge/meshes/R4Wheel_col.STL</uri>
            </mesh>
          </geometry>
          <surface>
            <contact>
              <ode/>
            </contact>
            <friction>
              <ode>
                <mu>1</mu>
                <mu2>1</mu2>
              </ode>
            </friction>
            <bounce/>
          </surface>
          <max_contacts>10</max_contacts>
        </collision>
        <visual name='R4Wheel_visual'>
          <pose frame=''>-0.996183 -0.685878 -1.28492 0 -0 0</pose>
          <material>
            <ambient>0.501961 0.501961 0.501961 1</ambient>
            <diffuse>0.501961 0.501961 0.501961 1</diffuse>
          </material>
          <geometry>
            <mesh>
              <scale>1 1 1</scale>
              <uri>model://Tank8Wedge/meshes/R4Wheel.STL</uri>
            </mesh>
          </geometry>
        </visual>
        <kinematic>0</kinematic>
      </link>
      <joint name='Chassis-R4Wheel' type='revolute'>
        <parent>Chassis</parent>
        <child>R4Wheel</child>
        <pose frame=''>-0.009525 0 0 0 -0 0</pose>
        <axis>
          <xyz>-1 0 0</xyz>
          <dynamics>
            <damping>1</damping>
            <friction>1</friction>
            <spring_reference>0</spring_reference>
            <spring_stiffness>0</spring_stiffness>
          </dynamics>
          <limit>
            <effort>20</effort>
            <lower>-1e+16</lower>
            <upper>1e+16</upper>
          </limit>
          <use_parent_model_frame>0</use_parent_model_frame>
        </axis>
      </joint>
      <link name='Wedge'>
        <gravity>1</gravity>
        <self_collide>0</self_collide>
        <pose frame=''>-0.098513 0.30794 0.154167 1.5708 -0 1.5708</pose>
        <must_be_base_link>0</must_be_base_link>
        <velocity_decay>
          <linear>0</linear>
          <angular>0</angular>
        </velocity_decay>
        <inertial>
          <mass>1.96398</mass>
          <pose frame=''>0 0 0 0 -0 0</pose>
          <inertia>
            <ixx>0.118629</ixx>
            <ixy>1.86745e-18</ixy>
            <ixz>1.00012e-17</ixz>
            <iyy>0.11519</iyy>
            <iyz>0.0280995</iyz>
            <izz>0.0110411</izz>
          </inertia>
        </inertial>
        <collision name='Wedge_collision'>
          <pose frame=''>-0.640354 -0.788257 -0.501941 0 -0 0</pose>
          <geometry>
            <mesh>
              <scale>1 1 1</scale>
              <uri>model://Tank8Wedge/meshes/Wedge_col.STL</uri>
            </mesh>
          </geometry>
          <surface>
            <contact>
              <ode/>
            </contact>
            <friction>
              <ode>
                <mu>0</mu>
                <mu2>0</mu2>
              </ode>
            </friction>
            <bounce/>
          </surface>
          <max_contacts>10</max_contacts>
        </collision>
        <visual name='Wedge_visual'>
          <pose frame=''>-0.640354 -0.788257 -0.501941 0 -0 0</pose>
          <material>
            <ambient>1 0 0 1</ambient>
            <diffuse>1 0 0 1</diffuse>
          </material>
          <geometry>
            <mesh>
              <scale>1 1 1</scale>
              <uri>model://Tank8Wedge/meshes/Wedge.STL</uri>
            </mesh>
          </geometry>
        </visual>
        <kinematic>0</kinematic>
      </link>
      <joint name='Chassis-Wedge' type='revolute'>
        <parent>Chassis</parent>
        <child>Wedge</child>
        <pose frame=''>-0.000292 0.011038 0.104863 0 -0 0</pose>
        <axis>
          <xyz>1 0 0</xyz>
          <dynamics>
            <damping>0</damping>
            <friction>0</friction>
            <spring_reference>0</spring_reference>
            <spring_stiffness>0</spring_stiffness>
          </dynamics>
          <limit>
            <upper>0.2</upper>
            <lower>0</lower>
            <effort>1</effort>
          </limit>
          <use_parent_model_frame>0</use_parent_model_frame>
        </axis>
      </joint>
      <plugin name='Chassis-L1Wheel_motor' filename='libgz_dc_motor.so'>
        <joint>Chassis-L1Wheel</joint>
        <topic>/gazebo/frc/simulator/pwm/1</topic>
        <multiplier>25</multiplier>
      </plugin>
      <plugin name='Chassis-L1Wheel_encoder' filename='libgz_encoder.so'>
        <joint>Chassis-L1Wheel</joint>
        <topic>/gazebo/frc/simulator/dio/1/2</topic>
        <units>degrees</units>
      </plugin>
      <plugin name='Chassis-L2Wheel_motor' filename='libgz_dc_motor.so'>
        <joint>Chassis-L2Wheel</joint>
        <topic>/gazebo/frc/simulator/pwm/1</topic>
        <multiplier>25</multiplier>
      </plugin>
      <plugin name='Chassis-L3Wheel_motor' filename='libgz_dc_motor.so'>
        <joint>Chassis-L3Wheel</joint>
        <topic>/gazebo/frc/simulator/pwm/2</topic>
        <multiplier>25</multiplier>
      </plugin>
      <plugin name='Chassis-L4Wheel_motor' filename='libgz_dc_motor.so'>
        <joint>Chassis-L4Wheel</joint>
        <topic>/gazebo/frc/simulator/pwm/2</topic>
        <multiplier>25</multiplier>
      </plugin>
      <plugin name='Chassis-R1Wheel_motor' filename='libgz_dc_motor.so'>
        <joint>Chassis-R1Wheel</joint>
        <topic>/gazebo/frc/simulator/pwm/3</topic>
        <multiplier>25</multiplier>
      </plugin>
      <plugin name='Chassis-R1Wheel_encoder' filename='libgz_encoder.so'>
        <joint>Chassis-R1Wheel</joint>
        <topic>/gazebo/frc/simulator/dio/3/4</topic>
        <units>degrees</units>
      </plugin>
      <plugin name='Chassis-R2Wheel_motor' filename='libgz_dc_motor.so'>
        <joint>Chassis-R2Wheel</joint>
        <topic>/gazebo/frc/simulator/pwm/3</topic>
        <multiplier>25</multiplier>
      </plugin>
      <plugin name='Chassis-R3Wheel_motor' filename='libgz_dc_motor.so'>
        <joint>Chassis-R3Wheel</joint>
        <topic>/gazebo/frc/simulator/pwm/4</topic>
        <multiplier>25</multiplier>
      </plugin>
      <plugin name='Chassis-R4Wheel_motor' filename='libgz_dc_motor.so'>
        <joint>Chassis-R4Wheel</joint>
        <topic>/gazebo/frc/simulator/pwm/4</topic>
        <multiplier>25</multiplier>
      </plugin>
    </model>
    <model name='ground_plane'>
      <static>1</static>
      <link name='link'>
        <collision name='collision'>
          <geometry>
            <plane>
              <normal>0 0 1</normal>
              <size>100 100</size>
            </plane>
          </geometry>
          <surface>
            <friction>
              <ode>
                <mu>100</mu>
                <mu2>50</mu2>
              </ode>
            </friction>
            <contact>
              <ode/>
            </contact>
            <bounce/>
          </surface>
          <max_contacts>10</max_contacts>
        </collision>
        <visual name='visual'>
          <cast_shadows>0</cast_shadows>
          <geometry>
            <plane>
              <normal>0 0 1</normal>
              <size>100 100</size>
            </plane>
          </geometry>
          <material>
            <script>
              <uri>file://media/materials/scripts/gazebo.material</uri>
              <name>Gazebo/Grey</name>
            </script>
          </material>
        </visual>
        <self_collide>0</self_collide>
        <kinematic>0</kinematic>
        <gravity>1</gravity>
      </link>
    </model>
    <physics name='default_physics' default='0' type='ode'>
      <max_step_size>0.001</max_step_size>
      <real_time_factor>1</real_time_factor>
      <real_time_update_rate>1000</real_time_update_rate>
      <gravity>0 0 -9.8</gravity>
      <magnetic_field>6e-06 2.3e-05 -4.2e-05</magnetic_field>
    </physics>
    <scene>
      <ambient>0.4 0.4 0.4 1</ambient>
      <background>0.7 0.7 0.7 1</background>
      <shadows>1</shadows>
    </scene>
    <spherical_coordinates>
      <surface_model>EARTH_WGS84</surface_model>
      <latitude_deg>0</latitude_deg>
      <longitude_deg>0</longitude_deg>
      <elevation>0</elevation>
      <heading_deg>0</heading_deg>
    </spherical_coordinates>
    <model name='frc2016_rockwall'>
      <static>1</static>
      <link name='link'>
        <inertial>
          <mass>10</mass>
          <pose frame=''>0 0 0.08974 0 -0 0</pose>
          <inertia>
            <ixx>0.327091</ixx>
            <ixy>0</ixy>
            <ixz>0</ixz>
            <iyy>1.37417</iyy>
            <iyz>0</iyz>
            <izz>1.64109</izz>
          </inertia>
        </inertial>
        <visual name='platform'>
          <pose frame=''>0 0 0.06432 0 -0 0</pose>
          <geometry>
            <box>
              <size>1.27 0.5969 0.003175</size>
            </box>
          </geometry>
        </visual>
        <collision name='platform'>
          <pose frame=''>0 0 0.06432 0 -0 0</pose>
          <geometry>
            <box>
              <size>1.27 0.5969 0.003175</size>
            </box>
          </geometry>
          <max_contacts>10</max_contacts>
          <surface>
            <contact>
              <ode/>
            </contact>
            <bounce/>
            <friction>
              <ode/>
            </friction>
          </surface>
        </collision>
        <visual name='up1'>
          <pose frame=''>0 0.05166 0.12537 0 -0 0</pose>
          <geometry>
            <box>
              <size>1.27 0.00462 0.11892</size>
            </box>
          </geometry>
          <material>
            <ambient>0.46 0.46 0.46 1</ambient>
            <diffuse>0.46 0.46 0.46 1</diffuse>
          </material>
        </visual>
        <collision name='up1'>
          <pose frame=''>0 0.05166 0.12537 0 -0 0</pose>
          <geometry>
            <box>
              <size>1.27 0.00462 0.11892</size>
            </box>
          </geometry>
          <max_contacts>10</max_contacts>
          <surface>
            <contact>
              <ode/>
            </contact>
            <bounce/>
            <friction>
              <ode/>
            </friction>
          </surface>
        </collision>
        <visual name='up2'>
          <pose frame=''>0 -0.05801 0.12537 0 -0 0</pose>
          <geometry>
            <box>
              <size>1.27 0.00462 0.11892</size>
            </box>
          </geometry>
          <material>
            <ambient>0.46 0.46 0.46 1</ambient>
            <diffuse>0.46 0.46 0.46 1</diffuse>
          </material>
        </visual>
        <collision name='up2'>
          <pose frame=''>0 -0.05801 0.12537 0 -0 0</pose>
          <geometry>
            <box>
              <size>1.27 0.00462 0.11892</size>
            </box>
          </geometry>
          <max_contacts>10</max_contacts>
          <surface>
            <contact>
              <ode/>
            </contact>
            <bounce/>
            <friction>
              <ode/>
            </friction>
          </surface>
        </collision>
        <visual name='top'>
          <pose frame=''>0 -0.00249 0.18252 0 -0 0</pose>
          <geometry>
            <box>
              <size>1.27 0.1143 0.00462</size>
            </box>
          </geometry>
          <material>
            <ambient>0.46 0.46 0.46 1</ambient>
            <diffuse>0.46 0.46 0.46 1</diffuse>
          </material>
        </visual>
        <collision name='top'>
          <pose frame=''>0 -0.00249 0.18252 0 -0 0</pose>
          <geometry>
            <box>
              <size>1.27 0.1143 0.00462</size>
            </box>
          </geometry>
          <max_contacts>10</max_contacts>
          <surface>
            <contact>
              <ode/>
            </contact>
            <bounce/>
            <friction>
              <ode/>
            </friction>
          </surface>
        </collision>
        <self_collide>0</self_collide>
        <kinematic>0</kinematic>
        <gravity>1</gravity>
      </link>
      <pose frame=''>-0.584117 1 0 0 -0 0</pose>
    </model>
    <model name='frc2016_moat'>
      <static>1</static>
      <link name='link'>
        <inertial>
          <mass>10</mass>
          <pose frame=''>0 0 0.06738 0 -0 0</pose>
          <inertia>
            <ixx>0.312195</ixx>
            <ixy>0</ixy>
            <ixz>0</ixz>
            <iyy>1.35927</iyy>
            <iyz>0</iyz>
            <izz>1.64109</izz>
          </inertia>
        </inertial>
        <visual name='platform'>
          <pose frame=''>0 0 0.0381 0 -0 0</pose>
          <geometry>
            <box>
              <size>1.27 0.5969 0.0762</size>
            </box>
          </geometry>
        </visual>
        <collision name='platform'>
          <pose frame=''>0 0 0.0381 0 -0 0</pose>
          <geometry>
            <box>
              <size>1.27 0.5969 0.0762</size>
            </box>
          </geometry>
          <max_contacts>10</max_contacts>
          <surface>
            <contact>
              <ode/>
            </contact>
            <bounce/>
            <friction>
              <ode/>
            </friction>
          </surface>
        </collision>
        <visual name='tube1_side1'>
          <pose frame=''>0 -0.25876 0.10301 0 -0 0</pose>
          <geometry>
            <box>
              <size>1.27 0.003175 0.0635</size>
            </box>
          </geometry>
          <material>
            <ambient>0.46 0.46 0.46 1</ambient>
            <diffuse>0.46 0.46 0.46 1</diffuse>
          </material>
        </visual>
        <collision name='tube1_side1'>
          <pose frame=''>0 -0.25876 0.10301 0 -0 0</pose>
          <geometry>
            <box>
              <size>1.27 0.003175 0.0635</size>
            </box>
          </geometry>
          <max_contacts>10</max_contacts>
          <surface>
            <contact>
              <ode/>
            </contact>
            <bounce/>
            <friction>
              <ode/>
            </friction>
          </surface>
        </collision>
        <visual name='tube1_side2'>
          <pose frame=''>0 -0.22384 0.10301 0 -0 0</pose>
          <geometry>
            <box>
              <size>1.27 0.003175 0.0635</size>
            </box>
          </geometry>
          <material>
            <ambient>0.46 0.46 0.46 1</ambient>
            <diffuse>0.46 0.46 0.46 1</diffuse>
          </material>
        </visual>
        <collision name='tube1_side2'>
          <pose frame=''>0 -0.22384 0.10301 0 -0 0</pose>
          <geometry>
            <box>
              <size>1.27 0.003175 0.0635</size>
            </box>
          </geometry>
          <max_contacts>10</max_contacts>
          <surface>
            <contact>
              <ode/>
            </contact>
            <bounce/>
            <friction>
              <ode/>
            </friction>
          </surface>
        </collision>
        <visual name='tube1_top'>
          <pose frame=''>0 -0.2413 0.13317 0 -0 0</pose>
          <geometry>
            <box>
              <size>1.27 0.0381 0.003175</size>
            </box>
          </geometry>
          <material>
            <ambient>0.46 0.46 0.46 1</ambient>
            <diffuse>0.46 0.46 0.46 1</diffuse>
          </material>
        </visual>
        <collision name='tube1_top'>
          <pose frame=''>0 -0.2413 0.13317 0 -0 0</pose>
          <geometry>
            <box>
              <size>1.27 0.0381 0.003175</size>
            </box>
          </geometry>
          <max_contacts>10</max_contacts>
          <surface>
            <contact>
              <ode/>
            </contact>
            <bounce/>
            <friction>
              <ode/>
            </friction>
          </surface>
        </collision>
        <visual name='tube2_side1'>
          <pose frame=''>0 0.22384 0.10301 0 -0 0</pose>
          <geometry>
            <box>
              <size>1.27 0.003175 0.0635</size>
            </box>
          </geometry>
          <material>
            <ambient>0.46 0.46 0.46 1</ambient>
            <diffuse>0.46 0.46 0.46 1</diffuse>
          </material>
        </visual>
        <collision name='tube2_side1'>
          <pose frame=''>0 0.22384 0.10301 0 -0 0</pose>
          <geometry>
            <box>
              <size>1.27 0.003175 0.0635</size>
            </box>
          </geometry>
          <max_contacts>10</max_contacts>
          <surface>
            <contact>
              <ode/>
            </contact>
            <bounce/>
            <friction>
              <ode/>
            </friction>
          </surface>
        </collision>
        <visual name='tube2_side2'>
          <pose frame=''>0 0.25876 0.10301 0 -0 0</pose>
          <geometry>
            <box>
              <size>1.27 0.003175 0.0635</size>
            </box>
          </geometry>
          <material>
            <ambient>0.46 0.46 0.46 1</ambient>
            <diffuse>0.46 0.46 0.46 1</diffuse>
          </material>
        </visual>
        <collision name='tube2_side2'>
          <pose frame=''>0 0.25876 0.10301 0 -0 0</pose>
          <geometry>
            <box>
              <size>1.27 0.003175 0.0635</size>
            </box>
          </geometry>
          <max_contacts>10</max_contacts>
          <surface>
            <contact>
              <ode/>
            </contact>
            <bounce/>
            <friction>
              <ode/>
            </friction>
          </surface>
        </collision>
        <visual name='tube2_top'>
          <pose frame=''>0 0.2413 0.13317 0 -0 0</pose>
          <geometry>
            <box>
              <size>1.27 0.0381 0.003175</size>
            </box>
          </geometry>
          <material>
            <ambient>0.46 0.46 0.46 1</ambient>
            <diffuse>0.46 0.46 0.46 1</diffuse>
          </material>
        </visual>
        <collision name='tube2_top'>
          <pose frame=''>0 0.2413 0.13317 0 -0 0</pose>
          <geometry>
            <box>
              <size>1.27 0.0381 0.003175</size>
            </box>
          </geometry>
          <max_contacts>10</max_contacts>
          <surface>
            <contact>
              <ode/>
            </contact>
            <bounce/>
            <friction>
              <ode/>
            </friction>
          </surface>
        </collision>
        <self_collide>0</self_collide>
        <kinematic>0</kinematic>
        <gravity>1</gravity>
      </link>
      <pose frame=''>1.49502 1 0 0 -0 0</pose>
    </model>
    <model name='frc2016_roughterrain'>
      <static>1</static>
      <link name='link'>
        <visual name='platform'>
          <pose frame=''>0 0 0.08269 0 -0 0</pose>
          <geometry>
            <box>
              <size>1.27 0.5969 0.003175</size>
            </box>
          </geometry>
        </visual>
        <collision name='platform'>
          <pose frame=''>0 0 0.08269 0 -0 0</pose>
          <geometry>
            <box>
              <size>1.27 0.5969 0.003175</size>
            </box>
          </geometry>
          <max_contacts>10</max_contacts>
          <surface>
            <contact>
              <ode/>
            </contact>
            <bounce/>
            <friction>
              <ode/>
            </friction>
          </surface>
        </collision>
        <visual name='row1_block1_sm'>
          <pose frame=''>0.51435 0.1143 0.09698 0 -0 0</pose>
          <geometry>
            <box>
              <size>0.0762 0.0762 0.0254</size>
            </box>
          </geometry>
        </visual>
        <collision name='row1_block1_sm'>
          <pose frame=''>0.51435 0.1143 0.09698 0 -0 0</pose>
          <geometry>
            <box>
              <size>0.0762 0.0762 0.0254</size>
            </box>
          </geometry>
          <max_contacts>10</max_contacts>
          <surface>
            <contact>
              <ode/>
            </contact>
            <bounce/>
            <friction>
              <ode/>
            </friction>
          </surface>
        </collision>
        <visual name='row1_block2_lg'>
          <pose frame=''>0.40005 0.1143 0.12238 0 -0 0</pose>
          <geometry>
            <box>
              <size>0.0762 0.0762 0.0762</size>
            </box>
          </geometry>
        </visual>
        <collision name='row1_block2_lg'>
          <pose frame=''>0.40005 0.1143 0.12238 0 -0 0</pose>
          <geometry>
            <box>
              <size>0.0762 0.0762 0.0762</size>
            </box>
          </geometry>
          <max_contacts>10</max_contacts>
          <surface>
            <contact>
              <ode/>
            </contact>
            <bounce/>
            <friction>
              <ode/>
            </friction>
          </surface>
        </collision>
        <visual name='row1_block3_md'>
          <pose frame=''>0.28575 0.1143 0.10968 0 -0 0</pose>
          <geometry>
            <box>
              <size>0.0762 0.0762 0.0508</size>
            </box>
          </geometry>
        </visual>
        <collision name='row1_block3_md'>
          <pose frame=''>0.28575 0.1143 0.10968 0 -0 0</pose>
          <geometry>
            <box>
              <size>0.0762 0.0762 0.0508</size>
            </box>
          </geometry>
          <max_contacts>10</max_contacts>
          <surface>
            <contact>
              <ode/>
            </contact>
            <bounce/>
            <friction>
              <ode/>
            </friction>
          </surface>
        </collision>
        <visual name='row1_block4_sm'>
          <pose frame=''>0.17145 0.1143 0.09698 0 -0 0</pose>
          <geometry>
            <box>
              <size>0.0762 0.0762 0.0254</size>
            </box>
          </geometry>
        </visual>
        <collision name='row1_block4_sm'>
          <pose frame=''>0.17145 0.1143 0.09698 0 -0 0</pose>
          <geometry>
            <box>
              <size>0.0762 0.0762 0.0254</size>
            </box>
          </geometry>
          <max_contacts>10</max_contacts>
          <surface>
            <contact>
              <ode/>
            </contact>
            <bounce/>
            <friction>
              <ode/>
            </friction>
          </surface>
        </collision>
        <visual name='row1_block5_md'>
          <pose frame=''>0.05715 0.1143 0.10968 0 -0 0</pose>
          <geometry>
            <box>
              <size>0.0762 0.0762 0.0508</size>
            </box>
          </geometry>
        </visual>
        <collision name='row1_block5_md'>
          <pose frame=''>0.05715 0.1143 0.10968 0 -0 0</pose>
          <geometry>
            <box>
              <size>0.0762 0.0762 0.0508</size>
            </box>
          </geometry>
          <max_contacts>10</max_contacts>
          <surface>
            <contact>
              <ode/>
            </contact>
            <bounce/>
            <friction>
              <ode/>
            </friction>
          </surface>
        </collision>
        <visual name='row1_block6_lg'>
          <pose frame=''>-0.05715 0.1143 0.12238 0 -0 0</pose>
          <geometry>
            <box>
              <size>0.0762 0.0762 0.0762</size>
            </box>
          </geometry>
        </visual>
        <collision name='row1_block6_lg'>
          <pose frame=''>-0.05715 0.1143 0.12238 0 -0 0</pose>
          <geometry>
            <box>
              <size>0.0762 0.0762 0.0762</size>
            </box>
          </geometry>
          <max_contacts>10</max_contacts>
          <surface>
            <contact>
              <ode/>
            </contact>
            <bounce/>
            <friction>
              <ode/>
            </friction>
          </surface>
        </collision>
        <visual name='row1_block7_sm'>
          <pose frame=''>-0.17145 0.1143 0.09698 0 -0 0</pose>
          <geometry>
            <box>
              <size>0.0762 0.0762 0.0254</size>
            </box>
          </geometry>
        </visual>
        <collision name='row1_block7_sm'>
          <pose frame=''>-0.17145 0.1143 0.09698 0 -0 0</pose>
          <geometry>
            <box>
              <size>0.0762 0.0762 0.0254</size>
            </box>
          </geometry>
          <max_contacts>10</max_contacts>
          <surface>
            <contact>
              <ode/>
            </contact>
            <bounce/>
            <friction>
              <ode/>
            </friction>
          </surface>
        </collision>
        <visual name='row1_block8_sm'>
          <pose frame=''>-0.28575 0.1143 0.09698 0 -0 0</pose>
          <geometry>
            <box>
              <size>0.0762 0.0762 0.0254</size>
            </box>
          </geometry>
        </visual>
        <collision name='row1_block8_sm'>
          <pose frame=''>-0.28575 0.1143 0.09698 0 -0 0</pose>
          <geometry>
            <box>
              <size>0.0762 0.0762 0.0254</size>
            </box>
          </geometry>
          <max_contacts>10</max_contacts>
          <surface>
            <contact>
              <ode/>
            </contact>
            <bounce/>
            <friction>
              <ode/>
            </friction>
          </surface>
        </collision>
        <visual name='row1_block9_md'>
          <pose frame=''>-0.40005 0.1143 0.10968 0 -0 0</pose>
          <geometry>
            <box>
              <size>0.0762 0.0762 0.0508</size>
            </box>
          </geometry>
        </visual>
        <collision name='row1_block9_md'>
          <pose frame=''>-0.40005 0.1143 0.10968 0 -0 0</pose>
          <geometry>
            <box>
              <size>0.0762 0.0762 0.0508</size>
            </box>
          </geometry>
          <max_contacts>10</max_contacts>
          <surface>
            <contact>
              <ode/>
            </contact>
            <bounce/>
            <friction>
              <ode/>
            </friction>
          </surface>
        </collision>
        <visual name='row1_block10_lg'>
          <pose frame=''>-0.51435 0.1143 0.12238 0 -0 0</pose>
          <geometry>
            <box>
              <size>0.0762 0.0762 0.0762</size>
            </box>
          </geometry>
        </visual>
        <collision name='row1_block10_lg'>
          <pose frame=''>-0.51435 0.1143 0.12238 0 -0 0</pose>
          <geometry>
            <box>
              <size>0.0762 0.0762 0.0762</size>
            </box>
          </geometry>
          <max_contacts>10</max_contacts>
          <surface>
            <contact>
              <ode/>
            </contact>
            <bounce/>
            <friction>
              <ode/>
            </friction>
          </surface>
        </collision>
        <visual name='row2_block1_md'>
          <pose frame=''>0.5715 0 0.10968 0 -0 0</pose>
          <geometry>
            <box>
              <size>0.0762 0.0762 0.0508</size>
            </box>
          </geometry>
        </visual>
        <collision name='row2_block1_md'>
          <pose frame=''>0.5715 0 0.10968 0 -0 0</pose>
          <geometry>
            <box>
              <size>0.0762 0.0762 0.0508</size>
            </box>
          </geometry>
          <max_contacts>10</max_contacts>
          <surface>
            <contact>
              <ode/>
            </contact>
            <bounce/>
            <friction>
              <ode/>
            </friction>
          </surface>
        </collision>
        <visual name='row2_block2_sm'>
          <pose frame=''>0.4572 0 0.09698 0 -0 0</pose>
          <geometry>
            <box>
              <size>0.0762 0.0762 0.0254</size>
            </box>
          </geometry>
        </visual>
        <collision name='row2_block2_sm'>
          <pose frame=''>0.4572 0 0.09698 0 -0 0</pose>
          <geometry>
            <box>
              <size>0.0762 0.0762 0.0254</size>
            </box>
          </geometry>
          <max_contacts>10</max_contacts>
          <surface>
            <contact>
              <ode/>
            </contact>
            <bounce/>
            <friction>
              <ode/>
            </friction>
          </surface>
        </collision>
        <visual name='row2_block3_lg'>
          <pose frame=''>0.3429 0 0.12238 0 -0 0</pose>
          <geometry>
            <box>
              <size>0.0762 0.0762 0.0762</size>
            </box>
          </geometry>
        </visual>
        <collision name='row2_block3_lg'>
          <pose frame=''>0.3429 0 0.12238 0 -0 0</pose>
          <geometry>
            <box>
              <size>0.0762 0.0762 0.0762</size>
            </box>
          </geometry>
          <max_contacts>10</max_contacts>
          <surface>
            <contact>
              <ode/>
            </contact>
            <bounce/>
            <friction>
              <ode/>
            </friction>
          </surface>
        </collision>
        <visual name='row2_block4_md'>
          <pose frame=''>0.2286 0 0.10968 0 -0 0</pose>
          <geometry>
            <box>
              <size>0.0762 0.0762 0.0508</size>
            </box>
          </geometry>
        </visual>
        <collision name='row2_block4_md'>
          <pose frame=''>0.2286 0 0.10968 0 -0 0</pose>
          <geometry>
            <box>
              <size>0.0762 0.0762 0.0508</size>
            </box>
          </geometry>
          <max_contacts>10</max_contacts>
          <surface>
            <contact>
              <ode/>
            </contact>
            <bounce/>
            <friction>
              <ode/>
            </friction>
          </surface>
        </collision>
        <visual name='row2_block5_lg'>
          <pose frame=''>0.1143 0 0.12238 0 -0 0</pose>
          <geometry>
            <box>
              <size>0.0762 0.0762 0.0762</size>
            </box>
          </geometry>
        </visual>
        <collision name='row2_block5_lg'>
          <pose frame=''>0.1143 0 0.12238 0 -0 0</pose>
          <geometry>
            <box>
              <size>0.0762 0.0762 0.0762</size>
            </box>
          </geometry>
          <max_contacts>10</max_contacts>
          <surface>
            <contact>
              <ode/>
            </contact>
            <bounce/>
            <friction>
              <ode/>
            </friction>
          </surface>
        </collision>
        <visual name='row2_block6_sm'>
          <pose frame=''>0 0 0.09698 0 -0 0</pose>
          <geometry>
            <box>
              <size>0.0762 0.0762 0.0254</size>
            </box>
          </geometry>
        </visual>
        <collision name='row2_block6_sm'>
          <pose frame=''>0 0 0.09698 0 -0 0</pose>
          <geometry>
            <box>
              <size>0.0762 0.0762 0.0254</size>
            </box>
          </geometry>
          <max_contacts>10</max_contacts>
          <surface>
            <contact>
              <ode/>
            </contact>
            <bounce/>
            <friction>
              <ode/>
            </friction>
          </surface>
        </collision>
        <visual name='row2_block7_md'>
          <pose frame=''>-0.1143 0 0.10968 0 -0 0</pose>
          <geometry>
            <box>
              <size>0.0762 0.0762 0.0508</size>
            </box>
          </geometry>
        </visual>
        <collision name='row2_block7_md'>
          <pose frame=''>-0.1143 0 0.10968 0 -0 0</pose>
          <geometry>
            <box>
              <size>0.0762 0.0762 0.0508</size>
            </box>
          </geometry>
          <max_contacts>10</max_contacts>
          <surface>
            <contact>
              <ode/>
            </contact>
            <bounce/>
            <friction>
              <ode/>
            </friction>
          </surface>
        </collision>
        <visual name='row2_block8_lg'>
          <pose frame=''>-0.2286 0 0.12238 0 -0 0</pose>
          <geometry>
            <box>
              <size>0.0762 0.0762 0.0762</size>
            </box>
          </geometry>
        </visual>
        <collision name='row2_block8_lg'>
          <pose frame=''>-0.2286 0 0.12238 0 -0 0</pose>
          <geometry>
            <box>
              <size>0.0762 0.0762 0.0762</size>
            </box>
          </geometry>
          <max_contacts>10</max_contacts>
          <surface>
            <contact>
              <ode/>
            </contact>
            <bounce/>
            <friction>
              <ode/>
            </friction>
          </surface>
        </collision>
        <visual name='row2_block9_sm'>
          <pose frame=''>-0.3429 0 0.09698 0 -0 0</pose>
          <geometry>
            <box>
              <size>0.0762 0.0762 0.0254</size>
            </box>
          </geometry>
        </visual>
        <collision name='row2_block9_sm'>
          <pose frame=''>-0.3429 0 0.09698 0 -0 0</pose>
          <geometry>
            <box>
              <size>0.0762 0.0762 0.0254</size>
            </box>
          </geometry>
          <max_contacts>10</max_contacts>
          <surface>
            <contact>
              <ode/>
            </contact>
            <bounce/>
            <friction>
              <ode/>
            </friction>
          </surface>
        </collision>
        <visual name='row2_block10_lg'>
          <pose frame=''>-0.4572 0 0.12238 0 -0 0</pose>
          <geometry>
            <box>
              <size>0.0762 0.0762 0.0762</size>
            </box>
          </geometry>
        </visual>
        <collision name='row2_block10_lg'>
          <pose frame=''>-0.4572 0 0.12238 0 -0 0</pose>
          <geometry>
            <box>
              <size>0.0762 0.0762 0.0762</size>
            </box>
          </geometry>
          <max_contacts>10</max_contacts>
          <surface>
            <contact>
              <ode/>
            </contact>
            <bounce/>
            <friction>
              <ode/>
            </friction>
          </surface>
        </collision>
        <visual name='row2_block11_md'>
          <pose frame=''>-0.5715 0 0.10968 0 -0 0</pose>
          <geometry>
            <box>
              <size>0.0762 0.0762 0.0508</size>
            </box>
          </geometry>
        </visual>
        <collision name='row2_block11_md'>
          <pose frame=''>-0.5715 0 0.10968 0 -0 0</pose>
          <geometry>
            <box>
              <size>0.0762 0.0762 0.0508</size>
            </box>
          </geometry>
          <max_contacts>10</max_contacts>
          <surface>
            <contact>
              <ode/>
            </contact>
            <bounce/>
            <friction>
              <ode/>
            </friction>
          </surface>
        </collision>
        <visual name='row3_block1_lg'>
          <pose frame=''>0.51435 -0.1143 0.12238 0 -0 0</pose>
          <geometry>
            <box>
              <size>0.0762 0.0762 0.0762</size>
            </box>
          </geometry>
        </visual>
        <collision name='row3_block1_lg'>
          <pose frame=''>0.51435 -0.1143 0.12238 0 -0 0</pose>
          <geometry>
            <box>
              <size>0.0762 0.0762 0.0762</size>
            </box>
          </geometry>
          <max_contacts>10</max_contacts>
          <surface>
            <contact>
              <ode/>
            </contact>
            <bounce/>
            <friction>
              <ode/>
            </friction>
          </surface>
        </collision>
        <visual name='row3_block2_md'>
          <pose frame=''>0.40005 -0.1143 0.10968 0 -0 0</pose>
          <geometry>
            <box>
              <size>0.0762 0.0762 0.0508</size>
            </box>
          </geometry>
        </visual>
        <collision name='row3_block2_md'>
          <pose frame=''>0.40005 -0.1143 0.10968 0 -0 0</pose>
          <geometry>
            <box>
              <size>0.0762 0.0762 0.0508</size>
            </box>
          </geometry>
          <max_contacts>10</max_contacts>
          <surface>
            <contact>
              <ode/>
            </contact>
            <bounce/>
            <friction>
              <ode/>
            </friction>
          </surface>
        </collision>
        <visual name='row3_block3_lg'>
          <pose frame=''>0.28575 -0.1143 0.12238 0 -0 0</pose>
          <geometry>
            <box>
              <size>0.0762 0.0762 0.0762</size>
            </box>
          </geometry>
        </visual>
        <collision name='row3_block3_lg'>
          <pose frame=''>0.28575 -0.1143 0.12238 0 -0 0</pose>
          <geometry>
            <box>
              <size>0.0762 0.0762 0.0762</size>
            </box>
          </geometry>
          <max_contacts>10</max_contacts>
          <surface>
            <contact>
              <ode/>
            </contact>
            <bounce/>
            <friction>
              <ode/>
            </friction>
          </surface>
        </collision>
        <visual name='row3_block4_sm'>
          <pose frame=''>0.17145 -0.1143 0.09698 0 -0 0</pose>
          <geometry>
            <box>
              <size>0.0762 0.0762 0.0254</size>
            </box>
          </geometry>
        </visual>
        <collision name='row3_block4_sm'>
          <pose frame=''>0.17145 -0.1143 0.09698 0 -0 0</pose>
          <geometry>
            <box>
              <size>0.0762 0.0762 0.0254</size>
            </box>
          </geometry>
          <max_contacts>10</max_contacts>
          <surface>
            <contact>
              <ode/>
            </contact>
            <bounce/>
            <friction>
              <ode/>
            </friction>
          </surface>
        </collision>
        <visual name='row3_block5_md'>
          <pose frame=''>0.05715 -0.1143 0.10968 0 -0 0</pose>
          <geometry>
            <box>
              <size>0.0762 0.0762 0.0508</size>
            </box>
          </geometry>
        </visual>
        <collision name='row3_block5_md'>
          <pose frame=''>0.05715 -0.1143 0.10968 0 -0 0</pose>
          <geometry>
            <box>
              <size>0.0762 0.0762 0.0508</size>
            </box>
          </geometry>
          <max_contacts>10</max_contacts>
          <surface>
            <contact>
              <ode/>
            </contact>
            <bounce/>
            <friction>
              <ode/>
            </friction>
          </surface>
        </collision>
        <visual name='row3_block6_md'>
          <pose frame=''>-0.05715 -0.1143 0.10968 0 -0 0</pose>
          <geometry>
            <box>
              <size>0.0762 0.0762 0.0508</size>
            </box>
          </geometry>
        </visual>
        <collision name='row3_block6_md'>
          <pose frame=''>-0.05715 -0.1143 0.10968 0 -0 0</pose>
          <geometry>
            <box>
              <size>0.0762 0.0762 0.0508</size>
            </box>
          </geometry>
          <max_contacts>10</max_contacts>
          <surface>
            <contact>
              <ode/>
            </contact>
            <bounce/>
            <friction>
              <ode/>
            </friction>
          </surface>
        </collision>
        <visual name='row3_block7_lg'>
          <pose frame=''>-0.17145 -0.1143 0.12238 0 -0 0</pose>
          <geometry>
            <box>
              <size>0.0762 0.0762 0.0762</size>
            </box>
          </geometry>
        </visual>
        <collision name='row3_block7_lg'>
          <pose frame=''>-0.17145 -0.1143 0.12238 0 -0 0</pose>
          <geometry>
            <box>
              <size>0.0762 0.0762 0.0762</size>
            </box>
          </geometry>
          <max_contacts>10</max_contacts>
          <surface>
            <contact>
              <ode/>
            </contact>
            <bounce/>
            <friction>
              <ode/>
            </friction>
          </surface>
        </collision>
        <visual name='row3_block8_sm'>
          <pose frame=''>-0.28575 -0.1143 0.09698 0 -0 0</pose>
          <geometry>
            <box>
              <size>0.0762 0.0762 0.0254</size>
            </box>
          </geometry>
        </visual>
        <collision name='row3_block8_sm'>
          <pose frame=''>-0.28575 -0.1143 0.09698 0 -0 0</pose>
          <geometry>
            <box>
              <size>0.0762 0.0762 0.0254</size>
            </box>
          </geometry>
          <max_contacts>10</max_contacts>
          <surface>
            <contact>
              <ode/>
            </contact>
            <bounce/>
            <friction>
              <ode/>
            </friction>
          </surface>
        </collision>
        <visual name='row3_block9_md'>
          <pose frame=''>-0.40005 -0.1143 0.10968 0 -0 0</pose>
          <geometry>
            <box>
              <size>0.0762 0.0762 0.0508</size>
            </box>
          </geometry>
        </visual>
        <collision name='row3_block9_md'>
          <pose frame=''>-0.40005 -0.1143 0.10968 0 -0 0</pose>
          <geometry>
            <box>
              <size>0.0762 0.0762 0.0508</size>
            </box>
          </geometry>
          <max_contacts>10</max_contacts>
          <surface>
            <contact>
              <ode/>
            </contact>
            <bounce/>
            <friction>
              <ode/>
            </friction>
          </surface>
        </collision>
        <visual name='row3_block10_sm'>
          <pose frame=''>-0.51435 -0.1143 0.09698 0 -0 0</pose>
          <geometry>
            <box>
              <size>0.0762 0.0762 0.0254</size>
            </box>
          </geometry>
        </visual>
        <collision name='row3_block10_sm'>
          <pose frame=''>-0.51435 -0.1143 0.09698 0 -0 0</pose>
          <geometry>
            <box>
              <size>0.0762 0.0762 0.0254</size>
            </box>
          </geometry>
          <max_contacts>10</max_contacts>
          <surface>
            <contact>
              <ode/>
            </contact>
            <bounce/>
            <friction>
              <ode/>
            </friction>
          </surface>
        </collision>
        <self_collide>0</self_collide>
        <kinematic>0</kinematic>
        <gravity>1</gravity>
      </link>
      <pose frame=''>3 1 0 0 -0 0</pose>
    </model>
    <model name='frc2016_field'>
      <static>1</static>
      <link name='walls'>
        <visual name='walls_visual'>
          <geometry>
            <mesh>
              <uri>model://frc2016_field/meshes/walls.dae</uri>
            </mesh>
          </geometry>
        </visual>
        <collision name='front_turret'>
          <geometry>
            <mesh>
              <uri>model://frc2016_field/meshes/turret_collide.dae</uri>
            </mesh>
          </geometry>
          <max_contacts>10</max_contacts>
          <surface>
            <contact>
              <ode/>
            </contact>
            <bounce/>
            <friction>
              <ode/>
            </friction>
          </surface>
        </collision>
        <collision name='back_turret'>
          <pose frame=''>0 0 0 0 -0 3.1415</pose>
          <geometry>
            <mesh>
              <uri>model://frc2016_field/meshes/turret_collide.dae</uri>
            </mesh>
          </geometry>
          <max_contacts>10</max_contacts>
          <surface>
            <contact>
              <ode/>
            </contact>
            <bounce/>
            <friction>
              <ode/>
            </friction>
          </surface>
        </collision>
        <collision name='left_wall'>
          <pose frame=''>4.09997 0 0.2413 0 -0 0</pose>
          <geometry>
            <box>
              <size>0.1 16.4592 0.4826</size>
            </box>
          </geometry>
          <max_contacts>10</max_contacts>
          <surface>
            <contact>
              <ode/>
            </contact>
            <bounce/>
            <friction>
              <ode/>
            </friction>
          </surface>
        </collision>
        <collision name='right_wall'>
          <pose frame=''>-4.09997 0 0.2413 0 -0 0</pose>
          <geometry>
            <box>
              <size>0.1 16.4592 0.4826</size>
            </box>
          </geometry>
          <max_contacts>10</max_contacts>
          <surface>
            <contact>
              <ode/>
            </contact>
            <bounce/>
            <friction>
              <ode/>
            </friction>
          </surface>
        </collision>
        <collision name='front_solid_wall'>
          <pose frame=''>-2.2105 8.2196 1 0 -0 0</pose>
          <geometry>
            <box>
              <size>3.8 0.1 2</size>
            </box>
          </geometry>
          <max_contacts>10</max_contacts>
          <surface>
            <contact>
              <ode/>
            </contact>
            <bounce/>
            <friction>
              <ode/>
            </friction>
          </surface>
        </collision>
        <collision name='back_solid_wall'>
          <pose frame=''>2.2105 -8.2196 1 0 -0 0</pose>
          <geometry>
            <box>
              <size>3.8 0.1 2</size>
            </box>
          </geometry>
          <max_contacts>10</max_contacts>
          <surface>
            <contact>
              <ode/>
            </contact>
            <bounce/>
            <friction>
              <ode/>
            </friction>
          </surface>
        </collision>
        <collision name='front_partial_wall'>
          <pose frame=''>1.85 8.2196 1 0 -0 0</pose>
          <geometry>
            <box>
              <size>2.1 0.1 2</size>
            </box>
          </geometry>
          <max_contacts>10</max_contacts>
          <surface>
            <contact>
              <ode/>
            </contact>
            <bounce/>
            <friction>
              <ode/>
            </friction>
          </surface>
        </collision>
        <collision name='front_partial_wall_mid'>
          <pose frame=''>3.4 8.2196 0.86 0 -0 0</pose>
          <geometry>
            <box>
              <size>1.25 0.1 1.12</size>
            </box>
          </geometry>
          <max_contacts>10</max_contacts>
          <surface>
            <contact>
              <ode/>
            </contact>
            <bounce/>
            <friction>
              <ode/>
            </friction>
          </surface>
        </collision>
        <collision name='front_partial_wall_lower_left'>
          <pose frame=''>3.36 8.2196 0.25 0 -0 0</pose>
          <geometry>
            <box>
              <size>0.3 0.1 0.5</size>
            </box>
          </geometry>
          <max_contacts>10</max_contacts>
          <surface>
            <contact>
              <ode/>
            </contact>
            <bounce/>
            <friction>
              <ode/>
            </friction>
          </surface>
        </collision>
        <collision name='front_partial_wall_lower_right'>
          <pose frame=''>4 8.2196 0.25 0 -0 0</pose>
          <geometry>
            <box>
              <size>0.3 0.1 0.5</size>
            </box>
          </geometry>
          <max_contacts>10</max_contacts>
          <surface>
            <contact>
              <ode/>
            </contact>
            <bounce/>
            <friction>
              <ode/>
            </friction>
          </surface>
        </collision>
        <collision name='front_partial_wall_upper_right'>
          <pose frame=''>3.76 8.2196 1.7 0 -0 0</pose>
          <geometry>
            <box>
              <size>0.54 0.1 0.6</size>
            </box>
          </geometry>
          <max_contacts>10</max_contacts>
          <surface>
            <contact>
              <ode/>
            </contact>
            <bounce/>
            <friction>
              <ode/>
            </friction>
          </surface>
        </collision>
        <collision name='front_partial_wall_upper_left'>
          <pose frame=''>2.95 8.2196 1.7 0 -0 0</pose>
          <geometry>
            <box>
              <size>0.54 0.1 0.6</size>
            </box>
          </geometry>
          <max_contacts>10</max_contacts>
          <surface>
            <contact>
              <ode/>
            </contact>
            <bounce/>
            <friction>
              <ode/>
            </friction>
          </surface>
        </collision>
        <collision name='front_partial_wall_upper_mid'>
          <pose frame=''>3.36 8.2196 1.84 0 -0 0</pose>
          <geometry>
            <box>
              <size>0.3 0.1 0.3</size>
            </box>
          </geometry>
          <max_contacts>10</max_contacts>
          <surface>
            <contact>
              <ode/>
            </contact>
            <bounce/>
            <friction>
              <ode/>
            </friction>
          </surface>
        </collision>
        <collision name='back_partial_wall'>
          <pose frame=''>-1.85 -8.2196 1 0 -0 0</pose>
          <geometry>
            <box>
              <size>2.1 0.1 2</size>
            </box>
          </geometry>
          <max_contacts>10</max_contacts>
          <surface>
            <contact>
              <ode/>
            </contact>
            <bounce/>
            <friction>
              <ode/>
            </friction>
          </surface>
        </collision>
        <collision name='back_partial_wall_mid'>
          <pose frame=''>-3.4 -8.2196 0.86 0 -0 0</pose>
          <geometry>
            <box>
              <size>1.25 0.1 1.12</size>
            </box>
          </geometry>
          <max_contacts>10</max_contacts>
          <surface>
            <contact>
              <ode/>
            </contact>
            <bounce/>
            <friction>
              <ode/>
            </friction>
          </surface>
        </collision>
        <collision name='back_partial_wall_lower_left'>
          <pose frame=''>-3.36 -8.2196 0.25 0 -0 0</pose>
          <geometry>
            <box>
              <size>0.3 0.1 0.5</size>
            </box>
          </geometry>
          <max_contacts>10</max_contacts>
          <surface>
            <contact>
              <ode/>
            </contact>
            <bounce/>
            <friction>
              <ode/>
            </friction>
          </surface>
        </collision>
        <collision name='back_partial_wall_lower_right'>
          <pose frame=''>-4 -8.2196 0.25 0 -0 0</pose>
          <geometry>
            <box>
              <size>0.3 0.1 0.5</size>
            </box>
          </geometry>
          <max_contacts>10</max_contacts>
          <surface>
            <contact>
              <ode/>
            </contact>
            <bounce/>
            <friction>
              <ode/>
            </friction>
          </surface>
        </collision>
        <collision name='back_partial_wall_upper_right'>
          <pose frame=''>-3.76 -8.2196 1.7 0 -0 0</pose>
          <geometry>
            <box>
              <size>0.54 0.1 0.6</size>
            </box>
          </geometry>
          <max_contacts>10</max_contacts>
          <surface>
            <contact>
              <ode/>
            </contact>
            <bounce/>
            <friction>
              <ode/>
            </friction>
          </surface>
        </collision>
        <collision name='back_partial_wall_upper_left'>
          <pose frame=''>-2.95 -8.2196 1.7 0 -0 0</pose>
          <geometry>
            <box>
              <size>0.54 0.1 0.6</size>
            </box>
          </geometry>
          <max_contacts>10</max_contacts>
          <surface>
            <contact>
              <ode/>
            </contact>
            <bounce/>
            <friction>
              <ode/>
            </friction>
          </surface>
        </collision>
        <collision name='back_partial_wall_upper_mid'>
          <pose frame=''>-3.36 -8.2196 1.84 0 -0 0</pose>
          <geometry>
            <box>
              <size>0.3 0.1 0.3</size>
            </box>
          </geometry>
          <max_contacts>10</max_contacts>
          <surface>
            <contact>
              <ode/>
            </contact>
            <bounce/>
            <friction>
              <ode/>
            </friction>
          </surface>
        </collision>
        <visual name='blue_passage_border_long'>
          <pose frame=''>2.72665 4.5882 0.0127 0 -0 0</pose>
          <geometry>
            <box>
              <size>0.0762 7.3025 0.0254</size>
            </box>
          </geometry>
          <material>
            <ambient>0 0 1 1</ambient>
            <diffuse>0 0 1 1</diffuse>
          </material>
        </visual>
        <collision name='blue_passage_border_long'>
          <pose frame=''>2.72665 4.5882 0.0127 0 -0 0</pose>
          <geometry>
            <box>
              <size>0.0762 7.3025 0.0254</size>
            </box>
          </geometry>
          <max_contacts>10</max_contacts>
          <surface>
            <contact>
              <ode/>
            </contact>
            <bounce/>
            <friction>
              <ode/>
            </friction>
          </surface>
        </collision>
        <visual name='blue_passage_border_short'>
          <pose frame=''>3.37435 0.97352 0.0127 0 -0 0</pose>
          <geometry>
            <box>
              <size>1.37165 0.0762 0.0254</size>
            </box>
          </geometry>
          <material>
            <ambient>0 0 1 1</ambient>
            <diffuse>0 0 1 1</diffuse>
          </material>
        </visual>
        <collision name='blue_passage_border_short'>
          <pose frame=''>3.37435 0.97352 0.0127 0 -0 0</pose>
          <geometry>
            <box>
              <size>1.37165 0.0762 0.0254</size>
            </box>
          </geometry>
          <max_contacts>10</max_contacts>
          <surface>
            <contact>
              <ode/>
            </contact>
            <bounce/>
            <friction>
              <ode/>
            </friction>
          </surface>
        </collision>
        <visual name='blue_divider_1'>
          <pose frame=''>2.63052 2.80648 0.31114 0 -0 0</pose>
          <geometry>
            <box>
              <size>0.009525 1.2192 0.6096</size>
            </box>
          </geometry>
        </visual>
        <collision name='blue_divider_1'>
          <pose frame=''>2.63052 2.80648 0.31114 0 -0 0</pose>
          <geometry>
            <box>
              <size>0.009525 1.2192 0.6096</size>
            </box>
          </geometry>
          <max_contacts>10</max_contacts>
          <surface>
            <contact>
              <ode/>
            </contact>
            <bounce/>
            <friction>
              <ode/>
            </friction>
          </surface>
        </collision>
        <visual name='blue_divider_2'>
          <pose frame=''>1.28432 2.80648 0.31114 0 -0 0</pose>
          <geometry>
            <box>
              <size>0.009525 1.2192 0.6096</size>
            </box>
          </geometry>
        </visual>
        <collision name='blue_divider_2'>
          <pose frame=''>1.28432 2.80648 0.31114 0 -0 0</pose>
          <geometry>
            <box>
              <size>0.009525 1.2192 0.6096</size>
            </box>
          </geometry>
          <max_contacts>10</max_contacts>
          <surface>
            <contact>
              <ode/>
            </contact>
            <bounce/>
            <friction>
              <ode/>
            </friction>
          </surface>
        </collision>
        <visual name='blue_divider_3'>
          <pose frame=''>-0.06189 2.80648 0.31114 0 -0 0</pose>
          <geometry>
            <box>
              <size>0.009525 1.2192 0.6096</size>
            </box>
          </geometry>
        </visual>
        <collision name='blue_divider_3'>
          <pose frame=''>-0.06189 2.80648 0.31114 0 -0 0</pose>
          <geometry>
            <box>
              <size>0.009525 1.2192 0.6096</size>
            </box>
          </geometry>
          <max_contacts>10</max_contacts>
          <surface>
            <contact>
              <ode/>
            </contact>
            <bounce/>
            <friction>
              <ode/>
            </friction>
          </surface>
        </collision>
        <visual name='blue_divider_4'>
          <pose frame=''>-1.40809 2.80648 0.31114 0 -0 0</pose>
          <geometry>
            <box>
              <size>0.009525 1.2192 0.6096</size>
            </box>
          </geometry>
        </visual>
        <collision name='blue_divider_4'>
          <pose frame=''>-1.40809 2.80648 0.31114 0 -0 0</pose>
          <geometry>
            <box>
              <size>0.009525 1.2192 0.6096</size>
            </box>
          </geometry>
          <max_contacts>10</max_contacts>
          <surface>
            <contact>
              <ode/>
            </contact>
            <bounce/>
            <friction>
              <ode/>
            </friction>
          </surface>
        </collision>
        <visual name='blue_divider_5'>
          <pose frame=''>-2.75428 2.80648 0.31114 0 -0 0</pose>
          <geometry>
            <box>
              <size>0.009525 1.2192 0.6096</size>
            </box>
          </geometry>
        </visual>
        <collision name='blue_divider_5'>
          <pose frame=''>-2.75428 2.80648 0.31114 0 -0 0</pose>
          <geometry>
            <box>
              <size>0.009525 1.2192 0.6096</size>
            </box>
          </geometry>
          <max_contacts>10</max_contacts>
          <surface>
            <contact>
              <ode/>
            </contact>
            <bounce/>
            <friction>
              <ode/>
            </friction>
          </surface>
        </collision>
        <visual name='blue_barrier_ramp_up'>
          <pose frame=''>-0.7334 3.22301 0.05063 -0.248866 0 0</pose>
          <geometry>
            <box>
              <size>6.71817 0.3048 0.00635</size>
            </box>
          </geometry>
        </visual>
        <collision name='blue_barrier_ramp_up'>
          <pose frame=''>-0.7334 3.22301 0.05063 -0.248866 0 0</pose>
          <geometry>
            <box>
              <size>6.71817 0.3048 0.00635</size>
            </box>
          </geometry>
          <max_contacts>10</max_contacts>
          <surface>
            <contact>
              <ode/>
            </contact>
            <bounce/>
            <friction>
              <ode/>
            </friction>
          </surface>
        </collision>
        <visual name='blue_barrier_ramp_down'>
          <pose frame=''>-0.7334 2.31802 0.05063 0.248866 -0 0</pose>
          <geometry>
            <box>
              <size>6.71817 0.3048 0.00635</size>
            </box>
          </geometry>
        </visual>
        <collision name='blue_barrier_ramp_down'>
          <pose frame=''>-0.7334 2.31802 0.05063 0.248866 -0 0</pose>
          <geometry>
            <box>
              <size>6.71817 0.3048 0.00635</size>
            </box>
          </geometry>
          <max_contacts>10</max_contacts>
          <surface>
            <contact>
              <ode/>
            </contact>
            <bounce/>
            <friction>
              <ode/>
            </friction>
          </surface>
        </collision>
        <visual name='red_passage_border_long'>
          <pose frame=''>-2.7273 -4.58839 0.0127 0 -0 0</pose>
          <geometry>
            <box>
              <size>0.0762 7.3025 0.0254</size>
            </box>
          </geometry>
          <material>
            <ambient>1 0 0 1</ambient>
            <diffuse>1 0 0 1</diffuse>
          </material>
        </visual>
        <collision name='red_passage_border_long'>
          <pose frame=''>-2.7273 -4.58839 0.0127 0 -0 0</pose>
          <geometry>
            <box>
              <size>0.0762 7.3025 0.0254</size>
            </box>
          </geometry>
          <max_contacts>10</max_contacts>
          <surface>
            <contact>
              <ode/>
            </contact>
            <bounce/>
            <friction>
              <ode/>
            </friction>
          </surface>
        </collision>
        <visual name='red_passage_border_short'>
          <pose frame=''>-3.375 -0.97372 0.0127 0 -0 0</pose>
          <geometry>
            <box>
              <size>1.37165 0.0762 0.0254</size>
            </box>
          </geometry>
          <material>
            <ambient>1 0 0 1</ambient>
            <diffuse>1 0 0 1</diffuse>
          </material>
        </visual>
        <collision name='red_passage_border_short'>
          <pose frame=''>-3.375 -0.97372 0.0127 0 -0 0</pose>
          <geometry>
            <box>
              <size>1.37165 0.0762 0.0254</size>
            </box>
          </geometry>
          <max_contacts>10</max_contacts>
          <surface>
            <contact>
              <ode/>
            </contact>
            <bounce/>
            <friction>
              <ode/>
            </friction>
          </surface>
        </collision>
        <visual name='red_divider_1'>
          <pose frame=''>-2.63117 -2.76442 0.31114 0 -0 0</pose>
          <geometry>
            <box>
              <size>0.009525 1.2192 0.6096</size>
            </box>
          </geometry>
        </visual>
        <collision name='red_divider_1'>
          <pose frame=''>-2.63117 -2.72845 0.31114 0 -0 0</pose>
          <geometry>
            <box>
              <size>0.009525 1.2192 0.6096</size>
            </box>
          </geometry>
          <max_contacts>10</max_contacts>
          <surface>
            <contact>
              <ode/>
            </contact>
            <bounce/>
            <friction>
              <ode/>
            </friction>
          </surface>
        </collision>
        <visual name='red_divider_2'>
          <pose frame=''>-1.28496 -2.76442 0.31114 0 -0 0</pose>
          <geometry>
            <box>
              <size>0.009525 1.2192 0.6096</size>
            </box>
          </geometry>
        </visual>
        <collision name='red_divider_2'>
          <pose frame=''>-1.28496 -2.76442 0.31114 0 -0 0</pose>
          <geometry>
            <box>
              <size>0.009525 1.2192 0.6096</size>
            </box>
          </geometry>
          <max_contacts>10</max_contacts>
          <surface>
            <contact>
              <ode/>
            </contact>
            <bounce/>
            <friction>
              <ode/>
            </friction>
          </surface>
        </collision>
        <visual name='red_divider_3'>
          <pose frame=''>0.06124 -2.76442 0.31114 0 -0 0</pose>
          <geometry>
            <box>
              <size>0.009525 1.2192 0.6096</size>
            </box>
          </geometry>
        </visual>
        <collision name='red_divider_3'>
          <pose frame=''>0.06124 -2.76442 0.31114 0 -0 0</pose>
          <geometry>
            <box>
              <size>0.009525 1.2192 0.6096</size>
            </box>
          </geometry>
          <max_contacts>10</max_contacts>
          <surface>
            <contact>
              <ode/>
            </contact>
            <bounce/>
            <friction>
              <ode/>
            </friction>
          </surface>
        </collision>
        <visual name='red_divider_4'>
          <pose frame=''>1.40744 -2.76442 0.31114 0 -0 0</pose>
          <geometry>
            <box>
              <size>0.009525 1.2192 0.6096</size>
            </box>
          </geometry>
        </visual>
        <collision name='red_divider_4'>
          <pose frame=''>1.40744 -2.76442 0.31114 0 -0 0</pose>
          <geometry>
            <box>
              <size>0.009525 1.2192 0.6096</size>
            </box>
          </geometry>
          <max_contacts>10</max_contacts>
          <surface>
            <contact>
              <ode/>
            </contact>
            <bounce/>
            <friction>
              <ode/>
            </friction>
          </surface>
        </collision>
        <visual name='red_divider_5'>
          <pose frame=''>2.75363 -2.76442 0.31114 0 -0 0</pose>
          <geometry>
            <box>
              <size>0.009525 1.2192 0.6096</size>
            </box>
          </geometry>
        </visual>
        <collision name='red_divider_5'>
          <pose frame=''>2.75363 -2.76442 0.31114 0 -0 0</pose>
          <geometry>
            <box>
              <size>0.009525 1.2192 0.6096</size>
            </box>
          </geometry>
          <max_contacts>10</max_contacts>
          <surface>
            <contact>
              <ode/>
            </contact>
            <bounce/>
            <friction>
              <ode/>
            </friction>
          </surface>
        </collision>
        <visual name='red_barrier_ramp_down'>
          <pose frame=''>0.73275 -2.31261 0.05063 -0.248866 0 0</pose>
          <geometry>
            <box>
              <size>6.71817 0.3048 0.00635</size>
            </box>
          </geometry>
        </visual>
        <collision name='red_barrier_ramp_down'>
          <pose frame=''>0.73275 -2.31261 0.05063 -0.248866 0 0</pose>
          <geometry>
            <box>
              <size>6.71817 0.3048 0.00635</size>
            </box>
          </geometry>
          <max_contacts>10</max_contacts>
          <surface>
            <contact>
              <ode/>
            </contact>
            <bounce/>
            <friction>
              <ode/>
            </friction>
          </surface>
        </collision>
        <visual name='red_barrier_ramp_up'>
          <pose frame=''>0.73275 -3.21691 0.05063 0.248866 -0 0</pose>
          <geometry>
            <box>
              <size>6.71817 0.3048 0.00635</size>
            </box>
          </geometry>
        </visual>
        <collision name='red_barrier_ramp_up'>
          <pose frame=''>0.73275 -3.21691 0.05063 0.248866 -0 0</pose>
          <geometry>
            <box>
              <size>6.71817 0.3048 0.00635</size>
            </box>
          </geometry>
          <max_contacts>10</max_contacts>
          <surface>
            <contact>
              <ode/>
            </contact>
            <bounce/>
            <friction>
              <ode/>
            </friction>
          </surface>
        </collision>
        <self_collide>0</self_collide>
        <kinematic>0</kinematic>
        <gravity>1</gravity>
      </link>
      <pose frame=''>0 0 0 0 -0 0</pose>
    </model>
    <model name='frc2016_ramparts'>
      <static>1</static>
      <link name='link'>
        <visual name='platform'>
          <pose frame=''>0 0 0.06967 0 -0 0</pose>
          <geometry>
            <box>
              <size>1.27 0.5969 0.003175</size>
            </box>
          </geometry>
        </visual>
        <collision name='platform'>
          <pose frame=''>0 0 0.06967 0 -0 0</pose>
          <geometry>
            <box>
              <size>1.27 0.5969 0.003175</size>
            </box>
          </geometry>
          <max_contacts>10</max_contacts>
          <surface>
            <contact>
              <ode/>
            </contact>
            <bounce/>
            <friction>
              <ode/>
            </friction>
          </surface>
        </collision>
        <visual name='ramp1'>
          <pose frame=''>0.30472 0.00588 0.1109 -0.13 0 0</pose>
          <geometry>
            <box>
              <size>0.60957 0.588891 0.00462</size>
            </box>
          </geometry>
          <material>
            <ambient>0.2 0.2 0.2 1</ambient>
            <diffuse>0.2 0.2 0.2 1</diffuse>
          </material>
        </visual>
        <collision name='ramp1'>
          <pose frame=''>0.30472 0.00588 0.1109 -0.13 0 0</pose>
          <geometry>
            <box>
              <size>0.60957 0.588891 0.00462</size>
            </box>
          </geometry>
          <max_contacts>10</max_contacts>
          <surface>
            <contact>
              <ode/>
            </contact>
            <bounce/>
            <friction>
              <ode/>
            </friction>
          </surface>
        </collision>
        <visual name='up1'>
          <pose frame=''>0.30472 -0.28806 0.11072 0 -0 0</pose>
          <geometry>
            <box>
              <size>0.60957 0.00462 0.07872</size>
            </box>
          </geometry>
          <material>
            <ambient>0.2 0.2 0.2 1</ambient>
            <diffuse>0.2 0.2 0.2 1</diffuse>
          </material>
        </visual>
        <collision name='up1'>
          <pose frame=''>0.30472 -0.28806 0.11072 0 -0 0</pose>
          <geometry>
            <box>
              <size>0.60957 0.00462 0.07872</size>
            </box>
          </geometry>
          <max_contacts>10</max_contacts>
          <surface>
            <contact>
              <ode/>
            </contact>
            <bounce/>
            <friction>
              <ode/>
            </friction>
          </surface>
        </collision>
        <visual name='ramp2'>
          <pose frame=''>-0.30472 -0.00619 0.1109 0.13 -0 0</pose>
          <geometry>
            <box>
              <size>0.60957 0.588891 0.00462</size>
            </box>
          </geometry>
          <material>
            <ambient>0.2 0.2 0.2 1</ambient>
            <diffuse>0.2 0.2 0.2 1</diffuse>
          </material>
        </visual>
        <collision name='ramp2'>
          <pose frame=''>-0.30472 -0.00619 0.1109 0.13 -0 0</pose>
          <geometry>
            <box>
              <size>0.60957 0.588891 0.00462</size>
            </box>
          </geometry>
          <max_contacts>10</max_contacts>
          <surface>
            <contact>
              <ode/>
            </contact>
            <bounce/>
            <friction>
              <ode/>
            </friction>
          </surface>
        </collision>
        <visual name='up2'>
          <pose frame=''>-0.30472 0.28806 0.11072 0 -0 0</pose>
          <geometry>
            <box>
              <size>0.60957 0.00462 0.07872</size>
            </box>
          </geometry>
          <material>
            <ambient>0.2 0.2 0.2 1</ambient>
            <diffuse>0.2 0.2 0.2 1</diffuse>
          </material>
        </visual>
        <collision name='up2'>
          <pose frame=''>-0.30472 0.28806 0.11072 0 -0 0</pose>
          <geometry>
            <box>
              <size>0.60957 0.00462 0.07872</size>
            </box>
          </geometry>
          <max_contacts>10</max_contacts>
          <surface>
            <contact>
              <ode/>
            </contact>
            <bounce/>
            <friction>
              <ode/>
            </friction>
          </surface>
        </collision>
        <self_collide>0</self_collide>
        <kinematic>0</kinematic>
        <gravity>1</gravity>
      </link>
      <pose frame=''>-2.431 3 0 0 -0 0</pose>
    </model>
    <state world_name='default'>
      <sim_time>1588 170000000</sim_time>
      <real_time>99 945533251</real_time>
      <wall_time>1453746821 325785459</wall_time>
      <iterations>51686</iterations>
      <model name='Tank8Wedge'>
        <pose frame=''>0.936283 -1.04951 0.061073 -1.9e-05 -0.000305 1.49671</pose>
        <link name='Chassis'>
          <pose frame=''>0.65242 -0.673165 0.107162 1.57049 1.9e-05 3.06751</pose>
          <velocity>-4e-05 -7.7e-05 -0.001122 -0.00086 0.002574 -4.7e-05</velocity>
          <acceleration>0.204506 0.026945 -6.36916 -0.63282 0.719058 -0.456055</acceleration>
          <wrench>4.70924 0.620483 -146.665 0 -0 0</wrench>
        </link>
        <link name='L1Wheel'>
          <pose frame=''>0.982958 -0.989379 0.112881 0.71203 1.9e-05 3.06751</pose>
          <velocity>-3.8e-05 -8.7e-05 -0.001699 -0.00086 0.002567 -4.5e-05</velocity>
          <acceleration>0.156547 -0.11784 -11.2574 2.1939 -0.363727 2.68178</acceleration>
          <wrench>0.207055 -0.15586 -14.8895 0 -0 0</wrench>
        </link>
        <link name='L2Wheel'>
          <pose frame=''>0.99828 -0.782932 0.097068 -2.83442 -5e-06 3.06752</pose>
          <velocity>0.000113 -8.5e-05 -0.001726 -0.001307 -0.003454 -0.000522</velocity>
          <acceleration>0.447434 -0.112269 -11.4847 -1.16339 0.162066 -1.60021</acceleration>
          <wrench>0.591794 -0.148491 -15.1901 0 -0 0</wrench>
        </link>
        <link name='L3Wheel'>
          <pose frame=''>1.0136 -0.57649 0.097133 0.678205 -4e-06 3.06751</pose>
          <velocity>9e-05 -7.3e-05 -0.002338 -0.001288 -0.00319 -0.000171</velocity>
          <acceleration>0.409805 -0.088895 -12.6839 -1.0902 0.025377 -0.627868</acceleration>
          <wrench>0.542025 -0.117576 -16.7762 0 -0 0</wrench>
        </link>
        <link name='L4Wheel'>
          <pose frame=''>1.02892 -0.370052 0.11307 0.708165 1.9e-05 3.06751</pose>
          <velocity>-1.8e-05 -9.2e-05 -0.002344 -0.000859 0.002585 -4.7e-05</velocity>
          <acceleration>0.421902 -0.144259 -12.9165 2.24126 -0.405977 2.67631</acceleration>
          <wrench>0.558024 -0.190803 -17.0839 0 -0 0</wrench>
        </link>
        <link name='R1Wheel'>
          <pose frame=''>0.279028 -0.937134 0.112867 -1.72763 1.9e-05 3.06751</pose>
          <velocity>-4.6e-05 -5.5e-05 6.4e-05 -0.000859 0.002585 -5.1e-05</velocity>
          <acceleration>0.152906 0.209328 0.083575 2.2391 -0.404573 2.66762</acceleration>
          <wrench>0.202239 0.276865 0.110539 0 -0 0</wrench>
        </link>
        <link name='R2Wheel'>
          <pose frame=''>0.294352 -0.730686 0.097055 0.801837 8.3e-05 3.06752</pose>
          <velocity>-1.4e-05 -4.6e-05 -0.000146 0.000406 0.000134 -7.6e-05</velocity>
          <acceleration>0.324542 0.181269 -0.445317 1.34887 -0.28701 3.10682</acceleration>
          <wrench>0.429252 0.239753 -0.588994 0 -0 0</wrench>
        </link>
        <link name='R3Wheel'>
          <pose frame=''>0.309673 -0.524244 0.097119 1.94137 1.9e-05 3.06751</pose>
          <velocity>-6.7e-05 -7e-05 -0.000361 -0.000859 0.002577 -4.9e-05</velocity>
          <acceleration>0.088802 0.172958 -1.01842 2.23925 -0.382848 2.66713</acceleration>
          <wrench>0.117453 0.228761 -1.347 0 -0 0</wrench>
        </link>
        <link name='R4Wheel'>
          <pose frame=''>0.324994 -0.317807 0.113057 -1.39413 1.9e-05 3.06751</pose>
          <velocity>-1.5e-05 -5.7e-05 -0.000575 -0.000859 0.002572 -5e-05</velocity>
          <acceleration>0.447217 0.189178 -1.56844 2.23723 -0.372683 2.66536</acceleration>
          <wrench>0.591507 0.250214 -2.07448 0 -0 0</wrench>
        </link>
        <link name='Wedge'>
          <pose frame=''>0.62189 -1.12501 0.215204 1.57049 1.9e-05 3.06751</pose>
          <velocity>0.000205 1.4e-05 -0.000657 -0.000926 0.002466 -4.1e-05</velocity>
          <acceleration>1.71229 0.198951 -5.21892 2.13992 0.721631 -0.292809</acceleration>
          <wrench>3.3629 0.390736 -10.2498 0 -0 0</wrench>
        </link>
      </model>
      <model name='frc2016_chevaldefrise'>
        <pose frame=''>2.01746 -2.69804 -0 0 -0 0</pose>
        <link name='base'>
          <pose frame=''>2.01746 -2.69804 -0 0 -0 0</pose>
          <velocity>0 0 0 0 -0 0</velocity>
          <acceleration>-0 -0 0 0 -0 0</acceleration>
          <wrench>-0 -0 0 0 -0 0</wrench>
        </link>
        <link name='slant1'>
          <pose frame=''>1.56026 -2.68497 0.1997 -0.39732 0 0</pose>
          <velocity>-0 -0 0 0 -0 0</velocity>
          <acceleration>-0 -0 -0 0 -0 0</acceleration>
          <wrench>-0 -0 -0 0 -0 0</wrench>
        </link>
        <link name='slant2'>
          <pose frame=''>1.86506 -2.71111 0.1997 0.39732 -0 0</pose>
          <velocity>-0 -0 0 0 -0 0</velocity>
          <acceleration>-0 0 -0 2e-06 -0 0</acceleration>
          <wrench>-0 0 -0 0 -0 0</wrench>
        </link>
        <link name='slant3'>
          <pose frame=''>2.16986 -2.68497 0.1997 -0.39732 0 0</pose>
          <velocity>-0 -0 0 1e-06 -0 0</velocity>
          <acceleration>-0 -9e-06 -2.1e-05 -0.000233 -0 0</acceleration>
          <wrench>-0 -1.8e-05 -4.3e-05 0 -0 0</wrench>
        </link>
        <link name='slant4'>
          <pose frame=''>2.47466 -2.71111 0.1997 0.39732 -0 0</pose>
          <velocity>-0 -0 0 -0.000101 -0 0</velocity>
          <acceleration>-0 0.000976 -0.002326 0.02522 -0 0</acceleration>
          <wrench>-0 0.001952 -0.004651 0 -0 0</wrench>
        </link>
      </model>
      <model name='frc2016_drawbridge'>
        <pose frame=''>-0.627294 -2.70396 0 0 -1e-06 3.14127</pose>
        <link name='base'>
          <pose frame=''>-0.627294 -2.70396 0 0 -1e-06 3.14127</pose>
          <velocity>-0.000145 0.000324 0.004033 0.002298 -0.003906 -0.0005</velocity>
          <acceleration>-9.05192 -4.42477 7.87834 1.87653 -0.643473 3.06379</acceleration>
          <wrench>-90.5192 -44.2477 78.7834 0 -0 0</wrench>
        </link>
        <link name='bridge'>
          <pose frame=''>-0.627386 -2.98641 0.50577 1e-06 -1e-06 3.14127</pose>
          <velocity>-0.002127 -0.000872 0.003353 0.002645 -0.003984 -0.000321</velocity>
          <acceleration>-0.146436 0.688393 7.85116 1.88431 -0.565495 3.07955</acceleration>
          <wrench>-0.292872 1.37679 15.7023 0 -0 0</wrench>
        </link>
      </model>
      <model name='frc2016_field'>
        <pose frame=''>-0.048315 0.061381 0 0 -0 0</pose>
        <link name='walls'>
          <pose frame=''>-0.048315 0.061381 0 0 -0 0</pose>
          <velocity>0 0 0 0 -0 0</velocity>
          <acceleration>0 0 0 0 -0 0</acceleration>
          <wrench>0 0 0 0 -0 0</wrench>
        </link>
      </model>
      <model name='frc2016_lowbar_0_0'>
        <pose frame=''>-3.45571 2.81213 -1.4e-05 -4.7e-05 -0 0.010612</pose>
        <link name='base'>
          <pose frame=''>-3.45571 2.81213 -1.4e-05 -4.7e-05 -0 0.010612</pose>
          <velocity>-2e-06 -3.9e-05 -0.00894 -0.062135 -0.000659 -6e-06</velocity>
          <acceleration>0.019019 -0.040107 -9.62311 -1.08534 -0.139384 0.011705</acceleration>
          <wrench>0.950942 -2.00534 -481.156 0 -0 0</wrench>
        </link>
        <link name='wall'>
          <pose frame=''>-3.45382 2.63421 0.243223 -0.000449 -2e-06 0.010612</pose>
          <velocity>2e-05 0.001513 0.002382 -0.099743 -0.000582 6.5e-05</velocity>
          <acceleration>-1.17612 2.79184 5.51148 -0.360495 -1.20761 0.035759</acceleration>
          <wrench>-1.17612 2.79184 5.51148 0 -0 0</wrench>
        </link>
      </model>
      <model name='frc2016_moat'>
        <pose frame=''>0.544454 2.83217 -0.019486 0 -0 0</pose>
        <link name='link'>
          <pose frame=''>0.544454 2.83217 -0.019486 0 -0 0</pose>
          <velocity>0 0 0 0 -0 0</velocity>
          <acceleration>0 0 0 0 -0 0</acceleration>
          <wrench>0 0 0 0 -0 0</wrench>
        </link>
      </model>
      <model name='frc2016_portcullis_0'>
        <pose frame=''>0.684433 -2.70317 0 1e-06 -0 0.005163</pose>
        <link name='base'>
          <pose frame=''>0.684433 -2.70317 0 1e-06 -0 0.005163</pose>
          <velocity>2.1e-05 -2.1e-05 0.000385 4.5e-05 -0.000163 -9.4e-05</velocity>
          <acceleration>-2.27128 1.40194 1.20109 1.31878 -1.25066 1.44189</acceleration>
          <wrench>-113.564 70.0972 60.0546 0 -0 0</wrench>
        </link>
        <link name='gate'>
          <pose frame=''>0.655585 -2.67447 0.933268 0 -0 0.005163</pose>
          <velocity>-9e-06 -0.000139 0.000831 -0.000774 -0.000461 -0.002162</velocity>
          <acceleration>-1.92403 1.18382 0.98955 0.497991 -0.889532 -0.14549</acceleration>
          <wrench>-3.84807 2.36764 1.9791 0 -0 0</wrench>
        </link>
      </model>
      <model name='frc2016_ramparts'>
        <pose frame=''>-2.12565 2.82209 0.032078 0 -0 0</pose>
        <link name='link'>
          <pose frame=''>-2.12565 2.82209 0.032078 0 -0 0</pose>
          <velocity>0 0 0 0 -0 0</velocity>
          <acceleration>0 0 0 0 -0 0</acceleration>
          <wrench>0 0 0 0 -0 0</wrench>
        </link>
      </model>
      <model name='frc2016_rockwall'>
        <pose frame=''>2.00868 2.81309 0.054755 0 -0 0</pose>
        <link name='link'>
          <pose frame=''>2.00868 2.81309 0.054755 0 -0 0</pose>
          <velocity>0 0 0 0 -0 0</velocity>
          <acceleration>0 0 0 0 -0 0</acceleration>
          <wrench>0 0 0 0 -0 0</wrench>
        </link>
      </model>
      <model name='frc2016_roughterrain'>
        <pose frame=''>-0.727044 2.83742 -0.008615 0 -0 0</pose>
        <link name='link'>
          <pose frame=''>-0.727044 2.83742 -0.008615 0 -0 0</pose>
          <velocity>0 0 0 0 -0 0</velocity>
          <acceleration>0 0 0 0 -0 0</acceleration>
          <wrench>0 0 0 0 -0 0</wrench>
        </link>
      </model>
      <model name='frc2016_sallyport'>
        <pose frame=''>-2.03495 -2.70877 0.023636 0.007784 0.054244 0.033158</pose>
        <link name='base'>
          <pose frame=''>-2.03495 -2.70877 0.023636 0.007784 0.054244 0.033158</pose>
          <velocity>-0 0 -0 0 -1e-06 0</velocity>
          <acceleration>0 -0 0 0 -0 0</acceleration>
          <wrench>0 -0 0 0 -0 0</wrench>
        </link>
        <link name='door'>
          <pose frame=''>-1.98242 -2.98971 0.423015 0.004539 0.054609 -0.026483</pose>
          <velocity>-1e-06 0 -0 0 -1e-06 0</velocity>
          <acceleration>-0 -0 0 0 -0 0</acceleration>
          <wrench>-0 -0 0 0 -0 0</wrench>
        </link>
      </model>
      <model name='ground_plane'>
        <pose frame=''>0 0 0 0 -0 0</pose>
        <link name='link'>
          <pose frame=''>0 0 0 0 -0 0</pose>
          <velocity>0 0 0 0 -0 0</velocity>
          <acceleration>0 0 0 0 -0 0</acceleration>
          <wrench>0 0 0 0 -0 0</wrench>
        </link>
      </model>
    </state>
    <gui fullscreen='0'>
      <camera name='user_camera'>
        <pose frame=''>4.11758 4.05068 3.05001 0 0.529801 -1.975</pose>
        <view_controller>orbit</view_controller>
        <projection_type>perspective</projection_type>
      </camera>
    </gui>
    <model name='frc2016_lowbar_0_0'>
      <link name='base'>
        <inertial>
          <mass>50</mass>
          <inertia>
            <ixx>0.035543</ixx>
            <ixy>0</ixy>
            <ixz>0</ixz>
            <iyy>0.134412</iyy>
            <iyz>0</iyz>
            <izz>0.165376</izz>
          </inertia>
        </inertial>
        <visual name='platform'>
          <pose frame=''>0 0 0.039065 0 -0 0</pose>
          <geometry>
            <box>
              <size>1.26 0.5996 0.07813</size>
            </box>
          </geometry>
        </visual>
        <collision name='platform'>
          <pose frame=''>0 0 0.039065 0 -0 0</pose>
          <geometry>
            <box>
              <size>1.27 0.6096 0.07813</size>
            </box>
          </geometry>
          <max_contacts>10</max_contacts>
          <surface>
            <contact>
              <ode/>
            </contact>
            <bounce/>
            <friction>
              <ode/>
            </friction>
          </surface>
        </collision>
        <visual name='right_column'>
          <pose frame=''>-0.57845 -0.18464 0.26863 0 -0 0</pose>
          <geometry>
            <cylinder>
              <radius>0.0254</radius>
              <length>0.381</length>
            </cylinder>
          </geometry>
        </visual>
        <collision name='right_column'>
          <pose frame=''>-0.57845 -0.18464 0.26863 0 -0 0</pose>
          <geometry>
            <cylinder>
              <radius>0.0254</radius>
              <length>0.381</length>
            </cylinder>
          </geometry>
          <max_contacts>10</max_contacts>
          <surface>
            <contact>
              <ode/>
            </contact>
            <bounce/>
            <friction>
              <ode/>
            </friction>
          </surface>
        </collision>
        <visual name='left_column'>
          <pose frame=''>0.57845 -0.18464 0.26863 0 -0 0</pose>
          <geometry>
            <cylinder>
              <radius>0.0254</radius>
              <length>0.381</length>
            </cylinder>
          </geometry>
        </visual>
        <collision name='left_column'>
          <pose frame=''>0.57845 -0.18464 0.26863 0 -0 0</pose>
          <geometry>
            <cylinder>
              <radius>0.0254</radius>
              <length>0.381</length>
            </cylinder>
          </geometry>
          <max_contacts>10</max_contacts>
          <surface>
            <contact>
              <ode/>
            </contact>
            <bounce/>
            <friction>
              <ode/>
            </friction>
          </surface>
        </collision>
        <visual name='horizontal'>
          <pose frame=''>0 -0.18464 0.43556 0 1.5707 0</pose>
          <geometry>
            <cylinder>
              <radius>0.0254</radius>
              <length>1.2018</length>
            </cylinder>
          </geometry>
        </visual>
        <collision name='horizontal'>
          <pose frame=''>0 -0.18464 0.43556 0 1.5707 0</pose>
          <geometry>
            <cylinder>
              <radius>0.0254</radius>
              <length>1.2018</length>
            </cylinder>
          </geometry>
          <max_contacts>10</max_contacts>
          <surface>
            <contact>
              <ode/>
            </contact>
            <bounce/>
            <friction>
              <ode/>
            </friction>
          </surface>
        </collision>
        <self_collide>0</self_collide>
        <kinematic>0</kinematic>
        <gravity>1</gravity>
      </link>
      <link name='wall'>
        <pose frame=''>0 -0.1778 0.24323 0 -0 0</pose>
        <inertial>
          <mass>1</mass>
          <inertia>
            <ixx>0.00774528</ixx>
            <ixy>0</ixy>
            <ixz>0</ixz>
            <iyy>0.116613</iyy>
            <iyz>0</iyz>
            <izz>0.108874</izz>
          </inertia>
        </inertial>
        <visual name='visual'>
          <geometry>
            <box>
              <size>1.1176 0.00635 0.3</size>
            </box>
          </geometry>
          <material>
            <ambient>0.46 0.46 0.46 1</ambient>
            <diffuse>0.46 0.46 0.46 1</diffuse>
          </material>
        </visual>
        <collision name='collision'>
          <geometry>
            <box>
              <size>1.143 0.00635 0.3</size>
            </box>
          </geometry>
          <max_contacts>10</max_contacts>
          <surface>
            <contact>
              <ode/>
            </contact>
            <bounce/>
            <friction>
              <ode/>
            </friction>
          </surface>
        </collision>
        <self_collide>0</self_collide>
        <kinematic>0</kinematic>
        <gravity>1</gravity>
      </link>
      <joint name='bar_joint' type='revolute'>
        <pose frame=''>0 0 0.36378 0 -0 0</pose>
        <parent>base</parent>
        <child>wall</child>
        <axis>
          <xyz>1 0 0</xyz>
          <limit>
            <lower>-1.5707</lower>
            <upper>1.5707</upper>
          </limit>
          <use_parent_model_frame>0</use_parent_model_frame>
          <dynamics>
            <spring_reference>0</spring_reference>
            <spring_stiffness>0</spring_stiffness>
          </dynamics>
        </axis>
      </joint>
      <pose frame=''>-3.451 3 0 0 -0 0</pose>
    </model>
    <model name='frc2016_sallyport'>
      <link name='base'>
        <inertial>
          <mass>50</mass>
          <pose frame=''>0 0 0.35406 0 -0 0</pose>
          <inertia>
            <ixx>0.727808</ixx>
            <ixy>0</ixy>
            <ixz>0</ixz>
            <iyy>1.77488</iyy>
            <iyz>0</iyz>
            <izz>1.64109</izz>
          </inertia>
        </inertial>
        <visual name='platform'>
          <pose frame=''>0 0 0.06974 0 -0 0</pose>
          <geometry>
            <box>
              <size>1.27 0.5969 0.003175</size>
            </box>
          </geometry>
        </visual>
        <collision name='platform'>
          <pose frame=''>0 0 0.06974 0 -0 0</pose>
          <geometry>
            <box>
              <size>1.27 0.5969 0.003175</size>
            </box>
          </geometry>
          <max_contacts>10</max_contacts>
          <surface>
            <contact>
              <ode/>
            </contact>
            <bounce/>
            <friction>
              <ode/>
            </friction>
          </surface>
        </collision>
        <visual name='left_column'>
          <pose frame=''>-0.5588 0.00318 0.38876 0 -0 0</pose>
          <geometry>
            <box>
              <size>0.1524 0.38735 0.635</size>
            </box>
          </geometry>
        </visual>
        <collision name='left_column'>
          <pose frame=''>-0.5588 0.00318 0.38876 0 -0 0</pose>
          <geometry>
            <box>
              <size>0.1524 0.38735 0.635</size>
            </box>
          </geometry>
          <max_contacts>10</max_contacts>
          <surface>
            <contact>
              <ode/>
            </contact>
            <bounce/>
            <friction>
              <ode/>
            </friction>
          </surface>
        </collision>
        <visual name='right_column'>
          <pose frame=''>0.6096 0.00635 0.38876 0 -0 0</pose>
          <geometry>
            <box>
              <size>0.0508 0.381 0.635</size>
            </box>
          </geometry>
        </visual>
        <collision name='right_column'>
          <pose frame=''>0.6096 0.00635 0.38876 0 -0 0</pose>
          <geometry>
            <box>
              <size>0.0508 0.381 0.635</size>
            </box>
          </geometry>
          <max_contacts>10</max_contacts>
          <surface>
            <contact>
              <ode/>
            </contact>
            <bounce/>
            <friction>
              <ode/>
            </friction>
          </surface>
        </collision>
        <visual name='castor1'>
          <pose frame=''>-0.45886 0.15389 0.03487 0 -0 0</pose>
          <geometry>
            <sphere>
              <radius>0.03487</radius>
            </sphere>
          </geometry>
        </visual>
        <collision name='castor1'>
          <pose frame=''>-0.45886 0.15389 0.03487 0 -0 0</pose>
          <geometry>
            <sphere>
              <radius>0.03487</radius>
            </sphere>
          </geometry>
          <max_contacts>10</max_contacts>
          <surface>
            <contact>
              <ode/>
            </contact>
            <bounce/>
            <friction>
              <ode/>
            </friction>
          </surface>
        </collision>
        <visual name='castor2'>
          <pose frame=''>-0.28117 -0.22559 0.03487 0 -0 0</pose>
          <geometry>
            <sphere>
              <radius>0.03487</radius>
            </sphere>
          </geometry>
        </visual>
        <collision name='castor2'>
          <pose frame=''>-0.28117 -0.22559 0.03487 0 -0 0</pose>
          <geometry>
            <sphere>
              <radius>0.03487</radius>
            </sphere>
          </geometry>
          <max_contacts>10</max_contacts>
          <surface>
            <contact>
              <ode/>
            </contact>
            <bounce/>
            <friction>
              <ode/>
            </friction>
          </surface>
        </collision>
        <visual name='castor3'>
          <pose frame=''>0.27933 -0.2272 0.03487 0 -0 0</pose>
          <geometry>
            <sphere>
              <radius>0.03487</radius>
            </sphere>
          </geometry>
        </visual>
        <collision name='castor3'>
          <pose frame=''>0.27933 -0.2272 0.03487 0 -0 0</pose>
          <geometry>
            <sphere>
              <radius>0.03487</radius>
            </sphere>
          </geometry>
          <max_contacts>10</max_contacts>
          <surface>
            <contact>
              <ode/>
            </contact>
            <bounce/>
            <friction>
              <ode/>
            </friction>
          </surface>
        </collision>
        <visual name='castor4'>
          <pose frame=''>0.4571 0.15424 0.03487 0 -0 0</pose>
          <geometry>
            <sphere>
              <radius>0.03487</radius>
            </sphere>
          </geometry>
        </visual>
        <collision name='castor4'>
          <pose frame=''>0.4571 0.15424 0.03487 0 -0 0</pose>
          <geometry>
            <sphere>
              <radius>0.03487</radius>
            </sphere>
          </geometry>
          <max_contacts>10</max_contacts>
          <surface>
            <contact>
              <ode/>
            </contact>
            <bounce/>
            <friction>
              <ode/>
            </friction>
          </surface>
        </collision>
        <self_collide>0</self_collide>
        <kinematic>0</kinematic>
        <gravity>1</gravity>
      </link>
      <link name='door'>
        <pose frame=''>0.02255 -0.24321 0.40332 0 -0 0</pose>
        <inertial>
          <pose frame=''>0 0 0 -1.5707 0 0</pose>
          <mass>2</mass>
          <inertia>
            <ixx>0.0619421</ixx>
            <ixy>0</ixy>
            <ixz>0</ixz>
            <iyy>0.246462</iyy>
            <iyz>0</iyz>
            <izz>0.30839</izz>
          </inertia>
        </inertial>
        <visual name='visual'>
          <geometry>
            <box>
              <size>1.21603 0.00635 0.6096</size>
            </box>
          </geometry>
          <material>
            <script>
              <name>Gazebo/WoodFloor</name>
              <uri>__default__</uri>
            </script>
          </material>
        </visual>
        <collision name='collision'>
          <geometry>
            <box>
              <size>1.21603 0.00635 0.6096</size>
            </box>
          </geometry>
          <max_contacts>10</max_contacts>
          <surface>
            <contact>
              <ode/>
            </contact>
            <bounce/>
            <friction>
              <ode/>
            </friction>
          </surface>
        </collision>
        <self_collide>0</self_collide>
        <kinematic>0</kinematic>
        <gravity>1</gravity>
      </link>
      <joint name='door_joint' type='revolute'>
        <pose frame=''>-0.608015 0 0 0 -0 0</pose>
        <parent>base</parent>
        <child>door</child>
        <axis>
          <xyz>0 0 1</xyz>
          <limit>
            <lower>-3.1415</lower>
            <upper>0</upper>
          </limit>
          <use_parent_model_frame>0</use_parent_model_frame>
          <dynamics>
            <spring_reference>0</spring_reference>
            <spring_stiffness>0</spring_stiffness>
          </dynamics>
        </axis>
      </joint>
      <pose frame=''>-2 -2.54971 0 0 -0 0</pose>
    </model>
    <model name='frc2016_drawbridge'>
      <link name='base'>
        <inertial>
          <mass>10</mass>
          <pose frame=''>0 0 1 0 -0 0</pose>
          <inertia>
            <ixx>3.64907</ixx>
            <ixy>0</ixy>
            <ixz>0</ixz>
            <iyy>4.67075</iyy>
            <iyz>0</iyz>
            <izz>1.66649</izz>
          </inertia>
        </inertial>
        <visual name='platform'>
          <pose frame=''>0 0 0.0425 0 -0 0</pose>
          <geometry>
            <box>
              <size>1.27 0.5969 0.085</size>
            </box>
          </geometry>
        </visual>
        <collision name='platform'>
          <pose frame=''>0 0 0.0425 0 -0 0</pose>
          <geometry>
            <box>
              <size>1.27 0.5969 0.085</size>
            </box>
          </geometry>
          <max_contacts>10</max_contacts>
          <surface>
            <contact>
              <ode/>
            </contact>
            <bounce/>
            <friction>
              <ode/>
            </friction>
          </surface>
        </collision>
        <visual name='right_wall'>
          <pose frame=''>0.55879 0.04444 0.889 0 -0 0</pose>
          <geometry>
            <box>
              <size>0.05715 0.45698 1.77165</size>
            </box>
          </geometry>
        </visual>
        <collision name='right_wall'>
          <pose frame=''>0.55879 0.04444 0.889 0 -0 0</pose>
          <geometry>
            <box>
              <size>0.05715 0.45698 1.77165</size>
            </box>
          </geometry>
          <max_contacts>10</max_contacts>
          <surface>
            <contact>
              <ode/>
            </contact>
            <bounce/>
            <friction>
              <ode/>
            </friction>
          </surface>
        </collision>
        <visual name='left_wall'>
          <pose frame=''>-0.55879 0.04444 0.889 0 -0 0</pose>
          <geometry>
            <box>
              <size>0.05715 0.45698 1.77165</size>
            </box>
          </geometry>
        </visual>
        <collision name='left_wall'>
          <pose frame=''>-0.55879 0.04444 0.889 0 -0 0</pose>
          <geometry>
            <box>
              <size>0.05715 0.45698 1.77165</size>
            </box>
          </geometry>
          <max_contacts>10</max_contacts>
          <surface>
            <contact>
              <ode/>
            </contact>
            <bounce/>
            <friction>
              <ode/>
            </friction>
          </surface>
        </collision>
        <visual name='front_upper_wall'>
          <pose frame=''>0 0.27611 1.84286 0 -0 0</pose>
          <geometry>
            <box>
              <size>1.1557 0.006347 0.254</size>
            </box>
          </geometry>
        </visual>
        <collision name='front_upper_wall'>
          <pose frame=''>0 0.27611 1.84286 0 -0 0</pose>
          <geometry>
            <box>
              <size>1.1557 0.006347 0.254</size>
            </box>
          </geometry>
          <max_contacts>10</max_contacts>
          <surface>
            <contact>
              <ode/>
            </contact>
            <bounce/>
            <friction>
              <ode/>
            </friction>
          </surface>
        </collision>
        <visual name='back_upper_wall'>
          <pose frame=''>0 -0.18722 1.84286 0 -0 0</pose>
          <geometry>
            <box>
              <size>1.1557 0.006347 0.254</size>
            </box>
          </geometry>
        </visual>
        <collision name='back_upper_wall'>
          <pose frame=''>0 -0.18722 1.84286 0 -0 0</pose>
          <geometry>
            <box>
              <size>1.1557 0.006347 0.254</size>
            </box>
          </geometry>
          <max_contacts>10</max_contacts>
          <surface>
            <contact>
              <ode/>
            </contact>
            <bounce/>
            <friction>
              <ode/>
            </friction>
          </surface>
        </collision>
        <self_collide>0</self_collide>
        <kinematic>0</kinematic>
        <gravity>1</gravity>
      </link>
      <link name='bridge'>
        <pose frame=''>0 0.28245 0.50577 0 -0 0</pose>
        <inertial>
          <mass>2</mass>
          <pose frame=''>0 -0.28245 -0.50577 0 -0 0</pose>
          <inertia>
            <ixx>0.139361</ixx>
            <ixy>0</ixy>
            <ixz>0</ixz>
            <iyy>0.357088</iyy>
            <iyz>0</iyz>
            <izz>0.217741</izz>
          </inertia>
        </inertial>
        <visual name='visual'>
          <geometry>
            <box>
              <size>1.14298 0.006347 0.9144</size>
            </box>
          </geometry>
          <material>
            <script>
              <name>Gazebo/WoodFloor</name>
              <uri>__default__</uri>
            </script>
          </material>
        </visual>
        <collision name='collision'>
          <geometry>
            <box>
              <size>1.14298 0.006347 0.9144</size>
            </box>
          </geometry>
          <max_contacts>10</max_contacts>
          <surface>
            <contact>
              <ode/>
            </contact>
            <bounce/>
            <friction>
              <ode/>
            </friction>
          </surface>
        </collision>
        <self_collide>0</self_collide>
        <kinematic>0</kinematic>
        <gravity>1</gravity>
      </link>
      <joint name='bridge_joint' type='revolute'>
        <pose frame=''>0 0 -0.4172 0 -0 0</pose>
        <parent>base</parent>
        <child>bridge</child>
        <axis>
          <xyz>1 0 0</xyz>
          <limit>
            <lower>-2</lower>
            <upper>0</upper>
          </limit>
          <use_parent_model_frame>0</use_parent_model_frame>
          <dynamics>
            <spring_reference>0</spring_reference>
            <spring_stiffness>0</spring_stiffness>
          </dynamics>
        </axis>
      </joint>
      <pose frame=''>-0.57844 -3 0 0 -0 0</pose>
    </model>
    <model name='frc2016_portcullis_0'>
      <link name='base'>
        <inertial>
          <mass>50</mass>
          <pose frame=''>0 0 1.02941 0 -0 0</pose>
          <inertia>
            <ixx>3.81711</ixx>
            <ixy>0</ixy>
            <ixz>0</ixz>
            <iyy>4.87698</iyy>
            <iyz>0</iyz>
            <izz>1.6283</izz>
          </inertia>
        </inertial>
        <visual name='platform'>
          <pose frame=''>0 0 0.07284 0 -0 0</pose>
          <geometry>
            <box>
              <size>1.27 0.5842 0.003175</size>
            </box>
          </geometry>
        </visual>
        <collision name='platform'>
          <pose frame=''>0 0 0.07284 0 -0 0</pose>
          <geometry>
            <box>
              <size>1.27 0.5842 0.003175</size>
            </box>
          </geometry>
          <max_contacts>10</max_contacts>
          <surface>
            <contact>
              <ode/>
            </contact>
            <bounce/>
            <friction>
              <ode/>
            </friction>
          </surface>
        </collision>
        <visual name='left_column'>
          <pose frame=''>0.59284 0 0.99042 0 -0 0</pose>
          <geometry>
            <box>
              <size>0.08375 0.28575 1.83198</size>
            </box>
          </geometry>
        </visual>
        <collision name='left_column'>
          <pose frame=''>0.59284 0 0.99042 0 -0 0</pose>
          <geometry>
            <box>
              <size>0.08375 0.28575 1.83198</size>
            </box>
          </geometry>
          <max_contacts>10</max_contacts>
          <surface>
            <contact>
              <ode/>
            </contact>
            <bounce/>
            <friction>
              <ode/>
            </friction>
          </surface>
        </collision>
        <visual name='right_column'>
          <pose frame=''>-0.57759 0 0.99042 0 -0 0</pose>
          <geometry>
            <box>
              <size>0.08375 0.28575 1.83198</size>
            </box>
          </geometry>
        </visual>
        <collision name='right_column'>
          <pose frame=''>-0.57759 0 0.99042 0 -0 0</pose>
          <geometry>
            <box>
              <size>0.08375 0.28575 1.83198</size>
            </box>
          </geometry>
          <max_contacts>10</max_contacts>
          <surface>
            <contact>
              <ode/>
            </contact>
            <bounce/>
            <friction>
              <ode/>
            </friction>
          </surface>
        </collision>
        <visual name='top'>
          <pose frame=''>-0.00034 0 1.77722 0 -0 0</pose>
          <geometry>
            <box>
              <size>1.22962 0.28575 0.26657</size>
            </box>
          </geometry>
        </visual>
        <collision name='top'>
          <pose frame=''>-0.00034 0 1.77722 0 -0 0</pose>
          <geometry>
            <box>
              <size>1.22962 0.28575 0.26657</size>
            </box>
          </geometry>
          <max_contacts>10</max_contacts>
          <surface>
            <contact>
              <ode/>
            </contact>
            <bounce/>
            <friction>
              <ode/>
            </friction>
          </surface>
        </collision>
        <visual name='castor1'>
          <pose frame=''>-0.45651 -0.16234 0.03272 0 -0 0</pose>
          <geometry>
            <sphere>
              <radius>0.03272</radius>
            </sphere>
          </geometry>
        </visual>
        <collision name='castor1'>
          <pose frame=''>-0.45651 -0.16234 0.03272 0 -0 0</pose>
          <geometry>
            <sphere>
              <radius>0.03272</radius>
            </sphere>
          </geometry>
          <max_contacts>10</max_contacts>
          <surface>
            <contact>
              <ode/>
            </contact>
            <bounce/>
            <friction>
              <ode/>
            </friction>
          </surface>
        </collision>
        <visual name='castor2'>
          <pose frame=''>-0.27883 0.21836 0.03272 0 -0 0</pose>
          <geometry>
            <sphere>
              <radius>0.03272</radius>
            </sphere>
          </geometry>
        </visual>
        <collision name='castor2'>
          <pose frame=''>-0.27883 0.21836 0.03272 0 -0 0</pose>
          <geometry>
            <sphere>
              <radius>0.03272</radius>
            </sphere>
          </geometry>
          <max_contacts>10</max_contacts>
          <surface>
            <contact>
              <ode/>
            </contact>
            <bounce/>
            <friction>
              <ode/>
            </friction>
          </surface>
        </collision>
        <visual name='castor3'>
          <pose frame=''>0.28083 0.21906 0.03272 0 -0 0</pose>
          <geometry>
            <sphere>
              <radius>0.03272</radius>
            </sphere>
          </geometry>
        </visual>
        <collision name='castor3'>
          <pose frame=''>0.28083 0.21906 0.03272 0 -0 0</pose>
          <geometry>
            <sphere>
              <radius>0.03272</radius>
            </sphere>
          </geometry>
          <max_contacts>10</max_contacts>
          <surface>
            <contact>
              <ode/>
            </contact>
            <bounce/>
            <friction>
              <ode/>
            </friction>
          </surface>
        </collision>
        <visual name='castor4'>
          <pose frame=''>0.45871 -0.16186 0.03272 0 -0 0</pose>
          <geometry>
            <sphere>
              <radius>0.03272</radius>
            </sphere>
          </geometry>
        </visual>
        <collision name='castor4'>
          <pose frame=''>0.45871 -0.16186 0.03272 0 -0 0</pose>
          <geometry>
            <sphere>
              <radius>0.03272</radius>
            </sphere>
          </geometry>
          <max_contacts>10</max_contacts>
          <surface>
            <contact>
              <ode/>
            </contact>
            <bounce/>
            <friction>
              <ode/>
            </friction>
          </surface>
        </collision>
        <self_collide>0</self_collide>
        <kinematic>0</kinematic>
        <gravity>1</gravity>
      </link>
      <link name='gate'>
        <pose frame=''>-0.0287 0.02885 0.93327 0 -0 0</pose>
        <inertial>
          <mass>2</mass>
          <pose frame=''>0 0 0 0 -0 0</pose>
          <inertia>
            <ixx>3.81711</ixx>
            <ixy>0</ixy>
            <ixz>0</ixz>
            <iyy>4.87698</iyy>
            <iyz>0</iyz>
            <izz>1.6283</izz>
          </inertia>
        </inertial>
        <collision name='collision'>
          <geometry>
            <box>
              <size>1.1938 0.02496 1.45732</size>
            </box>
          </geometry>
          <max_contacts>10</max_contacts>
          <surface>
            <contact>
              <ode/>
            </contact>
            <bounce/>
            <friction>
              <ode/>
            </friction>
          </surface>
        </collision>
        <visual name='horz_1'>
          <pose frame=''>0 0 -0.70326 0 -0 0</pose>
          <geometry>
            <box>
              <size>1.1938 0.02496 0.0508</size>
            </box>
          </geometry>
          <material>
            <ambient>0.4 0.4 0.4 1</ambient>
            <diffuse>0.4 0.4 0.4 1</diffuse>
          </material>
        </visual>
        <visual name='horz_2'>
          <pose frame=''>0 0 -0.44926 0 -0 0</pose>
          <geometry>
            <box>
              <size>1.1938 0.02496 0.0508</size>
            </box>
          </geometry>
          <material>
            <ambient>0.4 0.4 0.4 1</ambient>
            <diffuse>0.4 0.4 0.4 1</diffuse>
          </material>
        </visual>
        <visual name='horz_3'>
          <pose frame=''>0 0 -0.14517 0 -0 0</pose>
          <geometry>
            <box>
              <size>1.1938 0.02496 0.0508</size>
            </box>
          </geometry>
          <material>
            <ambient>0.4 0.4 0.4 1</ambient>
            <diffuse>0.4 0.4 0.4 1</diffuse>
          </material>
        </visual>
        <visual name='horz_4'>
          <pose frame=''>0 0 0.16034 0 -0 0</pose>
          <geometry>
            <box>
              <size>1.1938 0.02496 0.0508</size>
            </box>
          </geometry>
          <material>
            <ambient>0.4 0.4 0.4 1</ambient>
            <diffuse>0.4 0.4 0.4 1</diffuse>
          </material>
        </visual>
        <visual name='horz_5'>
          <pose frame=''>0 0 0.46514 0 -0 0</pose>
          <geometry>
            <box>
              <size>1.1938 0.02496 0.0508</size>
            </box>
          </geometry>
          <material>
            <ambient>0.4 0.4 0.4 1</ambient>
            <diffuse>0.4 0.4 0.4 1</diffuse>
          </material>
        </visual>
        <visual name='horz_6'>
          <pose frame=''>0 0 0.72994 0 -0 0</pose>
          <geometry>
            <box>
              <size>1.1938 0.02496 0.0508</size>
            </box>
          </geometry>
          <material>
            <ambient>0.4 0.4 0.4 1</ambient>
            <diffuse>0.4 0.4 0.4 1</diffuse>
          </material>
        </visual>
        <visual name='vert_1'>
          <pose frame=''>-0.58448 0 0 0 -0 0</pose>
          <geometry>
            <box>
              <size>0.02495 0.02496 1.45732</size>
            </box>
          </geometry>
          <material>
            <ambient>0.4 0.4 0.4 1</ambient>
            <diffuse>0.4 0.4 0.4 1</diffuse>
          </material>
        </visual>
        <visual name='vert_2'>
          <pose frame=''>-0.38128 0 0 0 -0 0</pose>
          <geometry>
            <box>
              <size>0.0508 0.02496 1.45732</size>
            </box>
          </geometry>
          <material>
            <ambient>0.4 0.4 0.4 1</ambient>
            <diffuse>0.4 0.4 0.4 1</diffuse>
          </material>
        </visual>
        <visual name='vert_3'>
          <pose frame=''>-0.12728 0 0 0 -0 0</pose>
          <geometry>
            <box>
              <size>0.0508 0.02496 1.45732</size>
            </box>
          </geometry>
          <material>
            <ambient>0.4 0.4 0.4 1</ambient>
            <diffuse>0.4 0.4 0.4 1</diffuse>
          </material>
        </visual>
        <visual name='vert_4'>
          <pose frame=''>0.12672 0 0 0 -0 0</pose>
          <geometry>
            <box>
              <size>0.0508 0.02496 1.45732</size>
            </box>
          </geometry>
          <material>
            <ambient>0.4 0.4 0.4 1</ambient>
            <diffuse>0.4 0.4 0.4 1</diffuse>
          </material>
        </visual>
        <visual name='vert_5'>
          <pose frame=''>0.38072 0 0 0 -0 0</pose>
          <geometry>
            <box>
              <size>0.0508 0.02496 1.45732</size>
            </box>
          </geometry>
          <material>
            <ambient>0.4 0.4 0.4 1</ambient>
            <diffuse>0.4 0.4 0.4 1</diffuse>
          </material>
        </visual>
        <visual name='vert_6'>
          <pose frame=''>0.58392 0 0 0 -0 0</pose>
          <geometry>
            <box>
              <size>0.02495 0.02496 1.45732</size>
            </box>
          </geometry>
          <material>
            <ambient>0.4 0.4 0.4 1</ambient>
            <diffuse>0.4 0.4 0.4 1</diffuse>
          </material>
        </visual>
        <self_collide>0</self_collide>
        <kinematic>0</kinematic>
        <gravity>1</gravity>
      </link>
      <joint name='joint' type='prismatic'>
        <parent>base</parent>
        <child>gate</child>
        <axis>
          <xyz>0 0 1</xyz>
          <limit>
            <lower>0</lower>
            <upper>1</upper>
          </limit>
          <use_parent_model_frame>0</use_parent_model_frame>
          <dynamics>
            <spring_reference>0</spring_reference>
            <spring_stiffness>0</spring_stiffness>
          </dynamics>
        </axis>
      </joint>
      <pose frame=''>1 -3 0 0 -0 0</pose>
    </model>
    <model name='frc2016_chevaldefrise'>
      <link name='base'>
        <inertial>
          <mass>10</mass>
          <pose frame=''>0 0 0.15672 0 -0 0</pose>
          <inertia>
            <ixx>0.380221</ixx>
            <ixy>0</ixy>
            <ixz>0</ixz>
            <iyy>1.43365</iyy>
            <iyz>0</iyz>
            <izz>1.64745</izz>
          </inertia>
        </inertial>
        <visual name='platform'>
          <pose frame=''>0 0 0.06968 0 -0 0</pose>
          <geometry>
            <box>
              <size>1.27 0.5969 0.003175</size>
            </box>
          </geometry>
        </visual>
        <collision name='platform'>
          <pose frame=''>0 0 0.06968 0 -0 0</pose>
          <geometry>
            <box>
              <size>1.27 0.5969 0.003175</size>
            </box>
          </geometry>
          <max_contacts>10</max_contacts>
          <surface>
            <contact>
              <ode/>
            </contact>
            <bounce/>
            <friction>
              <ode/>
            </friction>
          </surface>
        </collision>
        <visual name='bar'>
          <pose frame=''>0 0 0.16855 0 1.5707 0</pose>
          <geometry>
            <cylinder>
              <radius>0.02108</radius>
              <length>1.273</length>
            </cylinder>
          </geometry>
        </visual>
        <collision name='bar'>
          <pose frame=''>0 0 0.16855 0 1.5707 0</pose>
          <geometry>
            <cylinder>
              <radius>0.02108</radius>
              <length>1.27</length>
            </cylinder>
          </geometry>
          <max_contacts>10</max_contacts>
          <surface>
            <contact>
              <ode/>
            </contact>
            <bounce/>
            <friction>
              <ode/>
            </friction>
          </surface>
        </collision>
        <visual name='castor1'>
          <pose frame=''>-0.45653 -0.16581 0.03175 0 -0 0</pose>
          <geometry>
            <sphere>
              <radius>0.03175</radius>
            </sphere>
          </geometry>
        </visual>
        <collision name='castor1'>
          <pose frame=''>-0.45653 -0.16581 0.03175 0 -0 0</pose>
          <geometry>
            <sphere>
              <radius>0.03175</radius>
            </sphere>
          </geometry>
          <max_contacts>10</max_contacts>
          <surface>
            <contact>
              <ode/>
            </contact>
            <bounce/>
            <friction>
              <ode/>
            </friction>
          </surface>
        </collision>
        <visual name='castor2'>
          <pose frame=''>-0.27855 0.21408 0.03175 0 -0 0</pose>
          <geometry>
            <sphere>
              <radius>0.03175</radius>
            </sphere>
          </geometry>
        </visual>
        <collision name='castor2'>
          <pose frame=''>-0.27855 0.21408 0.03175 0 -0 0</pose>
          <geometry>
            <sphere>
              <radius>0.03175</radius>
            </sphere>
          </geometry>
          <max_contacts>10</max_contacts>
          <surface>
            <contact>
              <ode/>
            </contact>
            <bounce/>
            <friction>
              <ode/>
            </friction>
          </surface>
        </collision>
        <visual name='castor3'>
          <pose frame=''>0.28191 0.21419 0.03175 0 -0 0</pose>
          <geometry>
            <sphere>
              <radius>0.03175</radius>
            </sphere>
          </geometry>
        </visual>
        <collision name='castor3'>
          <pose frame=''>0.28191 0.21419 0.03175 0 -0 0</pose>
          <geometry>
            <sphere>
              <radius>0.03175</radius>
            </sphere>
          </geometry>
          <max_contacts>10</max_contacts>
          <surface>
            <contact>
              <ode/>
            </contact>
            <bounce/>
            <friction>
              <ode/>
            </friction>
          </surface>
        </collision>
        <visual name='castor4'>
          <pose frame=''>0.45965 -0.16602 0.03175 0 -0 0</pose>
          <geometry>
            <sphere>
              <radius>0.03175</radius>
            </sphere>
          </geometry>
        </visual>
        <collision name='castor4'>
          <pose frame=''>0.45965 -0.16602 0.03175 0 -0 0</pose>
          <geometry>
            <sphere>
              <radius>0.03175</radius>
            </sphere>
          </geometry>
          <max_contacts>10</max_contacts>
          <surface>
            <contact>
              <ode/>
            </contact>
            <bounce/>
            <friction>
              <ode/>
            </friction>
          </surface>
        </collision>
        <self_collide>0</self_collide>
        <kinematic>0</kinematic>
        <gravity>1</gravity>
      </link>
      <link name='slant1'>
        <pose frame=''>-0.4572 0.01307 0.1997 -0.39732 0 0</pose>
        <inertial>
          <pose frame=''>0 0.1 0 0 -0 0</pose>
          <mass>2</mass>
          <inertia>
            <ixx>0.0606857</ixx>
            <ixy>0</ixy>
            <ixz>0</ixz>
            <iyy>0.0148723</iyy>
            <iyz>0</iyz>
            <izz>0.0755042</izz>
          </inertia>
        </inertial>
        <visual name='visual'>
          <geometry>
            <box>
              <size>0.29845 0.593285 0.0127</size>
            </box>
          </geometry>
          <material>
            <script>
              <name>Gazebo/WoodFloor</name>
              <uri>__default__</uri>
            </script>
          </material>
        </visual>
        <collision name='collision'>
          <geometry>
            <box>
              <size>0.29845 0.593285 0.0127</size>
            </box>
          </geometry>
          <max_contacts>10</max_contacts>
          <surface>
            <contact>
              <ode/>
            </contact>
            <bounce/>
            <friction>
              <ode/>
            </friction>
          </surface>
        </collision>
        <self_collide>0</self_collide>
        <kinematic>0</kinematic>
        <gravity>1</gravity>
      </link>
      <link name='slant2'>
        <pose frame=''>-0.1524 -0.01307 0.1997 0.39732 -0 0</pose>
        <inertial>
          <mass>2</mass>
          <pose frame=''>0 -0.1 0 0 -0 0</pose>
          <inertia>
            <ixx>0.0606857</ixx>
            <ixy>0</ixy>
            <ixz>0</ixz>
            <iyy>0.0148723</iyy>
            <iyz>0</iyz>
            <izz>0.0755042</izz>
          </inertia>
        </inertial>
        <visual name='visual'>
          <geometry>
            <box>
              <size>0.29845 0.593285 0.0127</size>
            </box>
          </geometry>
          <material>
            <script>
              <name>Gazebo/WoodFloor</name>
              <uri>__default__</uri>
            </script>
          </material>
        </visual>
        <collision name='collision'>
          <geometry>
            <box>
              <size>0.29845 0.593285 0.0127</size>
            </box>
          </geometry>
          <max_contacts>10</max_contacts>
          <surface>
            <contact>
              <ode/>
            </contact>
            <bounce/>
            <friction>
              <ode/>
            </friction>
          </surface>
        </collision>
        <self_collide>0</self_collide>
        <kinematic>0</kinematic>
        <gravity>1</gravity>
      </link>
      <link name='slant3'>
        <pose frame=''>0.1524 0.01307 0.1997 -0.39732 0 0</pose>
        <inertial>
          <pose frame=''>0 0.1 0 0 -0 0</pose>
          <mass>2</mass>
          <inertia>
            <ixx>0.0606857</ixx>
            <ixy>0</ixy>
            <ixz>0</ixz>
            <iyy>0.0148723</iyy>
            <iyz>0</iyz>
            <izz>0.0755042</izz>
          </inertia>
        </inertial>
        <visual name='visual'>
          <geometry>
            <box>
              <size>0.29845 0.593285 0.0127</size>
            </box>
          </geometry>
          <material>
            <script>
              <name>Gazebo/WoodFloor</name>
              <uri>__default__</uri>
            </script>
          </material>
        </visual>
        <collision name='collision'>
          <geometry>
            <box>
              <size>0.29845 0.593285 0.0127</size>
            </box>
          </geometry>
          <max_contacts>10</max_contacts>
          <surface>
            <contact>
              <ode/>
            </contact>
            <bounce/>
            <friction>
              <ode/>
            </friction>
          </surface>
        </collision>
        <self_collide>0</self_collide>
        <kinematic>0</kinematic>
        <gravity>1</gravity>
      </link>
      <link name='slant4'>
        <pose frame=''>0.4572 -0.01307 0.1997 0.39732 -0 0</pose>
        <inertial>
          <pose frame=''>0 -0.1 0 0 -0 0</pose>
          <mass>2</mass>
          <inertia>
            <ixx>0.0606857</ixx>
            <ixy>0</ixy>
            <ixz>0</ixz>
            <iyy>0.0148723</iyy>
            <iyz>0</iyz>
            <izz>0.0755042</izz>
          </inertia>
        </inertial>
        <visual name='visual'>
          <geometry>
            <box>
              <size>0.29845 0.593285 0.0127</size>
            </box>
          </geometry>
          <material>
            <script>
              <name>Gazebo/WoodFloor</name>
              <uri>__default__</uri>
            </script>
          </material>
        </visual>
        <collision name='collision'>
          <geometry>
            <box>
              <size>0.29845 0.593285 0.0127</size>
            </box>
          </geometry>
          <max_contacts>10</max_contacts>
          <surface>
            <contact>
              <ode/>
            </contact>
            <bounce/>
            <friction>
              <ode/>
            </friction>
          </surface>
        </collision>
        <self_collide>0</self_collide>
        <kinematic>0</kinematic>
        <gravity>1</gravity>
      </link>
      <joint name='slant1_joint' type='revolute'>
        <parent>base</parent>
        <child>slant1</child>
        <axis>
          <xyz>1 0 0</xyz>
          <limit>
            <lower>0</lower>
            <upper>1.5707</upper>
          </limit>
          <use_parent_model_frame>0</use_parent_model_frame>
          <dynamics>
            <spring_reference>0</spring_reference>
            <spring_stiffness>0</spring_stiffness>
          </dynamics>
        </axis>
      </joint>
      <joint name='slant2_joint' type='revolute'>
        <parent>base</parent>
        <child>slant2</child>
        <axis>
          <xyz>1 0 0</xyz>
          <limit>
            <lower>-1.5707</lower>
            <upper>0</upper>
          </limit>
          <use_parent_model_frame>0</use_parent_model_frame>
          <dynamics>
            <spring_reference>0</spring_reference>
            <spring_stiffness>0</spring_stiffness>
          </dynamics>
        </axis>
      </joint>
      <joint name='slant3_joint' type='revolute'>
        <parent>base</parent>
        <child>slant3</child>
        <axis>
          <xyz>1 0 0</xyz>
          <limit>
            <lower>0</lower>
            <upper>1.5707</upper>
          </limit>
          <use_parent_model_frame>0</use_parent_model_frame>
          <dynamics>
            <spring_reference>0</spring_reference>
            <spring_stiffness>0</spring_stiffness>
          </dynamics>
        </axis>
      </joint>
      <joint name='slant4_joint' type='revolute'>
        <parent>base</parent>
        <child>slant4</child>
        <axis>
          <xyz>1 0 0</xyz>
          <limit>
            <lower>-1.5707</lower>
            <upper>0</upper>
          </limit>
          <use_parent_model_frame>0</use_parent_model_frame>
          <dynamics>
            <spring_reference>0</spring_reference>
            <spring_stiffness>0</spring_stiffness>
          </dynamics>
        </axis>
      </joint>
      <pose frame=''>2 -2.57476 0 0 -0 0</pose>
    </model>
  </world>
</sdf>
