<?xml version="1.0" encoding="utf-8"?>
<sdf version="1.5">
  <model name="SimBot">
    <pose>0 0 0.00254000000000018 0 0 0</pose>
    <plugin name="clock" filename="libclock.so">
      <topic>/gazebo/frc/time</topic>
    </plugin>
    <link name="Chassis">
      <gravity>1</gravity>
      <self_collide>0</self_collide>
      <pose>-0.417787729909074 -0.370900839250168 0.109796495445787 1.5707963267949 9.43689570931383E-16 -1.5707963267949</pose>
      <must_be_base_link>1</must_be_base_link>
      <velocity_decay>
        <linear>0</linear>
        <angular>0</angular>
      </velocity_decay>
      <inertial>
        <mass>48.6161363090323</mass>
        <pose>0 0 0 0 0 0</pose>
        <inertia>
          <ixx>6.85956286111502</ixx>
          <ixy>0.0505958405428025</ixy>
          <ixz>0.0454904755903607</ixz>
          <iyy>11.0679921953325</iyy>
          <iyz>0.0206054821955621</iyz>
          <izz>5.66912323899694</izz>
        </inertia>
      </inertial>
      <collision name="Chassis_collision">
        <pose>0.00374916074983288 -0.143685830615581 -0.417787729909074 0 0 0</pose>
        <geometry>
          <mesh>
            <scale>1 1 1</scale>
            <uri>model://SimBot/meshes/Chassis_col.STL</uri>
          </mesh>
        </geometry>
        <surface>
          <contact>
            <ode />
          </contact>
          <friction>
            <ode>
              <mu>0</mu>
              <mu2>0</mu2>
            </ode>
          </friction>
        </surface>
      </collision>
      <visual name="Chassis_visual">
        <pose>0.00374916074983288 -0.143685830615581 -0.417787729909074 0 0 0</pose>
        <material>
          <ambient>0 0.250980392156863 1 1</ambient>
          <diffuse>0 0.250980392156863 1 1</diffuse>
        </material>
        <geometry>
          <mesh>
            <scale>1 1 1</scale>
            <uri>model://SimBot/meshes/Chassis.STL</uri>
          </mesh>
        </geometry>
      </visual>
      <sensor name="ChassisCamera" type="camera">
        <visualize>1</visualize>
        <always_on>1</always_on>
        <updateRate>10.0</updateRate>
        <pose>0.17 0.23 -0.37 -1.57 1.57000 0.0</pose>
        <camera name="Chassiscamera">
          <horizontal_fov>0.87</horizontal_fov>
          <image>
            <width>320</width>
            <height>240</height>
          </image>
          <clip>
            <near>0.1</near>
            <far>30</far>
          </clip>
          <save enabled="true">
              <path>/tmp/target-camera</path>
          </save>
        </camera>
      </sensor>
      <sensor name="DriverCamera" type="camera">
        <visualize>0</visualize>
        <always_on>1</always_on>
         <pose>0.0 0.23 -0.3 -1.57 1.57 0.0</pose>
        <camera name="Bodycamera">
          <horizontal_fov>1.0471975511966</horizontal_fov>
          <image>
            <width>320</width>
            <height>240</height>
          </image>
          <clip>
            <near>0.01</near>
            <far>30</far>
          </clip>
          <save enabled="true">
              <path>/tmp/driver-camera</path>
          </save>
        </camera>
      </sensor>
      <sensor name="ChassisUltrasonic" type="sonar">
        <always_on>1</always_on>
        <visualize>0</visualize>
        <pose>0.17 0.318095647047724 -0.369811570125635 -0.2 0.2 0</pose>
        <sonar>
          <min>0.1</min>
          <max>2</max>
          <radius>0.2</radius>
        </sonar>
      </sensor>
    </link>
    <link name="L1Wheel">
      <gravity>1</gravity>
      <self_collide>0</self_collide>
      <pose>-0.114300000000001 -0.0431800000000009 0.0349249999999985 1.5707963267949 9.43689570931383E-16 -1.5707963267949</pose>
      <must_be_base_link>0</must_be_base_link>
      <velocity_decay>
        <linear>0</linear>
        <angular>0</angular>
      </velocity_decay>
      <inertial>
        <mass>0.408395441319621</mass>
        <pose>0 0 0 0 0 0</pose>
        <inertia>
          <ixx>0.00522885625259631</ixx>
          <ixy>0</ixy>
          <ixz>0</ixz>
          <iyy>0.00347976426556731</iyy>
          <iyz>0</iyz>
          <izz>0.00347976426556731</izz>
        </inertia>
      </inertial>
      <collision name="L1Wheel_collision">
        <pose>0.33147 -0.0688143351697925 -0.1143 0 0 0</pose>
        <geometry>
          <mesh>
            <scale>1 1 1</scale>
            <uri>model://SimBot/meshes/L1Wheel_col.STL</uri>
          </mesh>
        </geometry>
        <surface>
          <contact>
            <ode />
          </contact>
          <friction>
            <ode>
              <mu>1</mu>
              <mu2>1</mu2>
            </ode>
          </friction>
        </surface>
      </collision>
      <visual name="L1Wheel_visual">
        <pose>0.33147 -0.0688143351697925 -0.1143 0 0 0</pose>
        <material>
          <ambient>0.752941176470588 0.752941176470588 0.752941176470588 1</ambient>
          <diffuse>0.752941176470588 0.752941176470588 0.752941176470588 1</diffuse>
        </material>
        <geometry>
          <mesh>
            <scale>1 1 1</scale>
            <uri>model://SimBot/meshes/L1Wheel.STL</uri>
          </mesh>
        </geometry>
      </visual>
    </link>
    <joint name="Chassis-L1Wheel" type="revolute">
      <parent>Chassis</parent>
      <child>L1Wheel</child>
      <pose>0.02286 9.71445146547012E-17 1.38777878078145E-17 0 0 0</pose>
      <axis>
        <xyz>-1 -3.45075536041801E-15 0</xyz>
        <dynamics>
          <damping>1</damping>
          <friction>1</friction>
        </dynamics>
        <limit>
          <effort>100</effort>
        </limit>
      </axis>
    </joint>
    <link name="L2Wheel">
      <gravity>1</gravity>
      <self_collide>0</self_collide>
      <pose>-0.315134153322 -0.043180000000001 0.0285749999999969 1.5707963267949 9.43689570931383E-16 -1.5707963267949</pose>
      <must_be_base_link>0</must_be_base_link>
      <velocity_decay>
        <linear>0</linear>
        <angular>0</angular>
      </velocity_decay>
      <inertial>
        <mass>0.408395441319621</mass>
        <pose>0 0 0 0 0 0</pose>
        <inertia>
          <ixx>0.00522885625259631</ixx>
          <ixy>0</ixy>
          <ixz>0</ixz>
          <iyy>0.00347976426556731</iyy>
          <iyz>0</iyz>
          <izz>0.00347976426556731</izz>
        </inertia>
      </inertial>
      <collision name="L2Wheel_collision">
        <pose>0.33147 -0.0624643351697909 -0.315134153322 0 0 0</pose>
        <geometry>
          <mesh>
            <scale>1 1 1</scale>
            <uri>model://SimBot/meshes/L2Wheel_col.STL</uri>
          </mesh>
        </geometry>
        <surface>
          <contact>
            <ode />
          </contact>
          <friction>
            <ode>
              <mu>1</mu>
              <mu2>1</mu2>
            </ode>
          </friction>
        </surface>
      </collision>
      <visual name="L2Wheel_visual">
        <pose>0.33147 -0.0624643351697909 -0.315134153322 0 0 0</pose>
        <material>
          <ambient>0.752941176470588 0.752941176470588 0.752941176470588 1</ambient>
          <diffuse>0.752941176470588 0.752941176470588 0.752941176470588 1</diffuse>
        </material>
        <geometry>
          <mesh>
            <scale>1 1 1</scale>
            <uri>model://SimBot/meshes/L2Wheel.STL</uri>
          </mesh>
        </geometry>
      </visual>
    </link>
    <joint name="Chassis-L2Wheel" type="revolute">
      <parent>Chassis</parent>
      <child>L2Wheel</child>
      <pose>0.02286 9.71445146547012E-17 0 0 0 0</pose>
      <axis>
        <xyz>-1 -3.52264609709339E-15 0</xyz>
        <dynamics>
          <damping>1</damping>
          <friction>1</friction>
        </dynamics>
        <limit>
          <effort>100</effort>
        </limit>
      </axis>
    </joint>
    <link name="L3Wheel">
      <gravity>1</gravity>
      <self_collide>0</self_collide>
      <pose>-0.535765846678 -0.0431800000000008 0.0285749999999952 1.5707963267949 9.43689570931383E-16 -1.5707963267949</pose>
      <must_be_base_link>0</must_be_base_link>
      <velocity_decay>
        <linear>0</linear>
        <angular>0</angular>
      </velocity_decay>
      <inertial>
        <mass>0.408395441319621</mass>
        <pose>0 0 0 0 0 0</pose>
        <inertia>
          <ixx>0.00522885625259631</ixx>
          <ixy>0</ixy>
          <ixz>0</ixz>
          <iyy>0.00347976426556731</iyy>
          <iyz>0</iyz>
          <izz>0.00347976426556731</izz>
        </inertia>
      </inertial>
      <collision name="L3Wheel_collision">
        <pose>0.33147 -0.0624643351697891 -0.535765846678 0 0 0</pose>
        <geometry>
          <mesh>
            <scale>1 1 1</scale>
            <uri>model://SimBot/meshes/L3Wheel_col.STL</uri>
          </mesh>
        </geometry>
        <surface>
          <contact>
            <ode />
          </contact>
          <friction>
            <ode>
              <mu>1</mu>
              <mu2>1</mu2>
            </ode>
          </friction>
        </surface>
      </collision>
      <visual name="L3Wheel_visual">
        <pose>0.33147 -0.0624643351697891 -0.535765846678 0 0 0</pose>
        <material>
          <ambient>0.752941176470588 0.752941176470588 0.752941176470588 1</ambient>
          <diffuse>0.752941176470588 0.752941176470588 0.752941176470588 1</diffuse>
        </material>
        <geometry>
          <mesh>
            <scale>1 1 1</scale>
            <uri>model://SimBot/meshes/L3Wheel.STL</uri>
          </mesh>
        </geometry>
      </visual>
    </link>
    <joint name="Chassis-L3Wheel" type="revolute">
      <parent>Chassis</parent>
      <child>L3Wheel</child>
      <pose>0.0228600000000002 9.0205620750794E-17 0 0 0 0</pose>
      <axis>
        <xyz>-1 -3.52264609709339E-15 0</xyz>
        <dynamics>
          <damping>1</damping>
          <friction>1</friction>
        </dynamics>
        <limit>
          <effort>100</effort>
        </limit>
      </axis>
    </joint>
    <link name="L4Wheel">
      <gravity>1</gravity>
      <self_collide>0</self_collide>
      <pose>-0.7366 -0.0431800000000009 0.0349249999999936 1.5707963267949 9.43689570931383E-16 -1.5707963267949</pose>
      <must_be_base_link>0</must_be_base_link>
      <velocity_decay>
        <linear>0</linear>
        <angular>0</angular>
      </velocity_decay>
      <inertial>
        <mass>0.408395441319621</mass>
        <pose>0 0 0 0 0 0</pose>
        <inertia>
          <ixx>0.00522885625259631</ixx>
          <ixy>0</ixy>
          <ixz>0</ixz>
          <iyy>0.00347976426556731</iyy>
          <iyz>0</iyz>
          <izz>0.00347976426556731</izz>
        </inertia>
      </inertial>
      <collision name="L4Wheel_collision">
        <pose>0.33147 -0.0688143351697875 -0.7366 0 0 0</pose>
        <geometry>
          <mesh>
            <scale>1 1 1</scale>
            <uri>model://SimBot/meshes/L4Wheel_col.STL</uri>
          </mesh>
        </geometry>
        <surface>
          <contact>
            <ode />
          </contact>
          <friction>
            <ode>
              <mu>1</mu>
              <mu2>1</mu2>
            </ode>
          </friction>
        </surface>
      </collision>
      <visual name="L4Wheel_visual">
        <pose>0.33147 -0.0688143351697875 -0.7366 0 0 0</pose>
        <material>
          <ambient>0.752941176470588 0.752941176470588 0.752941176470588 1</ambient>
          <diffuse>0.752941176470588 0.752941176470588 0.752941176470588 1</diffuse>
        </material>
        <geometry>
          <mesh>
            <scale>1 1 1</scale>
            <uri>model://SimBot/meshes/L4Wheel.STL</uri>
          </mesh>
        </geometry>
      </visual>
    </link>
    <joint name="Chassis-L4Wheel" type="revolute">
      <parent>Chassis</parent>
      <child>L4Wheel</child>
      <pose>0.0228600000000002 9.71445146547012E-17 2.22044604925031E-16 0 0 0</pose>
      <axis>
        <xyz>-1 -3.45075536041802E-15 0</xyz>
        <dynamics>
          <damping>1</damping>
          <friction>1</friction>
        </dynamics>
        <limit>
          <effort>100</effort>
        </limit>
      </axis>
    </joint>
    <link name="R1Wheel">
      <gravity>1</gravity>
      <self_collide>0</self_collide>
      <pose>-0.114299999999999 -0.706120000000001 0.0349249999999995 1.5707963267949 9.43689570931383E-16 -1.5707963267949</pose>
      <must_be_base_link>0</must_be_base_link>
      <velocity_decay>
        <linear>0</linear>
        <angular>0</angular>
      </velocity_decay>
      <inertial>
        <mass>0.408395441319621</mass>
        <pose>0 0 0 0 0 0</pose>
        <inertia>
          <ixx>0.00522885625259631</ixx>
          <ixy>0</ixy>
          <ixz>0</ixz>
          <iyy>0.00347976426556731</iyy>
          <iyz>0</iyz>
          <izz>0.00347976426556731</izz>
        </inertia>
      </inertial>
      <collision name="R1Wheel_collision">
        <pose>-0.33147 -0.0688143351697941 -0.114299999999999 0 0 0</pose>
        <geometry>
          <mesh>
            <scale>1 1 1</scale>
            <uri>model://SimBot/meshes/R1Wheel_col.STL</uri>
          </mesh>
        </geometry>
        <surface>
          <contact>
            <ode />
          </contact>
          <friction>
            <ode>
              <mu>1</mu>
              <mu2>1</mu2>
            </ode>
          </friction>
        </surface>
      </collision>
      <visual name="R1Wheel_visual">
        <pose>-0.33147 -0.0688143351697941 -0.114299999999999 0 0 0</pose>
        <material>
          <ambient>0.752941176470588 0.752941176470588 0.752941176470588 1</ambient>
          <diffuse>0.752941176470588 0.752941176470588 0.752941176470588 1</diffuse>
        </material>
        <geometry>
          <mesh>
            <scale>1 1 1</scale>
            <uri>model://SimBot/meshes/R1Wheel.STL</uri>
          </mesh>
        </geometry>
      </visual>
    </link>
    <joint name="Chassis-R1Wheel" type="revolute">
      <parent>Chassis</parent>
      <child>R1Wheel</child>
      <pose>-0.0228599999999999 0 0 0 0 0</pose>
      <axis>
        <xyz>1 0 0</xyz>
        <dynamics>
          <damping>1</damping>
          <friction>1</friction>
        </dynamics>
        <limit>
          <effort>100</effort>
        </limit>
      </axis>
    </joint>
    <link name="R2Wheel">
      <gravity>1</gravity>
      <self_collide>0</self_collide>
      <pose>-0.315134153321999 -0.706120000000001 0.028575000000001 1.5707963267949 9.43689570931383E-16 -1.5707963267949</pose>
      <must_be_base_link>0</must_be_base_link>
      <velocity_decay>
        <linear>0</linear>
        <angular>0</angular>
      </velocity_decay>
      <inertial>
        <mass>0.408395441319621</mass>
        <pose>0 0 0 0 0 0</pose>
        <inertia>
          <ixx>0.00522885625259631</ixx>
          <ixy>0</ixy>
          <ixz>0</ixz>
          <iyy>0.00347976426556731</iyy>
          <iyz>0</iyz>
          <izz>0.00347976426556731</izz>
        </inertia>
      </inertial>
      <collision name="R2Wheel_collision">
        <pose>-0.33147 -0.0624643351697957 -0.315134153321999 0 0 0</pose>
        <geometry>
          <mesh>
            <scale>1 1 1</scale>
            <uri>model://SimBot/meshes/R2Wheel_col.STL</uri>
          </mesh>
        </geometry>
        <surface>
          <contact>
            <ode />
          </contact>
          <friction>
            <ode>
              <mu>1</mu>
              <mu2>1</mu2>
            </ode>
          </friction>
        </surface>
      </collision>
      <visual name="R2Wheel_visual">
        <pose>-0.33147 -0.0624643351697957 -0.315134153321999 0 0 0</pose>
        <material>
          <ambient>0.752941176470588 0.752941176470588 0.752941176470588 1</ambient>
          <diffuse>0.752941176470588 0.752941176470588 0.752941176470588 1</diffuse>
        </material>
        <geometry>
          <mesh>
            <scale>1 1 1</scale>
            <uri>model://SimBot/meshes/R2Wheel.STL</uri>
          </mesh>
        </geometry>
      </visual>
    </link>
    <joint name="Chassis-R2Wheel" type="revolute">
      <parent>Chassis</parent>
      <child>R2Wheel</child>
      <pose>-0.02286 0 0 0 0 0</pose>
      <axis>
        <xyz>1 0 0</xyz>
        <dynamics>
          <damping>1</damping>
          <friction>1</friction>
        </dynamics>
        <limit>
          <effort>100</effort>
        </limit>
      </axis>
    </joint>
    <link name="R3Wheel">
      <gravity>1</gravity>
      <self_collide>0</self_collide>
      <pose>-0.535765846677999 -0.706120000000001 0.0285750000000027 1.5707963267949 9.43689570931383E-16 -1.5707963267949</pose>
      <must_be_base_link>0</must_be_base_link>
      <velocity_decay>
        <linear>0</linear>
        <angular>0</angular>
      </velocity_decay>
      <inertial>
        <mass>0.408395441319621</mass>
        <pose>0 0 0 0 0 0</pose>
        <inertia>
          <ixx>0.00522885625259631</ixx>
          <ixy>0</ixy>
          <ixz>0</ixz>
          <iyy>0.00347976426556731</iyy>
          <iyz>0</iyz>
          <izz>0.00347976426556731</izz>
        </inertia>
      </inertial>
      <collision name="R3Wheel_collision">
        <pose>-0.33147 -0.0624643351697973 -0.535765846677999 0 0 0</pose>
        <geometry>
          <mesh>
            <scale>1 1 1</scale>
            <uri>model://SimBot/meshes/R3Wheel_col.STL</uri>
          </mesh>
        </geometry>
        <surface>
          <contact>
            <ode />
          </contact>
          <friction>
            <ode>
              <mu>1</mu>
              <mu2>1</mu2>
            </ode>
          </friction>
        </surface>
      </collision>
      <visual name="R3Wheel_visual">
        <pose>-0.33147 -0.0624643351697973 -0.535765846677999 0 0 0</pose>
        <material>
          <ambient>0.752941176470588 0.752941176470588 0.752941176470588 1</ambient>
          <diffuse>0.752941176470588 0.752941176470588 0.752941176470588 1</diffuse>
        </material>
        <geometry>
          <mesh>
            <scale>1 1 1</scale>
            <uri>model://SimBot/meshes/R3Wheel.STL</uri>
          </mesh>
        </geometry>
      </visual>
    </link>
    <joint name="Chassis-R3Wheel" type="revolute">
      <parent>Chassis</parent>
      <child>R3Wheel</child>
      <pose>-0.02286 0 0 0 0 0</pose>
      <axis>
        <xyz>1 0 0</xyz>
        <dynamics>
          <damping>1</damping>
          <friction>1</friction>
        </dynamics>
        <limit>
          <effort>100</effort>
        </limit>
      </axis>
    </joint>
    <link name="R4Wheel">
      <gravity>1</gravity>
      <self_collide>0</self_collide>
      <pose>-0.736599999999999 -0.706120000000001 0.0349250000000045 1.5707963267949 9.43689570931383E-16 -1.5707963267949</pose>
      <must_be_base_link>0</must_be_base_link>
      <velocity_decay>
        <linear>0</linear>
        <angular>0</angular>
      </velocity_decay>
      <inertial>
        <mass>0.408395441319621</mass>
        <pose>0 0 0 0 0 0</pose>
        <inertia>
          <ixx>0.00522885625259631</ixx>
          <ixy>0</ixy>
          <ixz>0</ixz>
          <iyy>0.00347976426556731</iyy>
          <iyz>0</iyz>
          <izz>0.00347976426556731</izz>
        </inertia>
      </inertial>
      <collision name="R4Wheel_collision">
        <pose>-0.33147 -0.068814335169799 -0.736599999999999 0 0 0</pose>
        <geometry>
          <mesh>
            <scale>1 1 1</scale>
            <uri>model://SimBot/meshes/R4Wheel_col.STL</uri>
          </mesh>
        </geometry>
        <surface>
          <contact>
            <ode />
          </contact>
          <friction>
            <ode>
              <mu>1</mu>
              <mu2>1</mu2>
            </ode>
          </friction>
        </surface>
      </collision>
      <visual name="R4Wheel_visual">
        <pose>-0.33147 -0.068814335169799 -0.736599999999999 0 0 0</pose>
        <material>
          <ambient>0.752941176470588 0.752941176470588 0.752941176470588 1</ambient>
          <diffuse>0.752941176470588 0.752941176470588 0.752941176470588 1</diffuse>
        </material>
        <geometry>
          <mesh>
            <scale>1 1 1</scale>
            <uri>model://SimBot/meshes/R4Wheel.STL</uri>
          </mesh>
        </geometry>
      </visual>
    </link>
    <joint name="Chassis-R4Wheel" type="revolute">
      <parent>Chassis</parent>
      <child>R4Wheel</child>
      <pose>-0.02286 8.32667268468867E-17 2.22044604925031E-16 0 0 0</pose>
      <axis>
        <xyz>1 0 0</xyz>
        <dynamics>
          <damping>1</damping>
          <friction>1</friction>
        </dynamics>
        <limit>
          <effort>100</effort>
        </limit>
      </axis>
    </joint>
    <link name="BallPusher">
      <gravity>1</gravity>
      <self_collide>0</self_collide>
      <pose>-0.238570181492384 -0.375450100000002 0.19377226965446 1.5707963267949 9.43689570931383E-16 -1.5707963267949</pose>
      <must_be_base_link>0</must_be_base_link>
      <velocity_decay>
        <linear>0</linear>
        <angular>0</angular>
      </velocity_decay>
      <inertial>
        <mass>0.35512835424996</mass>
        <pose>0 0 0 0 0 0</pose>
        <inertia>
          <ixx>0.00398094008995737</ixx>
          <ixy>3.11690149718261E-17</ixy>
          <ixz>2.20178364811434E-17</ixz>
          <iyy>0.0516965584441365</iyy>
          <iyz>0.00161224196633065</iyz>
          <izz>0.0535800222476808</izz>
        </inertia>
      </inertial>
      <collision name="BallPusher_collision">
        <pose>-0.000800100000000598 -0.227661604824254 -0.238570181492384 0 0 0</pose>
        <geometry>
          <mesh>
            <scale>1 1 1</scale>
            <uri>model://SimBot/meshes/BallPusher_col.STL</uri>
          </mesh>
        </geometry>
        <surface>
          <contact>
            <ode />
          </contact>
          <friction>
            <ode>
              <mu>1</mu>
              <mu2>1</mu2>
            </ode>
          </friction>
        </surface>
      </collision>
      <visual name="BallPusher_visual">
        <pose>-0.000800100000000598 -0.227661604824254 -0.238570181492384 0 0 0</pose>
        <material>
          <ambient>1 0.752941176470588 0.501960784313725 1</ambient>
          <diffuse>1 0.752941176470588 0.501960784313725 1</diffuse>
        </material>
        <geometry>
          <mesh>
            <scale>1 1 1</scale>
            <uri>model://SimBot/meshes/BallPusher.STL</uri>
          </mesh>
        </geometry>
      </visual>
    </link>
    <joint name="Chassis-BallPusher" type="prismatic">
      <parent>Chassis</parent>
      <child>BallPusher</child>
      <pose>0 0 0 0 0 0</pose>
      <axis>
       <xyz>0 0.5 1</xyz>
        <dynamics>
          <damping>1</damping>
          <friction>1</friction>
        </dynamics>
        <limit>
          <upper>0.5</upper>
          <lower>0.0</lower>
          <effort>100</effort>
        </limit>
      </axis>
    </joint>
    <link name="GearPlate">
      <gravity>1</gravity>
      <self_collide>0</self_collide>
      <pose>-0.034925 -0.374650000000001 0.225425 1.5707963267949 9.43689570931383E-16 -1.5707963267949</pose>
      <must_be_base_link>0</must_be_base_link>
      <velocity_decay>
        <linear>0</linear>
        <angular>0</angular>
      </velocity_decay>
      <inertial>
        <mass>0.0286773620000001</mass>
        <pose>0 0 0 0 0 0</pose>
        <inertia>
          <ixx>0.001</ixx>
          <ixy>0</ixy>
          <ixz>0</ixz>
          <iyy>0.003</iyy>
          <iyz>0</iyz>
          <izz>0.001</izz>
        </inertia>
      </inertial>
      <collision name="GearPlate_collision">
        <pose>-1.33685024238989E-16 -0.259314335169794 -0.034925 0 0 0</pose>
        <geometry>
          <mesh>
            <scale>1 1 1</scale>
            <uri>model://SimBot/meshes/GearPlate_col.STL</uri>
          </mesh>
        </geometry>
        <surface>
          <contact>
            <ode />
          </contact>
          <friction>
            <ode>
              <mu>1</mu>
              <mu2>1</mu2>
            </ode>
          </friction>
        </surface>
      </collision>
      <visual name="GearPlate_visual">
        <pose>-1.33685024238989E-16 -0.259314335169794 -0.034925 0 0 0</pose>
        <material>
          <ambient>1 0 0 1</ambient>
          <diffuse>1 0 0 1</diffuse>
        </material>
        <geometry>
          <mesh>
            <scale>1 1 1</scale>
            <uri>model://SimBot/meshes/GearPlate.STL</uri>
          </mesh>
        </geometry>
      </visual>
    </link>
    <joint name="Chassis-GearPlate" type="prismatic">
      <parent>Chassis</parent>
      <child>GearPlate</child>
      <pose>-0.04445 0.00317500000000004 -0.0254 0 0 0</pose>
      <axis>
        <xyz>0 0 1</xyz>
        <dynamics>
          <damping>0.2</damping>
          <friction>0.2</friction>
        </dynamics>
        <limit>
          <upper>0.05</upper>
          <lower>0.0</lower>
          <effort>100</effort>
        </limit>
      </axis>
    </joint>
    <plugin name="Chassis_rangefinder" filename="librangefinder.so">
      <topic>/gazebo/frc/simulator/analog/0</topic>
      <sensor>ChassisUltrasonic</sensor>
    </plugin>
    <plugin name="Chassis-L1Wheel_motor" filename="libdc_motor.so">
      <joint>Chassis-L1Wheel</joint>
      <topic>/gazebo/frc/simulator/pwm/2</topic>
      <multiplier>25</multiplier>
    </plugin>
    <plugin name="Chassis-L2Wheel_motor" filename="libdc_motor.so">
      <joint>Chassis-L2Wheel</joint>
      <topic>/gazebo/frc/simulator/pwm/2</topic>
      <multiplier>25</multiplier>
    </plugin>
    <plugin name="Chassis-L2Wheel_encoder" filename="libencoder.so">
      <joint>Chassis-L2Wheel</joint>
      <topic>/gazebo/frc/simulator/dio/3/4</topic>
      <units>degrees</units>
    </plugin>
    <plugin name="Chassis-L3Wheel_motor" filename="libdc_motor.so">
      <joint>Chassis-L3Wheel</joint>
      <topic>/gazebo/frc/simulator/pwm/2</topic>
      <multiplier>25</multiplier>
    </plugin>
    <plugin name="Chassis-L4Wheel_motor" filename="libdc_motor.so">
      <joint>Chassis-L4Wheel</joint>
      <topic>/gazebo/frc/simulator/pwm/2</topic>
      <multiplier>25</multiplier>
    </plugin>
    <plugin name="Chassis-R1Wheel_motor" filename="libdc_motor.so">
      <joint>Chassis-R1Wheel</joint>
      <topic>/gazebo/frc/simulator/pwm/4</topic>
      <multiplier>25</multiplier>
    </plugin>
    <plugin name="Chassis-R2Wheel_motor" filename="libdc_motor.so">
      <joint>Chassis-R2Wheel</joint>
      <topic>/gazebo/frc/simulator/pwm/4</topic>
      <multiplier>25</multiplier>
    </plugin>
    <plugin name="Chassis-R2Wheel_encoder" filename="libencoder.so">
      <joint>Chassis-R2Wheel</joint>
      <topic>/gazebo/frc/simulator/dio/7/8</topic>
      <units>degrees</units>
    </plugin>
    <plugin name="Chassis-R3Wheel_motor" filename="libdc_motor.so">
      <joint>Chassis-R3Wheel</joint>
      <topic>/gazebo/frc/simulator/pwm/4</topic>
      <multiplier>25</multiplier>
    </plugin>
    <plugin name="Chassis-R4Wheel_motor" filename="libdc_motor.so">
      <joint>Chassis-R4Wheel</joint>
      <topic>/gazebo/frc/simulator/pwm/4</topic>
      <multiplier>25</multiplier>
    </plugin>
    <plugin name="Chassis-Gearplate" filename="libpneumatic_piston.so">
      <joint>Chassis-GearPlate</joint>
      <direction>forward</direction>
      <forward-force>1</forward-force>
      <reverse-force>1</reverse-force>
      <topic>/gazebo/frc/simulator/pneumatic/1/1</topic>
    </plugin>
    <plugin name="Chassis-BallPusher_motor" filename="libdc_motor.so">
      <joint>Chassis-BallPusher</joint>
      <topic>/gazebo/frc/simulator/pwm/5</topic>
      <multiplier>25</multiplier>
    </plugin>
    <plugin name="BallPusher_fwdlimit" filename="liblimit_switch.so">
      <joint>Chassis-BallPusher</joint>
      <topic>/gazebo/frc/simulator/dio/10</topic>
      <units>radians</units>
      <type>internal</type>
      <min>0.45</min>
      <max>0.5</max>
    </plugin>
    <plugin name="BallPusher_revlimit" filename="liblimit_switch.so">
      <joint>Chassis-BallPusher</joint>
      <topic>/gazebo/frc/simulator/dio/9</topic>
      <units>radians</units>
      <type>internal</type>
      <min>0</min>
      <max>0.1</max>
    </plugin>
    <plugin name="Chassis" filename="libgyro.so">
      <link>Chassis</link>
      <topic>/gazebo/frc/simulator/analog/3</topic>
      <units>degrees</units>
      <axis>yaw</axis>
    </plugin>

  </model>
</sdf>
