<?xml version="1.0" encoding="utf-8"?>
<sdf version="1.5">
  <model name="Switch">
    <pose>0 0 1.73472347597681E-17 0 0 0</pose>
    <plugin name="clock" filename="libclock.so">
      <topic>/gazebo/frc/time</topic>
    </plugin>
    <link name="SwitchBase">
      <gravity>1</gravity>
      <self_collide>0</self_collide>
      <pose>-1.94930231043484 -0.710660931772002 0.235895978961787 1.56083715346702 -0.0111679625054779 -1.58452574383917</pose>
      <must_be_base_link>0</must_be_base_link>
      <velocity_decay>
        <linear>0</linear>
        <angular>0</angular>
      </velocity_decay>
      <inertial>
        <mass>81.8371477628258</mass>
        <pose>0 0 0 0 0 0</pose>
        <inertia>
          <ixx>0.671725360517504</ixx>
          <ixy>0.414975205473895</ixy>
          <ixz>1.70824830286996</ixz>
          <iyy>18.2756885389048</iyy>
          <iyz>0.0226876778943001</iyz>
          <izz>18.1734623592377</izz>
        </inertia>
      </inertial>
      <collision name="SwitchBase_collision">
        <pose>0.00278733220058235 -0.234161479413464 0.0192355113635591 0 0 0</pose>
        <geometry>
          <mesh>
            <scale>1 1 1</scale>
            <uri>model://Switch/meshes/SwitchBase_col.STL</uri>
          </mesh>
        </geometry>
        <surface>
          <contact>
            <ode />
          </contact>
          <friction>
            <ode>
              <mu>1</mu>
              <mu2>1</mu2>
            </ode>
          </friction>
        </surface>
      </collision>
      <visual name="SwitchBase_visual">
        <pose>0.00278733220058235 -0.234161479413464 0.0192355113635591 0 0 0</pose>
        <material>
          <ambient>0.501960784313725 1 0.501960784313725 1</ambient>
          <diffuse>0.501960784313725 1 0.501960784313725 1</diffuse>
        </material>
        <geometry>
          <mesh>
            <scale>1 1 1</scale>
            <uri>model://Switch/meshes/SwitchBase.STL</uri>
          </mesh>
        </geometry>
      </visual>
    </link>
  
    <joint name="SwitchBase-World" type="fixed">
      <parent>world</parent>
      <child>SwitchBase</child>
   </joint>
<!-- -->
    <link name="SwitchArm">
      <gravity>1</gravity>
      <self_collide>0</self_collide>
      <pose>-1.95097470543896 -0.71121363366971 0.277429681849084 1.56083715346702 -0.0111679625054779 -1.58452574383917</pose>
      <must_be_base_link>0</must_be_base_link>
      <velocity_decay>
        <linear>0</linear>
        <angular>0</angular>
      </velocity_decay>
      <inertial>
        <mass>38.1967963297716</mass>
        <pose>0 0 0 0 0 0</pose>
        <inertia>
          <ixx>53.1684372630027</ixx>
          <ixy>0.0207602613518314</ixy>
          <ixz>0.70905846230451</ixz>
          <iyy>55.0577635708108</iyy>
          <iyz>0.00376744054542572</iyz>
          <izz>1.94863377057256</izz>
        </inertia>
      </inertial>
      <collision name="SwitchArm_collision">
        <pose>0.00174792080733605 -0.275667526401305 0.017157399873175 0 0 0</pose>
        <geometry>
          <mesh>
            <scale>1 1 1</scale>
            <uri>model://Switch/meshes/SwitchArm_col.STL</uri>
          </mesh>
        </geometry>
        <surface>
          <contact>
            <ode />
          </contact>
          <friction>
            <ode>
              <mu>1</mu>
            </ode>
          </friction>
        </surface>
      </collision>
      <visual name="SwitchArm_visual">
        <pose>0.00174792080733605 -0.275667526401305 0.017157399873175 0 0 0</pose>
        <material>
          <ambient>1 0.250980392156863 0.501960784313725 1</ambient>
          <diffuse>1 0.250980392156863 0.501960784313725 1</diffuse>
        </material>
        <geometry>
          <mesh>
            <scale>1 1 1</scale>
            <uri>model://Switch/meshes/SwitchArm.STL</uri>
          </mesh>
        </geometry>
      </visual>
    </link>
    <joint name="SwitchBase-SwitchArm" type="revolute">
      <parent>SwitchBase</parent>
      <child>SwitchArm</child>
      <pose>0.00156401763844416 0.141795833491346 -1.08259137786212E-05 0 0 0</pose>
      <axis>
        <xyz>0.999843397866503 -0.0110293969633813 -0.0138395139145314</xyz>
        <dynamics>
          <damping>1</damping>
          <friction>1</friction>
        </dynamics>
        <limit>
          <upper>0.05</upper>
          <lower>-0.05</lower>
          <effort>1</effort>
        </limit>
      </axis>
    </joint>

  </model>
</sdf>
