<?xml version="1.0" encoding="utf-8"?>
<sdf version="1.5">
  <model name="2018Robot2">
    <pose>0 0 0.07612 0 0 0</pose>
    <plugin name="clock" filename="libclock.so">
      <topic>/gazebo/frc/time</topic>
    </plugin>
    <link name="Body">
      <gravity>1</gravity>
      <self_collide>0</self_collide>
      <pose>0.0433693299416092 1.24492768995206E-06 0.0150575767105084 1.5707963267949 0 1.5707963267949</pose>
      <must_be_base_link>1</must_be_base_link>
      <velocity_decay>
        <linear>0</linear>
        <angular>0</angular>
      </velocity_decay>
      <inertial>
        <mass>22.7190107961189</mass>
        <pose>1.35525271560688E-20 -3.46944695195361E-17 -5.20417042793042E-18 0 0 0</pose>
        <inertia>
          <ixx>0</ixx>
          <ixy>0</ixy>
          <ixz>0</ixz>
          <iyy>0</iyy>
          <iyz>0</iyz>
          <izz>0</izz>
        </inertia>
      </inertial>
      <collision name="Body_collision">
        <pose>-7.15618803542915E-05 -0.0136589799305968 0.00809292482246544 0 0 0</pose>
        <geometry>
          <mesh>
            <scale>1 1 1</scale>
            <uri>model://2018Robot2/meshes/Body_col.STL</uri>
          </mesh>
        </geometry>
        <surface>
          <contact>
            <ode />
          </contact>
          <friction>
            <ode>
              <mu>1</mu>
              <mu2>1</mu2>
            </ode>
          </friction>
        </surface>
      </collision>
      <visual name="Body_visual">
        <pose>-7.15618803542915E-05 -0.0136589799305968 0.00809292482246544 0 0 0</pose>
        <material>
          <ambient>0 0 1 1</ambient>
          <diffuse>0 0 1 1</diffuse>
        </material>
        <geometry>
          <mesh>
            <scale>1 1 1</scale>
            <uri>model://2018Robot2/meshes/Body.STL</uri>
          </mesh>
        </geometry>
      </visual>
      <sensor name="BodyCamera" type="camera">
        <visualize>1</visualize>
        <always_on>1</always_on>
        <pose>-1.24492768898031E-06 0.0611424232894916 0.220235735460366 4.71238898038469 4.71238898038469 0</pose>
        <camera name="Bodycamera">
          <horizontal_fov>1.5707963267949</horizontal_fov>
          <image>
            <width>320</width>
            <height>240</height>
          </image>
          <clip>
            <near>0.1</near>
            <far>100</far>
          </clip>
        </camera>
      </sensor>
    </link>
    <link name="Bumpers">
      <gravity>1</gravity>
      <self_collide>0</self_collide>
      <pose>0.0468968962464854 -3.51584763099529E-05 0.0504398952900915 1.5707963267949 0 1.5707963267949</pose>
      <must_be_base_link>0</must_be_base_link>
      <velocity_decay>
        <linear>0</linear>
        <angular>0</angular>
      </velocity_decay>
      <inertial>
        <mass>0.398486040545588</mass>
        <pose>6.7762635780344E-21 0 -4.33680868994202E-18 0 0 0</pose>
        <inertia>
          <ixx>0</ixx>
          <ixy>1.03639166087484E-14</ixy>
          <ixz>2.06193574704558E-06</ixz>
          <iyy>0.05253931798121</iyy>
          <iyz>4.06737867734299E-19</iyz>
          <izz>0.0525393179002881</izz>
        </inertia>
      </inertial>
      <collision name="Bumpers_collision">
        <pose>-3.51584763543873E-05 -0.04904129851018 0.00456535851758921 0 0 0</pose>
        <geometry>
          <mesh>
            <scale>1 1 1</scale>
            <uri>model://2018Robot2/meshes/Bumpers_col.STL</uri>
          </mesh>
        </geometry>
        <surface>
          <contact>
            <ode />
          </contact>
          <friction>
            <ode>
              <mu>1</mu>
              <mu2>1</mu2>
            </ode>
          </friction>
        </surface>
      </collision>
      <visual name="Bumpers_visual">
        <pose>-3.51584763543873E-05 -0.04904129851018 0.00456535851758921 0 0 0</pose>
        <material>
          <ambient>1 0 0 1</ambient>
          <diffuse>1 0 0 1</diffuse>
        </material>
        <geometry>
          <mesh>
            <scale>1 1 1</scale>
            <uri>model://2018Robot2/meshes/Bumpers.STL</uri>
          </mesh>
        </geometry>
      </visual>
    </link>
    <joint name="Body-Bumpers" type="prismatic">
      <parent>Body</parent>
      <child>Bumpers</child>
      <pose>0.304835158476311 -0.0554398952900915 6.07153216591882E-18 0 0 0</pose>
      <axis>
        <xyz>0 0 1</xyz>
        <dynamics>
          <damping>1</damping>
          <friction>1</friction>
        </dynamics>
        <limit>
          <upper>0</upper>
          <lower>0</lower>
          <effort>1</effort>
        </limit>
      </axis>
    </joint>
    <link name="LFWheel">
      <gravity>1</gravity>
      <self_collide>0</self_collide>
      <pose>0.345346896246474 0.328549000000001 0.026924 1.5707963267949 0 1.5707963267949</pose>
      <must_be_base_link>0</must_be_base_link>
      <velocity_decay>
        <linear>0</linear>
        <angular>0</angular>
      </velocity_decay>
      <inertial>
        <mass>0.593273105209116</mass>
        <pose>0 0 0 0 0 0</pose>
        <inertia>
          <ixx>0</ixx>
          <ixy>0</ixy>
          <ixz>0</ixz>
          <iyy>0</iyy>
          <iyz>0</iyz>
          <izz>0</izz>
        </inertia>
      </inertial>
      <collision name="LFWheel_collision">
        <pose>-0.328619316952665 -0.0255254032200884 -0.2938846414824 0 0 0</pose>
        <geometry>
          <mesh>
            <scale>1 1 1</scale>
            <uri>model://2018Robot2/meshes/LFWheel_col.STL</uri>
          </mesh>
        </geometry>
        <surface>
          <contact>
            <ode>
              <kp>1000000</kp>
              <kd>10</kd>
            </ode>
          </contact>
          <friction>
            <ode>
              <mu>1</mu>
              <mu2>1</mu2>
            </ode>
          </friction>
        </surface>
      </collision>
      <visual name="LFWheel_visual">
        <pose>-0.328619316952665 -0.0255254032200884 -0.2938846414824 0 0 0</pose>
        <material>
          <ambient>0.501960784313725 0.501960784313725 0.501960784313725 1</ambient>
          <diffuse>0.501960784313725 0.501960784313725 0.501960784313725 1</diffuse>
        </material>
        <geometry>
          <mesh>
            <scale>1 1 1</scale>
            <uri>model://2018Robot2/meshes/LFWheel.STL</uri>
          </mesh>
        </geometry>
      </visual>
    </link>
    <joint name="Body-LFWheel" type="revolute">
      <parent>Body</parent>
      <child>LFWheel</child>
      <pose>0 2.77555756156289E-17 -5.55111512312578E-17 0 0 3.14159265358979</pose>
      <axis>
        <xyz>-1 -1.22460635382238E-16 0</xyz>
        <dynamics>
          <damping>1</damping>
          <friction>1</friction>
        </dynamics>
        <limit>
          <effort>20</effort>
        </limit>
      </axis>
    </joint>
    <link name="LCWheel">
      <gravity>1</gravity>
      <self_collide>0</self_collide>
      <pose>0.0468968962464743 0.328549000000001 0.0220472 1.5707963267949 0 1.5707963267949</pose>
      <must_be_base_link>0</must_be_base_link>
      <velocity_decay>
        <linear>0</linear>
        <angular>0</angular>
      </velocity_decay>
      <inertial>
        <mass>0.593273105209116</mass>
        <pose>0 0 0 0 0 0</pose>
        <inertia>
          <ixx>0</ixx>
          <ixy>0</ixy>
          <ixz>0</ixz>
          <iyy>0</iyy>
          <iyz>0</iyz>
          <izz>0</izz>
        </inertia>
      </inertial>
      <collision name="LCWheel_collision">
        <pose>-0.328619316952665 -0.0206486032200884 0.00456535851760044 0 0 0</pose>
        <geometry>
          <mesh>
            <scale>1 1 1</scale>
            <uri>model://2018Robot2/meshes/LCWheel_col.STL</uri>
          </mesh>
        </geometry>
        <surface>
          <contact>
            <ode>
              <kp>1000000</kp>
              <kd>10</kd>
            </ode>
          </contact>
          <friction>
            <ode>
              <mu>1</mu>
              <mu2>1</mu2>
            </ode>
          </friction>
        </surface>
      </collision>
      <visual name="LCWheel_visual">
        <pose>-0.328619316952665 -0.0206486032200884 0.00456535851760044 0 0 0</pose>
        <material>
          <ambient>0.501960784313725 0.501960784313725 0.501960784313725 1</ambient>
          <diffuse>0.501960784313725 0.501960784313725 0.501960784313725 1</diffuse>
        </material>
        <geometry>
          <mesh>
            <scale>1 1 1</scale>
            <uri>model://2018Robot2/meshes/LCWheel.STL</uri>
          </mesh>
        </geometry>
      </visual>
    </link>
    <joint name="Body-LCWheel" type="revolute">
      <parent>Body</parent>
      <child>LCWheel</child>
      <pose>0 6.93889390390723E-18 -3.46944695195361E-18 0 0 3.14159265358979</pose>
      <axis>
        <xyz>-1 -1.22460635382238E-16 0</xyz>
        <dynamics>
          <damping>1</damping>
          <friction>1</friction>
        </dynamics>
        <limit>
          <effort>20</effort>
        </limit>
      </axis>
    </joint>
    <link name="LBWheel">
      <gravity>1</gravity>
      <self_collide>0</self_collide>
      <pose>-0.251553103753526 0.328549000000001 0.0269239999999999 1.5707963267949 0 1.5707963267949</pose>
      <must_be_base_link>0</must_be_base_link>
      <velocity_decay>
        <linear>0</linear>
        <angular>0</angular>
      </velocity_decay>
      <inertial>
        <mass>0.593273105209116</mass>
        <pose>0 0 0 0 0 0</pose>
        <inertia>
          <ixx>0</ixx>
          <ixy>0</ixy>
          <ixz>0</ixz>
          <iyy>0</iyy>
          <iyz>0</iyz>
          <izz>0</izz>
        </inertia>
      </inertial>
      <collision name="LBWheel_collision">
        <pose>-0.328619316952665 -0.0255254032200885 0.3030153585176 0 0 0</pose>
        <geometry>
          <mesh>
            <scale>1 1 1</scale>
            <uri>model://2018Robot2/meshes/LBWheel_col.STL</uri>
          </mesh>
        </geometry>
        <surface>
          <contact>
            <ode>
              <kp>1000000</kp>
              <kd>10</kd>
            </ode>
          </contact>
          <friction>
            <ode>
              <mu>1</mu>
              <mu2>1</mu2>
            </ode>
          </friction>
        </surface>
      </collision>
      <visual name="LBWheel_visual">
        <pose>-0.328619316952665 -0.0255254032200885 0.3030153585176 0 0 0</pose>
        <material>
          <ambient>0.501960784313725 0.501960784313725 0.501960784313725 1</ambient>
          <diffuse>0.501960784313725 0.501960784313725 0.501960784313725 1</diffuse>
        </material>
        <geometry>
          <mesh>
            <scale>1 1 1</scale>
            <uri>model://2018Robot2/meshes/LBWheel.STL</uri>
          </mesh>
        </geometry>
      </visual>
    </link>
    <joint name="Body-LBWheel" type="revolute">
      <parent>Body</parent>
      <child>LBWheel</child>
      <pose>0 -1.73472347597681E-17 5.55111512312578E-17 0 0 3.14159265358979</pose>
      <axis>
        <xyz>-1 -1.22460635382238E-16 0</xyz>
        <dynamics>
          <damping>1</damping>
          <friction>1</friction>
        </dynamics>
        <limit>
          <effort>20</effort>
        </limit>
      </axis>
    </joint>
    <link name="RFWheel">
      <gravity>1</gravity>
      <self_collide>0</self_collide>
      <pose>0.347862527162241 -0.328548999999999 0.0280925888899449 1.5707963267949 0 1.5707963267949</pose>
      <must_be_base_link>0</must_be_base_link>
      <velocity_decay>
        <linear>0</linear>
        <angular>0</angular>
      </velocity_decay>
      <inertial>
        <mass>0.593273105209116</mass>
        <pose>0 0 0 0 0 0</pose>
        <inertia>
          <ixx>0</ixx>
          <ixy>0</ixy>
          <ixz>0</ixz>
          <iyy>0</iyy>
          <iyz>0</iyz>
          <izz>0</izz>
        </inertia>
      </inertial>
      <collision name="RFWheel_collision">
        <pose>0.328478683047335 -0.0266939921100333 -0.296400272398166 0 0 0</pose>
        <geometry>
          <mesh>
            <scale>1 1 1</scale>
            <uri>model://2018Robot2/meshes/RFWheel_col.STL</uri>
          </mesh>
        </geometry>
        <surface>
          <contact>
            <ode>
              <kp>1000000</kp>
              <kd>10</kd>
            </ode>
          </contact>
          <friction>
            <ode>
              <mu>1</mu>
              <mu2>1</mu2>
            </ode>
          </friction>
        </surface>
      </collision>
      <visual name="RFWheel_visual">
        <pose>0.328478683047335 -0.0266939921100333 -0.296400272398166 0 0 0</pose>
        <material>
          <ambient>0.501960784313725 0.501960784313725 0.501960784313725 1</ambient>
          <diffuse>0.501960784313725 0.501960784313725 0.501960784313725 1</diffuse>
        </material>
        <geometry>
          <mesh>
            <scale>1 1 1</scale>
            <uri>model://2018Robot2/meshes/RFWheel.STL</uri>
          </mesh>
        </geometry>
      </visual>
    </link>
    <joint name="Body-RFWheel" type="revolute">
      <parent>Body</parent>
      <child>RFWheel</child>
      <pose>5.55111512312578E-17 -6.93889390390723E-18 0 0 0 3.14159265358979</pose>
      <axis>
        <xyz>-1 -1.22460635382238E-16 0</xyz>
        <dynamics>
          <damping>1</damping>
          <friction>1</friction>
        </dynamics>
        <limit>
          <effort>20</effort>
        </limit>
      </axis>
    </joint>
    <link name="RCWheel">
      <gravity>1</gravity>
      <self_collide>0</self_collide>
      <pose>0.0494125271622406 -0.328548999999999 0.0232157888899448 1.5707963267949 0 1.5707963267949</pose>
      <must_be_base_link>0</must_be_base_link>
      <velocity_decay>
        <linear>0</linear>
        <angular>0</angular>
      </velocity_decay>
      <inertial>
        <mass>0.593273105209116</mass>
        <pose>0 0 0 0 0 0</pose>
        <inertia>
          <ixx>0</ixx>
          <ixy>0</ixy>
          <ixz>0</ixz>
          <iyy>0</iyy>
          <iyz>0</iyz>
          <izz>0</izz>
        </inertia>
      </inertial>
      <collision name="RCWheel_collision">
        <pose>0.328478683047335 -0.0218171921100333 0.00204972760183393 0 0 0</pose>
        <geometry>
          <mesh>
            <scale>1 1 1</scale>
            <uri>model://2018Robot2/meshes/RCWheel_col.STL</uri>
          </mesh>
        </geometry>
        <surface>
          <contact>
            <ode>
              <kp>1000000</kp>
              <kd>10</kd>
            </ode>
          </contact>
          <friction>
            <ode>
              <mu>1</mu>
              <mu2>1</mu2>
            </ode>
          </friction>
        </surface>
      </collision>
      <visual name="RCWheel_visual">
        <pose>0.328478683047335 -0.0218171921100333 0.00204972760183393 0 0 0</pose>
        <material>
          <ambient>0.501960784313725 0.501960784313725 0.501960784313725 1</ambient>
          <diffuse>0.501960784313725 0.501960784313725 0.501960784313725 1</diffuse>
        </material>
        <geometry>
          <mesh>
            <scale>1 1 1</scale>
            <uri>model://2018Robot2/meshes/RCWheel.STL</uri>
          </mesh>
        </geometry>
      </visual>
    </link>
    <joint name="Body-RCWheel" type="revolute">
      <parent>Body</parent>
      <child>RCWheel</child>
      <pose>0 6.93889390390723E-18 -3.46944695195361E-18 0 0 3.14159265358979</pose>
      <axis>
        <xyz>-1 -1.22460635382238E-16 0</xyz>
        <dynamics>
          <damping>1</damping>
          <friction>1</friction>
        </dynamics>
        <limit>
          <effort>20</effort>
        </limit>
      </axis>
    </joint>
    <link name="RBWheel">
      <gravity>1</gravity>
      <self_collide>0</self_collide>
      <pose>-0.249037472837759 -0.328548999999999 0.0280925888899448 1.5707963267949 0 1.5707963267949</pose>
      <must_be_base_link>0</must_be_base_link>
      <velocity_decay>
        <linear>0</linear>
        <angular>0</angular>
      </velocity_decay>
      <inertial>
        <mass>0.593273105209116</mass>
        <pose>0 0 0 0 0 0</pose>
        <inertia>
          <ixx>0</ixx>
          <ixy>0</ixy>
          <ixz>0</ixz>
          <iyy>0</iyy>
          <iyz>0</iyz>
          <izz>0</izz>
        </inertia>
      </inertial>
      <collision name="RBWheel_collision">
        <pose>0.328478683047335 -0.0266939921100333 0.300499727601834 0 0 0</pose>
        <geometry>
          <mesh>
            <scale>1 1 1</scale>
            <uri>model://2018Robot2/meshes/RBWheel_col.STL</uri>
          </mesh>
        </geometry>
        <surface>
          <contact>
            <ode>
              <kp>1000000</kp>
              <kd>10</kd>
            </ode>
          </contact>
          <friction>
            <ode>
              <mu>1</mu>
              <mu2>1</mu2>
            </ode>
          </friction>
        </surface>
      </collision>
      <visual name="RBWheel_visual">
        <pose>0.328478683047335 -0.0266939921100333 0.300499727601834 0 0 0</pose>
        <material>
          <ambient>0.501960784313725 0.501960784313725 0.501960784313725 1</ambient>
          <diffuse>0.501960784313725 0.501960784313725 0.501960784313725 1</diffuse>
        </material>
        <geometry>
          <mesh>
            <scale>1 1 1</scale>
            <uri>model://2018Robot2/meshes/RBWheel.STL</uri>
          </mesh>
        </geometry>
      </visual>
    </link>
    <joint name="Body-RBWheel" type="revolute">
      <parent>Body</parent>
      <child>RBWheel</child>
      <pose>0 3.46944695195361E-18 -5.55111512312578E-17 0 0 3.14159265358979</pose>
      <axis>
        <xyz>-1 -1.22460635382238E-16 0</xyz>
        <dynamics>
          <damping>1</damping>
          <friction>1</friction>
        </dynamics>
        <limit>
          <effort>20</effort>
        </limit>
      </axis>
    </joint>
    <plugin name="Body_gyro" filename="libgyro.so">
      <link>Body</link>
      <topic>/gazebo/frc/simulator/analog/3</topic>
      <units>degrees</units>
      <axis>pitch</axis>
    </plugin>
    <plugin name="Body-LFWheel_motor" filename="libdc_motor.so">
      <joint>Body-LFWheel</joint>
      <topic>/gazebo/frc/simulator/pwm/2</topic>
      <multiplier>20</multiplier>
    </plugin>
    <plugin name="Body-LCWheel_motor" filename="libdc_motor.so">
      <joint>Body-LCWheel</joint>
      <topic>/gazebo/frc/simulator/pwm/2</topic>
      <multiplier>20</multiplier>
    </plugin>
    <plugin name="Body-LCWheel_encoder" filename="libencoder.so">
      <joint>Body-LCWheel</joint>
      <topic>/gazebo/frc/simulator/dio/3/4</topic>
      <units>degrees</units>
    </plugin>
    <plugin name="Body-LBWheel_motor" filename="libdc_motor.so">
      <joint>Body-LBWheel</joint>
      <topic>/gazebo/frc/simulator/pwm/2</topic>
      <multiplier>20</multiplier>
    </plugin>
    <plugin name="Body-RFWheel_motor" filename="libdc_motor.so">
      <joint>Body-RFWheel</joint>
      <topic>/gazebo/frc/simulator/pwm/4</topic>
      <multiplier>20</multiplier>
    </plugin>
    <plugin name="Body-RCWheel_motor" filename="libdc_motor.so">
      <joint>Body-RCWheel</joint>
      <topic>/gazebo/frc/simulator/pwm/4</topic>
      <multiplier>20</multiplier>
    </plugin>
    <plugin name="Body-RCWheel_encoder" filename="libencoder.so">
      <joint>Body-RCWheel</joint>
      <topic>/gazebo/frc/simulator/dio/7/8</topic>
      <units>degrees</units>
    </plugin>
    <plugin name="Body-RBWheel_motor" filename="libdc_motor.so">
      <joint>Body-RBWheel</joint>
      <topic>/gazebo/frc/simulator/pwm/4</topic>
      <multiplier>20</multiplier>
    </plugin>
  </model>
</sdf>