<?xml version="1.0" encoding="utf-8"?>
<sdf version="1.5">
  <model name="SimBot2019-2">
    <pose>0 0 0.12446 0 0 0</pose>
    <plugin name="clock" filename="libgz_clock.so">
      <topic>/gazebo/frc/time</topic>
    </plugin>
    <link name="Frame">
      <gravity>1</gravity>
      <self_collide>0</self_collide>
      <pose>-0.321553535676864 0.00175347404046746 -0.000511003682687343 -1.5707963267949 0 1.5707963267949</pose>
      <must_be_base_link>1</must_be_base_link>
      <velocity_decay>
        <linear>0</linear>
        <angular>0</angular>
      </velocity_decay>
      <inertial>
        <mass>3.62245562967997</mass>
        <pose>0 0 0 0 0 0</pose>
        <inertia>
          <ixx>0.2095541251639</ixx>
          <ixy>2.5056971384159E-05</ixy>
          <ixz>0.00167712046646788</ixz>
          <iyy>0.392915780451513</iyy>
          <iyz>0.000439438632626004</iyz>
          <izz>0.183814402513456</izz>
        </inertia>
      </inertial>
      <collision name="Frame_collision">
        <pose>-0.00175347404046739 -0.000511003682687411 0.0848464737230545 0 0 0</pose>
        <geometry>
          <mesh>
            <scale>1 1 1</scale>
            <uri>model://SimBot2019-2/meshes/Frame_col.STL</uri>
          </mesh>
        </geometry>
        <surface>
          <contact>
            <ode />
          </contact>
          <friction>
            <ode>
              <mu>1</mu>
              <mu2>1</mu2>
            </ode>
          </friction>
        </surface>
      </collision>
      <visual name="Frame_visual">
        <pose>-0.00175347404046739 -0.000511003682687411 0.0848464737230545 0 0 0</pose>
        <material>
          <ambient>0.501960784313725 0.501960784313725 0.501960784313725 1</ambient>
          <diffuse>0.501960784313725 0.501960784313725 0.501960784313725 1</diffuse>
        </material>
        <geometry>
          <mesh>
            <scale>1 1 1</scale>
            <uri>model://SimBot2019-2/meshes/Frame.STL</uri>
          </mesh>
        </geometry>
      </visual>
    </link>
    <link name="LFWheel">
      <gravity>1</gravity>
      <self_collide>0</self_collide>
      <pose>-0.673098436426671 0.303262709940693 0.00169521560483079 -1.5707963267949 0 1.5707963267949</pose>
      <must_be_base_link>0</must_be_base_link>
      <velocity_decay>
        <linear>0</linear>
        <angular>0</angular>
      </velocity_decay>
      <inertial>
        <mass>0.255325203825891</mass>
        <pose>0 0 0 0 0 0</pose>
        <inertia>
          <ixx>0</ixx>
          <ixy>0</ixy>
          <ixz>0</ixz>
          <iyy>0</iyy>
          <iyz>0</iyz>
          <izz>0</izz>
        </inertia>
      </inertial>
      <collision name="LFWheel_collision">
        <pose>-0.303262709940693 0.00169521560483064 -0.266698427026753 0 0 0</pose>
        <geometry>
          <mesh>
            <scale>1 1 1</scale>
            <uri>model://SimBot2019-2/meshes/LFWheel_col.STL</uri>
          </mesh>
        </geometry>
        <surface>
          <contact>
            <ode />
          </contact>
          <friction>
            <ode>
              <mu>1</mu>
              <mu2>1</mu2>
            </ode>
          </friction>
        </surface>
      </collision>
      <visual name="LFWheel_visual">
        <pose>-0.303262709940693 0.00169521560483064 -0.266698427026753 0 0 0</pose>
        <material>
          <ambient>0.501960784313725 0.501960784313725 0.501960784313725 1</ambient>
          <diffuse>0.501960784313725 0.501960784313725 0.501960784313725 1</diffuse>
        </material>
        <geometry>
          <mesh>
            <scale>1 1 1</scale>
            <uri>model://SimBot2019-2/meshes/LFWheel.STL</uri>
          </mesh>
        </geometry>
      </visual>
    </link>
    <joint name="Frame-LFWheel" type="revolute">
      <parent>Frame</parent>
      <child>LFWheel</child>
      <pose>-5.55111512312578E-17 4.42156048337892E-05 -2.76542456689732E-06 0 0 3.14159265358979</pose>
      <axis>
        <xyz>-1 -1.22460635382238E-16 0</xyz>
        <dynamics>
          <damping>1</damping>
          <friction>1</friction>
        </dynamics>
        <limit>
          <effort>50</effort>
        </limit>
      </axis>
    </joint>
    <link name="LCWheel">
      <gravity>1</gravity>
      <self_collide>0</self_collide>
      <pose>-0.405312671639957 0.303262709940693 -0.00385752270000407 -1.5707963267949 0 1.5707963267949</pose>
      <must_be_base_link>0</must_be_base_link>
      <velocity_decay>
        <linear>0</linear>
        <angular>0</angular>
      </velocity_decay>
      <inertial>
        <mass>0.255325203825891</mass>
        <pose>0 0 0 0 0 0</pose>
        <inertia>
          <ixx>0</ixx>
          <ixy>0</ixy>
          <ixz>0</ixz>
          <iyy>0</iyy>
          <iyz>0</iyz>
          <izz>0</izz>
        </inertia>
      </inertial>
      <collision name="LCWheel_collision">
        <pose>-0.303262709940693 -0.00385752270000416 0.0010873377599609 0 0 0</pose>
        <geometry>
          <mesh>
            <scale>1 1 1</scale>
            <uri>model://SimBot2019-2/meshes/LCWheel_col.STL</uri>
          </mesh>
        </geometry>
        <surface>
          <contact>
            <ode />
          </contact>
          <friction>
            <ode>
              <mu>1</mu>
              <mu2>1</mu2>
            </ode>
          </friction>
        </surface>
      </collision>
      <visual name="LCWheel_visual">
        <pose>-0.303262709940693 -0.00385752270000416 0.0010873377599609 0 0 0</pose>
        <material>
          <ambient>0.501960784313725 0.501960784313725 0.501960784313725 1</ambient>
          <diffuse>0.501960784313725 0.501960784313725 0.501960784313725 1</diffuse>
        </material>
        <geometry>
          <mesh>
            <scale>1 1 1</scale>
            <uri>model://SimBot2019-2/meshes/LCWheel.STL</uri>
          </mesh>
        </geometry>
      </visual>
    </link>
    <joint name="Frame-LCWheel" type="revolute">
      <parent>Frame</parent>
      <child>LCWheel</child>
      <pose>-5.55111512312578E-17 -0.000132954805310722 0.00113500257289437 0 0 0</pose>
      <axis>
        <xyz>1 0 0</xyz>
        <dynamics>
          <damping>1</damping>
          <friction>1</friction>
        </dynamics>
        <limit>
          <effort>50</effort>
        </limit>
      </axis>
    </joint>
    <link name="LBWheel">
      <gravity>1</gravity>
      <self_collide>0</self_collide>
      <pose>-0.139700620681278 0.303199220635696 0.00169514092477994 -1.5707963267949 0 1.5707963267949</pose>
      <must_be_base_link>0</must_be_base_link>
      <velocity_decay>
        <linear>0</linear>
        <angular>0</angular>
      </velocity_decay>
      <inertial>
        <mass>0.255325203825891</mass>
        <pose>0 0 0 0 0 0</pose>
        <inertia>
          <ixx>0</ixx>
          <ixy>0</ixy>
          <ixz>0</ixz>
          <iyy>0</iyy>
          <iyz>0</iyz>
          <izz>0</izz>
        </inertia>
      </inertial>
      <collision name="LBWheel_collision">
        <pose>-0.303199220635695 0.00169514092477991 0.26669938871864 0 0 0</pose>
        <geometry>
          <mesh>
            <scale>1 1 1</scale>
            <uri>model://SimBot2019-2/meshes/LBWheel_col.STL</uri>
          </mesh>
        </geometry>
        <surface>
          <contact>
            <ode />
          </contact>
          <friction>
            <ode>
              <mu>1</mu>
              <mu2>1</mu2>
            </ode>
          </friction>
        </surface>
      </collision>
      <visual name="LBWheel_visual">
        <pose>-0.303199220635695 0.00169514092477991 0.26669938871864 0 0 0</pose>
        <material>
          <ambient>0.501960784313725 0.501960784313725 0.501960784313725 1</ambient>
          <diffuse>0.501960784313725 0.501960784313725 0.501960784313725 1</diffuse>
        </material>
        <geometry>
          <mesh>
            <scale>1 1 1</scale>
            <uri>model://SimBot2019-2/meshes/LBWheel.STL</uri>
          </mesh>
        </geometry>
      </visual>
    </link>
    <joint name="Frame-LBWheel" type="revolute">
      <parent>Frame</parent>
      <child>LBWheel</child>
      <pose>-1.11022302462516E-16 4.41409247766737E-05 3.74376878553573E-06 0 0 0</pose>
      <axis>
        <xyz>1 0 0</xyz>
        <dynamics>
          <damping>1</damping>
          <friction>1</friction>
        </dynamics>
        <limit>
          <effort>50</effort>
        </limit>
      </axis>
    </joint>
    <link name="RFWheel">
      <gravity>1</gravity>
      <self_collide>0</self_collide>
      <pose>-0.673096893872116 -0.303262709940692 0.00169528357489551 -1.5707963267949 0 1.5707963267949</pose>
      <must_be_base_link>0</must_be_base_link>
      <velocity_decay>
        <linear>0</linear>
        <angular>0</angular>
      </velocity_decay>
      <inertial>
        <mass>0.255325203825891</mass>
        <pose>0 0 0 0 0 0</pose>
        <inertia>
          <ixx>0</ixx>
          <ixy>0</ixy>
          <ixz>0</ixz>
          <iyy>0</iyy>
          <iyz>0</iyz>
          <izz>0</izz>
        </inertia>
      </inertial>
      <collision name="RFWheel_collision">
        <pose>0.303262709940693 0.00169528357489536 -0.266696884472198 0 0 0</pose>
        <geometry>
          <mesh>
            <scale>1 1 1</scale>
            <uri>model://SimBot2019-2/meshes/RFWheel_col.STL</uri>
          </mesh>
        </geometry>
        <surface>
          <contact>
            <ode />
          </contact>
          <friction>
            <ode>
              <mu>1</mu>
              <mu2>1</mu2>
            </ode>
          </friction>
        </surface>
      </collision>
      <visual name="RFWheel_visual">
        <pose>0.303262709940693 0.00169528357489536 -0.266696884472198 0 0 0</pose>
        <material>
          <ambient>0.501960784313725 0.501960784313725 0.501960784313725 1</ambient>
          <diffuse>0.501960784313725 0.501960784313725 0.501960784313725 1</diffuse>
        </material>
        <geometry>
          <mesh>
            <scale>1 1 1</scale>
            <uri>model://SimBot2019-2/meshes/RFWheel.STL</uri>
          </mesh>
        </geometry>
      </visual>
    </link>
    <joint name="Frame-RFWheel" type="revolute">
      <parent>Frame</parent>
      <child>RFWheel</child>
      <pose>5.55111512312578E-17 4.42835748872173E-05 -1.20323087010599E-06 0 0 0</pose>
      <axis>
        <xyz>1 0 0</xyz>
        <dynamics>
          <damping>1</damping>
          <friction>1</friction>
        </dynamics>
        <limit>
          <effort>50</effort>
        </limit>
      </axis>
    </joint>
    <link name="RCWheel">
      <gravity>1</gravity>
      <self_collide>0</self_collide>
      <pose>-0.406431076654579 -0.303368868926879 -0.0036834982409925 -1.5707963267949 0 1.5707963267949</pose>
      <must_be_base_link>0</must_be_base_link>
      <velocity_decay>
        <linear>0</linear>
        <angular>0</angular>
      </velocity_decay>
      <inertial>
        <mass>0.255325203825891</mass>
        <pose>0 0 0 0 0 0</pose>
        <inertia>
          <ixx>0</ixx>
          <ixy>0</ixy>
          <ixz>0</ixz>
          <iyy>0</iyy>
          <iyz>0</iyz>
          <izz>0</izz>
        </inertia>
      </inertial>
      <collision name="RCWheel_collision">
        <pose>0.30336886892688 -0.00368349824099259 -3.10672546609658E-05 0 0 0</pose>
        <geometry>
          <mesh>
            <scale>1 1 1</scale>
            <uri>model://SimBot2019-2/meshes/RCWheel_col.STL</uri>
          </mesh>
        </geometry>
        <surface>
          <contact>
            <ode />
          </contact>
          <friction>
            <ode>
              <mu>1</mu>
              <mu2>1</mu2>
            </ode>
          </friction>
        </surface>
      </collision>
      <visual name="RCWheel_visual">
        <pose>0.30336886892688 -0.00368349824099259 -3.10672546609658E-05 0 0 0</pose>
        <material>
          <ambient>0.501960784313725 0.501960784313725 0.501960784313725 1</ambient>
          <diffuse>0.501960784313725 0.501960784313725 0.501960784313725 1</diffuse>
        </material>
        <geometry>
          <mesh>
            <scale>1 1 1</scale>
            <uri>model://SimBot2019-2/meshes/RCWheel.STL</uri>
          </mesh>
        </geometry>
      </visual>
    </link>
    <joint name="Frame-RCWheel" type="revolute">
      <parent>Frame</parent>
      <child>RCWheel</child>
      <pose>1.11022302462516E-16 0.000217839348982876 -0.00112495375183556 0 0 0</pose>
      <axis>
        <xyz>1 0 0</xyz>
        <dynamics>
          <damping>1</damping>
          <friction>1</friction>
        </dynamics>
        <limit>
          <effort>50</effort>
        </limit>
      </axis>
    </joint>
    <link name="RBWheel">
      <gravity>1</gravity>
      <self_collide>0</self_collide>
      <pose>-0.139681443305567 -0.303262709940693 0.0016889037946457 -1.5707963267949 0 1.5707963267949</pose>
      <must_be_base_link>0</must_be_base_link>
      <velocity_decay>
        <linear>0</linear>
        <angular>0</angular>
      </velocity_decay>
      <inertial>
        <mass>0.255325203825891</mass>
        <pose>0 0 0 0 0 0</pose>
        <inertia>
          <ixx>0</ixx>
          <ixy>0</ixy>
          <ixz>0</ixz>
          <iyy>0</iyy>
          <iyz>0</iyz>
          <izz>0</izz>
        </inertia>
      </inertial>
      <collision name="RBWheel_collision">
        <pose>0.303262709940693 0.00168890379464568 0.266718566094351 0 0 0</pose>
        <geometry>
          <mesh>
            <scale>1 1 1</scale>
            <uri>model://SimBot2019-2/meshes/RBWheel_col.STL</uri>
          </mesh>
        </geometry>
        <surface>
          <contact>
            <ode />
          </contact>
          <friction>
            <ode>
              <mu>0</mu>
              <mu2>0</mu2>
            </ode>
          </friction>
        </surface>
      </collision>
      <visual name="RBWheel_visual">
        <pose>0.303262709940693 0.00168890379464568 0.266718566094351 0 0 0</pose>
        <material>
          <ambient>0.501960784313725 0.501960784313725 0.501960784313725 1</ambient>
          <diffuse>0.501960784313725 0.501960784313725 0.501960784313725 1</diffuse>
        </material>
        <geometry>
          <mesh>
            <scale>1 1 1</scale>
            <uri>model://SimBot2019-2/meshes/RBWheel.STL</uri>
          </mesh>
        </geometry>
      </visual>
    </link>
    <joint name="Frame-RBWheel" type="revolute">
      <parent>Frame</parent>
      <child>RBWheel</child>
      <pose>5.55111512312578E-17 3.7903794642441E-05 2.29211444965349E-05 0 0 0</pose>
      <axis>
        <xyz>1 0 0</xyz>
        <dynamics>
          <damping>1</damping>
          <friction>1</friction>
        </dynamics>
        <limit>
          <effort>50</effort>
        </limit>
      </axis>
    </joint>
    <link name="Climber1">
      <gravity>1</gravity>
      <self_collide>0</self_collide>
      <pose>-0.323733307948634 0.00178585381407782 0.0353743678217534 -1.5707963267949 0 1.5707963267949</pose>
      <must_be_base_link>0</must_be_base_link>
      <velocity_decay>
        <linear>0</linear>
        <angular>0</angular>
      </velocity_decay>
      <inertial>
        <mass>1.09137603293812</mass>
        <pose>0 0 0 0 0 0</pose>
        <inertia>
          <ixx>0.0103078548798271</ixx>
          <ixy>1.34382460025718E-06</ixy>
          <ixz>2.10777898500688E-05</ixz>
          <iyy>0.0183089226570834</iyy>
          <iyz>0.000240141860446858</iyz>
          <izz>0.00812380263892143</izz>
        </inertia>
      </inertial>
      <collision name="Climber1_collision">
        <pose>-0.00178585381407775 0.0353743678217533 0.0826667014512842 0 0 0</pose>
        <geometry>
          <mesh>
            <scale>1 1 1</scale>
            <uri>model://SimBot2019-2/meshes/Climber1_col.STL</uri>
          </mesh>
        </geometry>
        <surface>
          <contact>
            <ode />
          </contact>
          <friction>
            <ode>
              <mu>0</mu>
              <mu2>0</mu2>
            </ode>
          </friction>
        </surface>
      </collision>
      <visual name="Climber1_visual">
        <pose>-0.00178585381407775 0.0353743678217533 0.0826667014512842 0 0 0</pose>
        <material>
          <ambient>0 0 1 1</ambient>
          <diffuse>0 0 1 1</diffuse>
        </material>
        <geometry>
          <mesh>
            <scale>1 1 1</scale>
            <uri>model://SimBot2019-2/meshes/Climber1.STL</uri>
          </mesh>
        </geometry>
      </visual>
    </link>
    <joint name="Frame-Climber1" type="revolute">
      <parent>Frame</parent>
      <child>Climber1</child>
      <pose>1.66967134562768E-16 -0.00590065564055302 -0.234832924196666 0 0 0</pose>
      <axis>
        <xyz>1 0 0</xyz>
        <dynamics>
          <damping>1</damping>
          <friction>1</friction>
        </dynamics>
        <limit>
          <upper>0</upper>
          <lower>0</lower>
          <effort>100</effort>
        </limit>
      </axis>
    </joint>
    <link name="Climber2">
      <gravity>1</gravity>
      <self_collide>0</self_collide>
      <pose>-0.42638491633238 0.00178585321055879 0.0435126444989845 -1.5707963267949 0 1.5707963267949</pose>
      <must_be_base_link>0</must_be_base_link>
      <velocity_decay>
        <linear>0</linear>
        <angular>0</angular>
      </velocity_decay>
      <inertial>
        <mass>0.409299999077662</mass>
        <pose>0 0 0 0 0 0</pose>
        <inertia>
          <ixx>1.19895149546238E-07</ixx>
          <ixy>1.30570888906081E-07</ixy>
          <ixz>1.96930921731175E-05</ixz>
          <iyy>0.00323490402888518</iyy>
          <iyz>7.94904525265603E-10</iyz>
          <izz>0.00323478414427652</izz>
        </inertia>
      </inertial>
      <collision name="Climber2_collision">
        <pose>-0.00178585321055869 0.0435126444989844 -0.0199849069324619 0 0 0</pose>
        <geometry>
          <mesh>
            <scale>1 1 1</scale>
            <uri>model://SimBot2019-2/meshes/Climber2_col.STL</uri>
          </mesh>
        </geometry>
        <surface>
          <contact>
            <ode />
          </contact>
          <friction>
            <ode>
              <mu>1</mu>
              <mu2>1</mu2>
            </ode>
          </friction>
        </surface>
      </collision>
      <visual name="Climber2_visual">
        <pose>-0.00178585321055869 0.0435126444989844 -0.0199849069324619 0 0 0</pose>
        <material>
          <ambient>0 0 0.501960784313725 1</ambient>
          <diffuse>0 0 0.501960784313725 1</diffuse>
        </material>
        <geometry>
          <mesh>
            <scale>1 1 1</scale>
            <uri>model://SimBot2019-2/meshes/Climber2.STL</uri>
          </mesh>
        </geometry>
      </visual>
    </link>
    <joint name="Climber1-Climber2" type="revolute">
      <parent>Climber1</parent>
      <child>Climber2</child>
      <pose>9.82287168271867E-17 -0.00158127981010294 0.24129407342068 0 0 3.14159265358979</pose>
      <axis>
        <xyz>-1 -1.22460635382238E-16 0</xyz>
        <dynamics>
          <damping>0</damping>
          <friction>0</friction>
        </dynamics>
        <limit>
          <upper>0</upper>
          <lower>0</lower>
          <effort>100</effort>
        </limit>
      </axis>
    </joint>
    <!--
    <link name="Bumpers">
      <gravity>1</gravity>
      <self_collide>0</self_collide>
      <pose>-0.406400009399918 0.000793750000000036 -0.0126987965985534 -1.5707963267949 0 1.5707963267949</pose>
      <must_be_base_link>0</must_be_base_link>
      <velocity_decay>
        <linear>0</linear>
        <angular>0</angular>
      </velocity_decay>
      <inertial>
        <mass>0.413207943277131</mass>
        <pose>0 0 0 0 0 0</pose>
        <inertia>
          <ixx>3.84618615196602E-11</ixx>
          <ixy>2.66716295485435E-16</ixy>
          <ixz>1.4380728313149E-06</ixz>
          <iyy>0.0537689385779799</iyy>
          <iyz>7.13343927971838E-21</iyz>
          <izz>0.053768938539518</izz>
        </inertia>
      </inertial>
      <collision name="Bumpers_collision">
        <pose>-0.000793749999999946 -0.0126987965985534 -4.45616451074324E-17 0 0 0</pose>
        <geometry>
          <mesh>
            <scale>1 1 1</scale>
            <uri>model://SimBot2019-2/meshes/Bumpers_col.STL</uri>
          </mesh>
        </geometry>
        <surface>
          <contact>
            <ode />
          </contact>
          <friction>
            <ode>
              <mu>0</mu>
              <mu2>0</mu2>
            </ode>
          </friction>
        </surface>
      </collision>
      <visual name="Bumpers_visual">
        <pose>-0.000793749999999946 -0.0126987965985534 -4.45616451074324E-17 0 0 0</pose>
        <material>
          <ambient>1 0 0 1</ambient>
          <diffuse>1 0 0 1</diffuse>
        </material>
        <geometry>
          <mesh>
            <scale>1 1 1</scale>
            <uri>model://SimBot2019-2/meshes/Bumpers.STL</uri>
          </mesh>
        </geometry>
      </visual>
    </link>
    <joint name="Frame-Bumpers" type="prismatic">
      <parent>Frame</parent>
      <child>Bumpers</child>
      <pose>-0.24209375 0.0127012034014436 1.09495061238254E-17 0 0 0</pose>
      <axis>
        <xyz>0 0 -1</xyz>
        <dynamics>
          <damping>0</damping>
          <friction>0</friction>
        </dynamics>
        <limit>
          <upper>0</upper>
          <lower>0</lower>
          <effort>1</effort>
        </limit>
      </axis>
    </joint>
    -->
    <plugin name="Frame-LFWheel_motor" filename="libgz_dc_motor.so">
      <joint>Frame-LFWheel</joint>
      <topic>/gazebo/frc/simulator/pwm/1</topic>
      <multiplier>10</multiplier>
    </plugin>
    <plugin name="Frame-LCWheel_motor" filename="libgz_dc_motor.so">
      <joint>Frame-LCWheel</joint>
      <topic>/gazebo/frc/simulator/pwm/1</topic>
      <multiplier>10</multiplier>
    </plugin>
    <plugin name="Frame-LBWheel_motor" filename="libgz_dc_motor.so">
      <joint>Frame-LBWheel</joint>
      <topic>/gazebo/frc/simulator/pwm/3</topic>
      <multiplier>10</multiplier>
    </plugin>
    <plugin name="Frame-RFWheel_motor" filename="libgz_dc_motor.so">
      <joint>Frame-RFWheel</joint>
      <topic>/gazebo/frc/simulator/pwm/4</topic>
      <multiplier>10</multiplier>
    </plugin>
    <plugin name="Frame-RCWheel_motor" filename="libgz_dc_motor.so">
      <joint>Frame-RCWheel</joint>
      <topic>/gazebo/frc/simulator/pwm/4</topic>
      <multiplier>10</multiplier>
    </plugin>
    <plugin name="Frame-RBWheel_motor" filename="libgz_dc_motor.so">
      <joint>Frame-RBWheel</joint>
      <topic>/gazebo/frc/simulator/pwm/4</topic>
      <multiplier>10</multiplier>
    </plugin>
    <plugin name="Frame-Climber1_motor" filename="libgz_dc_motor.so">
      <joint>Frame-Climber1</joint>
      <topic>/gazebo/frc/simulator/pwm/6</topic>
      <multiplier>50</multiplier>
    </plugin>
  </model>
</sdf>