<?xml version="1.0" encoding="utf-8"?>
<sdf version="1.5">
  <model name="SimBot2017">
    <pose>0 0 0.00254 0 0 0</pose>
    <plugin name="clock" filename="libclock.so">
      <topic>/gazebo/frc/time</topic>
    </plugin>
    <link name="Body">
      <gravity>1</gravity>
      <self_collide>0</self_collide>
      <pose>0.433463429874365 0.378319010392331 0.109948418222269 1.5707963267949 6.19090554227257E-16 -1.5707963267949</pose>
      <must_be_base_link>1</must_be_base_link>
      <velocity_decay>
        <linear>0</linear>
        <angular>0</angular>
      </velocity_decay>
      <inertial>
        <mass>48.658507020423</mass>
        <pose>0 0 0 0 0 0</pose>
        <inertia>
          <ixx>6.86715478373719</ixx>
          <ixy>0.0494549999321843</ixy>
          <ixz>0.043770857203321</ixz>
          <iyy>11.0750540467398</iyy>
          <iyz>0.0236003312460615</iyz>
          <izz>5.67179628825671</izz>
        </inertia>
      </inertial>
      <collision name="Body_collision">
        <pose>0.00366901039233079 -0.14383775339206 -0.417436570125635 0 0 0</pose>
        <geometry>
          <mesh>
            <scale>1 1 1</scale>
            <uri>model://SimBot2017/meshes/Body_col.STL</uri>
          </mesh>
        </geometry>
        <surface>
          <contact>
            <ode />
          </contact>
          <friction>
            <ode>
              <mu>1</mu>
              <mu2>1</mu2>
            </ode>
          </friction>
        </surface>
      </collision>
      <visual name="Body_visual">
        <pose>0.00366901039233079 -0.14383775339206 -0.417436570125635 0 0 0</pose>
        <material>
          <ambient>0 0.2 1 1</ambient>
          <diffuse>0 0.2 1 1</diffuse>
        </material>
        <geometry>
          <mesh>
            <scale>1 1 1</scale>
            <uri>model://SimBot2017/meshes/Body.STL</uri>
          </mesh>
        </geometry>
      </visual>
      <sensor name="TargetingCamera" type="camera">
        <visualize>1</visualize>
        <always_on>1</always_on>
        <pose>0.17 0.318095647047724 -0.369811570125635 -1.57 1.85707963267949 0.0</pose>
        <camera name="TargetingCamera">
          <horizontal_fov>0.66</horizontal_fov>
          <image>
            <width>320</width>
            <height>240</height>
          </image>
          <clip>
            <near>0.1</near>
            <far>30</far>
          </clip>
          <save enabled="true">
              <path>/tmp/shooter-camera</path>
          </save>
        </camera>
      </sensor>
      <sensor name="TopFrameUltrasonic" type="sonar">
        <always_on>1</always_on>
        <visualize>1</visualize>
        <update_rate>30</update_rate>
        <pose>0.17 0.318095647047724 -0.369811570125635 -0.2 0.2 0</pose>
        <sonar>
          <min>0.1</min>
          <max>1</max>
          <radius>0.2</radius>
        </sonar>
      </sensor>
<!--
      <sensor name="DriverCamera" type="camera">
        <visualize>0</visualize>
        <always_on>0</always_on>
        <pose>0.277281820936809 0.300315647047724 -0.369811570125635 1.5707963267949 1.5707963267949 0</pose>
        <camera name="Bodycamera">
          <horizontal_fov>1.0471975511966</horizontal_fov>
          <image>
            <width>320</width>
            <height>240</height>
          </image>
          <clip>
            <near>0.1</near>
            <far>100</far>
          </clip>
        </camera>
      </sensor>
-->
    </link>
   <link name="BallPusher">
      <gravity>1</gravity>
      <self_collide>0</self_collide>
      <pose>0.612329818507616 0.373849899999999 0.193772269654463 1.5707963267949 6.19090554227257E-16 -1.5707963267949</pose>
      <must_be_base_link>0</must_be_base_link>
      <velocity_decay>
        <linear>0</linear>
        <angular>0</angular>
      </velocity_decay>
      <inertial>
        <mass>0.322620322499994</mass>
        <pose>0 0 0 0 0 0</pose>
        <inertia>
          <ixx>0.00054533425889827</ixx>
          <ixy>4.69879398787724E-18</ixy>
          <ixz>3.0800697072875E-18</ixz>
          <iyy>0.00708172033481323</iyy>
          <iyz>0.000220855063880911</iyz>
          <izz>0.00733972907502477</izz>
        </inertia>
      </inertial>
      <collision name="BallPusher_collision">
        <pose>-0.00080010000000064 -0.227661604824254 -0.238570181492384 0 0 0</pose>
        <geometry>
          <mesh>
            <scale>1 1 1</scale>
            <uri>model://SimBot2017/meshes/BallPusher.STL</uri>
          </mesh>
        </geometry>
        <surface>
          <contact>
            <ode />
          </contact>
          <friction>
            <ode>
              <mu>1</mu>
              <mu2>1</mu2>
            </ode>
          </friction>
        </surface>
      </collision>
      <visual name="BallPusher_visual">
        <pose>-0.00080010000000064 -0.227661604824254 -0.238570181492384 0 0 0</pose>
        <material>
          <ambient>1 0 0 1</ambient>
          <diffuse>1 0 0 1</diffuse>
        </material>
        <geometry>
          <mesh>
            <scale>1 1 1</scale>
            <uri>model://SimBot2017/meshes/BallPusher.STL</uri>
          </mesh>
        </geometry>
      </visual>
    </link>
    <joint name="Body-BallPusher" type="prismatic">
      <parent>Body</parent>
      <child>BallPusher</child>
      <pose>-0.2413 -0.0415717899404686 0.0202444924764622 0 1.11762154483475 3.59476743554994</pose>
      <axis>
        <xyz>1 0 0</xyz>
<!--
        <xyz>0.8922371470722 0.39362902235274 -0.221289552726934</xyz>
-->
        <dynamics>
          <damping>0</damping>
          <friction>0</friction>
        </dynamics>
        <limit>
          <upper>1</upper>
          <lower>0</lower>
          <effort>100</effort>
        </limit>
      </axis>
    </joint>
    <link name="L1Wheel">
      <gravity>1</gravity>
      <self_collide>0</self_collide>
      <pose>0.736599999999999 0.70612 0.0349250000000019 1.5707963267949 6.19090554227257E-16 -1.5707963267949</pose>
      <must_be_base_link>0</must_be_base_link>
      <velocity_decay>
        <linear>0</linear>
        <angular>0</angular>
      </velocity_decay>
      <inertial>
        <mass>0.408395441319621</mass>
        <pose>0 0 0 0 0 0</pose>
        <inertia>
          <ixx>0.00522885625259631</ixx>
          <ixy>0</ixy>
          <ixz>0</ixz>
          <iyy>0.00347976426556731</iyy>
          <iyz>0</iyz>
          <izz>0.00347976426556731</izz>
        </inertia>
      </inertial>
      <collision name="L1Wheel_collision">
        <pose>0.33147 -0.0688143351697925 -0.1143 0 0 0</pose>
        <geometry>
          <mesh>
            <scale>1 1 1</scale>
            <uri>model://SimBot2017/meshes/L1Wheel_col.STL</uri>
          </mesh>
        </geometry>
        <surface>
		  <contact>
			<ode>
			  <max_vel>0.1</max_vel>
			  <soft_cfm>0.8</soft_cfm>
			  <soft_erp>0.8</soft_erp>
			  <kd>200</kd>
			  <kp>50000</kp>
			  <min_depth>0.0001</min_depth>
			</ode>
		  </contact>
          <friction>
            <ode>
              <mu>1</mu>
              <mu2>1</mu2>
            </ode>
          </friction>
        </surface>
      </collision>
      <visual name="L1Wheel_visual">
        <pose>0.33147 -0.0688143351697925 -0.1143 0 0 0</pose>
        <material>
          <ambient>0.501960784313725 0.501960784313725 0.501960784313725 1</ambient>
          <diffuse>0.501960784313725 0.501960784313725 0.501960784313725 1</diffuse>
        </material>
        <geometry>
          <mesh>
            <scale>1 1 1</scale>
            <uri>model://SimBot2017/meshes/L1Wheel.STL</uri>
          </mesh>
        </geometry>
      </visual>
    </link>
    <joint name="Body-L1Wheel" type="revolute">
      <parent>Body</parent>
      <child>L1Wheel</child>
      <pose>0.0228600000000001 8.32667268468867E-17 1.38777878078145E-17 0 0 3.14159265358979</pose>
      <axis>
        <xyz>1 0 0</xyz>
        <dynamics>
          <damping>2</damping>
          <friction>1</friction>
        </dynamics>
        <limit>
          <effort>50</effort>
        </limit>
      </axis>
    </joint>
    <link name="L2Wheel">
      <gravity>1</gravity>
      <self_collide>0</self_collide>
      <pose>0.535765846677999 0.70612 0.0285750000000002 1.5707963267949 6.19090554227257E-16 -1.5707963267949</pose>
      <must_be_base_link>0</must_be_base_link>
      <velocity_decay>
        <linear>0</linear>
        <angular>0</angular>
      </velocity_decay>
      <inertial>
        <mass>0.40839544131962</mass>
        <pose>0 0 0 0 0 0</pose>
        <inertia>
          <ixx>0.00522885625259631</ixx>
          <ixy>0</ixy>
          <ixz>0</ixz>
          <iyy>0.00347976426556731</iyy>
          <iyz>0</iyz>
          <izz>0.00347976426556731</izz>
        </inertia>
      </inertial>
      <collision name="L2Wheel_collision">
        <pose>0.33147 -0.0624643351697909 -0.315134153322 0 0 0</pose>
        <geometry>
          <mesh>
            <scale>1 1 1</scale>
            <uri>model://SimBot2017/meshes/L2Wheel_col.STL</uri>
          </mesh>
        </geometry>
        <surface>
		  <contact>
			<ode>
			  <max_vel>0.1</max_vel>
			  <soft_cfm>0.8</soft_cfm>
			  <soft_erp>0.8</soft_erp>
			  <kd>200</kd>
			  <kp>50000</kp>
			  <min_depth>0.0001</min_depth>
			</ode>
		  </contact>
          <friction>
            <ode>
              <mu>1</mu>
              <mu2>1</mu2>
            </ode>
          </friction>
        </surface>
      </collision>
      <visual name="L2Wheel_visual">
        <pose>0.33147 -0.0624643351697909 -0.315134153322 0 0 0</pose>
        <material>
          <ambient>0.501960784313725 0.501960784313725 0.501960784313725 1</ambient>
          <diffuse>0.501960784313725 0.501960784313725 0.501960784313725 1</diffuse>
        </material>
        <geometry>
          <mesh>
            <scale>1 1 1</scale>
            <uri>model://SimBot2017/meshes/L2Wheel.STL</uri>
          </mesh>
        </geometry>
      </visual>
    </link>
    <joint name="Body-L2Wheel" type="revolute">
      <parent>Body</parent>
      <child>L2Wheel</child>
      <pose>0.0228600000000002 9.0205620750794E-17 0 0 0 3.14159265358979</pose>
      <axis>
        <xyz>1 0 0</xyz>
        <dynamics>
          <damping>2</damping>
          <friction>1</friction>
        </dynamics>
        <limit>
          <effort>50</effort>
        </limit>
      </axis>
    </joint>
    <link name="L3Wheel">
      <gravity>1</gravity>
      <self_collide>0</self_collide>
      <pose>0.315134153322 0.70612 0.0285749999999982 1.5707963267949 6.19090554227257E-16 -1.5707963267949</pose>
      <must_be_base_link>0</must_be_base_link>
      <velocity_decay>
        <linear>0</linear>
        <angular>0</angular>
      </velocity_decay>
      <inertial>
        <mass>0.40839544131962</mass>
        <pose>0 0 0 0 0 0</pose>
        <inertia>
          <ixx>0.00522885625259631</ixx>
          <ixy>0</ixy>
          <ixz>0</ixz>
          <iyy>0.00347976426556731</iyy>
          <iyz>0</iyz>
          <izz>0.00347976426556731</izz>
        </inertia>
      </inertial>
      <collision name="L3Wheel_collision">
        <pose>0.33147 -0.0624643351697891 -0.535765846678 0 0 0</pose>
        <geometry>
          <mesh>
            <scale>1 1 1</scale>
            <uri>model://SimBot2017/meshes/L3Wheel_col.STL</uri>
          </mesh>
        </geometry>
        <surface>
		  <contact>
			<ode>
			  <max_vel>0.1</max_vel>
			  <soft_cfm>0.8</soft_cfm>
			  <soft_erp>0.8</soft_erp>
			  <kd>200</kd>
			  <kp>50000</kp>
			  <min_depth>0.0001</min_depth>
			</ode>
		  </contact>
          <friction>
            <ode>
              <mu>1</mu>
              <mu2>1</mu2>
            </ode>
          </friction>
        </surface>
      </collision>
      <visual name="L3Wheel_visual">
        <pose>0.33147 -0.0624643351697891 -0.535765846678 0 0 0</pose>
        <material>
          <ambient>0.501960784313725 0.501960784313725 0.501960784313725 1</ambient>
          <diffuse>0.501960784313725 0.501960784313725 0.501960784313725 1</diffuse>
        </material>
        <geometry>
          <mesh>
            <scale>1 1 1</scale>
            <uri>model://SimBot2017/meshes/L3Wheel.STL</uri>
          </mesh>
        </geometry>
      </visual>
    </link>
    <joint name="Body-L3Wheel" type="revolute">
      <parent>Body</parent>
      <child>L3Wheel</child>
      <pose>0.0228600000000002 9.0205620750794E-17 0 0 0 3.14159265358979</pose>
      <axis>
        <xyz>1 0 0</xyz>
        <dynamics>
          <damping>2</damping>
          <friction>1</friction>
        </dynamics>
        <limit>
          <effort>50</effort>
        </limit>
      </axis>
    </joint>
    <link name="L4Wheel">
      <gravity>1</gravity>
      <self_collide>0</self_collide>
      <pose>0.114299999999999 0.70612 0.0349249999999965 1.5707963267949 6.19090554227257E-16 -1.5707963267949</pose>
      <must_be_base_link>0</must_be_base_link>
      <velocity_decay>
        <linear>0</linear>
        <angular>0</angular>
      </velocity_decay>
      <inertial>
        <mass>0.40839544131962</mass>
        <pose>0 0 0 0 0 0</pose>
        <inertia>
          <ixx>0.00522885625259631</ixx>
          <ixy>0</ixy>
          <ixz>0</ixz>
          <iyy>0.00347976426556731</iyy>
          <iyz>0</iyz>
          <izz>0.00347976426556731</izz>
        </inertia>
      </inertial>
      <collision name="L4Wheel_collision">
        <pose>0.33147 -0.0688143351697875 -0.7366 0 0 0</pose>
        <geometry>
          <mesh>
            <scale>1 1 1</scale>
            <uri>model://SimBot2017/meshes/L4Wheel_col.STL</uri>
          </mesh>
        </geometry>
        <surface>
		  <contact>
			<ode>
			  <max_vel>0.1</max_vel>
			  <soft_cfm>0.8</soft_cfm>
			  <soft_erp>0.8</soft_erp>
			  <kd>200</kd>
			  <kp>50000</kp>
			  <min_depth>0.0001</min_depth>
			</ode>
		  </contact>
          <friction>
            <ode>
              <mu>1</mu>
              <mu2>1</mu2>
            </ode>
          </friction>
        </surface>
      </collision>
      <visual name="L4Wheel_visual">
        <pose>0.33147 -0.0688143351697875 -0.7366 0 0 0</pose>
        <material>
          <ambient>0.501960784313725 0.501960784313725 0.501960784313725 1</ambient>
          <diffuse>0.501960784313725 0.501960784313725 0.501960784313725 1</diffuse>
        </material>
        <geometry>
          <mesh>
            <scale>1 1 1</scale>
            <uri>model://SimBot2017/meshes/L4Wheel.STL</uri>
          </mesh>
        </geometry>
      </visual>
    </link>
    <joint name="Body-L4Wheel" type="revolute">
      <parent>Body</parent>
      <child>L4Wheel</child>
      <pose>0.0228600000000002 8.32667268468867E-17 0 0 0 3.14159265358979</pose>
      <axis>
        <xyz>1 0 0</xyz>
        <dynamics>
          <damping>2</damping>
          <friction>1</friction>
        </dynamics>
        <limit>
          <effort>50</effort>
        </limit>
      </axis>
    </joint>
    <link name="R1Wheel">
      <gravity>1</gravity>
      <self_collide>0</self_collide>
      <pose>0.736600000000001 0.0431799999999997 0.0349250000000032 1.5707963267949 6.19090554227257E-16 -1.5707963267949</pose>
      <must_be_base_link>0</must_be_base_link>
      <velocity_decay>
        <linear>0</linear>
        <angular>0</angular>
      </velocity_decay>
      <inertial>
        <mass>0.40839544131962</mass>
        <pose>0 0 0 0 0 0</pose>
        <inertia>
          <ixx>0.00522885625259631</ixx>
          <ixy>0</ixy>
          <ixz>0</ixz>
          <iyy>0.00347976426556731</iyy>
          <iyz>0</iyz>
          <izz>0.00347976426556731</izz>
        </inertia>
      </inertial>
      <collision name="R1Wheel_collision">
        <pose>-0.33147 -0.0688143351697942 -0.114299999999999 0 0 0</pose>
        <geometry>
          <mesh>
            <scale>1 1 1</scale>
            <uri>model://SimBot2017/meshes/R1Wheel_col.STL</uri>
          </mesh>
        </geometry>
        <surface>
		  <contact>
			<ode>
			  <max_vel>0.1</max_vel>
			  <soft_cfm>0.8</soft_cfm>
			  <soft_erp>0.8</soft_erp>
			  <kd>200</kd>
			  <kp>50000</kp>
			  <min_depth>0.0001</min_depth>
			</ode>
		  </contact>
          <friction>
            <ode>
              <mu>1</mu>
              <mu2>1</mu2>
            </ode>
          </friction>
        </surface>
      </collision>
      <visual name="R1Wheel_visual">
        <pose>-0.33147 -0.0688143351697942 -0.114299999999999 0 0 0</pose>
        <material>
          <ambient>0.501960784313725 0.501960784313725 0.501960784313725 1</ambient>
          <diffuse>0.501960784313725 0.501960784313725 0.501960784313725 1</diffuse>
        </material>
        <geometry>
          <mesh>
            <scale>1 1 1</scale>
            <uri>model://SimBot2017/meshes/R1Wheel.STL</uri>
          </mesh>
        </geometry>
      </visual>
    </link>
    <joint name="Body-R1Wheel" type="revolute">
      <parent>Body</parent>
      <child>R1Wheel</child>
      <pose>-0.0228600000000001 6.93889390390723E-17 1.38777878078145E-17 0 0 3.14159265358979</pose>
      <axis>
        <xyz>-1 0 0</xyz>
        <dynamics>
          <damping>2</damping>
          <friction>1</friction>
        </dynamics>
        <limit>
          <effort>50</effort>
        </limit>
      </axis>
    </joint>
    <link name="R2Wheel">
      <gravity>1</gravity>
      <self_collide>0</self_collide>
      <pose>0.535765846678001 0.0431799999999998 0.0285750000000045 1.5707963267949 6.19090554227257E-16 -1.5707963267949</pose>
      <must_be_base_link>0</must_be_base_link>
      <velocity_decay>
        <linear>0</linear>
        <angular>0</angular>
      </velocity_decay>
      <inertial>
        <mass>0.40839544131962</mass>
        <pose>0 0 0 0 0 0</pose>
        <inertia>
          <ixx>0.00522885625259631</ixx>
          <ixy>0</ixy>
          <ixz>0</ixz>
          <iyy>0.00347976426556731</iyy>
          <iyz>0</iyz>
          <izz>0.00347976426556731</izz>
        </inertia>
      </inertial>
      <collision name="R2Wheel_collision">
        <pose>-0.33147 -0.0624643351697956 -0.315134153321999 0 0 0</pose>
        <geometry>
          <mesh>
            <scale>1 1 1</scale>
            <uri>model://SimBot2017/meshes/R2Wheel_col.STL</uri>
          </mesh>
        </geometry>
        <surface>
		  <contact>
			<ode>
			  <max_vel>0.1</max_vel>
			  <soft_cfm>0.8</soft_cfm>
			  <soft_erp>0.8</soft_erp>
			  <kd>200</kd>
			  <kp>50000</kp>
			  <min_depth>0.0001</min_depth>
			</ode>
		  </contact>
          <friction>
            <ode>
              <mu>1</mu>
              <mu2>1</mu2>
            </ode>
          </friction>
        </surface>
      </collision>
      <visual name="R2Wheel_visual">
        <pose>-0.33147 -0.0624643351697956 -0.315134153321999 0 0 0</pose>
        <material>
          <ambient>0.501960784313725 0.501960784313725 0.501960784313725 1</ambient>
          <diffuse>0.501960784313725 0.501960784313725 0.501960784313725 1</diffuse>
        </material>
        <geometry>
          <mesh>
            <scale>1 1 1</scale>
            <uri>model://SimBot2017/meshes/R2Wheel.STL</uri>
          </mesh>
        </geometry>
      </visual>
    </link>
    <joint name="Body-R2Wheel" type="revolute">
      <parent>Body</parent>
      <child>R2Wheel</child>
      <pose>-0.0228600000000001 7.63278329429795E-17 -5.55111512312578E-17 0 0 3.14159265358979</pose>
      <axis>
        <xyz>-1 0 0</xyz>
        <dynamics>
          <damping>2</damping>
          <friction>1</friction>
        </dynamics>
        <limit>
          <effort>50</effort>
        </limit>
      </axis>
    </joint>
    <link name="R3Wheel">
      <gravity>1</gravity>
      <self_collide>0</self_collide>
      <pose>0.315134153322001 0.0431799999999997 0.028575000000006 1.5707963267949 6.19090554227257E-16 -1.5707963267949</pose>
      <must_be_base_link>0</must_be_base_link>
      <velocity_decay>
        <linear>0</linear>
        <angular>0</angular>
      </velocity_decay>
      <inertial>
        <mass>0.408395441319621</mass>
        <pose>0 0 0 0 0 0</pose>
        <inertia>
          <ixx>0.00522885625259631</ixx>
          <ixy>0</ixy>
          <ixz>0</ixz>
          <iyy>0.00347976426556731</iyy>
          <iyz>0</iyz>
          <izz>0.00347976426556731</izz>
        </inertia>
      </inertial>
      <collision name="R3Wheel_collision">
        <pose>-0.33147 -0.0624643351697973 -0.535765846677999 0 0 0</pose>
        <geometry>
          <mesh>
            <scale>1 1 1</scale>
            <uri>model://SimBot2017/meshes/R3Wheel_col.STL</uri>
          </mesh>
        </geometry>
        <surface>
		  <contact>
			<ode>
			  <max_vel>0.1</max_vel>
			  <soft_cfm>0.8</soft_cfm>
			  <soft_erp>0.8</soft_erp>
			  <kd>200</kd>
			  <kp>50000</kp>
			  <min_depth>0.0001</min_depth>
			</ode>
		  </contact>
          <friction>
            <ode>
              <mu>1</mu>
              <mu2>1</mu2>
            </ode>
          </friction>
        </surface>
      </collision>
      <visual name="R3Wheel_visual">
        <pose>-0.33147 -0.0624643351697973 -0.535765846677999 0 0 0</pose>
        <material>
          <ambient>0.501960784313725 0.501960784313725 0.501960784313725 1</ambient>
          <diffuse>0.501960784313725 0.501960784313725 0.501960784313725 1</diffuse>
        </material>
        <geometry>
          <mesh>
            <scale>1 1 1</scale>
            <uri>model://SimBot2017/meshes/R3Wheel.STL</uri>
          </mesh>
        </geometry>
      </visual>
    </link>
    <joint name="Body-R3Wheel" type="revolute">
      <parent>Body</parent>
      <child>R3Wheel</child>
      <pose>-0.02286 8.32667268468867E-17 0 0 0 3.14159265358979</pose>
      <axis>
        <xyz>-1 0 0</xyz>
        <dynamics>
          <damping>2</damping>
          <friction>1</friction>
        </dynamics>
        <limit>
          <effort>50</effort>
        </limit>
      </axis>
    </joint>
    <link name="R4Wheel">
      <gravity>1</gravity>
      <self_collide>0</self_collide>
      <pose>0.1143 0.0431799999999996 0.0349250000000077 1.5707963267949 6.19090554227257E-16 -1.5707963267949</pose>
      <must_be_base_link>0</must_be_base_link>
      <velocity_decay>
        <linear>0</linear>
        <angular>0</angular>
      </velocity_decay>
      <inertial>
        <mass>0.40839544131962</mass>
        <pose>0 0 0 0 0 0</pose>
        <inertia>
          <ixx>0.00522885625259631</ixx>
          <ixy>0</ixy>
          <ixz>0</ixz>
          <iyy>0.00347976426556731</iyy>
          <iyz>0</iyz>
          <izz>0.00347976426556731</izz>
        </inertia>
      </inertial>
      <collision name="R4Wheel_collision">
        <pose>-0.33147 -0.0688143351697991 -0.736599999999999 0 0 0</pose>
        <geometry>
          <mesh>
            <scale>1 1 1</scale>
            <uri>model://SimBot2017/meshes/R4Wheel_col.STL</uri>
          </mesh>
        </geometry>
        <surface>
		  <contact>
			<ode>
			  <max_vel>0.1</max_vel>
			  <soft_cfm>0.8</soft_cfm>
			  <soft_erp>0.8</soft_erp>
			  <kd>200</kd>
			  <kp>50000</kp>
			  <min_depth>0.0001</min_depth>
			</ode>
		  </contact>
          <friction>
            <ode>
              <mu>1</mu>
              <mu2>1</mu2>
            </ode>
          </friction>
        </surface>
      </collision>
      <visual name="R4Wheel_visual">
        <pose>-0.33147 -0.0688143351697991 -0.736599999999999 0 0 0</pose>
        <material>
          <ambient>0.501960784313725 0.501960784313725 0.501960784313725 1</ambient>
          <diffuse>0.501960784313725 0.501960784313725 0.501960784313725 1</diffuse>
        </material>
        <geometry>
          <mesh>
            <scale>1 1 1</scale>
            <uri>model://SimBot2017/meshes/R4Wheel.STL</uri>
          </mesh>
        </geometry>
      </visual>
    </link>
    <joint name="Body-R4Wheel" type="revolute">
      <parent>Body</parent>
      <child>R4Wheel</child>
      <pose>-0.0228600000000001 6.93889390390723E-17 0 0 0 3.14159265358979</pose>
      <axis>
        <xyz>-1 0 0</xyz>
        <dynamics>
          <damping>2</damping>
          <friction>1</friction>
        </dynamics>
        <limit>
          <effort>50</effort>
        </limit>
      </axis>
    </joint>   
    <plugin name="TopFrame_rangefinder" filename="librangefinder.so">
      <topic>/gazebo/frc/simulator/analog/0</topic>
      <sensor>TopFrameUltrasonic</sensor>
    </plugin>
    <plugin name="Body-L1Wheel_motor" filename="libdc_motor.so">
      <joint>Body-L1Wheel</joint>
      <topic>/gazebo/frc/simulator/pwm/2</topic>
      <multiplier>25</multiplier>
    </plugin>
    <plugin name="Body-L2Wheel_motor" filename="libdc_motor.so">
      <joint>Body-L2Wheel</joint>
      <topic>/gazebo/frc/simulator/pwm/2</topic>
      <multiplier>25</multiplier>
    </plugin>
    <plugin name="Body-L2Wheel_encoder" filename="libencoder.so">
      <joint>Body-L2Wheel</joint>
      <topic>/gazebo/frc/simulator/dio/3/4</topic>
      <units>degrees</units>
    </plugin>
    <plugin name="Body-L3Wheel_motor" filename="libdc_motor.so">
      <joint>Body-L3Wheel</joint>
      <topic>/gazebo/frc/simulator/pwm/2</topic>
      <multiplier>25</multiplier>
    </plugin>
    <plugin name="Body-L4Wheel_motor" filename="libdc_motor.so">
      <joint>Body-L4Wheel</joint>
      <topic>/gazebo/frc/simulator/pwm/2</topic>
      <multiplier>25</multiplier>
    </plugin>
    <plugin name="Body-R1Wheel_motor" filename="libdc_motor.so">
      <joint>Body-R1Wheel</joint>
      <topic>/gazebo/frc/simulator/pwm/4</topic>
      <multiplier>25</multiplier>
    </plugin>
    <plugin name="Body-R2Wheel_motor" filename="libdc_motor.so">
      <joint>Body-R2Wheel</joint>
      <topic>/gazebo/frc/simulator/pwm/4</topic>
      <multiplier>25</multiplier>
    </plugin>
    <plugin name="Body-R2Wheel_encoder" filename="libencoder.so">
      <joint>Body-R2Wheel</joint>
      <topic>/gazebo/frc/simulator/dio/7/8</topic>
      <units>degrees</units>
    </plugin>
    <plugin name="Body-R3Wheel_motor" filename="libdc_motor.so">
      <joint>Body-R3Wheel</joint>
      <topic>/gazebo/frc/simulator/pwm/4</topic>
      <multiplier>25</multiplier>
    </plugin>
    <plugin name="Body-R4Wheel_motor" filename="libdc_motor.so">
      <joint>Body-R4Wheel</joint>
      <topic>/gazebo/frc/simulator/pwm/4</topic>
      <multiplier>0</multiplier>
    </plugin>
  </model>
</sdf>
