<?xml version="1.0" encoding="utf-8"?>
<sdf version="1.5">
  <model name="2016-Robot">
    <pose>0 0 0.065730430959305 0 0 0</pose>
    <plugin name="clock" filename="libgz_clock.so">
      <topic>/gazebo/frc/time</topic>
    </plugin>
    <link name="TopFrame">
      <gravity>1</gravity>
      <self_collide>0</self_collide>
      <pose>-0.533395115139063 0.0789789299071872 -0.409750202936456 0 0 0</pose>
      <must_be_base_link>1</must_be_base_link>
      <velocity_decay>
        <linear>0</linear>
        <angular>0</angular>
      </velocity_decay>
      <inertial>
        <mass>13.8160240057403</mass>
        <pose>0 0 0 0 0 0</pose>
        <inertia>
          <ixx>0.31222904304344</ixx>
          <ixy>0.0788409764861491</ixy>
          <ixz>0.0675250877668005</ixz>
          <iyy>0.985211120460142</iyy>
          <iyz>0.00714138457032961</iyz>
          <izz>0.741213938550275</izz>
        </inertia>
      </inertial>
      <collision name="TopFrame_collision">
        <pose>0.486409190947529 -0.147727906234985 0.0878118630643742 0 0 0</pose>
        <geometry>
          <mesh>
            <scale>1 1 1</scale>
            <uri>model://2016-Robot/meshes/TopFrame_col.STL</uri>
          </mesh>
        </geometry>
        <surface>
          <contact>
            <ode />
          </contact>
          <friction>
            <ode>
              <mu>1</mu>
              <mu2>1</mu2>
            </ode>
          </friction>
        </surface>
      </collision>
      <visual name="TopFrame_visual">
        <pose>0.486409190947529 -0.147727906234985 0.0878118630643742 0 0 0</pose>
        <material>
          <ambient>0 0 1 1</ambient>
          <diffuse>0 0 1 1</diffuse>
        </material>
        <geometry>
          <mesh>
            <scale>1 1 1</scale>
            <uri>model://2016-Robot/meshes/TopFrame.STL</uri>
          </mesh>
        </geometry>
      </visual>
      <sensor name="TopFrameUltrasonic" type="sonar">
        <always_on>1</always_on>
        <visualize>1</visualize>
        <pose>0.35392290741695 0.0693575980565701 -0.0852072970635439 3.14159265358979 6.10865238198015 1.5707963267949</pose>
        <sonar>
          <min>0.05</min>
          <max>7</max>
          <radius>0.05</radius>
        </sonar>
      </sensor>
    </link>
    <link name="LeftFrame">
      <gravity>1</gravity>
      <self_collide>0</self_collide>
      <pose>-0.618450351055012 0.0631432788048647 -0.127836742892201 0 0 0</pose>
      <must_be_base_link>0</must_be_base_link>
      <velocity_decay>
        <linear>0</linear>
        <angular>0</angular>
      </velocity_decay>
      <inertial>
        <mass>9.85785490756741</mass>
        <pose>0 0 0 0 0 0</pose>
        <inertia>
          <ixx>0.0471972045701552</ixx>
          <ixy>0.00766399735288125</ixy>
          <ixz>0.0465516804306948</ixz>
          <iyy>0.22382148793727</iyy>
          <iyz>0.00045431168494742</iyz>
          <izz>0.191818995212824</izz>
        </inertia>
      </inertial>
      <collision name="LeftFrame_collision">
        <pose>0.571464426863478 -0.131892255132663 -0.19410159697988 0 0 0</pose>
        <geometry>
          <mesh>
            <scale>1 1 1</scale>
            <uri>model://2016-Robot/meshes/LeftFrame_col.STL</uri>
          </mesh>
        </geometry>
        <surface>
          <contact>
            <ode />
          </contact>
          <friction>
            <ode>
              <mu>0</mu>
              <mu2>0</mu2>
            </ode>
          </friction>
        </surface>
      </collision>
      <visual name="LeftFrame_visual">
        <pose>0.571464426863478 -0.131892255132663 -0.19410159697988 0 0 0</pose>
        <material>
          <ambient>0 1 0 1</ambient>
          <diffuse>0 1 0 1</diffuse>
        </material>
        <geometry>
          <mesh>
            <scale>1 1 1</scale>
            <uri>model://2016-Robot/meshes/LeftFrame.STL</uri>
          </mesh>
        </geometry>
      </visual>
    </link>
    <joint name="TopFrame-LeftFrame" type="revolute">
      <parent>TopFrame</parent>
      <child>LeftFrame</child>
      <pose>0.239026470664604 -0.0128274597641691 0.108786742892201 0 0 0</pose>
      <axis>
        <xyz>0 1.35912835505685E-15 -1</xyz>
        <dynamics>
          <damping>1</damping>
          <friction>1</friction>
        </dynamics>
        <limit>
          <upper>0.1</upper>
          <lower>-0.1</lower>
          <effort>1</effort>
        </limit>
      </axis>
    </joint>
    <link name="L1Wheel">
      <gravity>1</gravity>
      <self_collide>0</self_collide>
      <pose>-0.683804458189783 0.067805241523013 0.0420138912902915 0 0 0</pose>
      <must_be_base_link>0</must_be_base_link>
      <velocity_decay>
        <linear>0</linear>
        <angular>0</angular>
      </velocity_decay>
      <inertial>
        <mass>0.563089722339732</mass>
        <pose>0 0 0 0 0 0</pose>
        <inertia>
          <ixx>0.00128473699848457</ixx>
          <ixy>8.45306973151724E-08</ixy>
          <ixz>5.92558377875995E-08</ixz>
          <iyy>0.00128284435761216</iyy>
          <iyz>4.61662650868699E-07</iyz>
          <izz>0.00217022940821743</izz>
        </inertia>
      </inertial>
      <collision name="L1Wheel_collision">
        <pose>0.636818533998249 -0.136554217850811 -0.363952231162373 0 0 0</pose>
        <geometry>
          <mesh>
            <scale>1 1 1</scale>
            <uri>model://2016-Robot/meshes/L1Wheel_col.STL</uri>
          </mesh>
        </geometry>
        <surface>
          <contact>
            <ode />
          </contact>
          <friction>
            <ode>
              <mu>1</mu>
              <mu2>1</mu2>
            </ode>
          </friction>
        </surface>
      </collision>
      <visual name="L1Wheel_visual">
        <pose>0.636818533998249 -0.136554217850811 -0.363952231162373 0 0 0</pose>
        <material>
          <ambient>0.501960784313725 0.501960784313725 0.501960784313725 1</ambient>
          <diffuse>0.501960784313725 0.501960784313725 0.501960784313725 1</diffuse>
        </material>
        <geometry>
          <mesh>
            <scale>1 1 1</scale>
            <uri>model://2016-Robot/meshes/L1Wheel.STL</uri>
          </mesh>
        </geometry>
      </visual>
    </link>
    <joint name="LeftFrame-L1Wheel" type="revolute">
      <parent>LeftFrame</parent>
      <child>L1Wheel</child>
      <pose>-5.34292188936192E-06 -0.00126202869450837 -0.00280159194936064 0 4.71238898038469 0</pose>
      <axis>
        <xyz>1 3.55220947471457E-15 5.86987368327021E-16</xyz>
        <dynamics>
          <damping>1</damping>
          <friction>1</friction>
        </dynamics>
        <limit>
          <effort>40</effort>
        </limit>
      </axis>
    </joint>
    <link name="L2Wheel">
      <gravity>1</gravity>
      <self_collide>0</self_collide>
      <pose>-0.481242773451086 0.0445413810430762 0.0420138866140045 0 0 0</pose>
      <must_be_base_link>0</must_be_base_link>
      <velocity_decay>
        <linear>0</linear>
        <angular>0</angular>
      </velocity_decay>
      <inertial>
        <mass>0.563090205861147</mass>
        <pose>0 0 0 0 0 0</pose>
        <inertia>
          <ixx>0.00128356016764172</ixx>
          <ixy>9.2339648226236E-07</ixy>
          <ixz>3.42107097068741E-07</ixz>
          <iyy>0.00128402353546046</iyy>
          <iyz>3.15330251327029E-07</iyz>
          <izz>0.00217023168571162</izz>
        </inertia>
      </inertial>
      <collision name="L2Wheel_collision">
        <pose>0.434256849259552 -0.113290357370874 -0.363952226486086 0 0 0</pose>
        <geometry>
          <mesh>
            <scale>1 1 1</scale>
            <uri>model://2016-Robot/meshes/L2Wheel_col.STL</uri>
          </mesh>
        </geometry>
        <surface>
          <contact>
            <ode />
          </contact>
          <friction>
            <ode>
              <mu>1</mu>
              <mu2>1</mu2>
            </ode>
          </friction>
        </surface>
      </collision>
      <visual name="L2Wheel_visual">
        <pose>0.434256849259552 -0.113290357370874 -0.363952226486086 0 0 0</pose>
        <material>
          <ambient>0.501960784313725 0.501960784313725 0.501960784313725 1</ambient>
          <diffuse>0.501960784313725 0.501960784313725 0.501960784313725 1</diffuse>
        </material>
        <geometry>
          <mesh>
            <scale>1 1 1</scale>
            <uri>model://2016-Robot/meshes/L2Wheel.STL</uri>
          </mesh>
        </geometry>
      </visual>
    </link>
    <joint name="LeftFrame-L2Wheel" type="revolute">
      <parent>LeftFrame</parent>
      <child>L2Wheel</child>
      <pose>-0.00103245970220861 -0.000725942680307748 -0.00280158727307361 0 4.71238898038469 0</pose>
      <axis>
        <xyz>1 2.43453495446626E-15 -3.63619758917495E-15</xyz>
        <dynamics>
          <damping>1</damping>
          <friction>1</friction>
        </dynamics>
        <limit>
          <effort>40</effort>
        </limit>
      </axis>
    </joint>
    <link name="L3Wheel">
      <gravity>1</gravity>
      <self_collide>0</self_collide>
      <pose>-0.278176638184261 0.0371667821828672 0.0420138866144454 0 0 0</pose>
      <must_be_base_link>0</must_be_base_link>
      <velocity_decay>
        <linear>0</linear>
        <angular>0</angular>
      </velocity_decay>
      <inertial>
        <mass>0.563090205845961</mass>
        <pose>0 0 0 0 0 0</pose>
        <inertia>
          <ixx>0.00128356016759542</ixx>
          <ixy>9.23396523951151E-07</ixy>
          <ixz>3.42107083886171E-07</ixz>
          <iyy>0.00128402353541832</iyy>
          <iyz>3.15330267071781E-07</iyz>
          <izz>0.00217023168563124</izz>
        </inertia>
      </inertial>
      <collision name="L3Wheel_collision">
        <pose>0.231190713992727 -0.105915758510665 -0.363952226486527 0 0 0</pose>
        <geometry>
          <mesh>
            <scale>1 1 1</scale>
            <uri>model://2016-Robot/meshes/L3Wheel_col.STL</uri>
          </mesh>
        </geometry>
        <surface>
          <contact>
            <ode />
          </contact>
          <friction>
            <ode>
              <mu>1</mu>
              <mu2>1</mu2>
            </ode>
          </friction>
        </surface>
      </collision>
      <visual name="L3Wheel_visual">
        <pose>0.231190713992727 -0.105915758510665 -0.363952226486527 0 0 0</pose>
        <material>
          <ambient>0.501960784313725 0.501960784313725 0.501960784313725 1</ambient>
          <diffuse>0.501960784313725 0.501960784313725 0.501960784313725 1</diffuse>
        </material>
        <geometry>
          <mesh>
            <scale>1 1 1</scale>
            <uri>model://2016-Robot/meshes/L3Wheel.STL</uri>
          </mesh>
        </geometry>
      </visual>
    </link>
    <joint name="LeftFrame-L3Wheel" type="revolute">
      <parent>LeftFrame</parent>
      <child>L3Wheel</child>
      <pose>-0.0010324597035182 -0.000725942678857908 -0.00280158727351471 0 4.71238898038469 0</pose>
      <axis>
        <xyz>1 2.43483933929782E-15 -3.8166088306764E-15</xyz>
        <dynamics>
          <damping>1</damping>
          <friction>1</friction>
        </dynamics>
        <limit>
          <effort>40</effort>
        </limit>
      </axis>
    </joint>
    <link name="L4Wheel">
      <gravity>1</gravity>
      <self_collide>0</self_collide>
      <pose>-0.0746705021316641 0.0456315417934899 0.0420138872494831 0 0 0</pose>
      <must_be_base_link>0</must_be_base_link>
      <velocity_decay>
        <linear>0</linear>
        <angular>0</angular>
      </velocity_decay>
      <inertial>
        <mass>0.563090139948905</mass>
        <pose>0 0 0 0 0 0</pose>
        <inertia>
          <ixx>0.00128326689289071</ixx>
          <ixy>7.94197569308375E-07</ixy>
          <ixz>4.26488835310565E-07</ixz>
          <iyy>0.00128431676319944</iyy>
          <iyz>1.85963542213683E-07</iyz>
          <izz>0.00217023164813033</izz>
        </inertia>
      </inertial>
      <collision name="L4Wheel_collision">
        <pose>0.0276845779401301 -0.114380518121288 -0.363952227121565 0 0 0</pose>
        <geometry>
          <mesh>
            <scale>1 1 1</scale>
            <uri>model://2016-Robot/meshes/L4Wheel_col.STL</uri>
          </mesh>
        </geometry>
        <surface>
          <contact>
            <ode />
          </contact>
          <friction>
            <ode>
              <mu>1</mu>
              <mu2>1</mu2>
            </ode>
          </friction>
        </surface>
      </collision>
      <visual name="L4Wheel_visual">
        <pose>0.0276845779401301 -0.114380518121288 -0.363952227121565 0 0 0</pose>
        <material>
          <ambient>0.501960784313725 0.501960784313725 0.501960784313725 1</ambient>
          <diffuse>0.501960784313725 0.501960784313725 0.501960784313725 1</diffuse>
        </material>
        <geometry>
          <mesh>
            <scale>1 1 1</scale>
            <uri>model://2016-Robot/meshes/L4Wheel.STL</uri>
          </mesh>
        </geometry>
      </visual>
    </link>
    <joint name="LeftFrame-L4Wheel" type="revolute">
      <parent>LeftFrame</parent>
      <child>L4Wheel</child>
      <pose>0.00108055233672497 -0.000652200909677103 -0.00280158790855251 0 4.71238898038469 0</pose>
      <axis>
        <xyz>1 1.36238167480024E-16 3.96748462011841E-15</xyz>
        <dynamics>
          <damping>1</damping>
          <friction>1</friction>
        </dynamics>
        <limit>
          <effort>40</effort>
        </limit>
      </axis>
    </joint>
    <link name="R1Wheel">
      <gravity>1</gravity>
      <self_collide>0</self_collide>
      <pose>-0.674628433756941 0.0558288492220792 -0.58493888661413 0 0 0</pose>
      <must_be_base_link>0</must_be_base_link>
      <velocity_decay>
        <linear>0</linear>
        <angular>0</angular>
      </velocity_decay>
      <inertial>
        <mass>0.563090205855884</mass>
        <pose>0 0 0 0 0 0</pose>
        <inertia>
          <ixx>0.00128320297787334</ixx>
          <ixy>7.48041643819943E-07</ixy>
          <ixz>4.00451867667559E-07</ixz>
          <iyy>0.00128438072523263</iyy>
          <iyz>2.36872825132452E-07</iyz>
          <izz>0.00217023168571774</izz>
        </inertia>
      </inertial>
      <collision name="R1Wheel_collision">
        <pose>0.627642509565407 -0.124577825549877 0.263000546742048 0 0 0</pose>
        <geometry>
          <mesh>
            <scale>1 1 1</scale>
            <uri>model://2016-Robot/meshes/R1Wheel_col.STL</uri>
          </mesh>
        </geometry>
        <surface>
          <contact>
            <ode />
          </contact>
          <friction>
            <ode>
              <mu>1</mu>
              <mu2>1</mu2>
            </ode>
          </friction>
        </surface>
      </collision>
      <visual name="R1Wheel_visual">
        <pose>0.627642509565407 -0.124577825549877 0.263000546742048 0 0 0</pose>
        <material>
          <ambient>0.501960784313725 0.501960784313725 0.501960784313725 1</ambient>
          <diffuse>0.501960784313725 0.501960784313725 0.501960784313725 1</diffuse>
        </material>
        <geometry>
          <mesh>
            <scale>1 1 1</scale>
            <uri>model://2016-Robot/meshes/R1Wheel.STL</uri>
          </mesh>
        </geometry>
      </visual>
    </link>
    <joint name="TopFrame-R1Wheel" type="revolute">
      <parent>TopFrame</parent>
      <child>R1Wheel</child>
      <pose>-0.00116137209352352 0.000494146406825241 0.00280158727319829 0 4.71238898038469 0</pose>
      <axis>
        <xyz>1 3.00445054017627E-15 3.78565018088647E-15</xyz>
        <dynamics>
          <damping>1</damping>
          <friction>1</friction>
        </dynamics>
        <limit>
          <effort>40</effort>
        </limit>
      </axis>
    </joint>
    <link name="R2Wheel">
      <gravity>1</gravity>
      <self_collide>0</self_collide>
      <pose>-0.471503565015896 0.0399146424688072 -0.584938891290733 0 0 0</pose>
      <must_be_base_link>0</must_be_base_link>
      <velocity_decay>
        <linear>0</linear>
        <angular>0</angular>
      </velocity_decay>
      <inertial>
        <mass>0.563089722324534</mass>
        <pose>0 0 0 0 0 0</pose>
        <inertia>
          <ixx>0.00128473733920884</ixx>
          <ixy>8.06253560253119E-08</ixy>
          <ixz>1.89055806378122E-08</ixz>
          <iyy>0.00128284401679943</iyy>
          <iyz>4.65065842063287E-07</iyz>
          <izz>0.00217022940813703</izz>
        </inertia>
      </inertial>
      <collision name="R2Wheel_collision">
        <pose>0.424517640824362 -0.108663618796605 0.263000551418651 0 0 0</pose>
        <geometry>
          <mesh>
            <scale>1 1 1</scale>
            <uri>model://2016-Robot/meshes/R2Wheel_col.STL</uri>
          </mesh>
        </geometry>
        <surface>
          <contact>
            <ode />
          </contact>
          <friction>
            <ode>
              <mu>1</mu>
              <mu2>1</mu2>
            </ode>
          </friction>
        </surface>
      </collision>
      <visual name="R2Wheel_visual">
        <pose>0.424517640824362 -0.108663618796605 0.263000551418651 0 0 0</pose>
        <material>
          <ambient>0.501960784313725 0.501960784313725 0.501960784313725 1</ambient>
          <diffuse>0.501960784313725 0.501960784313725 0.501960784313725 1</diffuse>
        </material>
        <geometry>
          <mesh>
            <scale>1 1 1</scale>
            <uri>model://2016-Robot/meshes/R2Wheel.STL</uri>
          </mesh>
        </geometry>
      </visual>
    </link>
    <joint name="TopFrame-R2Wheel" type="revolute">
      <parent>TopFrame</parent>
      <child>R2Wheel</child>
      <pose>-0.000115013626851679 0.0012567883031019 0.00280159194980162 0 4.71238898038469 0</pose>
      <axis>
        <xyz>1 3.64692314456558E-15 -7.1037221242052E-16</xyz>
        <dynamics>
          <damping>1</damping>
          <friction>1</friction>
        </dynamics>
        <limit>
          <effort>40</effort>
        </limit>
      </axis>
    </joint>
    <link name="R3Wheel">
      <gravity>1</gravity>
      <self_collide>0</self_collide>
      <pose>-0.268298933750979 0.039914509470502 -0.584938891290291 0 0 0</pose>
      <must_be_base_link>0</must_be_base_link>
      <velocity_decay>
        <linear>0</linear>
        <angular>0</angular>
      </velocity_decay>
      <inertial>
        <mass>0.563089722339755</mass>
        <pose>0 0 0 0 0 0</pose>
        <inertia>
          <ixx>0.00128472234969804</ixx>
          <ixy>1.86160532930484E-07</ixy>
          <ixz>7.21304634677883E-09</ixz>
          <iyy>0.00128285900639875</iyy>
          <iyz>4.6539405827201E-07</iyz>
          <izz>0.00217022940821748</izz>
        </inertia>
      </inertial>
      <collision name="R3Wheel_collision">
        <pose>0.221313009559445 -0.1086634857983 0.263000551418209 0 0 0</pose>
        <geometry>
          <mesh>
            <scale>1 1 1</scale>
            <uri>model://2016-Robot/meshes/R3Wheel_col.STL</uri>
          </mesh>
        </geometry>
        <surface>
          <contact>
            <ode />
          </contact>
          <friction>
            <ode>
              <mu>1</mu>
              <mu2>1</mu2>
            </ode>
          </friction>
        </surface>
      </collision>
      <visual name="R3Wheel_visual">
        <pose>0.221313009559445 -0.1086634857983 0.263000551418209 0 0 0</pose>
        <material>
          <ambient>0.501960784313725 0.501960784313725 0.501960784313725 1</ambient>
          <diffuse>0.501960784313725 0.501960784313725 0.501960784313725 1</diffuse>
        </material>
        <geometry>
          <mesh>
            <scale>1 1 1</scale>
            <uri>model://2016-Robot/meshes/R3Wheel.STL</uri>
          </mesh>
        </geometry>
      </visual>
    </link>
    <joint name="TopFrame-R3Wheel" type="revolute">
      <parent>TopFrame</parent>
      <child>R3Wheel</child>
      <pose>-0.000185334670375403 0.00124835733367312 0.00280159194936008 0 4.71238898038469 0</pose>
      <axis>
        <xyz>1 3.6805931371173E-15 -6.99260972436613E-16</xyz>
        <dynamics>
          <damping>1</damping>
          <friction>1</friction>
        </dynamics>
        <limit>
          <effort>40</effort>
        </limit>
      </axis>
    </joint>
    <link name="R4Wheel">
      <gravity>1</gravity>
      <self_collide>0</self_collide>
      <pose>-0.0650989337490239 0.055789509470554 -0.584938891290732 0 0 0</pose>
      <must_be_base_link>0</must_be_base_link>
      <velocity_decay>
        <linear>0</linear>
        <angular>0</angular>
      </velocity_decay>
      <inertial>
        <mass>0.56308972232454</mass>
        <pose>0 0 0 0 0 0</pose>
        <inertia>
          <ixx>0.00128472234969553</ixx>
          <ixy>1.86160532932675E-07</ixy>
          <ixz>7.21302584444049E-09</ixz>
          <iyy>0.00128285900631277</iyy>
          <iyz>4.65394059575121E-07</iyz>
          <izz>0.00217022940813706</izz>
        </inertia>
      </inertial>
      <collision name="R4Wheel_collision">
        <pose>0.0181130095574899 -0.124538485798352 0.26300055141865 0 0 0</pose>
        <geometry>
          <mesh>
            <scale>1 1 1</scale>
            <uri>model://2016-Robot/meshes/R4Wheel_col.STL</uri>
          </mesh>
        </geometry>
        <surface>
          <contact>
            <ode />
          </contact>
          <friction>
            <ode>
              <mu>1</mu>
              <mu2>1</mu2>
            </ode>
          </friction>
        </surface>
      </collision>
      <visual name="R4Wheel_visual">
        <pose>0.0181130095574899 -0.124538485798352 0.26300055141865 0 0 0</pose>
        <material>
          <ambient>0.501960784313725 0.501960784313725 0.501960784313725 1</ambient>
          <diffuse>0.501960784313725 0.501960784313725 0.501960784313725 1</diffuse>
        </material>
        <geometry>
          <mesh>
            <scale>1 1 1</scale>
            <uri>model://2016-Robot/meshes/R4Wheel.STL</uri>
          </mesh>
        </geometry>
      </visual>
    </link>
    <joint name="TopFrame-R4Wheel" type="revolute">
      <parent>TopFrame</parent>
      <child>R4Wheel</child>
      <pose>-0.000185334672337046 0.00124835733362015 0.00280159194980151 0 4.71238898038469 0</pose>
      <axis>
        <xyz>1 3.68823085207016E-15 -6.02116457768805E-16</xyz>
        <dynamics>
          <damping>1</damping>
          <friction>1</friction>
        </dynamics>
        <limit>
          <effort>40</effort>
        </limit>
      </axis>
    </joint>
    <link name="Shooter">
      <gravity>1</gravity>
      <self_collide>0</self_collide>
      <pose>-0.3452125646057 0.101204251488885 -0.307552937501568 0 0 0</pose>
      <must_be_base_link>0</must_be_base_link>
      <velocity_decay>
        <linear>0</linear>
        <angular>0</angular>
      </velocity_decay>
      <inertial>
        <mass>6.63369828386752</mass>
        <pose>0 0 0 0 0 0</pose>
        <inertia>
          <ixx>0.171310220379697</ixx>
          <ixy>0.0010443743257843</ixy>
          <ixz>0.0377045727072385</ixz>
          <iyy>0.205940534733888</iyy>
          <iyz>0.00351408985970373</iyz>
          <izz>0.0696525597090275</izz>
        </inertia>
      </inertial>
      <collision name="Shooter_collision">
        <pose>0.298226640414166 -0.169953227816683 -0.0143854023705138 0 0 0</pose>
        <geometry>
          <mesh>
            <scale>1 1 1</scale>
            <uri>model://2016-Robot/meshes/Shooter_col.STL</uri>
          </mesh>
        </geometry>
        <surface>
          <contact>
            <ode />
          </contact>
          <friction>
            <ode>
              <mu>0</mu>
              <mu2>0</mu2>
            </ode>
          </friction>
        </surface>
      </collision>
      <visual name="Shooter_visual">
        <pose>0.298226640414166 -0.169953227816683 -0.0143854023705138 0 0 0</pose>
        <material>
          <ambient>0 0.501960784313725 0.501960784313725 1</ambient>
          <diffuse>0 0.501960784313725 0.501960784313725 1</diffuse>
        </material>
        <geometry>
          <mesh>
            <scale>1 1 1</scale>
            <uri>model://2016-Robot/meshes/Shooter.STL</uri>
          </mesh>
        </geometry>
      </visual>
      <sensor name="ShooterCamera" type="camera">
        <visualize>1</visualize>
        <always_on>1</always_on>
        <pose>-0.0437018903432867 0.0952380706583773 -0.49432296944776 1.5707963267949 0 3.14159265358979</pose>
        <camera name="Shootercamera">
          <horizontal_fov>1.02974425867665</horizontal_fov>
          <image>
            <width>320</width>
            <height>240</height>
          </image>
          <clip>
            <near>0.1</near>
            <far>100</far>
          </clip>
        </camera>
      </sensor>
      <sensor name="ShooterUltrasonic" type="sonar">
        <always_on>1</always_on>
        <visualize>1</visualize>
        <pose>-0.0437018903432867 0.0952380706583773 -0.49432296944776 1.57079632679492 0 1.53580122962653</pose>
        <sonar>
          <min>1</min>
          <max>4</max>
          <radius>0.01</radius>
        </sonar>
      </sensor>
    </link>
    <joint name="TopFrame-Shooter" type="revolute">
      <parent>TopFrame</parent>
      <child>Shooter</child>
      <pose>0.127663684215292 0.0484653175518104 -0.219092062498432 0 0 0</pose>
      <axis>
        <xyz>0 0 -1</xyz>
        <dynamics>
          <damping>1</damping>
          <friction>1</friction>
        </dynamics>
        <limit>
          <upper>1.3</upper>
          <lower>0</lower>
          <effort>30</effort>
        </limit>
      </axis>
    </joint>
    <link name="PushWheel">
      <gravity>1</gravity>
      <self_collide>0</self_collide>
      <pose>-0.217627427327181 0.14835881648459 -0.428965755137175 0 0 0</pose>
      <must_be_base_link>0</must_be_base_link>
      <velocity_decay>
        <linear>0</linear>
        <angular>0</angular>
      </velocity_decay>
      <inertial>
        <mass>0.596238102075934</mass>
        <pose>0 0 0 0 0 0</pose>
        <inertia>
          <ixx>0.000669967858234903</ixx>
          <ixy>2.05740863147869E-05</ixy>
          <ixz>4.46928575378656E-07</ixz>
          <iyy>0.00125126089988878</iyy>
          <iyz>1.2143612895254E-07</iyz>
          <izz>0.000668907774058869</izz>
        </inertia>
      </inertial>
      <collision name="PushWheel_collision">
        <pose>0.170641503135647 -0.217107792812388 0.107027415265093 0 0 0</pose>
        <geometry>
          <mesh>
            <scale>1 1 1</scale>
            <uri>model://2016-Robot/meshes/PushWheel_col.STL</uri>
          </mesh>
        </geometry>
        <surface>
          <contact>
            <ode />
          </contact>
          <friction>
            <ode>
              <mu>1</mu>
              <mu2>1</mu2>
            </ode>
          </friction>
        </surface>
      </collision>
      <visual name="PushWheel_visual">
        <pose>0.170641503135647 -0.217107792812388 0.107027415265093 0 0 0</pose>
        <material>
          <ambient>0.501960784313725 0.501960784313725 0.501960784313725 1</ambient>
          <diffuse>0.501960784313725 0.501960784313725 0.501960784313725 1</diffuse>
        </material>
        <geometry>
          <mesh>
            <scale>1 1 1</scale>
            <uri>model://2016-Robot/meshes/PushWheel.STL</uri>
          </mesh>
        </geometry>
      </visual>
    </link>
    <joint name="Shooter-PushWheel" type="revolute">
      <parent>Shooter</parent>
      <child>PushWheel</child>
      <pose>2.91246608821183E-05 -0.00010093373826156 2.25928913457352E-05 0 1.28607625788662E-15 4.71238898038469</pose>
      <axis>
        <xyz>0.999387734075552 -0.0349879547749582 -7.87420668946189E-19</xyz>
        <dynamics>
          <damping>1</damping>
          <friction>1</friction>
        </dynamics>
        <limit>
          <effort>50</effort>
        </limit>
      </axis>
    </joint>
    <link name="LeftFW">
      <gravity>1</gravity>
      <self_collide>0</self_collide>
      <pose>-0.420690753823349 0.155472197994548 -0.11145415305803 0 0 0</pose>
      <must_be_base_link>0</must_be_base_link>
      <velocity_decay>
        <linear>0</linear>
        <angular>0</angular>
      </velocity_decay>
      <inertial>
        <mass>1.80417289681754</mass>
        <pose>0 0 0 0 0 0</pose>
        <inertia>
          <ixx>0.00209273157148267</ixx>
          <ixy>6.40453678387408E-05</ixy>
          <ixz>7.1350830068574E-07</ixz>
          <iyy>0.00390910359610518</iyy>
          <iyz>1.76725981146584E-07</iyz>
          <izz>0.00208953516377663</izz>
        </inertia>
      </inertial>
      <collision name="LeftFW_collision">
        <pose>0.373704829631815 -0.224221174322345 -0.210484186814052 0 0 0</pose>
        <geometry>
          <mesh>
            <scale>1 1 1</scale>
            <uri>model://2016-Robot/meshes/LeftFW_col.STL</uri>
          </mesh>
        </geometry>
        <surface>
          <contact>
            <ode />
          </contact>
          <friction>
            <ode>
              <mu>1</mu>
              <mu2>1</mu2>
            </ode>
          </friction>
        </surface>
      </collision>
      <visual name="LeftFW_visual">
        <pose>0.373704829631815 -0.224221174322345 -0.210484186814052 0 0 0</pose>
        <material>
          <ambient>0.501960784313725 0.250980392156863 0.250980392156863 1</ambient>
          <diffuse>0.501960784313725 0.250980392156863 0.250980392156863 1</diffuse>
        </material>
        <geometry>
          <mesh>
            <scale>1 1 1</scale>
            <uri>model://2016-Robot/meshes/LeftFW.STL</uri>
          </mesh>
        </geometry>
      </visual>
    </link>
    <joint name="Shooter-LeftFW" type="revolute">
      <parent>Shooter</parent>
      <child>LeftFW</child>
      <pose>1.68635929079786E-05 -0.000104762837945721 1.09908122066515E-05 0 0 0</pose>
      <axis>
        <xyz>0.0349879547749602 0.999387734075552 1.28607625788662E-15</xyz>
        <dynamics>
          <damping>1</damping>
          <friction>0.1</friction>
        </dynamics>
        <limit>
          <effort>800</effort>
        </limit>
      </axis>
    </joint>
    <link name="RightFW">
      <gravity>1</gravity>
      <self_collide>0</self_collide>
      <pose>-0.420690753824298 0.155472197994564 -0.428954153057988 0 0 0</pose>
      <must_be_base_link>0</must_be_base_link>
      <velocity_decay>
        <linear>0</linear>
        <angular>0</angular>
      </velocity_decay>
      <inertial>
        <mass>1.80417289681754</mass>
        <pose>0 0 0 0 0 0</pose>
        <inertia>
          <ixx>0.00209273157148267</ixx>
          <ixy>6.40453678387408E-05</ixy>
          <ixz>7.13508300685892E-07</ixz>
          <iyy>0.00390910359610518</iyy>
          <iyz>1.76725981146568E-07</iyz>
          <izz>0.00208953516377663</izz>
        </inertia>
      </inertial>
      <collision name="RightFW_collision">
        <pose>0.373704829632764 -0.224221174322362 0.107015813185906 0 0 0</pose>
        <geometry>
          <mesh>
            <scale>1 1 1</scale>
            <uri>model://2016-Robot/meshes/RightFW_col.STL</uri>
          </mesh>
        </geometry>
        <surface>
          <contact>
            <ode />
          </contact>
          <friction>
            <ode>
              <mu>1</mu>
              <mu2>1</mu2>
            </ode>
          </friction>
        </surface>
      </collision>
      <visual name="RightFW_visual">
        <pose>0.373704829632764 -0.224221174322362 0.107015813185906 0 0 0</pose>
        <material>
          <ambient>0.501960784313725 0.250980392156863 0.250980392156863 1</ambient>
          <diffuse>0.501960784313725 0.250980392156863 0.250980392156863 1</diffuse>
        </material>
        <geometry>
          <mesh>
            <scale>1 1 1</scale>
            <uri>model://2016-Robot/meshes/RightFW.STL</uri>
          </mesh>
        </geometry>
      </visual>
    </link>
    <joint name="Shooter-RightFW" type="revolute">
      <parent>Shooter</parent>
      <child>RightFW</child>
      <pose>1.68635929080341E-05 -0.000104762837945721 1.09908122066377E-05 0 1.28607625788662E-15 4.71238898038469</pose>
      <axis>
        <xyz>0.999387734075552 -0.0349879547749582 -7.87420668946189E-19</xyz>
        <dynamics>
          <damping>1</damping>
          <friction>0.1</friction>
        </dynamics>
        <limit>
          <effort>800</effort>
        </limit>
      </axis>
    </joint>
    <link name="Gate">
      <gravity>1</gravity>
      <self_collide>0</self_collide>
      <pose>-0.286610593775159 0.220651054337706 -0.191527913656735 0 0 0</pose>
      <must_be_base_link>0</must_be_base_link>
      <velocity_decay>
        <linear>0</linear>
        <angular>0</angular>
      </velocity_decay>
      <inertial>
        <mass>0.960186388308137</mass>
        <pose>0 0 0 0 0 0</pose>
        <inertia>
          <ixx>0.0153375222360578</ixx>
          <ixy>0.000354154457683089</ixy>
          <ixz>0.00138425122892932</ixz>
          <iyy>0.0147107285610633</iyy>
          <iyz>0.00273772453518106</iyz>
          <izz>0.00119726786805538</izz>
        </inertia>
      </inertial>
      <collision name="Gate_collision">
        <pose>0.239624669583625 -0.289400030665504 -0.130410426215347 0 0 0</pose>
        <geometry>
          <mesh>
            <scale>1 1 1</scale>
            <uri>model://2016-Robot/meshes/Gate_col.STL</uri>
          </mesh>
        </geometry>
        <surface>
          <contact>
            <ode />
          </contact>
          <friction>
            <ode>
              <mu>1</mu>
              <mu2>1</mu2>
            </ode>
          </friction>
        </surface>
      </collision>
      <visual name="Gate_visual">
        <pose>0.239624669583625 -0.289400030665504 -0.130410426215347 0 0 0</pose>
        <material>
          <ambient>0.501960784313725 0.501960784313725 0.501960784313725 1</ambient>
          <diffuse>0.501960784313725 0.501960784313725 0.501960784313725 1</diffuse>
        </material>
        <geometry>
          <mesh>
            <scale>1 1 1</scale>
            <uri>model://2016-Robot/meshes/Gate.STL</uri>
          </mesh>
        </geometry>
      </visual>
    </link>
    <joint name="Shooter-Gate" type="revolute">
      <parent>Shooter</parent>
      <child>Gate</child>
      <pose>-0.00681733039237628 -0.0604802108268497 0.0749505750930962 0 6.28318530717958 1.5707963267949</pose>
      <axis>
        <xyz>0.999387734075552 -0.0349879547749585 -4.56408536411128E-16</xyz>
        <dynamics>
          <damping>1</damping>
          <friction>1</friction>
        </dynamics>
        <limit>
          <upper>1.5</upper>
          <lower>0</lower>
          <effort>30</effort>
        </limit>
      </axis>
    </joint>
    <link name="LoaderArms">
      <gravity>1</gravity>
      <self_collide>0</self_collide>
      <pose>0.0591026573428566 0.20152698141138 -0.274634811593649 0 0 0</pose>
      <must_be_base_link>0</must_be_base_link>
      <velocity_decay>
        <linear>0</linear>
        <angular>0</angular>
      </velocity_decay>
      <inertial>
        <mass>0.732988607816135</mass>
        <pose>0 0 0 0 0 0</pose>
        <inertia>
          <ixx>0.054275929978911</ixx>
          <ixy>0.00692462269522377</ixy>
          <ixz>1.51638858197564E-07</ixz>
          <iyy>0.0927010449020016</iyy>
          <iyz>6.39550722207616E-08</iyz>
          <izz>0.0433544800914644</izz>
        </inertia>
      </inertial>
      <collision name="LoaderArms_collision">
        <pose>-0.106088581534391 -0.270275957739178 -0.0473035282784325 0 0 0</pose>
        <geometry>
          <mesh>
            <scale>1 1 1</scale>
            <uri>model://2016-Robot/meshes/LoaderArms_col.STL</uri>
          </mesh>
        </geometry>
        <surface>
          <contact>
            <ode />
          </contact>
          <friction>
            <ode>
              <mu>0</mu>
              <mu2>0</mu2>
            </ode>
          </friction>
        </surface>
      </collision>
      <visual name="LoaderArms_visual">
        <pose>-0.106088581534391 -0.270275957739178 -0.0473035282784325 0 0 0</pose>
        <material>
          <ambient>0.501960784313725 0.501960784313725 0.501960784313725 1</ambient>
          <diffuse>0.501960784313725 0.501960784313725 0.501960784313725 1</diffuse>
        </material>
        <geometry>
          <mesh>
            <scale>1 1 1</scale>
            <uri>model://2016-Robot/meshes/LoaderArms.STL</uri>
          </mesh>
        </geometry>
      </visual>
    </link>
    <joint name="TopFrame-LoaderArms" type="revolute">
      <parent>TopFrame</parent>
      <child>LoaderArms</child>
      <pose>-0.418341799065042 0.0299225876293149 0.257489811593649 0 4.71238898038469 0</pose>
      <axis>
        <xyz>1 0 -2.22044604925031E-16</xyz>
        <dynamics>
          <damping>1</damping>
          <friction>1</friction>
        </dynamics>
        <limit>
          <upper>1.5</upper>
          <lower>0</lower>
          <effort>30</effort>
        </limit>
      </axis>
    </joint>
    <link name="Roller1">
      <gravity>1</gravity>
      <self_collide>0</self_collide>
      <pose>0.224953221706018 0.234436626484345 -0.271446063862467 0 0 0</pose>
      <must_be_base_link>0</must_be_base_link>
      <velocity_decay>
        <linear>0</linear>
        <angular>0</angular>
      </velocity_decay>
      <inertial>
        <mass>0.526942367386523</mass>
        <pose>0 0 0 0 0 0</pose>
        <inertia>
          <ixx>0.0115810188691856</ixx>
          <ixy>5.59773451754265E-37</ixy>
          <ixz>1.35407327457437E-19</ixz>
          <iyy>0.0115810188691856</iyy>
          <iyz>1.6308473913801E-35</iyz>
          <izz>0.000242427168181158</izz>
        </inertia>
      </inertial>
      <collision name="Roller1_collision">
        <pose>-0.271939145897552 -0.303185602812143 -0.0504922760096153 0 0 0</pose>
        <geometry>
          <mesh>
            <scale>1 1 1</scale>
            <uri>model://2016-Robot/meshes/Roller1_col.STL</uri>
          </mesh>
        </geometry>
        <surface>
          <contact>
            <ode>
              <kp>10000</kp>
              <kd>1</kd>
            </ode>
          </contact>
          <friction>
            <ode>
              <mu>1</mu>
              <mu2>1</mu2>
            </ode>
          </friction>
        </surface>
      </collision>
      <visual name="Roller1_visual">
        <pose>-0.271939145897552 -0.303185602812143 -0.0504922760096153 0 0 0</pose>
        <material>
          <ambient>0 0.752941176470588 0.501960784313725 1</ambient>
          <diffuse>0 0.752941176470588 0.501960784313725 1</diffuse>
        </material>
        <geometry>
          <mesh>
            <scale>1 1 1</scale>
            <uri>model://2016-Robot/meshes/Roller1.STL</uri>
          </mesh>
        </geometry>
      </visual>
    </link>
    <joint name="LoaderArms-Roller1" type="revolute">
      <parent>LoaderArms</parent>
      <child>Roller1</child>
      <pose>-1.77635683940025E-15 -6.66133814775094E-16 0.291289813862465 0 1.5707963267949 0</pose>
      <axis>
        <xyz>1 0 -2.22044604925031E-16</xyz>
        <dynamics>
          <damping>0.1</damping>
          <friction>0.1</friction>
        </dynamics>
        <limit>
          <effort>30</effort>
        </limit>
      </axis>
    </joint>
    <link name="Roller2">
      <gravity>1</gravity>
      <self_collide>0</self_collide>
      <pose>0.27730434326201 0.182618138742714 -0.274629583031857 0 0 0</pose>
      <must_be_base_link>0</must_be_base_link>
      <velocity_decay>
        <linear>0</linear>
        <angular>0</angular>
      </velocity_decay>
      <inertial>
        <mass>0.579541729393841</mass>
        <pose>0 0 0 0 0 0</pose>
        <inertia>
          <ixx>0.0152694532864243</ixx>
          <ixy>6.28539831294219E-37</ixy>
          <ixz>5.54014200092236E-21</ixz>
          <iyy>0.0152694532864243</iyy>
          <iyz>2.03706348655073E-35</iyz>
          <izz>0.000270689844992958</izz>
        </inertia>
      </inertial>
      <collision name="Roller2_collision">
        <pose>-0.324290267453544 -0.251367115070511 -0.0473087568402249 0 0 0</pose>
        <geometry>
          <mesh>
            <scale>1 1 1</scale>
            <uri>model://2016-Robot/meshes/Roller2_col.STL</uri>
          </mesh>
        </geometry>
        <surface>
          <contact>
            <ode>
              <kp>10000</kp>
              <kd>1</kd>
            </ode>
          </contact>
          <friction>
            <ode>
              <mu>1</mu>
              <mu2>1</mu2>
            </ode>
          </friction>
        </surface>
      </collision>
      <visual name="Roller2_visual">
        <pose>-0.324290267453544 -0.251367115070511 -0.0473087568402249 0 0 0</pose>
        <material>
          <ambient>0 0.752941176470588 0.501960784313725 1</ambient>
          <diffuse>0 0.752941176470588 0.501960784313725 1</diffuse>
        </material>
        <geometry>
          <mesh>
            <scale>1 1 1</scale>
            <uri>model://2016-Robot/meshes/Roller2.STL</uri>
          </mesh>
        </geometry>
      </visual>
    </link>
    <joint name="LoaderArms-Roller2" type="revolute">
      <parent>LoaderArms</parent>
      <child>Roller2</child>
      <pose>0 0 0.294473333031856 0 1.5707963267949 0</pose>
      <axis>
        <xyz>1 0 -2.22044604925031E-16</xyz>
        <dynamics>
          <damping>0.1</damping>
          <friction>0.1</friction>
        </dynamics>
        <limit>
          <effort>30</effort>
        </limit>
      </axis>
    </joint>
    <link name="Roller3">
      <gravity>1</gravity>
      <self_collide>0</self_collide>
      <pose>0.326045042641728 0.13437333981085 -0.274629583031857 0 0 0</pose>
      <must_be_base_link>0</must_be_base_link>
      <velocity_decay>
        <linear>0</linear>
        <angular>0</angular>
      </velocity_decay>
      <inertial>
        <mass>0.579541729393841</mass>
        <pose>0 0 0 0 0 0</pose>
        <inertia>
          <ixx>0.0152694532864243</ixx>
          <ixy>6.28539831294219E-37</ixy>
          <ixz>5.54014200092236E-21</ixz>
          <iyy>0.0152694532864243</iyy>
          <iyz>2.03706348655073E-35</iyz>
          <izz>0.000270689844992958</izz>
        </inertia>
      </inertial>
      <collision name="Roller3_collision">
        <pose>-0.373030966833262 -0.203122316138648 -0.0473087568402249 0 0 0</pose>
        <geometry>
          <mesh>
            <scale>1 1 1</scale>
            <uri>model://2016-Robot/meshes/Roller3_col.STL</uri>
          </mesh>
        </geometry>
        <surface>
          <contact>
            <ode>
              <kp>10000</kp>
              <kd>1</kd>
            </ode>
          </contact>
          <friction>
            <ode>
              <mu>1</mu>
              <mu2>1</mu2>
            </ode>
          </friction>
        </surface>
      </collision>
      <visual name="Roller3_visual">
        <pose>-0.373030966833262 -0.203122316138648 -0.0473087568402249 0 0 0</pose>
        <material>
          <ambient>0 0.752941176470588 0.501960784313725 1</ambient>
          <diffuse>0 0.752941176470588 0.501960784313725 1</diffuse>
        </material>
        <geometry>
          <mesh>
            <scale>1 1 1</scale>
            <uri>model://2016-Robot/meshes/Roller3.STL</uri>
          </mesh>
        </geometry>
      </visual>
    </link>
    <joint name="LoaderArms-Roller3" type="revolute">
      <parent>LoaderArms</parent>
      <child>Roller3</child>
      <pose>0 0 0.294473333031856 0 1.5707963267949 0</pose>
      <axis>
        <xyz>1 0 -2.22044604925031E-16</xyz>
        <dynamics>
          <damping>0.1</damping>
          <friction>0.1</friction>
        </dynamics>
        <limit>
          <effort>30</effort>
        </limit>
      </axis>
    </joint>
    <link name="Roller4">
      <gravity>1</gravity>
      <self_collide>0</self_collide>
      <pose>0.374785742021447 0.0861285408789869 -0.274629583031857 0 0 0</pose>
      <must_be_base_link>0</must_be_base_link>
      <velocity_decay>
        <linear>0</linear>
        <angular>0</angular>
      </velocity_decay>
      <inertial>
        <mass>0.579541729393841</mass>
        <pose>0 0 0 0 0 0</pose>
        <inertia>
          <ixx>0.0152694532864243</ixx>
          <ixy>6.28539831294219E-37</ixy>
          <ixz>5.54014200092236E-21</ixz>
          <iyy>0.0152694532864243</iyy>
          <iyz>2.03706348655073E-35</iyz>
          <izz>0.000270689844992958</izz>
        </inertia>
      </inertial>
      <collision name="Roller4_collision">
        <pose>-0.421771666212981 -0.154877517206785 -0.0473087568402251 0 0 0</pose>
        <geometry>
          <mesh>
            <scale>1 1 1</scale>
            <uri>model://2016-Robot/meshes/Roller4_col.STL</uri>
          </mesh>
        </geometry>
        <surface>
          <contact>
            <ode>
              <kp>10000</kp>
              <kd>1</kd>
            </ode>
          </contact>
          <friction>
            <ode>
              <mu>1</mu>
              <mu2>1</mu2>
            </ode>
          </friction>
        </surface>
      </collision>
      <visual name="Roller4_visual">
        <pose>-0.421771666212981 -0.154877517206785 -0.0473087568402251 0 0 0</pose>
        <material>
          <ambient>0 0.752941176470588 0.501960784313725 1</ambient>
          <diffuse>0 0.752941176470588 0.501960784313725 1</diffuse>
        </material>
        <geometry>
          <mesh>
            <scale>1 1 1</scale>
            <uri>model://2016-Robot/meshes/Roller4.STL</uri>
          </mesh>
        </geometry>
      </visual>
    </link>
    <joint name="LoaderArms-Roller4" type="revolute">
      <parent>LoaderArms</parent>
      <child>Roller4</child>
      <pose>5.55111512312578E-17 2.77555756156289E-17 0.294473333031856 0 1.5707963267949 0</pose>
      <axis>
        <xyz>1 0 -2.22044604925031E-16</xyz>
        <dynamics>
          <damping>0.1</damping>
          <friction>0.1</friction>
        </dynamics>
        <limit>
          <effort>30</effort>
        </limit>
      </axis>
    </joint>
    <link name="Roller5">
      <gravity>1</gravity>
      <self_collide>0</self_collide>
      <pose>0.423526441401167 0.037883741947124 -0.274629583031857 0 0 0</pose>
      <must_be_base_link>0</must_be_base_link>
      <velocity_decay>
        <linear>0</linear>
        <angular>0</angular>
      </velocity_decay>
      <inertial>
        <mass>0.579541729393841</mass>
        <pose>0 0 0 0 0 0</pose>
        <inertia>
          <ixx>0.0152694532864243</ixx>
          <ixy>6.28539831294219E-37</ixy>
          <ixz>5.54014200092236E-21</ixz>
          <iyy>0.0152694532864243</iyy>
          <iyz>2.03706348655073E-35</iyz>
          <izz>0.000270689844992958</izz>
        </inertia>
      </inertial>
      <collision name="Roller5_collision">
        <pose>-0.470512365592701 -0.106632718274922 -0.0473087568402249 0 0 0</pose>
        <geometry>
          <mesh>
            <scale>1 1 1</scale>
            <uri>model://2016-Robot/meshes/Roller5_col.STL</uri>
          </mesh>
        </geometry>
        <surface>
          <contact>
            <ode>
              <kp>10000</kp>
              <kd>1</kd>
            </ode>
          </contact>
          <friction>
            <ode>
              <mu>1</mu>
              <mu2>1</mu2>
            </ode>
          </friction>
        </surface>
      </collision>
      <visual name="Roller5_visual">
        <pose>-0.470512365592701 -0.106632718274922 -0.0473087568402249 0 0 0</pose>
        <material>
          <ambient>0 0.752941176470588 0.501960784313725 1</ambient>
          <diffuse>0 0.752941176470588 0.501960784313725 1</diffuse>
        </material>
        <geometry>
          <mesh>
            <scale>1 1 1</scale>
            <uri>model://2016-Robot/meshes/Roller5.STL</uri>
          </mesh>
        </geometry>
      </visual>
    </link>
    <joint name="LoaderArms-Roller5" type="revolute">
      <parent>LoaderArms</parent>
      <child>Roller5</child>
      <pose>-1.99840144432528E-15 -3.19189119579733E-16 0.294473333031856 0 1.5707963267949 0</pose>
      <axis>
        <xyz>1 0 -2.22044604925031E-16</xyz>
        <dynamics>
          <damping>0.1</damping>
          <friction>0.1</friction>
        </dynamics>
        <limit>
          <effort>30</effort>
        </limit>
      </axis>
    </joint>
    <plugin name="TopFrame_rangefinder" filename="libgz_rangefinder.so">
      <topic>/gazebo/frc/simulator/analog/2</topic>
      <sensor>TopFrameUltrasonic</sensor>
    </plugin>
    <plugin name="TopFrame_gyro" filename="libgz_gyro.so">
      <link>TopFrame</link>
      <topic>/gazebo/frc/simulator/analog/3</topic>
      <units>degrees</units>
      <axis>yaw</axis>
    </plugin>
    <plugin name="LeftFrame-L1Wheel_motor" filename="libgz_dc_motor.so">
      <joint>LeftFrame-L1Wheel</joint>
      <topic>/gazebo/frc/simulator/pwm/1</topic>
      <multiplier>25</multiplier>
    </plugin>
    <plugin name="LeftFrame-L1Wheel_encoder" filename="libgz_encoder.so">
      <joint>LeftFrame-L1Wheel</joint>
      <topic>/gazebo/frc/simulator/dio/1/2</topic>
      <units>degrees</units>
    </plugin>
    <plugin name="LeftFrame-L2Wheel_motor" filename="libgz_dc_motor.so">
      <joint>LeftFrame-L2Wheel</joint>
      <topic>/gazebo/frc/simulator/pwm/1</topic>
      <multiplier>25</multiplier>
    </plugin>
    <plugin name="LeftFrame-L3Wheel_motor" filename="libgz_dc_motor.so">
      <joint>LeftFrame-L3Wheel</joint>
      <topic>/gazebo/frc/simulator/pwm/1</topic>
      <multiplier>25</multiplier>
    </plugin>
    <plugin name="LeftFrame-L4Wheel_motor" filename="libgz_dc_motor.so">
      <joint>LeftFrame-L4Wheel</joint>
      <topic>/gazebo/frc/simulator/pwm/1</topic>
      <multiplier>25</multiplier>
    </plugin>
    <plugin name="TopFrame-R1Wheel_motor" filename="libgz_dc_motor.so">
      <joint>TopFrame-R1Wheel</joint>
      <topic>/gazebo/frc/simulator/pwm/2</topic>
      <multiplier>25</multiplier>
    </plugin>
    <plugin name="TopFrame-R1Wheel_encoder" filename="libgz_encoder.so">
      <joint>TopFrame-R1Wheel</joint>
      <topic>/gazebo/frc/simulator/dio/3/4</topic>
      <units>degrees</units>
    </plugin>
    <plugin name="TopFrame-R2Wheel_motor" filename="libgz_dc_motor.so">
      <joint>TopFrame-R2Wheel</joint>
      <topic>/gazebo/frc/simulator/pwm/2</topic>
      <multiplier>25</multiplier>
    </plugin>
    <plugin name="TopFrame-R3Wheel_motor" filename="libgz_dc_motor.so">
      <joint>TopFrame-R3Wheel</joint>
      <topic>/gazebo/frc/simulator/pwm/2</topic>
      <multiplier>25</multiplier>
    </plugin>
    <plugin name="TopFrame-R4Wheel_motor" filename="libgz_dc_motor.so">
      <joint>TopFrame-R4Wheel</joint>
      <topic>/gazebo/frc/simulator/pwm/2</topic>
      <multiplier>25</multiplier>
    </plugin>
    <plugin name="TopFrame-Shooter_motor" filename="libgz_dc_motor.so">
      <joint>TopFrame-Shooter</joint>
      <topic>/gazebo/frc/simulator/pwm/9</topic>
      <multiplier>50</multiplier>
    </plugin>
    <plugin name="Shooter_rangefinder" filename="libgz_rangefinder.so">
      <topic>/gazebo/frc/simulator/analog/1</topic>
      <sensor>ShooterUltrasonic</sensor>
    </plugin>
    <plugin name="Shooter_gyro" filename="libgz_gyro.so">
      <link>Shooter</link>
      <topic>/gazebo/frc/simulator/analog/1</topic>
      <units>degrees</units>
      <axis>pitch</axis>
    </plugin>
    <plugin name="TopFrame-Shooter_intlimit" filename="libgz_limit_switch.so">
      <joint>TopFrame-Shooter</joint>
      <topic>/gazebo/frc/simulator/dio/4</topic>
      <type>internal</type>
      <units>radians</units>
      <min>0</min>
      <max>0.00349065850398866</max>
    </plugin>
    <plugin name="Shooter-PushWheel_motor" filename="libgz_dc_motor.so">
      <joint>Shooter-PushWheel</joint>
      <topic>/gazebo/frc/simulator/pwm/7</topic>
      <multiplier>50</multiplier>
    </plugin>
    <plugin name="Shooter-LeftFW_motor" filename="libgz_dc_motor.so">
      <joint>Shooter-LeftFW</joint>
      <topic>/gazebo/frc/simulator/pwm/6</topic>
      <multiplier>500</multiplier>
    </plugin>
    <plugin name="Shooter-LeftFW_encoder" filename="libgz_encoder.so">
      <joint>Shooter-LeftFW</joint>
      <topic>/gazebo/frc/simulator/dio/11/12</topic>
      <units>degrees</units>
    </plugin>
    <plugin name="Shooter-RightFW_motor" filename="libgz_dc_motor.so">
      <joint>Shooter-RightFW</joint>
      <topic>/gazebo/frc/simulator/pwm/8</topic>
      <multiplier>500</multiplier>
    </plugin>
    <plugin name="Shooter-RightFW_encoder" filename="libgz_encoder.so">
      <joint>Shooter-RightFW</joint>
      <topic>/gazebo/frc/simulator/dio/15/16</topic>
      <units>degrees</units>
    </plugin>
    <plugin name="Shooter-Gate_motor" filename="libgz_dc_motor.so">
      <joint>Shooter-Gate</joint>
      <topic>/gazebo/frc/simulator/pwm/5</topic>
      <multiplier>30</multiplier>
    </plugin>
    <plugin name="Shooter-Gate_intlimit" filename="libgz_limit_switch.so">
      <joint>Shooter-Gate</joint>
      <topic>/gazebo/frc/simulator/dio/1</topic>
      <type>internal</type>
      <units>radians</units>
      <min>0</min>
      <max>1.5</max>
    </plugin>
    <plugin name="Shooter-Gate_intlimit" filename="libgz_limit_switch.so">
      <joint>Shooter-Gate</joint>
      <topic>/gazebo/frc/simulator/dio/0</topic>
      <type>internal</type>
      <units>radians</units>
      <min>0</min>
      <max>0.3</max>
    </plugin>
    <plugin name="TopFrame-LoaderArms_motor" filename="libgz_dc_motor.so">
      <joint>TopFrame-LoaderArms</joint>
      <topic>/gazebo/frc/simulator/pwm/11</topic>
      <multiplier>40</multiplier>
    </plugin>
    <plugin name="TopFrame-LoaderArms_intlimit" filename="libgz_limit_switch.so">
      <joint>TopFrame-LoaderArms</joint>
      <topic>/gazebo/frc/simulator/dio/2</topic>
      <type>internal</type>
      <units>radians</units>
      <min>0</min>
      <max>0.2</max>
    </plugin>
    <plugin name="LoaderArms_gyro" filename="libgz_gyro.so">
      <link>LoaderArms</link>
      <topic>/gazebo/frc/simulator/analog/4</topic>
      <units>degrees</units>
      <axis>pitch</axis>
    </plugin>
    <plugin name="LoaderArms-Roller1_motor" filename="libgz_dc_motor.so">
      <joint>LoaderArms-Roller1</joint>
      <topic>/gazebo/frc/simulator/pwm/10</topic>
      <multiplier>20</multiplier>
    </plugin>
    <plugin name="LoaderArms-Roller2_motor" filename="libgz_dc_motor.so">
      <joint>LoaderArms-Roller2</joint>
      <topic>/gazebo/frc/simulator/pwm/10</topic>
      <multiplier>20</multiplier>
    </plugin>
    <plugin name="LoaderArms-Roller3_motor" filename="libgz_dc_motor.so">
      <joint>LoaderArms-Roller3</joint>
      <topic>/gazebo/frc/simulator/pwm/10</topic>
      <multiplier>20</multiplier>
    </plugin>
    <plugin name="LoaderArms-Roller4_motor" filename="libgz_dc_motor.so">
      <joint>LoaderArms-Roller4</joint>
      <topic>/gazebo/frc/simulator/pwm/10</topic>
      <multiplier>20</multiplier>
    </plugin>
    <plugin name="LoaderArms-Roller5_motor" filename="libgz_dc_motor.so">
      <joint>LoaderArms-Roller5</joint>
      <topic>/gazebo/frc/simulator/pwm/10</topic>
      <multiplier>20</multiplier>
    </plugin>
  </model>
</sdf>