<?xml version="1.0" encoding="utf-8"?>
<sdf version="1.5">
  <model name="2016-Robot">
    <pose>0 0 0.0657304309593055 0 0 0</pose>
    <plugin name="clock" filename="libclock.so">
      <topic>/gazebo/frc/time</topic>
    </plugin>
    <link name="TopFrame">
      <gravity>1</gravity>
      <self_collide>0</self_collide>
      <pose>-0.535307595952707 0.079389377388493 -0.409869768507395 0 0 0</pose>
      <must_be_base_link>1</must_be_base_link>
      <velocity_decay>
        <linear>0</linear>
        <angular>0</angular>
      </velocity_decay>
      <inertial>
        <mass>13.8297277168868</mass>
        <pose>0 0 0 0 0 0</pose>
        <inertia>
          <ixx>0.313059263324208</ixx>
          <ixy>0.0778786014409201</ixy>
          <ixz>0.0746278907399316</ixz>
          <iyy>0.983339132668531</iyy>
          <iyz>0.00643566090734072</iyz>
          <izz>0.739761318359366</izz>
        </inertia>
      </inertial>
      <collision name="TopFrame_collision">
        <pose>0.408350476250101 -0.148138353716291 -0.0309526314353708 0 0 0</pose>
        <geometry>
          <mesh>
            <scale>1 1 1</scale>
            <uri>model://2016-Robot/meshes/TopFrame_col.STL</uri>
          </mesh>
        </geometry>
        <surface>
          <contact>
            <ode />
          </contact>
          <friction>
            <ode>
              <mu>1</mu>
              <mu2>1</mu2>
            </ode>
          </friction>
        </surface>
      </collision>
      <visual name="TopFrame_visual">
        <pose>0.408350476250101 -0.148138353716291 -0.0309526314353708 0 0 0</pose>
        <material>
          <ambient>0 0 1 1</ambient>
          <diffuse>0 0 1 1</diffuse>
        </material>
        <geometry>
          <mesh>
            <scale>1 1 1</scale>
            <uri>model://2016-Robot/meshes/TopFrame.STL</uri>
          </mesh>
        </geometry>
      </visual>
      <sensor name="TopFrameUltrasonic" type="sonar">
        <always_on>1</always_on>
        <visualize>1</visualize>
        <pose>0.378133715562307 0.0939945064287015 -0.0839425713687923 2.86033440532693 0 3.14159265358979</pose>
        <sonar>
          <min>0.05</min>
          <max>7</max>
          <radius>0.05</radius>
        </sonar>
      </sensor>
    </link>
    <link name="LeftFrame">
      <gravity>1</gravity>
      <self_collide>0</self_collide>
      <pose>-0.618450351055012 0.0631432788048649 -0.127836742892201 0 0 0</pose>
      <must_be_base_link>0</must_be_base_link>
      <velocity_decay>
        <linear>0</linear>
        <angular>0</angular>
      </velocity_decay>
      <inertial>
        <mass>9.85785490756741</mass>
        <pose>0 0 0 0 0 0</pose>
        <inertia>
          <ixx>0.0471972045701552</ixx>
          <ixy>0.00766399735288121</ixy>
          <ixz>0.0465516804306947</ixz>
          <iyy>0.223821487937269</iyy>
          <iyz>0.00045431168494742</iyz>
          <izz>0.191818995212824</izz>
        </inertia>
      </inertial>
      <collision name="LeftFrame_collision">
        <pose>0.491493231352406 -0.131892255132663 -0.312985657050564 0 0 0</pose>
        <geometry>
          <mesh>
            <scale>1 1 1</scale>
            <uri>model://2016-Robot/meshes/LeftFrame_col.STL</uri>
          </mesh>
        </geometry>
        <surface>
          <contact>
            <ode />
          </contact>
          <friction>
            <ode>
              <mu>0</mu>
              <mu2>0</mu2>
            </ode>
          </friction>
        </surface>
      </collision>
      <visual name="LeftFrame_visual">
        <pose>0.491493231352406 -0.131892255132663 -0.312985657050564 0 0 0</pose>
        <material>
          <ambient>0 1 0 1</ambient>
          <diffuse>0 1 0 1</diffuse>
        </material>
        <geometry>
          <mesh>
            <scale>1 1 1</scale>
            <uri>model://2016-Robot/meshes/LeftFrame.STL</uri>
          </mesh>
        </geometry>
      </visual>
    </link>
    <joint name="TopFrame-LeftFrame" type="revolute">
      <parent>TopFrame</parent>
      <child>LeftFrame</child>
      <pose>0.239026470664604 -0.0128274597641692 0.108786742892201 0 0 0</pose>
      <axis>
        <xyz>0 1.35912835505685E-15 -1</xyz>
        <dynamics>
          <damping>1</damping>
          <friction>2</friction>
        </dynamics>
        <limit>
          <upper>0.05</upper>
          <lower>-0.05</lower>
          <effort>1</effort>
        </limit>
      </axis>
    </joint>
    <link name="L1Wheel">
      <gravity>1</gravity>
      <self_collide>0</self_collide>
      <pose>-0.683804458189783 0.0678052415230133 0.0420138912902915 0 0 0</pose>
      <must_be_base_link>0</must_be_base_link>
      <velocity_decay>
        <linear>0</linear>
        <angular>0</angular>
      </velocity_decay>
      <inertial>
        <mass>0.563089722339735</mass>
        <pose>0 0 0 0 0 0</pose>
        <inertia>
          <ixx>0.00128473699848457</ixx>
          <ixy>8.45306973208419E-08</ixy>
          <ixz>5.92558377875651E-08</ixz>
          <iyy>0.00128284435761217</iyy>
          <iyz>4.61662650870344E-07</iyz>
          <izz>0.00217022940821745</izz>
        </inertia>
      </inertial>
      <collision name="L1Wheel_collision">
        <pose>0.556847338487177 -0.136554217850812 -0.482836291233057 0 0 0</pose>
        <geometry>
          <mesh>
            <scale>1 1 1</scale>
            <uri>model://2016-Robot/meshes/L1Wheel_col.STL</uri>
          </mesh>
        </geometry>
        <surface>
          <contact>
            <ode />
          </contact>
          <friction>
            <ode>
              <mu>2</mu>
              <mu2>2</mu2>
            </ode>
          </friction>
        </surface>
      </collision>
      <visual name="L1Wheel_visual">
        <pose>0.556847338487177 -0.136554217850812 -0.482836291233057 0 0 0</pose>
        <material>
          <ambient>0.501960784313725 0.501960784313725 0.501960784313725 1</ambient>
          <diffuse>0.501960784313725 0.501960784313725 0.501960784313725 1</diffuse>
        </material>
        <geometry>
          <mesh>
            <scale>1 1 1</scale>
            <uri>model://2016-Robot/meshes/L1Wheel.STL</uri>
          </mesh>
        </geometry>
      </visual>
    </link>
    <joint name="LeftFrame-L1Wheel" type="revolute">
      <parent>LeftFrame</parent>
      <child>L1Wheel</child>
      <pose>-5.3429218892509E-06 -0.0012620286945087 -0.00280159194936069 0 4.71238898038469 0</pose>
      <axis>
        <xyz>1 3.55220947471457E-15 5.86987368327021E-16</xyz>
        <dynamics>
          <damping>1</damping>
          <friction>1</friction>
        </dynamics>
        <limit>
          <effort>40</effort>
        </limit>
      </axis>
    </joint>
    <link name="L2Wheel">
      <gravity>1</gravity>
      <self_collide>0</self_collide>
      <pose>-0.481242773451086 0.0445413810430768 0.0420138866140037 0 0 0</pose>
      <must_be_base_link>0</must_be_base_link>
      <velocity_decay>
        <linear>0</linear>
        <angular>0</angular>
      </velocity_decay>
      <inertial>
        <mass>0.563090205861153</mass>
        <pose>0 0 0 0 0 0</pose>
        <inertia>
          <ixx>0.00128356016764174</ixx>
          <ixy>9.23396482263744E-07</ixy>
          <ixz>3.42107097070309E-07</ixz>
          <iyy>0.00128402353546046</iyy>
          <iyz>3.15330251315635E-07</iyz>
          <izz>0.00217023168571162</izz>
        </inertia>
      </inertial>
      <collision name="L2Wheel_collision">
        <pose>0.35428565374848 -0.113290357370875 -0.482836286556769 0 0 0</pose>
        <geometry>
          <mesh>
            <scale>1 1 1</scale>
            <uri>model://2016-Robot/meshes/L2Wheel_col.STL</uri>
          </mesh>
        </geometry>
        <surface>
          <contact>
            <ode />
          </contact>
          <friction>
            <ode>
              <mu>2</mu>
              <mu2>2</mu2>
            </ode>
          </friction>
        </surface>
      </collision>
      <visual name="L2Wheel_visual">
        <pose>0.35428565374848 -0.113290357370875 -0.482836286556769 0 0 0</pose>
        <material>
          <ambient>0.501960784313725 0.501960784313725 0.501960784313725 1</ambient>
          <diffuse>0.501960784313725 0.501960784313725 0.501960784313725 1</diffuse>
        </material>
        <geometry>
          <mesh>
            <scale>1 1 1</scale>
            <uri>model://2016-Robot/meshes/L2Wheel.STL</uri>
          </mesh>
        </geometry>
      </visual>
    </link>
    <joint name="LeftFrame-L2Wheel" type="revolute">
      <parent>LeftFrame</parent>
      <child>L2Wheel</child>
      <pose>-0.00103245970220855 -0.0007259426803084 -0.002801587273073 0 4.71238898038469 0</pose>
      <axis>
        <xyz>1 2.43453495446626E-15 -3.63619758917495E-15</xyz>
        <dynamics>
          <damping>1</damping>
          <friction>1</friction>
        </dynamics>
        <limit>
          <effort>40</effort>
        </limit>
      </axis>
    </joint>
    <link name="L3Wheel">
      <gravity>1</gravity>
      <self_collide>0</self_collide>
      <pose>-0.278176638184261 0.0371667821828673 0.0420138866144452 0 0 0</pose>
      <must_be_base_link>0</must_be_base_link>
      <velocity_decay>
        <linear>0</linear>
        <angular>0</angular>
      </velocity_decay>
      <inertial>
        <mass>0.563090205845957</mass>
        <pose>0 0 0 0 0 0</pose>
        <inertia>
          <ixx>0.00128356016759542</ixx>
          <ixy>9.23396523954833E-07</ixy>
          <ixz>3.4210708388328E-07</ixz>
          <iyy>0.00128402353541831</iyy>
          <iyz>3.15330267068369E-07</iyz>
          <izz>0.00217023168563123</izz>
        </inertia>
      </inertial>
      <collision name="L3Wheel_collision">
        <pose>0.151219518481655 -0.105915758510666 -0.482836286557211 0 0 0</pose>
        <geometry>
          <mesh>
            <scale>1 1 1</scale>
            <uri>model://2016-Robot/meshes/L3Wheel_col.STL</uri>
          </mesh>
        </geometry>
        <surface>
          <contact>
            <ode />
          </contact>
          <friction>
            <ode>
              <mu>2</mu>
              <mu2>2</mu2>
            </ode>
          </friction>
        </surface>
      </collision>
      <visual name="L3Wheel_visual">
        <pose>0.151219518481655 -0.105915758510666 -0.482836286557211 0 0 0</pose>
        <material>
          <ambient>0.501960784313725 0.501960784313725 0.501960784313725 1</ambient>
          <diffuse>0.501960784313725 0.501960784313725 0.501960784313725 1</diffuse>
        </material>
        <geometry>
          <mesh>
            <scale>1 1 1</scale>
            <uri>model://2016-Robot/meshes/L3Wheel.STL</uri>
          </mesh>
        </geometry>
      </visual>
    </link>
    <joint name="LeftFrame-L3Wheel" type="revolute">
      <parent>LeftFrame</parent>
      <child>L3Wheel</child>
      <pose>-0.0010324597035187 -0.000725942678857977 -0.00280158727351448 0 4.71238898038469 0</pose>
      <axis>
        <xyz>1 2.43483933929782E-15 -3.8166088306764E-15</xyz>
        <dynamics>
          <damping>1</damping>
          <friction>1</friction>
        </dynamics>
        <limit>
          <effort>40</effort>
        </limit>
      </axis>
    </joint>
    <link name="L4Wheel">
      <gravity>1</gravity>
      <self_collide>0</self_collide>
      <pose>-0.0746705021316634 0.0456315417934892 0.0420138872494832 0 0 0</pose>
      <must_be_base_link>0</must_be_base_link>
      <velocity_decay>
        <linear>0</linear>
        <angular>0</angular>
      </velocity_decay>
      <inertial>
        <mass>0.563090139948893</mass>
        <pose>0 0 0 0 0 0</pose>
        <inertia>
          <ixx>0.0012832668928907</ixx>
          <ixy>7.94197569313527E-07</ixy>
          <ixz>4.26488835306683E-07</ixz>
          <iyy>0.00128431676319942</iyy>
          <iyz>1.85963542209426E-07</iyz>
          <izz>0.00217023164813031</izz>
        </inertia>
      </inertial>
      <collision name="L4Wheel_collision">
        <pose>-0.0522866175709424 -0.114380518121287 -0.482836287192249 0 0 0</pose>
        <geometry>
          <mesh>
            <scale>1 1 1</scale>
            <uri>model://2016-Robot/meshes/L4Wheel_col.STL</uri>
          </mesh>
        </geometry>
        <surface>
          <contact>
            <ode />
          </contact>
          <friction>
            <ode>
              <mu>2</mu>
              <mu2>2</mu2>
            </ode>
          </friction>
        </surface>
      </collision>
      <visual name="L4Wheel_visual">
        <pose>-0.0522866175709424 -0.114380518121287 -0.482836287192249 0 0 0</pose>
        <material>
          <ambient>0.501960784313725 0.501960784313725 0.501960784313725 1</ambient>
          <diffuse>0.501960784313725 0.501960784313725 0.501960784313725 1</diffuse>
        </material>
        <geometry>
          <mesh>
            <scale>1 1 1</scale>
            <uri>model://2016-Robot/meshes/L4Wheel.STL</uri>
          </mesh>
        </geometry>
      </visual>
    </link>
    <joint name="LeftFrame-L4Wheel" type="revolute">
      <parent>LeftFrame</parent>
      <child>L4Wheel</child>
      <pose>0.00108055233672433 -0.000652200909676395 -0.00280158790855251 0 4.71238898038469 0</pose>
      <axis>
        <xyz>1 1.36238167480024E-16 3.96748462011841E-15</xyz>
        <dynamics>
          <damping>1</damping>
          <friction>1</friction>
        </dynamics>
        <limit>
          <effort>40</effort>
        </limit>
      </axis>
    </joint>
    <link name="R1Wheel">
      <gravity>1</gravity>
      <self_collide>0</self_collide>
      <pose>-0.674628433756941 0.0558288492220785 -0.58493888661413 0 0 0</pose>
      <must_be_base_link>0</must_be_base_link>
      <velocity_decay>
        <linear>0</linear>
        <angular>0</angular>
      </velocity_decay>
      <inertial>
        <mass>0.563090205855883</mass>
        <pose>0 0 0 0 0 0</pose>
        <inertia>
          <ixx>0.00128320297787333</ixx>
          <ixy>7.48041643814086E-07</ixy>
          <ixz>4.00451867668724E-07</ixz>
          <iyy>0.00128438072523264</iyy>
          <iyz>2.36872825130441E-07</iyz>
          <izz>0.00217023168571774</izz>
        </inertia>
      </inertial>
      <collision name="R1Wheel_collision">
        <pose>0.547671314054335 -0.124577825549877 0.144116486671365 0 0 0</pose>
        <geometry>
          <mesh>
            <scale>1 1 1</scale>
            <uri>model://2016-Robot/meshes/R1Wheel_col.STL</uri>
          </mesh>
        </geometry>
        <surface>
          <contact>
            <ode />
          </contact>
          <friction>
            <ode>
              <mu>2</mu>
              <mu2>2</mu2>
            </ode>
          </friction>
        </surface>
      </collision>
      <visual name="R1Wheel_visual">
        <pose>0.547671314054335 -0.124577825549877 0.144116486671365 0 0 0</pose>
        <material>
          <ambient>0.501960784313725 0.501960784313725 0.501960784313725 1</ambient>
          <diffuse>0.501960784313725 0.501960784313725 0.501960784313725 1</diffuse>
        </material>
        <geometry>
          <mesh>
            <scale>1 1 1</scale>
            <uri>model://2016-Robot/meshes/R1Wheel.STL</uri>
          </mesh>
        </geometry>
      </visual>
    </link>
    <joint name="TopFrame-R1Wheel" type="revolute">
      <parent>TopFrame</parent>
      <child>R1Wheel</child>
      <pose>-0.00116137209352363 0.000494146406825449 0.00280158727319843 0 4.71238898038469 0</pose>
      <axis>
        <xyz>1 3.00445054017627E-15 3.78565018088647E-15</xyz>
        <dynamics>
          <damping>1</damping>
          <friction>1</friction>
        </dynamics>
        <limit>
          <effort>40</effort>
        </limit>
      </axis>
    </joint>
    <link name="R2Wheel">
      <gravity>1</gravity>
      <self_collide>0</self_collide>
      <pose>-0.471503565015896 0.0399146424688076 -0.584938891290733 0 0 0</pose>
      <must_be_base_link>0</must_be_base_link>
      <velocity_decay>
        <linear>0</linear>
        <angular>0</angular>
      </velocity_decay>
      <inertial>
        <mass>0.563089722324542</mass>
        <pose>0 0 0 0 0 0</pose>
        <inertia>
          <ixx>0.00128473733920885</ixx>
          <ixy>8.06253560326491E-08</ixy>
          <ixz>1.89055806391865E-08</ixz>
          <iyy>0.00128284401679942</iyy>
          <iyz>4.65065842064345E-07</iyz>
          <izz>0.00217022940813704</izz>
        </inertia>
      </inertial>
      <collision name="R2Wheel_collision">
        <pose>0.34454644531329 -0.108663618796606 0.144116491347968 0 0 0</pose>
        <geometry>
          <mesh>
            <scale>1 1 1</scale>
            <uri>model://2016-Robot/meshes/R2Wheel_col.STL</uri>
          </mesh>
        </geometry>
        <surface>
          <contact>
            <ode />
          </contact>
          <friction>
            <ode>
              <mu>2</mu>
              <mu2>2</mu2>
            </ode>
          </friction>
        </surface>
      </collision>
      <visual name="R2Wheel_visual">
        <pose>0.34454644531329 -0.108663618796606 0.144116491347968 0 0 0</pose>
        <material>
          <ambient>0.501960784313725 0.501960784313725 0.501960784313725 1</ambient>
          <diffuse>0.501960784313725 0.501960784313725 0.501960784313725 1</diffuse>
        </material>
        <geometry>
          <mesh>
            <scale>1 1 1</scale>
            <uri>model://2016-Robot/meshes/R2Wheel.STL</uri>
          </mesh>
        </geometry>
      </visual>
    </link>
    <joint name="TopFrame-R2Wheel" type="revolute">
      <parent>TopFrame</parent>
      <child>R2Wheel</child>
      <pose>-0.000115013626851346 0.00125678830310155 0.00280159194980167 0 4.71238898038469 0</pose>
      <axis>
        <xyz>1 3.64692314456558E-15 -7.1037221242052E-16</xyz>
        <dynamics>
          <damping>1</damping>
          <friction>1</friction>
        </dynamics>
        <limit>
          <effort>40</effort>
        </limit>
      </axis>
    </joint>
    <link name="R3Wheel">
      <gravity>1</gravity>
      <self_collide>0</self_collide>
      <pose>-0.268298933750979 0.0399145094705027 -0.584938891290291 0 0 0</pose>
      <must_be_base_link>0</must_be_base_link>
      <velocity_decay>
        <linear>0</linear>
        <angular>0</angular>
      </velocity_decay>
      <inertial>
        <mass>0.563089722339745</mass>
        <pose>0 0 0 0 0 0</pose>
        <inertia>
          <ixx>0.00128472234969803</ixx>
          <ixy>1.86160532932712E-07</ixy>
          <ixz>7.21304634287442E-09</ixz>
          <iyy>0.00128285900639873</iyy>
          <iyz>4.65394058277787E-07</iyz>
          <izz>0.00217022940821746</izz>
        </inertia>
      </inertial>
      <collision name="R3Wheel_collision">
        <pose>0.141341814048373 -0.108663485798301 0.144116491347526 0 0 0</pose>
        <geometry>
          <mesh>
            <scale>1 1 1</scale>
            <uri>model://2016-Robot/meshes/R3Wheel_col.STL</uri>
          </mesh>
        </geometry>
        <surface>
          <contact>
            <ode />
          </contact>
          <friction>
            <ode>
              <mu>2</mu>
              <mu2>2</mu2>
            </ode>
          </friction>
        </surface>
      </collision>
      <visual name="R3Wheel_visual">
        <pose>0.141341814048373 -0.108663485798301 0.144116491347526 0 0 0</pose>
        <material>
          <ambient>0.501960784313725 0.501960784313725 0.501960784313725 1</ambient>
          <diffuse>0.501960784313725 0.501960784313725 0.501960784313725 1</diffuse>
        </material>
        <geometry>
          <mesh>
            <scale>1 1 1</scale>
            <uri>model://2016-Robot/meshes/R3Wheel.STL</uri>
          </mesh>
        </geometry>
      </visual>
    </link>
    <joint name="TopFrame-R3Wheel" type="revolute">
      <parent>TopFrame</parent>
      <child>R3Wheel</child>
      <pose>-0.000185334670375542 0.00124835733367243 0.00280159194936069 0 4.71238898038469 0</pose>
      <axis>
        <xyz>1 3.6805931371173E-15 -6.99260972436613E-16</xyz>
        <dynamics>
          <damping>1</damping>
          <friction>1</friction>
        </dynamics>
        <limit>
          <effort>40</effort>
        </limit>
      </axis>
    </joint>
    <link name="R4Wheel">
      <gravity>1</gravity>
      <self_collide>0</self_collide>
      <pose>-0.0650989337490238 0.0557895094705538 -0.584938891290732 0 0 0</pose>
      <must_be_base_link>0</must_be_base_link>
      <velocity_decay>
        <linear>0</linear>
        <angular>0</angular>
      </velocity_decay>
      <inertial>
        <mass>0.563089722324528</mass>
        <pose>0 0 0 0 0 0</pose>
        <inertia>
          <ixx>0.00128472234969552</ixx>
          <ixy>1.86160532931666E-07</ixy>
          <ixz>7.21302584728866E-09</ixz>
          <iyy>0.00128285900631276</iyy>
          <iyz>4.65394059577841E-07</iyz>
          <izz>0.00217022940813704</izz>
        </inertia>
      </inertial>
      <collision name="R4Wheel_collision">
        <pose>-0.0618581859535821 -0.124538485798352 0.144116491347967 0 0 0</pose>
        <geometry>
          <mesh>
            <scale>1 1 1</scale>
            <uri>model://2016-Robot/meshes/R4Wheel_col.STL</uri>
          </mesh>
        </geometry>
        <surface>
          <contact>
            <ode />
          </contact>
          <friction>
            <ode>
              <mu>2</mu>
              <mu2>2</mu2>
            </ode>
          </friction>
        </surface>
      </collision>
      <visual name="R4Wheel_visual">
        <pose>-0.0618581859535821 -0.124538485798352 0.144116491347967 0 0 0</pose>
        <material>
          <ambient>0.501960784313725 0.501960784313725 0.501960784313725 1</ambient>
          <diffuse>0.501960784313725 0.501960784313725 0.501960784313725 1</diffuse>
        </material>
        <geometry>
          <mesh>
            <scale>1 1 1</scale>
            <uri>model://2016-Robot/meshes/R4Wheel.STL</uri>
          </mesh>
        </geometry>
      </visual>
    </link>
    <joint name="TopFrame-R4Wheel" type="revolute">
      <parent>TopFrame</parent>
      <child>R4Wheel</child>
      <pose>-0.000185334672336945 0.00124835733362035 0.00280159194980142 0 4.71238898038469 0</pose>
      <axis>
        <xyz>1 3.68823085207016E-15 -6.02116457768805E-16</xyz>
        <dynamics>
          <damping>1</damping>
          <friction>1</friction>
        </dynamics>
        <limit>
          <effort>40</effort>
        </limit>
      </axis>
    </joint>
    <link name="Shooter">
      <gravity>1</gravity>
      <self_collide>0</self_collide>
      <pose>-0.340310489398496 0.103954571323554 -0.307805095817558 0 0 0</pose>
      <must_be_base_link>0</must_be_base_link>
      <velocity_decay>
        <linear>0</linear>
        <angular>0</angular>
      </velocity_decay>
      <inertial>
        <mass>6.64740199501403</mass>
        <pose>0 0 0 0 0 0</pose>
        <inertia>
          <ixx>0.171657472750375</ixx>
          <ixy>0.00116501609502727</ixy>
          <ixz>0.0375602019526637</ixz>
          <iyy>0.206253740580983</iyy>
          <iyz>0.00368474642058147</iyz>
          <izz>0.0699035155040497</izz>
        </inertia>
      </inertial>
      <collision name="Shooter_collision">
        <pose>0.21335336969589 -0.172703547651352 -0.133017304125207 0 0 0</pose>
        <geometry>
          <mesh>
            <scale>1 1 1</scale>
            <uri>model://2016-Robot/meshes/Shooter_col.STL</uri>
          </mesh>
        </geometry>
        <surface>
          <contact>
            <ode />
          </contact>
          <friction>
            <ode>
              <mu>0.2</mu>
              <mu2>0.2</mu2>
            </ode>
          </friction>
        </surface>
      </collision>
      <visual name="Shooter_visual">
        <pose>0.21335336969589 -0.172703547651352 -0.133017304125207 0 0 0</pose>
        <material>
          <ambient>0 0.501960784313725 0.501960784313725 1</ambient>
          <diffuse>0 0.501960784313725 0.501960784313725 1</diffuse>
        </material>
        <geometry>
          <mesh>
            <scale>1 1 1</scale>
            <uri>model://2016-Robot/meshes/Shooter.STL</uri>
          </mesh>
        </geometry>
      </visual>
      <sensor name="ShooterCamera" type="camera">
        <visualize>1</visualize>
        <always_on>1</always_on>
        <pose>-0.124206581565228 0.103144755538481 -0.122064904182656 1.5707963267949 0 3.14159265358979</pose>
        <camera name="Shootercamera">
          <horizontal_fov>1.02974425867665</horizontal_fov>
          <image>
            <width>320</width>
            <height>240</height>
          </image>
          <clip>
            <near>0.1</near>
            <far>100</far>
          </clip>
        </camera>
      </sensor>
      <sensor name="ShooterUltrasonic" type="sonar">
        <always_on>1</always_on>
        <visualize>1</visualize>
        <pose>-0.124206581565228 0.103144755538481 -0.122064904182656 1.57079632679492 0 1.53580122962653</pose>
        <sonar>
          <min>1</min>
          <max>10</max>
          <radius>0.01</radius>
        </sonar>
      </sensor>
    </link>
    <joint name="TopFrame-Shooter" type="revolute">
      <parent>TopFrame</parent>
      <child>Shooter</child>
      <pose>0.127841609008088 0.0482549977171403 -0.218839904182442 0 0 0</pose>
      <axis>
        <xyz>0 0 -1</xyz>
        <dynamics>
          <damping>1</damping>
          <friction>1</friction>
        </dynamics>
        <limit>
          <upper>1.3</upper>
          <lower>-0.05</lower>
          <effort>30</effort>
        </limit>
      </axis>
    </joint>
    <link name="PushWheel">
      <gravity>1</gravity>
      <self_collide>0</self_collide>
      <pose>-0.212547427327181 0.15089881648459 -0.428965755137175 0 0 0</pose>
      <must_be_base_link>0</must_be_base_link>
      <velocity_decay>
        <linear>0</linear>
        <angular>0</angular>
      </velocity_decay>
      <inertial>
        <mass>0.596238102075934</mass>
        <pose>0 0 0 0 0 0</pose>
        <inertia>
          <ixx>0.000669967858234903</ixx>
          <ixy>2.05740863147868E-05</ixy>
          <ixz>4.46928575378656E-07</ixz>
          <iyy>0.00125126089988878</iyy>
          <iyz>1.21436128952592E-07</iyz>
          <izz>0.000668907774058868</izz>
        </inertia>
      </inertial>
      <collision name="PushWheel_collision">
        <pose>0.0855903076245748 -0.219647792812388 -0.0118566448055908 0 0 0</pose>
        <geometry>
          <mesh>
            <scale>1 1 1</scale>
            <uri>model://2016-Robot/meshes/PushWheel_col.STL</uri>
          </mesh>
        </geometry>
        <surface>
          <contact>
            <ode />
          </contact>
          <friction>
            <ode>
              <mu>2</mu>
              <mu2>2</mu2>
            </ode>
          </friction>
        </surface>
      </collision>
      <visual name="PushWheel_visual">
        <pose>0.0855903076245748 -0.219647792812388 -0.0118566448055908 0 0 0</pose>
        <material>
          <ambient>0.501960784313725 0.501960784313725 0.501960784313725 1</ambient>
          <diffuse>0.501960784313725 0.501960784313725 0.501960784313725 1</diffuse>
        </material>
        <geometry>
          <mesh>
            <scale>1 1 1</scale>
            <uri>model://2016-Robot/meshes/PushWheel.STL</uri>
          </mesh>
        </geometry>
      </visual>
    </link>
    <joint name="Shooter-PushWheel" type="revolute">
      <parent>Shooter</parent>
      <child>PushWheel</child>
      <pose>2.91246608820905E-05 -0.000100933738261588 2.2592891345723E-05 0 1.28607625788662E-15 4.71238898038469</pose>
      <axis>
        <xyz>0.999387734075552 -0.0349879547749582 -7.87420668946189E-19</xyz>
        <dynamics>
          <damping>1</damping>
          <friction>1</friction>
        </dynamics>
        <limit>
          <effort>50</effort>
        </limit>
      </axis>
    </joint>
    <link name="LeftFW">
      <gravity>1</gravity>
      <self_collide>0</self_collide>
      <pose>-0.415610753823349 0.158012197994547 -0.11145415305803 0 0 0</pose>
      <must_be_base_link>0</must_be_base_link>
      <velocity_decay>
        <linear>0</linear>
        <angular>0</angular>
      </velocity_decay>
      <inertial>
        <mass>1.80417289681754</mass>
        <pose>0 0 0 0 0 0</pose>
        <inertia>
          <ixx>0.00209273157148267</ixx>
          <ixy>6.40453678387408E-05</ixy>
          <ixz>7.13508300685869E-07</ixz>
          <iyy>0.00390910359610518</iyy>
          <iyz>1.76725981146519E-07</iyz>
          <izz>0.00208953516377663</izz>
        </inertia>
      </inertial>
      <collision name="LeftFW_collision">
        <pose>0.288653634120743 -0.226761174322345 -0.329368246884736 0 0 0</pose>
        <geometry>
          <mesh>
            <scale>1 1 1</scale>
            <uri>model://2016-Robot/meshes/LeftFW_col.STL</uri>
          </mesh>
        </geometry>
        <surface>
          <contact>
            <ode />
          </contact>
          <friction>
            <ode>
              <mu>1</mu>
              <mu2>1</mu2>
            </ode>
          </friction>
        </surface>
      </collision>
      <visual name="LeftFW_visual">
        <pose>0.288653634120743 -0.226761174322345 -0.329368246884736 0 0 0</pose>
        <material>
          <ambient>0.501960784313725 0.250980392156863 0.250980392156863 1</ambient>
          <diffuse>0.501960784313725 0.250980392156863 0.250980392156863 1</diffuse>
        </material>
        <geometry>
          <mesh>
            <scale>1 1 1</scale>
            <uri>model://2016-Robot/meshes/LeftFW.STL</uri>
          </mesh>
        </geometry>
      </visual>
    </link>
    <joint name="Shooter-LeftFW" type="revolute">
      <parent>Shooter</parent>
      <child>LeftFW</child>
      <pose>1.68635929080896E-05 -0.000104762837945721 1.09908122065683E-05 0 0 0</pose>
      <axis>
        <xyz>0.0349879547749602 0.999387734075552 1.28607625788662E-15</xyz>
        <dynamics>
          <damping>0.1</damping>
          <friction>0.1</friction>
        </dynamics>
        <limit>
          <effort>800</effort>
        </limit>
      </axis>
    </joint>
    <link name="RightFW">
      <gravity>1</gravity>
      <self_collide>0</self_collide>
      <pose>-0.415610753824298 0.158012197994564 -0.428954153057988 0 0 0</pose>
      <must_be_base_link>0</must_be_base_link>
      <velocity_decay>
        <linear>0</linear>
        <angular>0</angular>
      </velocity_decay>
      <inertial>
        <mass>1.80417289681754</mass>
        <pose>0 0 0 0 0 0</pose>
        <inertia>
          <ixx>0.00209273157148267</ixx>
          <ixy>6.40453678387408E-05</ixy>
          <ixz>7.13508300685666E-07</ixz>
          <iyy>0.00390910359610518</iyy>
          <iyz>1.76725981146582E-07</iyz>
          <izz>0.00208953516377663</izz>
        </inertia>
      </inertial>
      <collision name="RightFW_collision">
        <pose>0.288653634121692 -0.226761174322362 -0.0118682468847776 0 0 0</pose>
        <geometry>
          <mesh>
            <scale>1 1 1</scale>
            <uri>model://2016-Robot/meshes/RightFW_col.STL</uri>
          </mesh>
        </geometry>
        <surface>
          <contact>
            <ode />
          </contact>
          <friction>
            <ode>
              <mu>1</mu>
              <mu2>1</mu2>
            </ode>
          </friction>
        </surface>
      </collision>
      <visual name="RightFW_visual">
        <pose>0.288653634121692 -0.226761174322362 -0.0118682468847776 0 0 0</pose>
        <material>
          <ambient>0.501960784313725 0.250980392156863 0.250980392156863 1</ambient>
          <diffuse>0.501960784313725 0.250980392156863 0.250980392156863 1</diffuse>
        </material>
        <geometry>
          <mesh>
            <scale>1 1 1</scale>
            <uri>model://2016-Robot/meshes/RightFW.STL</uri>
          </mesh>
        </geometry>
      </visual>
    </link>
    <joint name="Shooter-RightFW" type="revolute">
      <parent>Shooter</parent>
      <child>RightFW</child>
      <pose>1.68635929080341E-05 -0.000104762837945693 1.0990812206662E-05 0 1.28607625788662E-15 4.71238898038469</pose>
      <axis>
        <xyz>0.999387734075552 -0.0349879547749582 -7.87420668946189E-19</xyz>
        <dynamics>
          <damping>0.1</damping>
          <friction>0.1</friction>
        </dynamics>
        <limit>
          <effort>800</effort>
        </limit>
      </axis>
    </joint>
    <link name="Gate">
      <gravity>1</gravity>
      <self_collide>0</self_collide>
      <pose>-0.281727026435127 0.208590914273208 -0.196709340406911 0 0 0</pose>
      <must_be_base_link>0</must_be_base_link>
      <velocity_decay>
        <linear>0</linear>
        <angular>0</angular>
      </velocity_decay>
      <inertial>
        <mass>0.97357481216971</mass>
        <pose>0 0 0 0 0 0</pose>
        <inertia>
          <ixx>0.0153460471952248</ixx>
          <ixy>0.000252255606287957</ixy>
          <ixz>0.00153103111576089</ixz>
          <iyy>0.015246859354429</iyy>
          <iyz>0.00179956604756092</iyz>
          <izz>0.000731699374220779</izz>
        </inertia>
      </inertial>
      <collision name="Gate_collision">
        <pose>0.154769906732521 -0.277339890601006 -0.244113059535854 0 0 0</pose>
        <geometry>
          <mesh>
            <scale>1 1 1</scale>
            <uri>model://2016-Robot/meshes/Gate_col.STL</uri>
          </mesh>
        </geometry>
        <surface>
          <contact>
            <ode />
          </contact>
          <friction>
            <ode>
              <mu>2</mu>
              <mu2>2</mu2>
            </ode>
          </friction>
        </surface>
      </collision>
      <visual name="Gate_visual">
        <pose>0.154769906732521 -0.277339890601006 -0.244113059535854 0 0 0</pose>
        <material>
          <ambient>0.501960784313725 0.501960784313725 0.501960784313725 1</ambient>
          <diffuse>0.501960784313725 0.501960784313725 0.501960784313725 1</diffuse>
        </material>
        <geometry>
          <mesh>
            <scale>1 1 1</scale>
            <uri>model://2016-Robot/meshes/Gate.STL</uri>
          </mesh>
        </geometry>
      </visual>
    </link>
    <joint name="Shooter-Gate" type="revolute">
      <parent>Shooter</parent>
      <child>Gate</child>
      <pose>-0.00662089773240832 -0.0458800707623518 0.080132001843273 0 6.28318530717958 1.5707963267949</pose>
      <axis>
        <xyz>0.999387734075552 -0.0349879547749585 -4.56408536411128E-16</xyz>
        <dynamics>
          <damping>1</damping>
          <friction>1</friction>
        </dynamics>
        <limit>
          <upper>1.5</upper>
          <lower>0</lower>
          <effort>30</effort>
        </limit>
      </axis>
    </joint>
    <link name="LoaderArms">
      <gravity>1</gravity>
      <self_collide>0</self_collide>
      <pose>-0.0429843103419675 0.202130957451525 -0.280170450049733 0 0 0</pose>
      <must_be_base_link>0</must_be_base_link>
      <velocity_decay>
        <linear>0</linear>
        <angular>0</angular>
      </velocity_decay>
      <inertial>
        <mass>0.746692318962654</mass>
        <pose>0 0 0 0 0 0</pose>
        <inertia>
          <ixx>0.0555146703517775</ixx>
          <ixy>0.00685119939707641</ixy>
          <ixz>0.00067279696469742</ixz>
          <iyy>0.0943016791438931</iyy>
          <iyz>0.000133468901931659</iyz>
          <izz>0.0437458172633139</izz>
        </inertia>
      </inertial>
      <collision name="LoaderArms_collision">
        <pose>-0.0839728093606384 -0.270879933779324 -0.160651949893032 0 0 0</pose>
        <geometry>
          <mesh>
            <scale>1 1 1</scale>
            <uri>model://2016-Robot/meshes/LoaderArms_col.STL</uri>
          </mesh>
        </geometry>
        <surface>
          <contact>
            <ode />
          </contact>
          <friction>
            <ode>
              <mu>0</mu>
              <mu2>0</mu2>
            </ode>
          </friction>
        </surface>
      </collision>
      <visual name="LoaderArms_visual">
        <pose>-0.0839728093606384 -0.270879933779324 -0.160651949893032 0 0 0</pose>
        <material>
          <ambient>0.501960784313725 0.501960784313725 0.501960784313725 1</ambient>
          <diffuse>0.501960784313725 0.501960784313725 0.501960784313725 1</diffuse>
        </material>
        <geometry>
          <mesh>
            <scale>1 1 1</scale>
            <uri>model://2016-Robot/meshes/LoaderArms.STL</uri>
          </mesh>
        </geometry>
      </visual>
      <sensor name="LoaderArmsCamera" type="camera">
        <visualize>1</visualize>
        <always_on>1</always_on>
        <pose>0.20090678291553 0.0323056690328187 -0.296092049950268 4.71238898038469 0 0</pose>
        <camera name="LoaderArmscamera">
          <horizontal_fov>1.5707963267949</horizontal_fov>
          <image>
            <width>320</width>
            <height>240</height>
          </image>
          <clip>
            <near>0.1</near>
            <far>100</far>
          </clip>
        </camera>
      </sensor>
    </link>
    <joint name="TopFrame-LoaderArms" type="revolute">
      <parent>TopFrame</parent>
      <child>LoaderArms</child>
      <pose>-0.42138558051267 0.029318611589169 0.263025450049734 0 4.71238898038469 0</pose>
      <axis>
        <xyz>1 0 -2.22044604925031E-16</xyz>
        <dynamics>
          <damping>1</damping>
          <friction>1</friction>
        </dynamics>
        <limit>
          <upper>1.5</upper>
          <lower>0</lower>
          <effort>30</effort>
        </limit>
      </axis>
    </joint>
    <link name="Roller1">
      <gravity>1</gravity>
      <self_collide>0</self_collide>
      <pose>0.119822472573566 0.234436626484345 -0.271446063862466 0 0 0</pose>
      <must_be_base_link>0</must_be_base_link>
      <velocity_decay>
        <linear>0</linear>
        <angular>0</angular>
      </velocity_decay>
      <inertial>
        <mass>0.526942367386523</mass>
        <pose>0 0 0 0 0 0</pose>
        <inertia>
          <ixx>0.0115810188691856</ixx>
          <ixy>5.59773451754265E-37</ixy>
          <ixz>1.06935116022663E-19</ixz>
          <iyy>0.0115810188691856</iyy>
          <iyz>1.6308473913801E-35</iyz>
          <izz>0.000242427168181158</izz>
        </inertia>
      </inertial>
      <collision name="Roller1_collision">
        <pose>-0.246779592276172 -0.303185602812143 -0.1693763360803 0 0 0</pose>
        <geometry>
          <mesh>
            <scale>1 1 1</scale>
            <uri>model://2016-Robot/meshes/Roller1_col.STL</uri>
          </mesh>
        </geometry>
        <surface>
          <contact>
            <ode />
          </contact>
          <friction>
            <ode>
              <mu>2</mu>
              <mu2>2</mu2>
            </ode>
          </friction>
        </surface>
      </collision>
      <visual name="Roller1_visual">
        <pose>-0.246779592276172 -0.303185602812143 -0.1693763360803 0 0 0</pose>
        <material>
          <ambient>0 0.752941176470588 0.501960784313725 1</ambient>
          <diffuse>0 0.752941176470588 0.501960784313725 1</diffuse>
        </material>
        <geometry>
          <mesh>
            <scale>1 1 1</scale>
            <uri>model://2016-Robot/meshes/Roller1.STL</uri>
          </mesh>
        </geometry>
      </visual>
    </link>
    <joint name="LoaderArms-Roller1" type="revolute">
      <parent>LoaderArms</parent>
      <child>Roller1</child>
      <pose>-1.74860126378462E-15 -6.66133814775094E-16 0.291289813862465 0 1.5707963267949 0</pose>
      <axis>
        <xyz>1 0 -2.22044604925031E-16</xyz>
        <dynamics>
          <damping>0.2</damping>
          <friction>0.1</friction>
        </dynamics>
        <limit>
          <effort>30</effort>
        </limit>
      </axis>
    </joint>
    <link name="Roller2">
      <gravity>1</gravity>
      <self_collide>0</self_collide>
      <pose>0.172173594129558 0.182618138742713 -0.274628604566859 0 0 0</pose>
      <must_be_base_link>0</must_be_base_link>
      <velocity_decay>
        <linear>0</linear>
        <angular>0</angular>
      </velocity_decay>
      <inertial>
        <mass>0.413222659607486</mass>
        <pose>0 0 0 0 0 0</pose>
        <inertia>
          <ixx>0.0111057709709175</ixx>
          <ixy>1.08290434100624E-36</ixy>
          <ixz>5.75067345272411E-21</ixz>
          <iyy>0.0111057709709175</iyy>
          <iyz>2.28507392286953E-35</iyz>
          <izz>0.000211202145687561</izz>
        </inertia>
      </inertial>
      <collision name="Roller2_collision">
        <pose>-0.299130713832164 -0.251367115070511 -0.166193795375906 0 0 0</pose>
        <geometry>
          <mesh>
            <scale>1 1 1</scale>
            <uri>model://2016-Robot/meshes/Roller2_col.STL</uri>
          </mesh>
        </geometry>
        <surface>
          <contact>
            <ode />
          </contact>
          <friction>
            <ode>
              <mu>2</mu>
              <mu2>2</mu2>
            </ode>
          </friction>
        </surface>
      </collision>
      <visual name="Roller2_visual">
        <pose>-0.299130713832164 -0.251367115070511 -0.166193795375906 0 0 0</pose>
        <material>
          <ambient>0 0.752941176470588 0.501960784313725 1</ambient>
          <diffuse>0 0.752941176470588 0.501960784313725 1</diffuse>
        </material>
        <geometry>
          <mesh>
            <scale>1 1 1</scale>
            <uri>model://2016-Robot/meshes/Roller2.STL</uri>
          </mesh>
        </geometry>
      </visual>
    </link>
    <joint name="LoaderArms-Roller2" type="revolute">
      <parent>LoaderArms</parent>
      <child>Roller2</child>
      <pose>-5.55111512312578E-17 0 0.294472354566859 0 1.5707963267949 0</pose>
      <axis>
        <xyz>1 0 -2.22044604925031E-16</xyz>
        <dynamics>
          <damping>0.2</damping>
          <friction>0.1</friction>
        </dynamics>
        <limit>
          <effort>30</effort>
        </limit>
      </axis>
    </joint>
    <link name="Roller3">
      <gravity>1</gravity>
      <self_collide>0</self_collide>
      <pose>0.220914293509276 0.13437333981085 -0.274628604566859 0 0 0</pose>
      <must_be_base_link>0</must_be_base_link>
      <velocity_decay>
        <linear>0</linear>
        <angular>0</angular>
      </velocity_decay>
      <inertial>
        <mass>0.413222659607486</mass>
        <pose>0 0 0 0 0 0</pose>
        <inertia>
          <ixx>0.0111057709709175</ixx>
          <ixy>1.08290434100624E-36</ixy>
          <ixz>5.7506734527241E-21</ixz>
          <iyy>0.0111057709709175</iyy>
          <iyz>2.28507392286953E-35</iyz>
          <izz>0.000211202145687561</izz>
        </inertia>
      </inertial>
      <collision name="Roller3_collision">
        <pose>-0.347871413211882 -0.203122316138648 -0.166193795375906 0 0 0</pose>
        <geometry>
          <mesh>
            <scale>1 1 1</scale>
            <uri>model://2016-Robot/meshes/Roller3_col.STL</uri>
          </mesh>
        </geometry>
        <surface>
          <contact>
            <ode />
          </contact>
          <friction>
            <ode>
              <mu>2</mu>
              <mu2>2</mu2>
            </ode>
          </friction>
        </surface>
      </collision>
      <visual name="Roller3_visual">
        <pose>-0.347871413211882 -0.203122316138648 -0.166193795375906 0 0 0</pose>
        <material>
          <ambient>0 0.752941176470588 0.501960784313725 1</ambient>
          <diffuse>0 0.752941176470588 0.501960784313725 1</diffuse>
        </material>
        <geometry>
          <mesh>
            <scale>1 1 1</scale>
            <uri>model://2016-Robot/meshes/Roller3.STL</uri>
          </mesh>
        </geometry>
      </visual>
    </link>
    <joint name="LoaderArms-Roller3" type="revolute">
      <parent>LoaderArms</parent>
      <child>Roller3</child>
      <pose>-5.55111512312578E-17 0 0.294472354566859 0 1.5707963267949 0</pose>
      <axis>
        <xyz>1 0 -2.22044604925031E-16</xyz>
        <dynamics>
          <damping>0.2</damping>
          <friction>0.1</friction>
        </dynamics>
        <limit>
          <effort>30</effort>
        </limit>
      </axis>
    </joint>
    <link name="Roller4">
      <gravity>1</gravity>
      <self_collide>0</self_collide>
      <pose>0.269654992888995 0.0861285408789866 -0.274628604566859 0 0 0</pose>
      <must_be_base_link>0</must_be_base_link>
      <velocity_decay>
        <linear>0</linear>
        <angular>0</angular>
      </velocity_decay>
      <inertial>
        <mass>0.413222659607486</mass>
        <pose>0 0 0 0 0 0</pose>
        <inertia>
          <ixx>0.0111057709709175</ixx>
          <ixy>1.08290434100624E-36</ixy>
          <ixz>5.7506734527241E-21</ixz>
          <iyy>0.0111057709709175</iyy>
          <iyz>2.28507392286953E-35</iyz>
          <izz>0.000211202145687561</izz>
        </inertia>
      </inertial>
      <collision name="Roller4_collision">
        <pose>-0.396612112591601 -0.154877517206785 -0.166193795375906 0 0 0</pose>
        <geometry>
          <mesh>
            <scale>1 1 1</scale>
            <uri>model://2016-Robot/meshes/Roller4_col.STL</uri>
          </mesh>
        </geometry>
        <surface>
          <contact>
            <ode />
          </contact>
          <friction>
            <ode>
              <mu>2</mu>
              <mu2>2</mu2>
            </ode>
          </friction>
        </surface>
      </collision>
      <visual name="Roller4_visual">
        <pose>-0.396612112591601 -0.154877517206785 -0.166193795375906 0 0 0</pose>
        <material>
          <ambient>0 0.752941176470588 0.501960784313725 1</ambient>
          <diffuse>0 0.752941176470588 0.501960784313725 1</diffuse>
        </material>
        <geometry>
          <mesh>
            <scale>1 1 1</scale>
            <uri>model://2016-Robot/meshes/Roller4.STL</uri>
          </mesh>
        </geometry>
      </visual>
    </link>
    <joint name="LoaderArms-Roller4" type="revolute">
      <parent>LoaderArms</parent>
      <child>Roller4</child>
      <pose>5.55111512312578E-17 0 0.294472354566859 0 1.5707963267949 0</pose>
      <axis>
        <xyz>1 0 -2.22044604925031E-16</xyz>
        <dynamics>
          <damping>0.2</damping>
          <friction>0.1</friction>
        </dynamics>
        <limit>
          <effort>30</effort>
        </limit>
      </axis>
    </joint>
    <link name="Roller5">
      <gravity>1</gravity>
      <self_collide>0</self_collide>
      <pose>0.318395692268715 0.0378837419471236 -0.274628604566859 0 0 0</pose>
      <must_be_base_link>0</must_be_base_link>
      <velocity_decay>
        <linear>0</linear>
        <angular>0</angular>
      </velocity_decay>
      <inertial>
        <mass>0.413222659607486</mass>
        <pose>0 0 0 0 0 0</pose>
        <inertia>
          <ixx>0.0111057709709175</ixx>
          <ixy>1.08290434100624E-36</ixy>
          <ixz>5.7506734527241E-21</ixz>
          <iyy>0.0111057709709175</iyy>
          <iyz>2.28507392286953E-35</iyz>
          <izz>0.000211202145687561</izz>
        </inertia>
      </inertial>
      <collision name="Roller5_collision">
        <pose>-0.445352811971321 -0.106632718274922 -0.166193795375906 0 0 0</pose>
        <geometry>
          <mesh>
            <scale>1 1 1</scale>
            <uri>model://2016-Robot/meshes/Roller5_col.STL</uri>
          </mesh>
        </geometry>
        <surface>
          <contact>
            <ode />
          </contact>
          <friction>
            <ode>
              <mu>2</mu>
              <mu2>2</mu2>
            </ode>
          </friction>
        </surface>
      </collision>
      <visual name="Roller5_visual">
        <pose>-0.445352811971321 -0.106632718274922 -0.166193795375906 0 0 0</pose>
        <material>
          <ambient>0 0.752941176470588 0.501960784313725 1</ambient>
          <diffuse>0 0.752941176470588 0.501960784313725 1</diffuse>
        </material>
        <geometry>
          <mesh>
            <scale>1 1 1</scale>
            <uri>model://2016-Robot/meshes/Roller5.STL</uri>
          </mesh>
        </geometry>
      </visual>
    </link>
    <joint name="LoaderArms-Roller5" type="revolute">
      <parent>LoaderArms</parent>
      <child>Roller5</child>
      <pose>-1.99840144432528E-15 -3.33066907387547E-16 0.294472354566859 0 1.5707963267949 0</pose>
      <axis>
        <xyz>1 0 -2.22044604925031E-16</xyz>
        <dynamics>
          <damping>0.2</damping>
          <friction>0.1</friction>
        </dynamics>
        <limit>
          <effort>30</effort>
        </limit>
      </axis>
    </joint>
    <plugin name="TopFrame_rangefinder" filename="librangefinder.so">
      <topic>/gazebo/frc/simulator/analog/2</topic>
      <sensor>TopFrameUltrasonic</sensor>
    </plugin>
    <plugin name="TopFrame_gyro" filename="libgyro.so">
      <link>TopFrame</link>
      <topic>/gazebo/frc/simulator/analog/3</topic>
      <units>degrees</units>
      <axis>yaw</axis>
    </plugin>
    <plugin name="LeftFrame-L1Wheel_motor" filename="libdc_motor.so">
      <joint>LeftFrame-L1Wheel</joint>
      <topic>/gazebo/frc/simulator/pwm/1</topic>
      <multiplier>35</multiplier>
    </plugin>
    <plugin name="LeftFrame-L1Wheel_encoder" filename="libencoder.so">
      <joint>LeftFrame-L1Wheel</joint>
      <topic>/gazebo/frc/simulator/dio/1/2</topic>
      <units>degrees</units>
    </plugin>
    <plugin name="LeftFrame-L2Wheel_motor" filename="libdc_motor.so">
      <joint>LeftFrame-L2Wheel</joint>
      <topic>/gazebo/frc/simulator/pwm/1</topic>
      <multiplier>35</multiplier>
    </plugin>
    <plugin name="LeftFrame-L3Wheel_motor" filename="libdc_motor.so">
      <joint>LeftFrame-L3Wheel</joint>
      <topic>/gazebo/frc/simulator/pwm/1</topic>
      <multiplier>35</multiplier>
    </plugin>
    <plugin name="LeftFrame-L4Wheel_motor" filename="libdc_motor.so">
      <joint>LeftFrame-L4Wheel</joint>
      <topic>/gazebo/frc/simulator/pwm/1</topic>
      <multiplier>35</multiplier>
    </plugin>
    <plugin name="TopFrame-R1Wheel_motor" filename="libdc_motor.so">
      <joint>TopFrame-R1Wheel</joint>
      <topic>/gazebo/frc/simulator/pwm/2</topic>
      <multiplier>35</multiplier>
    </plugin>
    <plugin name="TopFrame-R1Wheel_encoder" filename="libencoder.so">
      <joint>TopFrame-R1Wheel</joint>
      <topic>/gazebo/frc/simulator/dio/3/4</topic>
      <units>degrees</units>
    </plugin>
    <plugin name="TopFrame-R2Wheel_motor" filename="libdc_motor.so">
      <joint>TopFrame-R2Wheel</joint>
      <topic>/gazebo/frc/simulator/pwm/2</topic>
      <multiplier>35</multiplier>
    </plugin>
    <plugin name="TopFrame-R3Wheel_motor" filename="libdc_motor.so">
      <joint>TopFrame-R3Wheel</joint>
      <topic>/gazebo/frc/simulator/pwm/2</topic>
      <multiplier>35</multiplier>
    </plugin>
    <plugin name="TopFrame-R4Wheel_motor" filename="libdc_motor.so">
      <joint>TopFrame-R4Wheel</joint>
      <topic>/gazebo/frc/simulator/pwm/2</topic>
      <multiplier>35</multiplier>
    </plugin>
    <plugin name="TopFrame-Shooter_motor" filename="libdc_motor.so">
      <joint>TopFrame-Shooter</joint>
      <topic>/gazebo/frc/simulator/pwm/9</topic>
      <multiplier>50</multiplier>
    </plugin>
    <plugin name="Shooter_rangefinder" filename="librangefinder.so">
      <topic>/gazebo/frc/simulator/analog/1</topic>
      <sensor>ShooterUltrasonic</sensor>
    </plugin>
    <plugin name="Shooter_gyro" filename="libgyro.so">
      <link>Shooter</link>
      <topic>/gazebo/frc/simulator/analog/1</topic>
      <units>degrees</units>
      <axis>pitch</axis>
    </plugin>
    <plugin name="TopFrame-Shooter_intlimit" filename="liblimit_switch.so">
      <joint>TopFrame-Shooter</joint>
      <topic>/gazebo/frc/simulator/dio/17</topic>
      <type>internal</type>
      <units>radians</units>
      <min>-0.05</min>
      <max>0.05</max>
    </plugin>
    <plugin name="Shooter-PushWheel_motor" filename="libdc_motor.so">
      <joint>Shooter-PushWheel</joint>
      <topic>/gazebo/frc/simulator/pwm/7</topic>
      <multiplier>50</multiplier>
    </plugin>
    <plugin name="Shooter-LeftFW_motor" filename="libdc_motor.so">
      <joint>Shooter-LeftFW</joint>
      <topic>/gazebo/frc/simulator/pwm/6</topic>
      <multiplier>500</multiplier>
    </plugin>
    <plugin name="Shooter-LeftFW_encoder" filename="libencoder.so">
      <joint>Shooter-LeftFW</joint>
      <topic>/gazebo/frc/simulator/dio/11/12</topic>
      <units>degrees</units>
    </plugin>
    <plugin name="Shooter-RightFW_motor" filename="libdc_motor.so">
      <joint>Shooter-RightFW</joint>
      <topic>/gazebo/frc/simulator/pwm/8</topic>
      <multiplier>500</multiplier>
    </plugin>
    <plugin name="Shooter-RightFW_encoder" filename="libencoder.so">
      <joint>Shooter-RightFW</joint>
      <topic>/gazebo/frc/simulator/dio/15/16</topic>
      <units>degrees</units>
    </plugin>
    <plugin name="Shooter-Gate_motor" filename="libdc_motor.so">
      <joint>Shooter-Gate</joint>
      <topic>/gazebo/frc/simulator/pwm/5</topic>
      <multiplier>30</multiplier>
    </plugin>
    <plugin name="Shooter-Gate_intlimit" filename="liblimit_switch.so">
      <joint>Shooter-Gate</joint>
      <topic>/gazebo/frc/simulator/dio/10</topic>
      <type>internal</type>
      <units>radians</units>
      <min>0.9</min>
      <max>1.5</max>
    </plugin>
    <plugin name="Shooter-Gate_intlimit" filename="liblimit_switch.so">
      <joint>Shooter-Gate</joint>
      <topic>/gazebo/frc/simulator/dio/9</topic>
      <type>internal</type>
      <units>radians</units>
      <min>0</min>
      <max>0.3</max>
    </plugin>
    <plugin name="Shooter-Gate_encoder" filename="libencoder.so">
      <joint>Shooter-Gate</joint>
      <topic>/gazebo/frc/simulator/dio/9/10</topic>
      <units>degrees</units>
    </plugin>
    <plugin name="TopFrame-LoaderArms_motor" filename="libdc_motor.so">
      <joint>TopFrame-LoaderArms</joint>
      <topic>/gazebo/frc/simulator/pwm/11</topic>
      <multiplier>40</multiplier>
    </plugin>
    <plugin name="TopFrame-LoaderArms_intlimit" filename="liblimit_switch.so">
      <joint>TopFrame-LoaderArms</joint>
      <topic>/gazebo/frc/simulator/dio/21</topic>
      <type>internal</type>
      <units>radians</units>
      <min>0</min>
      <max>0.2</max>
    </plugin>
    <plugin name="LoaderArms_gyro" filename="libgyro.so">
      <link>LoaderArms</link>
      <topic>/gazebo/frc/simulator/analog/4</topic>
      <units>degrees</units>
      <axis>pitch</axis>
    </plugin>
    <plugin name="LoaderArms-Roller1_motor" filename="libdc_motor.so">
      <joint>LoaderArms-Roller1</joint>
      <topic>/gazebo/frc/simulator/pwm/10</topic>
      <multiplier>20</multiplier>
    </plugin>
    <plugin name="LoaderArms-Roller2_motor" filename="libdc_motor.so">
      <joint>LoaderArms-Roller2</joint>
      <topic>/gazebo/frc/simulator/pwm/10</topic>
      <multiplier>20</multiplier>
    </plugin>
    <plugin name="LoaderArms-Roller3_motor" filename="libdc_motor.so">
      <joint>LoaderArms-Roller3</joint>
      <topic>/gazebo/frc/simulator/pwm/10</topic>
      <multiplier>20</multiplier>
    </plugin>
    <plugin name="LoaderArms-Roller4_motor" filename="libdc_motor.so">
      <joint>LoaderArms-Roller4</joint>
      <topic>/gazebo/frc/simulator/pwm/10</topic>
      <multiplier>20</multiplier>
    </plugin>
    <plugin name="LoaderArms-Roller5_motor" filename="libdc_motor.so">
      <joint>LoaderArms-Roller5</joint>
      <topic>/gazebo/frc/simulator/pwm/10</topic>
      <multiplier>20</multiplier>
    </plugin>
  </model>
</sdf>
